Workbook

Sheet Processed_Ratios
A1: DILUTED EPS | B1: 2025 | C1: 2024 | D1: 2023 | E1: 2022 | F1: 2021 | G1: 2020 | H1: 2019 | I1: 2018 | J1: 2017 | K1: 2016 | L1: 2015 | M1: 2014
A2: Adani Ports and Special Economic Zone Ltd | B2: 51.35 | C2: 37.55 | D2: 24.58 | E2: 22.39 | F2: 24.58 | G2: 18.35 | H2: 19.27 | I2: 17.74 | J2: 18.89 | K2: 13.99 | L2: 11.18 | M2: 8.45
A3: Asian Paints Ltd | B3: 38.25 | C3: 56.94 | D3: 42.82 | E3: 31.59 | F3: 32.73 | G3: 28.2 | H3: 22.48 | I3: 21.26 | J3: 20.22 | K3: 18.19 | L3: 14.54 | M3: 12.71
A4: AXIS Bank Ltd | B4: 90.18 | C4: 85.01 | D4: 35.04 | E4: 45.91 | F4: 24.19 | G4: 6.8 | H4: 19.49 | I4: 2.1015 | J4: 16.48 | K4: 34.93 | L4: 31.23 | M4: 134.2
A5: Bajaj Finserv Ltd | B5: 9.7 | C5: 7.3 | D5: 4.6 | E5: 26.6 | F5: 11.2 | G5: 41.9 | H5: 19.3 | I5: 8.9 | J5: 4.4 | K5: 10.3 | L5: 7.9 | M5: 5.2
A6: Bajaj Finance Ltd | B6: 187.439 | C6: 187.439 | D6: 187.439 | E6: 115.79 | F6: 73 | G6: 89.07 | H6: 68.75 | I6: 47.05 | J6: 33.67 | K6: 187.439 | L6: 177.7 | M6: 143.65
A7: Bharat Electronics Ltd | B7: 7.28 | C7: 5.45 | D7: 4.09 | E7: 9.85 | F7: 8.62 | G7: 7.49 | H7: 7.74 | I7: 5.83 | J7: 5.94 | K7: 5.57 | L7: 149.65 | M7: 118.91
A8: Bharti Airtel Ltd | B8: 56.04 | C8: 12.8 | D8: 14.57 | E8: 7.63 | F8: 2.1015 | G8: 2.1015 | H8: 2.1015 | I8: 2.75 | J8: 9.51 | K8: 15.2 | L8: 11.56 | M8: 7.01
A9: HCL Technologies Ltd | B9: 64.09 | C9: 57.86 | D9: 54.79 | E9: 49.77 | F9: 41.07 | G9: 40.75 | H9: 73.55 | I9: 62.19 | J9: 60.27 | K9: 39.69 | L9: 51.79 | M9: 91.93
A10: HDFC Bank Ltd | B10: 92.39 | C10: 90.01 | D10: 82.27 | E10: 68.31 | F10: 57.61 | G10: 49.46 | H10: 82.51 | I10: 70.76 | J10: 59.16 | K10: 50.24 | L10: 43.6 | M10: 36.31
A11: Hindustan Unilever Ltd | B11: 45.32 | C11: 43.74 | D11: 43.07 | E11: 37.79 | F11: 34.03 | G11: 31.17 | H11: 27.96 | I11: 24.08 | J11: 20.67 | K11: 19.09 | L11: 20.16 | M11: 18.23
A12: ICICI Bank Ltd | B12: 71.14 | C12: 61.96 | D12: 47.84 | E12: 35.44 | F12: 26.83 | G12: 14.55 | H12: 6.53 | I12: 11.89 | J12: 15.84 | K12: 17.41 | L12: 21.17 | M12: 95.65
... A30: UltraTech Cement Ltd | B30: 187.439 | C30: 187.439 | D30: 175.54 | E30: 187.439 | F30: 187.439 | G30: 187.439 | H30: 84 | I30: 80.92 | J30: 98.88 | K30: 90.25 | L30: 76.44 | M30: 80.42
A32: Max | B32: =MAX(E2:M30) -> 187.439
A34: PAYOUT RATIO | B34: (PR)2025 | C34: (PR)2024 | D34: (PR)2023 | E34: (PR)2022 | F34: (PR)2021 | G34: (PR)2020 | H34: (PR)2019 | I34: (PR)2018 | J34: (PR)2017 | K34: (PR)2016 | L34: (PR)2015 | M34: (PR)2014
A35: Adani Ports and Special Economic Zone Ltd | B35: 11.68 | C35: 13.31 | D35: 19.88 | E35: 21.59 | F35: 0 | G35: 18.37 | H35: 10.38 | I35: 7.32 | J35: 0 | K35: 15.72 | L35: 9.83 | M35: 12.28
A36: Asian Paints Ltd | B36: 84.74 | C36: 46.37 | D36: 46.48 | E36: 57.44 | F36: 10.23 | G36: 64.35 | H36: 39.59 | I36: 48.45 | J36: 39.31 | K36: 35.72 | L36: 41.93 | M36: 41.71
A37: AXIS Bank Ltd | B37: 1.19 | C37: 1.25 | D37: 3.25 | E37: 1.24 | F37: 1.52 | G37: 1.25 | H37: 2.33 | I37: 1.39 | J37: 1.53 | K37: 1.09 | L37: 1.005 | M37: 1.32
A38: Bajaj Finserv Ltd | B38: 1.79 | C38: 1.56 | D38: 0.99 | E38: 1.04 | F38: 0 | G38: 3.54 | H38: 0.86 | I38: 1.05 | J38: 0 | K38: 1.49 | L38: 1.64 | M38: 1.8
A39: Bajaj Finance Ltd | B39: 13.38 | C39: 12.56 | D39: 10.49 | E39: 8.57 | F39: 0 | G39: 18.04 | H39: 5.78 | I39: 7.4 | J39: 0 | K39: 10.99 | L39: 10.05 | M39: 11.15
A40: Bharat Electronics Ltd | B40: 31.59 | C40: 36.69 | D40: 41.63 | E40: 42.65 | F40: 48.75 | G40: 41.41 | H40: 27.12 | I40: 43.83 | J40: 40.43 | K40: 18.36 | L40: 19.51 | M40: 19.59
A41: Bharti Airtel Ltd | B41: 13.79 | C41: 30.47 | D41: 20.34 | E41: 0 | F41: 0 | G41: 0 | H41: 87.981 | I41: 87.981 | J41: 17.21 | K41: 17.57 | L41: 33.3 | M41: 0
A42: HCL Technologies Ltd | B42: 87.981 | C42: 87.981 | D42: 87.5 | E42: 84.38 | F42: 29.22 | G42: 12.27 | H42: 10.85 | I42: 19.4 | J42: 39.34 | K42: 48.15 | L42: 32.6 | M42: 10.75
A43: HDFC Bank Ltd | B43: 25.05 | C43: 24.38 | D43: 24.07 | E43: 23.28 | F43: 11.54 | G43: 0 | H43: 18.63 | I43: 19.32 | J43: 20.84 | K43: 20.67 | L43: 0 | M43: 0
A44: Hindustan Unilever Ltd | B44: 87.981 | C44: 87.981 | D44: 83.58 | E44: 84.68 | F44: 87.981 | G44: 77 | H44: 75.09 | I44: 74.72 | J44: 79.78 | K44: 81.03 | L44: 74.38 | M44: 71.25
A45: ICICI Bank Ltd | B45: 15.4 | C45: 15.9 | D45: 16.4 | E45: 13.8 | F45: 7.5 | G45: 0 | H45: 15 | I45: 12 | J45: 14 | K45: 29 | L45: 24 | M45: 24
A46: Infosys Ltd | B46: 75.97 | C46: 56 | D46: 56.57 | E46: 57.23 | F46: 47.12 | G46: 57.35 | H46: 87.981 | I46: 46.59 | J46: 48.43 | K46: 50.51 | L46: 41.14 | M46: 33.83
... A63: UltraTech Cement Ltd | B63: 33.4 | C63: 15.63 | D63: 21.57 | E63: 14.52 | F63: 6.86 | G63: 6.61 | H63: 14.46 | I63: 14.86 | J63: 9.6 | K63: 11.83 | L63: 11.77 | M63: 11.18
A65: Max | B65: =MAX(E35:M63) -> 87.981
A67: PROFIT MARGIN | B67: (PM)2025 | C67: (PM)2024 | D67: (PM)2023 | E67: (PM)2022 | F67: (PM)2021 | G67: (PM)2020 | H67: (PM)2019 | I67: (PM)2018 | J67: (PM)2017 | K67: (PM)2016 | L67: (PM)2015 | M67: (PM)2014
A68: Adani Ports and Special Economic Zone Ltd | B68: 31.9425 | C68: 30.94 | D68: 25.63 | E68: 28.88 | F68: 31.9425 | G68: 31.91 | H68: 31.9425 | I68: 31.9425 | J68: 31.9425 | K68: 31.9425 | L68: 31.9425 | M68: 31.9425
A69: Asian Paints Ltd | B69: 10.52 | C69: 15.28 | D69: 11.89 | E69: 10.49 | F69: 14.63 | G69: 13.47 | H69: 11.26 | I69: 12.19 | J69: 13.05 | K69: 12.39 | L69: 10.06 | M69: 9.93
A70: AXIS Bank Ltd | B70: 22.07 | C70: 23.43 | D70: 12.41 | E70: 20.57 | F70: 11.2 | G70: 2.94 | H70: 9 | I70: 0.99 | J70: 8.78 | K70: 20.18 | L70: 20.84 | M70: 20.52
A71: Bajaj Finserv Ltd | B71: 13.1 | C71: 14.12 | D71: 14.87 | E71: 12.15 | F71: 12.15 | G71: 11.02 | H71: 12.61 | I71: 12.7 | J71: 14.07 | K71: 29.37 | L71: 31.75 | M71: 31.9425
A72: Bajaj Finance Ltd | B72: 24.05 | C72: 26.27 | D72: 27.79 | E72: 22.21 | F72: 16.57 | G72: 19.95 | H72: 21.6 | I72: 19.89 | J72: 18.42 | K72: 17.5 | L72: 16.68 | M72: 17.65
A73: Bharat Electronics Ltd | B73: 22.24 | C73: 19.45 | D73: 16.57 | E73: 15.32 | F73: 14.66 | G73: 13.82 | H73: 15.19 | I73: 13.53 | J73: 17.27 | K73: 17.72 | L73: 16.87 | M73: 14.6
A74: Bharti Airtel Ltd | B74: 19.52 | C74: 3.89 | D74: 8.29 | E74: 5.04 | F74: 0.667 | G74: 0.667 | H74: 1.64 | I74: 1.33 | J74: 3.34 | K74: 6.03 | L74: 5.25 | M74: 3.51
A75: HCL Technologies Ltd | B75: 14.86 | C75: 14.29 | D75: 14.63 | E75: 15.78 | F75: 14.81 | G75: 15.64 | H75: 16.74 | I75: 17.22 | J75: 18.08 | K75: 17.97 | L75: 19.89 | M75: 20.24
A76: HDFC Bank Ltd | B76: 22.41 | C76: 23.53 | D76: 27.29 | E76: 28.93 | F76: 25.74 | G76: 22.86 | H76: 21.29 | I76: 21.79 | J76: 20.99 | K76: 20.41 | L76: 21.07 | M76: 20.61
A77: Hindustan Unilever Ltd | B77: 16.91 | C77: 16.61 | D77: 16.74 | E77: 16.95 | F77: 17 | G77: 16.98 | H77: 15.41 | I77: 14.7 | J77: 13.53 | K77: 12.92 | L77: 13.68 | M77: 13.53
...

Sheet Fuzzy_Inputs_10
A1: DILUTED EPS | B1: 2025 | C1: 2024 | D1: 2023 | E1: 2022 | F1: 2021 | G1: 2020 | H1: 2019 | I1: 2018 | J1: 2017 | K1: 2016 | L1: 2015 | M1: 2014
A2: Adani Ports and Special Economic Zone Ltd | B2: =(Processed_Ratios!B2 / Processed_Ratios!$B$32) * 10 -> 2.7395579 | C2: =(Processed_Ratios!C2 / Processed_Ratios!$B$32) * 10 -> 2.0033184 | D2: =(Processed_Ratios!D2 / Processed_Ratios!$B$32) * 10 -> 1.31136 | E2: =(Processed_Ratios!E2 / Processed_Ratios!$B$32) * 10 -> 1.194522 | F2: =(Processed_Ratios!F2 / Processed_Ratios!$B$32) * 10 -> 1.31136 | G2: =(Processed_Ratios!G2 / Processed_Ratios!$B$32) * 10 -> 0.97898516 | H2: =(Processed_Ratios!H2 / Processed_Ratios!$B$32) * 10 -> 1.0280678 | I2: =(Processed_Ratios!I2 / Processed_Ratios!$B$32) * 10 -> 0.94644124 | ... M2: =(Processed_Ratios!M2 / Processed_Ratios!$B$32) * 10 -> 0.45081333
A3: Asian Paints Ltd | B3: =(Processed_Ratios!B3 / Processed_Ratios!$B$32) * 10 -> 2.0406639 | C3: =(Processed_Ratios!C3 / Processed_Ratios!$B$32) * 10 -> 3.0377883 | D3: =(Processed_Ratios!D3 / Processed_Ratios!$B$32) * 10 -> 2.2844765 | E3: =(Processed_Ratios!E3 / Processed_Ratios!$B$32) * 10 -> 1.6853483 | F3: =(Processed_Ratios!F3 / Processed_Ratios!$B$32) * 10 -> 1.7461681 | G3: =(Processed_Ratios!G3 / Processed_Ratios!$B$32) * 10 -> 1.5044895 | H3: =(Processed_Ratios!H3 / Processed_Ratios!$B$32) * 10 -> 1.1993235 | I3: =(Processed_Ratios!I3 / Processed_Ratios!$B$32) * 10 -> 1.1342357 | ... M3: =(Processed_Ratios!M3 / Processed_Ratios!$B$32) * 10 -> 0.67808727
A4: AXIS Bank Ltd | B4: =(Processed_Ratios!B4 / Processed_Ratios!$B$32) * 10 -> 4.8111652 | C4: =(Processed_Ratios!C4 / Processed_Ratios!$B$32) * 10 -> 4.5353422 | D4: =(Processed_Ratios!D4 / Processed_Ratios!$B$32) * 10 -> 1.8694082 | E4: =(Processed_Ratios!E4 / Processed_Ratios!$B$32) * 10 -> 2.4493302 | F4: =(Processed_Ratios!F4 / Processed_Ratios!$B$32) * 10 -> 1.2905532 | G4: =(Processed_Ratios!G4 / Processed_Ratios!$B$32) * 10 -> 0.36278469 | H4: =(Processed_Ratios!H4 / Processed_Ratios!$B$32) * 10 -> 1.0398049 | I4: =(Processed_Ratios!I4 / Processed_Ratios!$B$32) * 10 -> 0.11211648 | ... M4: =(Processed_Ratios!M4 / Processed_Ratios!$B$32) * 10 -> 7.1596626
A5: Bajaj Finserv Ltd | B5: =(Processed_Ratios!B5 / Processed_Ratios!$B$32) * 10 -> 0.51750169 | C5: =(Processed_Ratios!C5 / Processed_Ratios!$B$32) * 10 -> 0.38946004 | D5: =(Processed_Ratios!D5 / Processed_Ratios!$B$32) * 10 -> 0.24541317 | E5: =(Processed_Ratios!E5 / Processed_Ratios!$B$32) * 10 -> 1.4191284 | F5: =(Processed_Ratios!F5 / Processed_Ratios!$B$32) * 10 -> 0.59752773 | G5: =(Processed_Ratios!G5 / Processed_Ratios!$B$32) * 10 -> 2.2353939 | H5: =(Processed_Ratios!H5 / Processed_Ratios!$B$32) * 10 -> 1.0296683 | I5: =(Processed_Ratios!I5 / Processed_Ratios!$B$32) * 10 -> 0.47482114 | ... M5: =(Processed_Ratios!M5 / Processed_Ratios!$B$32) * 10 -> 0.27742359
A6: Bajaj Finance Ltd | B6: =(Processed_Ratios!B6 / Processed_Ratios!$B$32) * 10 -> 10 | C6: =(Processed_Ratios!C6 / Processed_Ratios!$B$32) * 10 -> 10 | D6: =(Processed_Ratios!D6 / Processed_Ratios!$B$32) * 10 -> 10 | E6: =(Processed_Ratios!E6 / Processed_Ratios!$B$32) * 10 -> 6.1774764 | F6: =(Processed_Ratios!F6 / Processed_Ratios!$B$32) * 10 -> 3.8946004 | G6: =(Processed_Ratios!G6 / Processed_Ratios!$B$32) * 10 -> 4.751946 | H6: =(Processed_Ratios!H6 / Processed_Ratios!$B$32) * 10 -> 3.6678599 | I6: =(Processed_Ratios!I6 / Processed_Ratios!$B$32) * 10 -> 2.51015 | ... M6: =(Processed_Ratios!M6 / Processed_Ratios!$B$32) * 10 -> 7.6638266
A7: Bharat Electronics Ltd | B7: =(Processed_Ratios!B7 / Processed_Ratios!$B$32) * 10 -> 0.38839302 | C7: =(Processed_Ratios!C7 / Processed_Ratios!$B$32) * 10 -> 0.29076126 | D7: =(Processed_Ratios!D7 / Processed_Ratios!$B$32) * 10 -> 0.21820432 | E7: =(Processed_Ratios!E7 / Processed_Ratios!$B$32) * 10 -> 0.5255043 | F7: =(Processed_Ratios!F7 / Processed_Ratios!$B$32) * 10 -> 0.45988295 | G7: =(Processed_Ratios!G7 / Processed_Ratios!$B$32) * 10 -> 0.39959667 | H7: =(Processed_Ratios!H7 / Processed_Ratios!$B$32) * 10 -> 0.41293434 | I7: =(Processed_Ratios!I7 / Processed_Ratios!$B$32) * 10 -> 0.31103452 | ... M7: =(Processed_Ratios!M7 / Processed_Ratios!$B$32) * 10 -> 6.3439306
A8: Bharti Airtel Ltd | B8: =(Processed_Ratios!B8 / Processed_Ratios!$B$32) * 10 -> 2.9897727 | C8: =(Processed_Ratios!C8 / Processed_Ratios!$B$32) * 10 -> 0.68288883 | D8: =(Processed_Ratios!D8 / Processed_Ratios!$B$32) * 10 -> 0.77731955 | E8: =(Processed_Ratios!E8 / Processed_Ratios!$B$32) * 10 -> 0.40706577 | F8: =(Processed_Ratios!F8 / Processed_Ratios!$B$32) * 10 -> 0.11211648 | G8: =(Processed_Ratios!G8 / Processed_Ratios!$B$32) * 10 -> 0.11211648 | H8: =(Processed_Ratios!H8 / Processed_Ratios!$B$32) * 10 -> 0.11211648 | I8: =(Processed_Ratios!I8 / Processed_Ratios!$B$32) * 10 -> 0.1467144 | ... M8: =(Processed_Ratios!M8 / Processed_Ratios!$B$32) * 10 -> 0.37398834
A9: HCL Technologies Ltd | B9: =(Processed_Ratios!B9 / Processed_Ratios!$B$32) * 10 -> 3.4192457 | C9: =(Processed_Ratios!C9 / Processed_Ratios!$B$32) * 10 -> 3.0868709 | D9: =(Processed_Ratios!D9 / Processed_Ratios!$B$32) * 10 -> 2.9230843 | E9: =(Processed_Ratios!E9 / Processed_Ratios!$B$32) * 10 -> 2.6552638 | F9: =(Processed_Ratios!F9 / Processed_Ratios!$B$32) * 10 -> 2.1911128 | G9: =(Processed_Ratios!G9 / Processed_Ratios!$B$32) * 10 -> 2.1740406 | H9: =(Processed_Ratios!H9 / Processed_Ratios!$B$32) * 10 -> 3.9239433 | I9: =(Processed_Ratios!I9 / Processed_Ratios!$B$32) * 10 -> 3.3178794 | ... M9: =(Processed_Ratios!M9 / Processed_Ratios!$B$32) * 10 -> 4.9045289
A10: HDFC Bank Ltd | B10: =(Processed_Ratios!B10 / Processed_Ratios!$B$32) * 10 -> 4.9290703 | C10: =(Processed_Ratios!C10 / Processed_Ratios!$B$32) * 10 -> 4.8020956 | D10: =(Processed_Ratios!D10 / Processed_Ratios!$B$32) * 10 -> 4.3891613 | E10: =(Processed_Ratios!E10 / Processed_Ratios!$B$32) * 10 -> 3.6443856 | F10: =(Processed_Ratios!F10 / Processed_Ratios!$B$32) * 10 -> 3.0735333 | G10: =(Processed_Ratios!G10 / Processed_Ratios!$B$32) * 10 -> 2.6387251 | H10: =(Processed_Ratios!H10 / Processed_Ratios!$B$32) * 10 -> 4.4019654 | I10: =(Processed_Ratios!I10 / Processed_Ratios!$B$32) * 10 -> 3.7750948 | ... M10: =(Processed_Ratios!M10 / Processed_Ratios!$B$32) * 10 -> 1.9371636
A11: Hindustan Unilever Ltd | B11: =(Processed_Ratios!B11 / Processed_Ratios!$B$32) * 10 -> 2.4178533 | C11: =(Processed_Ratios!C11 / Processed_Ratios!$B$32) * 10 -> 2.3335592 | D11: =(Processed_Ratios!D11 / Processed_Ratios!$B$32) * 10 -> 2.2978142 | E11: =(Processed_Ratios!E11 / Processed_Ratios!$B$32) * 10 -> 2.0161226 | F11: =(Processed_Ratios!F11 / Processed_Ratios!$B$32) * 10 -> 1.815524 | G11: =(Processed_Ratios!G11 / Processed_Ratios!$B$32) * 10 -> 1.662941 | H11: =(Processed_Ratios!H11 / Processed_Ratios!$B$32) * 10 -> 1.4916853 | I11: =(Processed_Ratios!I11 / Processed_Ratios!$B$32) * 10 -> 1.2846846 | ... M11: =(Processed_Ratios!M11 / Processed_Ratios!$B$32) * 10 -> 0.97258308
A12: ICICI Bank Ltd | B12: =(Processed_Ratios!B12 / Processed_Ratios!$B$32) * 10 -> 3.7953681 | C12: =(Processed_Ratios!C12 / Processed_Ratios!$B$32) * 10 -> 3.3056088 | D12: =(Processed_Ratios!D12 / Processed_Ratios!$B$32) * 10 -> 2.552297 | E12: =(Processed_Ratios!E12 / Processed_Ratios!$B$32) * 10 -> 1.8907485 | F12: =(Processed_Ratios!F12 / Processed_Ratios!$B$32) * 10 -> 1.431399 | G12: =(Processed_Ratios!G12 / Processed_Ratios!$B$32) * 10 -> 0.77625254 | H12: =(Processed_Ratios!H12 / Processed_Ratios!$B$32) * 10 -> 0.34838001 | I12: =(Processed_Ratios!I12 / Processed_Ratios!$B$32) * 10 -> 0.63433971 | ... M12: =(Processed_Ratios!M12 / Processed_Ratios!$B$32) * 10 -> 5.1029935
A13: Infosys Ltd | B13: =(Processed_Ratios!B13 / Processed_Ratios!$B$32) * 10 -> 3.4325834 | C13: =(Processed_Ratios!C13 / Processed_Ratios!$B$32) * 10 -> 3.3819002 | D13: =(Processed_Ratios!D13 / Processed_Ratios!$B$32) * 10 -> 3.0697987 | E13: =(Processed_Ratios!E13 / Processed_Ratios!$B$32) * 10 -> 2.7961097 | F13: =(Processed_Ratios!F13 / Processed_Ratios!$B$32) * 10 -> 2.4285234 | G13: =(Processed_Ratios!G13 / Processed_Ratios!$B$32) * 10 -> 2.0758754 | H13: =(Processed_Ratios!H13 / Processed_Ratios!$B$32) * 10 -> 1.8875474 | I13: =(Processed_Ratios!I13 / Processed_Ratios!$B$32) * 10 -> 3.787899 | ... M13: =(Processed_Ratios!M13 / Processed_Ratios!$B$32) * 10 -> 9.9493702
... A30: UltraTech Cement Ltd | B30: =(Processed_Ratios!B30 / Processed_Ratios!$B$32) * 10 -> 10 | C30: =(Processed_Ratios!C30 / Processed_Ratios!$B$32) * 10 -> 10 | D30: =(Processed_Ratios!D30 / Processed_Ratios!$B$32) * 10 -> 9.3651801 | E30: =(Processed_Ratios!E30 / Processed_Ratios!$B$32) * 10 -> 10 | F30: =(Processed_Ratios!F30 / Processed_Ratios!$B$32) * 10 -> 10 | G30: =(Processed_Ratios!G30 / Processed_Ratios!$B$32) * 10 -> 10 | H30: =(Processed_Ratios!H30 / Processed_Ratios!$B$32) * 10 -> 4.481458 | I30: =(Processed_Ratios!I30 / Processed_Ratios!$B$32) * 10 -> 4.3171378 | ... M30: =(Processed_Ratios!M30 / Processed_Ratios!$B$32) * 10 -> 4.2904625
A34: PAYOUT RATIO | B34: (PR)2025 | C34: (PR)2024 | D34: (PR)2023 | E34: (PR)2022 | F34: (PR)2021 | G34: (PR)2020 | H34: (PR)2019 | I34: (PR)2018 | J34: (PR)2017 | K34: (PR)2016 | L34: (PR)2015 | M34: (PR)2014
A35: Adani Ports and Special Economic Zone Ltd | B35: =(Processed_Ratios!B35 / Processed_Ratios!$B$65) * 10 -> 1.3275594 | C35: =(Processed_Ratios!C35 / Processed_Ratios!$B$65) * 10 -> 1.5128266 | D35: =(Processed_Ratios!D35 / Processed_Ratios!$B$65) * 10 -> 2.2595788 | E35: =(Processed_Ratios!E35 / Processed_Ratios!$B$65) * 10 -> 2.4539389 | F35: =(Processed_Ratios!F35 / Processed_Ratios!$B$65) * 10 -> 0 | G35: =(Processed_Ratios!G35 / Processed_Ratios!$B$65) * 10 -> 2.0879508 | H35: =(Processed_Ratios!H35 / Processed_Ratios!$B$65) * 10 -> 1.1798002 | I35: =(Processed_Ratios!I35 / Processed_Ratios!$B$65) * 10 -> 0.83199782 | ... M35: =(Processed_Ratios!M35 / Processed_Ratios!$B$65) * 10 -> 1.3957559
A36: Asian Paints Ltd | B36: =(Processed_Ratios!B36 / Processed_Ratios!$B$65) * 10 -> 9.631625 | C36: =(Processed_Ratios!C36 / Processed_Ratios!$B$65) * 10 -> 5.2704561 | D36: =(Processed_Ratios!D36 / Processed_Ratios!$B$65) * 10 -> 5.2829588 | E36: =(Processed_Ratios!E36 / Processed_Ratios!$B$65) * 10 -> 6.5286823 | F36: =(Processed_Ratios!F36 / Processed_Ratios!$B$65) * 10 -> 1.162751 | G36: =(Processed_Ratios!G36 / Processed_Ratios!$B$65) * 10 -> 7.3140792 | H36: =(Processed_Ratios!H36 / Processed_Ratios!$B$65) * 10 -> 4.4998352 | I36: =(Processed_Ratios!I36 / Processed_Ratios!$B$65) * 10 -> 5.5068708 | ... M36: =(Processed_Ratios!M36 / Processed_Ratios!$B$65) * 10 -> 4.7407963
A37: AXIS Bank Ltd | B37: =(Processed_Ratios!B37 / Processed_Ratios!$B$65) * 10 -> 0.13525648 | C37: =(Processed_Ratios!C37 / Processed_Ratios!$B$65) * 10 -> 0.14207613 | D37: =(Processed_Ratios!D37 / Processed_Ratios!$B$65) * 10 -> 0.36939794 | E37: =(Processed_Ratios!E37 / Processed_Ratios!$B$65) * 10 -> 0.14093952 | F37: =(Processed_Ratios!F37 / Processed_Ratios!$B$65) * 10 -> 0.17276457 | G37: =(Processed_Ratios!G37 / Processed_Ratios!$B$65) * 10 -> 0.14207613 | H37: =(Processed_Ratios!H37 / Processed_Ratios!$B$65) * 10 -> 0.26482991 | I37: =(Processed_Ratios!I37 / Processed_Ratios!$B$65) * 10 -> 0.15798866 | ... M37: =(Processed_Ratios!M37 / Processed_Ratios!$B$65) * 10 -> 0.15003239
A38: Bajaj Finserv Ltd | B38: =(Processed_Ratios!B38 / Processed_Ratios!$B$65) * 10 -> 0.20345302 | C38: =(Processed_Ratios!C38 / Processed_Ratios!$B$65) * 10 -> 0.17731101 | D38: =(Processed_Ratios!D38 / Processed_Ratios!$B$65) * 10 -> 0.11252429 | E38: =(Processed_Ratios!E38 / Processed_Ratios!$B$65) * 10 -> 0.11820734 | F38: =(Processed_Ratios!F38 / Processed_Ratios!$B$65) * 10 -> 0 | G38: =(Processed_Ratios!G38 / Processed_Ratios!$B$65) * 10 -> 0.4023596 | H38: =(Processed_Ratios!H38 / Processed_Ratios!$B$65) * 10 -> 0.097748377 | I38: =(Processed_Ratios!I38 / Processed_Ratios!$B$65) * 10 -> 0.11934395 | ... M38: =(Processed_Ratios!M38 / Processed_Ratios!$B$65) * 10 -> 0.20458963
A39: Bajaj Finance Ltd | B39: =(Processed_Ratios!B39 / Processed_Ratios!$B$65) * 10 -> 1.5207829 | C39: =(Processed_Ratios!C39 / Processed_Ratios!$B$65) * 10 -> 1.427581 | D39: =(Processed_Ratios!D39 / Processed_Ratios!$B$65) * 10 -> 1.1923029 | E39: =(Processed_Ratios!E39 / Processed_Ratios!$B$65) * 10 -> 0.97407395 | F39: =(Processed_Ratios!F39 / Processed_Ratios!$B$65) * 10 -> 0 | G39: =(Processed_Ratios!G39 / Processed_Ratios!$B$65) * 10 -> 2.0504427 | H39: =(Processed_Ratios!H39 / Processed_Ratios!$B$65) * 10 -> 0.65696003 | I39: =(Processed_Ratios!I39 / Processed_Ratios!$B$65) * 10 -> 0.84109069 | ... M39: =(Processed_Ratios!M39 / Processed_Ratios!$B$65) * 10 -> 1.2673191
A40: Bharat Electronics Ltd | B40: =(Processed_Ratios!B40 / Processed_Ratios!$B$65) * 10 -> 3.590548 | C40: =(Processed_Ratios!C40 / Processed_Ratios!$B$65) * 10 -> 4.1702186 | D40: =(Processed_Ratios!D40 / Processed_Ratios!$B$65) * 10 -> 4.7317034 | E40: =(Processed_Ratios!E40 / Processed_Ratios!$B$65) * 10 -> 4.8476376 | F40: =(Processed_Ratios!F40 / Processed_Ratios!$B$65) * 10 -> 5.5409691 | G40: =(Processed_Ratios!G40 / Processed_Ratios!$B$65) * 10 -> 4.706698 | H40: =(Processed_Ratios!H40 / Processed_Ratios!$B$65) * 10 -> 3.0824837 | I40: =(Processed_Ratios!I40 / Processed_Ratios!$B$65) * 10 -> 4.9817574 | ... M40: =(Processed_Ratios!M40 / Processed_Ratios!$B$65) * 10 -> 2.2266171
A41: Bharti Airtel Ltd | B41: =(Processed_Ratios!B41 / Processed_Ratios!$B$65) * 10 -> 1.5673839 | C41: =(Processed_Ratios!C41 / Processed_Ratios!$B$65) * 10 -> 3.4632477 | D41: =(Processed_Ratios!D41 / Processed_Ratios!$B$65) * 10 -> 2.3118628 | E41: =(Processed_Ratios!E41 / Processed_Ratios!$B$65) * 10 -> 0 | F41: =(Processed_Ratios!F41 / Processed_Ratios!$B$65) * 10 -> 0 | G41: =(Processed_Ratios!G41 / Processed_Ratios!$B$65) * 10 -> 0 | H41: =(Processed_Ratios!H41 / Processed_Ratios!$B$65) * 10 -> 10 | I41: =(Processed_Ratios!I41 / Processed_Ratios!$B$65) * 10 -> 10 | ... M41: =(Processed_Ratios!M41 / Processed_Ratios!$B$65) * 10 -> 0
A42: HCL Technologies Ltd | B42: =(Processed_Ratios!B42 / Processed_Ratios!$B$65) * 10 -> 10 | C42: =(Processed_Ratios!C42 / Processed_Ratios!$B$65) * 10 -> 10 | D42: =(Processed_Ratios!D42 / Processed_Ratios!$B$65) * 10 -> 9.9453291 | E42: =(Processed_Ratios!E42 / Processed_Ratios!$B$65) * 10 -> 9.5907071 | F42: =(Processed_Ratios!F42 / Processed_Ratios!$B$65) * 10 -> 3.3211716 | G42: =(Processed_Ratios!G42 / Processed_Ratios!$B$65) * 10 -> 1.3946193 | H42: =(Processed_Ratios!H42 / Processed_Ratios!$B$65) * 10 -> 1.2332208 | I42: =(Processed_Ratios!I42 / Processed_Ratios!$B$65) * 10 -> 2.2050215 | ... M42: =(Processed_Ratios!M42 / Processed_Ratios!$B$65) * 10 -> 1.2218547
A43: HDFC Bank Ltd | B43: =(Processed_Ratios!B43 / Processed_Ratios!$B$65) * 10 -> 2.8472056 | C43: =(Processed_Ratios!C43 / Processed_Ratios!$B$65) * 10 -> 2.7710528 | D43: =(Processed_Ratios!D43 / Processed_Ratios!$B$65) * 10 -> 2.735818 | E43: =(Processed_Ratios!E43 / Processed_Ratios!$B$65) * 10 -> 2.6460258 | F43: =(Processed_Ratios!F43 / Processed_Ratios!$B$65) * 10 -> 1.3116468 | G43: =(Processed_Ratios!G43 / Processed_Ratios!$B$65) * 10 -> 0 | H43: =(Processed_Ratios!H43 / Processed_Ratios!$B$65) * 10 -> 2.1175026 | I43: =(Processed_Ratios!I43 / Processed_Ratios!$B$65) * 10 -> 2.1959287 | ... M43: =(Processed_Ratios!M43 / Processed_Ratios!$B$65) * 10 -> 0
A44: Hindustan Unilever Ltd | B44: =(Processed_Ratios!B44 / Processed_Ratios!$B$65) * 10 -> 10 | C44: =(Processed_Ratios!C44 / Processed_Ratios!$B$65) * 10 -> 10 | D44: =(Processed_Ratios!D44 / Processed_Ratios!$B$65) * 10 -> 9.4997784 | E44: =(Processed_Ratios!E44 / Processed_Ratios!$B$65) * 10 -> 9.6248054 | F44: =(Processed_Ratios!F44 / Processed_Ratios!$B$65) * 10 -> 10 | G44: =(Processed_Ratios!G44 / Processed_Ratios!$B$65) * 10 -> 8.7518896 | H44: =(Processed_Ratios!H44 / Processed_Ratios!$B$65) * 10 -> 8.5347973 | I44: =(Processed_Ratios!I44 / Processed_Ratios!$B$65) * 10 -> 8.4927428 | ... M44: =(Processed_Ratios!M44 / Processed_Ratios!$B$65) * 10 -> 8.0983394
A45: ICICI Bank Ltd | B45: =(Processed_Ratios!B45 / Processed_Ratios!$B$65) * 10 -> 1.7503779 | C45: =(Processed_Ratios!C45 / Processed_Ratios!$B$65) * 10 -> 1.8072084 | D45: =(Processed_Ratios!D45 / Processed_Ratios!$B$65) * 10 -> 1.8640388 | E45: =(Processed_Ratios!E45 / Processed_Ratios!$B$65) * 10 -> 1.5685205 | F45: =(Processed_Ratios!F45 / Processed_Ratios!$B$65) * 10 -> 0.85245678 | G45: =(Processed_Ratios!G45 / Processed_Ratios!$B$65) * 10 -> 0 | H45: =(Processed_Ratios!H45 / Processed_Ratios!$B$65) * 10 -> 1.7049136 | I45: =(Processed_Ratios!I45 / Processed_Ratios!$B$65) * 10 -> 1.3639308 | ... M45: =(Processed_Ratios!M45 / Processed_Ratios!$B$65) * 10 -> 2.7278617
A46: Infosys Ltd | B46: =(Processed_Ratios!B46 / Processed_Ratios!$B$65) * 10 -> 8.6348189 | C46: =(Processed_Ratios!C46 / Processed_Ratios!$B$65) * 10 -> 6.3650106 | D46: =(Processed_Ratios!D46 / Processed_Ratios!$B$65) * 10 -> 6.4297973 | E46: =(Processed_Ratios!E46 / Processed_Ratios!$B$65) * 10 -> 6.5048135 | F46: =(Processed_Ratios!F46 / Processed_Ratios!$B$65) * 10 -> 5.3557018 | G46: =(Processed_Ratios!G46 / Processed_Ratios!$B$65) * 10 -> 6.5184528 | H46: =(Processed_Ratios!H46 / Processed_Ratios!$B$65) * 10 -> 10 | I46: =(Processed_Ratios!I46 / Processed_Ratios!$B$65) * 10 -> 5.2954615 | ... M46: =(Processed_Ratios!M46 / Processed_Ratios!$B$65) * 10 -> 3.8451484
... A63: UltraTech Cement Ltd | B63: =(Processed_Ratios!B63 / Processed_Ratios!$B$65) * 10 -> 3.7962742 | C63: =(Processed_Ratios!C63 / Processed_Ratios!$B$65) * 10 -> 1.7765199 | D63: =(Processed_Ratios!D63 / Processed_Ratios!$B$65) * 10 -> 2.4516657 | E63: =(Processed_Ratios!E63 / Processed_Ratios!$B$65) * 10 -> 1.6503563 | F63: =(Processed_Ratios!F63 / Processed_Ratios!$B$65) * 10 -> 0.7797138 | G63: =(Processed_Ratios!G63 / Processed_Ratios!$B$65) * 10 -> 0.75129858 | H63: =(Processed_Ratios!H63 / Processed_Ratios!$B$65) * 10 -> 1.6435367 | I63: =(Processed_Ratios!I63 / Processed_Ratios!$B$65) * 10 -> 1.689001 | ... M63: =(Processed_Ratios!M63 / Processed_Ratios!$B$65) * 10 -> 1.2707289
A67: PROFIT MARGIN | B67: (PM)2025 | C67: (PM)2024 | D67: (PM)2023 | E67: (PM)2022 | F67: (PM)2021 | G67: (PM)2020 | H67: (PM)2019 | I67: (PM)2018 | J67: (PM)2017 | K67: (PM)2016 | L67: (PM)2015 | M67: (PM)2014
A68: Adani Ports and Special Economic Zone Ltd | B68: =(Processed_Ratios!B68 / Processed_Ratios!$B$98) * 10 -> 10 | C68: =(Processed_Ratios!C68 / Processed_Ratios!$B$98) * 10 -> 9.6861548 | D68: =(Processed_Ratios!D68 / Processed_Ratios!$B$98) * 10 -> 8.0237928 | E68: =(Processed_Ratios!E68 / Processed_Ratios!$B$98) * 10 -> 9.041246 | F68: =(Processed_Ratios!F68 / Processed_Ratios!$B$98) * 10 -> 10 | G68: =(Processed_Ratios!G68 / Processed_Ratios!$B$98) * 10 -> 9.9898255 | H68: =(Processed_Ratios!H68 / Processed_Ratios!$B$98) * 10 -> 10 | I68: =(Processed_Ratios!I68 / Processed_Ratios!$B$98) * 10 -> 10 | ... M68: =(Processed_Ratios!M68 / Processed_Ratios!$B$98) * 10 -> 10
A69: Asian Paints Ltd | B69: =(Processed_Ratios!B69 / Processed_Ratios!$B$98) * 10 -> 3.2934179 | C69: =(Processed_Ratios!C69 / Processed_Ratios!$B$98) * 10 -> 4.7835955 | D69: =(Processed_Ratios!D69 / Processed_Ratios!$B$98) * 10 -> 3.7223135 | E69: =(Processed_Ratios!E69 / Processed_Ratios!$B$98) * 10 -> 3.284026 | F69: =(Processed_Ratios!F69 / Processed_Ratios!$B$98) * 10 -> 4.5801049 | G69: =(Processed_Ratios!G69 / Processed_Ratios!$B$98) * 10 -> 4.2169523 | H69: =(Processed_Ratios!H69 / Processed_Ratios!$B$98) * 10 -> 3.5250841 | I69: =(Processed_Ratios!I69 / Processed_Ratios!$B$98) * 10 -> 3.8162323 | ... M69: =(Processed_Ratios!M69 / Processed_Ratios!$B$98) * 10 -> 3.108711
A70: AXIS Bank Ltd | B70: =(Processed_Ratios!B70 / Processed_Ratios!$B$98) * 10 -> 6.9092901 | C70: =(Processed_Ratios!C70 / Processed_Ratios!$B$98) * 10 -> 7.3350552 | D70: =(Processed_Ratios!D70 / Processed_Ratios!$B$98) * 10 -> 3.8851061 | E70: =(Processed_Ratios!E70 / Processed_Ratios!$B$98) * 10 -> 6.4396963 | F70: =(Processed_Ratios!F70 / Processed_Ratios!$B$98) * 10 -> 3.5063004 | G70: =(Processed_Ratios!G70 / Processed_Ratios!$B$98) * 10 -> 0.92040385 | H70: =(Processed_Ratios!H70 / Processed_Ratios!$B$98) * 10 -> 2.8175628 | I70: =(Processed_Ratios!I70 / Processed_Ratios!$B$98) * 10 -> 0.30993191 | ... M70: =(Processed_Ratios!M70 / Processed_Ratios!$B$98) * 10 -> 6.4240432
A71: Bajaj Finserv Ltd | B71: =(Processed_Ratios!B71 / Processed_Ratios!$B$98) * 10 -> 4.1011192 | C71: =(Processed_Ratios!C71 / Processed_Ratios!$B$98) * 10 -> 4.420443 | D71: =(Processed_Ratios!D71 / Processed_Ratios!$B$98) * 10 -> 4.6552399 | E71: =(Processed_Ratios!E71 / Processed_Ratios!$B$98) * 10 -> 3.8037098 | F71: =(Processed_Ratios!F71 / Processed_Ratios!$B$98) * 10 -> 3.8037098 | G71: =(Processed_Ratios!G71 / Processed_Ratios!$B$98) * 10 -> 3.4499491 | H71: =(Processed_Ratios!H71 / Processed_Ratios!$B$98) * 10 -> 3.9477186 | I71: =(Processed_Ratios!I71 / Processed_Ratios!$B$98) * 10 -> 3.9758942 | ... M71: =(Processed_Ratios!M71 / Processed_Ratios!$B$98) * 10 -> 10
A72: Bajaj Finance Ltd | B72: =(Processed_Ratios!B72 / Processed_Ratios!$B$98) * 10 -> 7.5291539 | C72: =(Processed_Ratios!C72 / Processed_Ratios!$B$98) * 10 -> 8.2241528 | D72: =(Processed_Ratios!D72 / Processed_Ratios!$B$98) * 10 -> 8.7000078 | E72: =(Processed_Ratios!E72 / Processed_Ratios!$B$98) * 10 -> 6.9531189 | F72: =(Processed_Ratios!F72 / Processed_Ratios!$B$98) * 10 -> 5.1874462 | G72: =(Processed_Ratios!G72 / Processed_Ratios!$B$98) * 10 -> 6.2455976 | H72: =(Processed_Ratios!H72 / Processed_Ratios!$B$98) * 10 -> 6.7621507 | I72: =(Processed_Ratios!I72 / Processed_Ratios!$B$98) * 10 -> 6.2268138 | ... M72: =(Processed_Ratios!M72 / Processed_Ratios!$B$98) * 10 -> 5.5255537
A73: Bharat Electronics Ltd | B73: =(Processed_Ratios!B73 / Processed_Ratios!$B$98) * 10 -> 6.9625108 | C73: =(Processed_Ratios!C73 / Processed_Ratios!$B$98) * 10 -> 6.0890663 | D73: =(Processed_Ratios!D73 / Processed_Ratios!$B$98) * 10 -> 5.1874462 | E73: =(Processed_Ratios!E73 / Processed_Ratios!$B$98) * 10 -> 4.796118 | F73: =(Processed_Ratios!F73 / Processed_Ratios!$B$98) * 10 -> 4.5894968 | G73: =(Processed_Ratios!G73 / Processed_Ratios!$B$98) * 10 -> 4.3265242 | H73: =(Processed_Ratios!H73 / Processed_Ratios!$B$98) * 10 -> 4.7554199 | I73: =(Processed_Ratios!I73 / Processed_Ratios!$B$98) * 10 -> 4.2357361 | ... M73: =(Processed_Ratios!M73 / Processed_Ratios!$B$98) * 10 -> 4.570713
A74: Bharti Airtel Ltd | B74: =(Processed_Ratios!B74 / Processed_Ratios!$B$98) * 10 -> 6.1109807 | C74: =(Processed_Ratios!C74 / Processed_Ratios!$B$98) * 10 -> 1.2178133 | D74: =(Processed_Ratios!D74 / Processed_Ratios!$B$98) * 10 -> 2.5952884 | E74: =(Processed_Ratios!E74 / Processed_Ratios!$B$98) * 10 -> 1.5778352 | F74: =(Processed_Ratios!F74 / Processed_Ratios!$B$98) * 10 -> 0.20881271 | G74: =(Processed_Ratios!G74 / Processed_Ratios!$B$98) * 10 -> 0.20881271 | H74: =(Processed_Ratios!H74 / Processed_Ratios!$B$98) * 10 -> 0.51342256 | I74: =(Processed_Ratios!I74 / Processed_Ratios!$B$98) * 10 -> 0.41637317 | ... M74: =(Processed_Ratios!M74 / Processed_Ratios!$B$98) * 10 -> 1.0988495
A75: HCL Technologies Ltd | B75: =(Processed_Ratios!B75 / Processed_Ratios!$B$98) * 10 -> 4.6521093 | C75: =(Processed_Ratios!C75 / Processed_Ratios!$B$98) * 10 -> 4.4736636 | D75: =(Processed_Ratios!D75 / Processed_Ratios!$B$98) * 10 -> 4.5801049 | E75: =(Processed_Ratios!E75 / Processed_Ratios!$B$98) * 10 -> 4.9401268 | F75: =(Processed_Ratios!F75 / Processed_Ratios!$B$98) * 10 -> 4.6364561 | G75: =(Processed_Ratios!G75 / Processed_Ratios!$B$98) * 10 -> 4.896298 | H75: =(Processed_Ratios!H75 / Processed_Ratios!$B$98) * 10 -> 5.2406668 | I75: =(Processed_Ratios!I75 / Processed_Ratios!$B$98) * 10 -> 5.3909368 | ... M75: =(Processed_Ratios!M75 / Processed_Ratios!$B$98) * 10 -> 6.3363857
A76: HDFC Bank Ltd | B76: =(Processed_Ratios!B76 / Processed_Ratios!$B$98) * 10 -> 7.0157314 | C76: =(Processed_Ratios!C76 / Processed_Ratios!$B$98) * 10 -> 7.3663614 | D76: =(Processed_Ratios!D76 / Processed_Ratios!$B$98) * 10 -> 8.5434766 | E76: =(Processed_Ratios!E76 / Processed_Ratios!$B$98) * 10 -> 9.0568991 | F76: =(Processed_Ratios!F76 / Processed_Ratios!$B$98) * 10 -> 8.0582296 | G76: =(Processed_Ratios!G76 / Processed_Ratios!$B$98) * 10 -> 7.1566095 | H76: =(Processed_Ratios!H76 / Processed_Ratios!$B$98) * 10 -> 6.6651014 | I76: =(Processed_Ratios!I76 / Processed_Ratios!$B$98) * 10 -> 6.8216326 | ... M76: =(Processed_Ratios!M76 / Processed_Ratios!$B$98) * 10 -> 6.4522188
A77: Hindustan Unilever Ltd | B77: =(Processed_Ratios!B77 / Processed_Ratios!$B$98) * 10 -> 5.2938875 | C77: =(Processed_Ratios!C77 / Processed_Ratios!$B$98) * 10 -> 5.1999687 | D77: =(Processed_Ratios!D77 / Processed_Ratios!$B$98) * 10 -> 5.2406668 | E77: =(Processed_Ratios!E77 / Processed_Ratios!$B$98) * 10 -> 5.30641 | F77: =(Processed_Ratios!F77 / Processed_Ratios!$B$98) * 10 -> 5.3220631 | G77: =(Processed_Ratios!G77 / Processed_Ratios!$B$98) * 10 -> 5.3158018 | H77: =(Processed_Ratios!H77 / Processed_Ratios!$B$98) * 10 -> 4.8242937 | I77: =(Processed_Ratios!I77 / Processed_Ratios!$B$98) * 10 -> 4.6020193 | ... M77: =(Processed_Ratios!M77 / Processed_Ratios!$B$98) * 10 -> 4.2357361
A78: ICICI Bank Ltd | B78: =(Processed_Ratios!B78 / Processed_Ratios!$B$98) * 10 -> 9.141426 | C78: =(Processed_Ratios!C78 / Processed_Ratios!$B$98) * 10 -> 8.8314941 | D78: =(Processed_Ratios!D78 / Processed_Ratios!$B$98) * 10 -> 8.9097597 | E78: =(Processed_Ratios!E78 / Processed_Ratios!$B$98) * 10 -> 8.4589497 | F78: =(Processed_Ratios!F78 / Processed_Ratios!$B$98) * 10 -> 7.0971277 | G78: =(Processed_Ratios!G78 / Processed_Ratios!$B$98) * 10 -> 4.1418173 | H78: =(Processed_Ratios!H78 / Processed_Ratios!$B$98) * 10 -> 2.473194 | I78: =(Processed_Ratios!I78 / Processed_Ratios!$B$98) * 10 -> 4.5801049 | ... M78: =(Processed_Ratios!M78 / Processed_Ratios!$B$98) * 10 -> 7.3882758
...

Sheet Fuzzy_Parameters
A1: DILUTED EPS
A2: TMF Coords
A3: a | B3: P20 | C3: =_xlfn.PERCENTILE.INC(Fuzzy_Inputs_10!$E$2:$M$30, 0.2) -> 0.54951211
A4: b | B4: P40 | C4: =_xlfn.PERCENTILE.INC(Fuzzy_Inputs_10!$E$2:$M$30, 0.4) -> 1.0280678
A5: c | B5: P60 | C5: =_xlfn.PERCENTILE.INC(Fuzzy_Inputs_10!$E$2:$M$30, 0.6) -> 2.1174889
A6: d | B6: P80 | C6: =_xlfn.PERCENTILE.INC(Fuzzy_Inputs_10!$E$2:$M$30, 0.8) -> 4.0125054
A9: PAYOUT RATIO
A10: TMF Coords
A11: a | B11: P20 | C11: =_xlfn.PERCENTILE.INC(Fuzzy_Inputs_10!$E$35:$M$63, 0.2) -> 0.39213012
A12: b | B12: P40 | C12: =_xlfn.PERCENTILE.INC(Fuzzy_Inputs_10!$E$35:$M$63, 0.4) -> 1.689001
A13: c | B13: P60 | C13: =_xlfn.PERCENTILE.INC(Fuzzy_Inputs_10!$E$35:$M$63, 0.6) -> 2.7960582
A14: d | B14: P80 | C14: =_xlfn.PERCENTILE.INC(Fuzzy_Inputs_10!$E$35:$M$63, 0.8) -> 4.8203589
A17: PROFIT MARGIN
A18: TMF Coords
A19: a | B19: P20 | C19: =_xlfn.PERCENTILE.INC(Fuzzy_Inputs_10!$E$68:$M$96, 0.2) -> 1.8282852
A20: b | B20: P40 | C20: =_xlfn.PERCENTILE.INC(Fuzzy_Inputs_10!$E$68:$M$96, 0.4) -> 3.3716835
A21: c | B21: P60 | C21: =_xlfn.PERCENTILE.INC(Fuzzy_Inputs_10!$E$68:$M$96, 0.6) -> 4.896298
A22: d | B22: P80 | C22: =_xlfn.PERCENTILE.INC(Fuzzy_Inputs_10!$E$68:$M$96, 0.8) -> 6.8216326
A25: DEBT TO EQUITY
A26: TMF Coords
A27: a | B27: P20 | C27: =_xlfn.PERCENTILE.INC(Fuzzy_Inputs_10!$E$101:$M$129, 0.2) -> 0.82337012
A28: b | B28: P40 | C28: =_xlfn.PERCENTILE.INC(Fuzzy_Inputs_10!$E$101:$M$129, 0.4) -> 1.7406395
A29: c | B29: P60 | C29: =_xlfn.PERCENTILE.INC(Fuzzy_Inputs_10!$E$101:$M$129, 0.6) -> 3.1632456
A30: d | B30: P80 | C30: =_xlfn.PERCENTILE.INC(Fuzzy_Inputs_10!$E$101:$M$129, 0.8) -> 5.7480858

Sheet Membership_Functions
A1: Factors in terms of linguistic variables | B1: Linguistic Values | C1: Fuzzy Trapezoidal Membership (a,b,c,d)
A2: Diluted EPS | B2: Low | C2: (0,0,0.5495121079, 1.028067798)
B3: Standard | C3: (0.5495121079, 1.028067798, 2.11748889, 4.012505402)
B4: High | C4: (2.11748889, 4.012505402,10,10)
A5: Payout Ratio | B5: Low | C5: (0,0,0.392130119, 1.689001034)
B6: Standard | C6: (0.392130119, 1.689001034, 2.79605824, 4.820358941)
B7: High | C7: (2.79605824, 4.820358941,10,10)
A8: Profit Margin | B8: Low | C8: (0,0,1.8282852, 3.371683494)
B9: Standard | C9: (1.8282852, 3.371683494, 4.896298036, 6.821632621)
B10: High | C10: (4.896298036, 6.821632621,10,10)
A11: Debt to Equity | B11: Low | C11: (0,0,0.8233701189, 1.740639476)
B12: Standard | C12: (0.8233701189, 1.740639476, 3.163245581, 5.748085778)
B13: High | C13: ( 3.163245581, 5.748085778,10,10)

Sheet Membership_Grades
A1: Stock | B1: Year | C1: EPS_L | D1: EPS_S | E1: EPS_H | F1: PAYOUT_L | G1: PAYOUT_S | H1: PAYOUT_H | I1: PM_L | J1: PM_S | K1: PM_H | L1: DE_L | M1: DE_S | N1: DE_H
A2: Adani Ports and Special Economic Zone Ltd | B2: 2022 | C2: =MAX(MIN(1, (Fuzzy_Parameters!$C$4 - Fuzzy_Inputs_10!E2)/(Fuzzy_Parameters!$C$4 - Fuzzy_Parameters!$C$3)), 0) -> 0
A3: Adani Ports and Special Economic Zone Ltd | B3: 2021 | C3: =MAX(MIN(1, (Fuzzy_Parameters!$C$4 - Fuzzy_Inputs_10!F2)/(Fuzzy_Parameters!$C$4 - Fuzzy_Parameters!$C$3)), 0) -> 0
A4: Adani Ports and Special Economic Zone Ltd | B4: 2020 | C4: =MAX(MIN(1, (Fuzzy_Parameters!$C$4 - Fuzzy_Inputs_10!G2)/(Fuzzy_Parameters!$C$4 - Fuzzy_Parameters!$C$3)), 0) -> 0.1025641
A5: Adani Ports and Special Economic Zone Ltd | B5: 2019 | C5: =MAX(MIN(1, (Fuzzy_Parameters!$C$4 - Fuzzy_Inputs_10!H2)/(Fuzzy_Parameters!$C$4 - Fuzzy_Parameters!$C$3)), 0) -> 0
A6: Adani Ports and Special Economic Zone Ltd | B6: 2018 | C6: =MAX(MIN(1, (Fuzzy_Parameters!$C$4 - Fuzzy_Inputs_10!I2)/(Fuzzy_Parameters!$C$4 - Fuzzy_Parameters!$C$3)), 0) -> 0.17056856
A7: Adani Ports and Special Economic Zone Ltd | B7: 2017 | C7: =MAX(MIN(1, (Fuzzy_Parameters!$C$4 - Fuzzy_Inputs_10!J2)/(Fuzzy_Parameters!$C$4 - Fuzzy_Parameters!$C$3)), 0) -> 0.042363434
A8: Adani Ports and Special Economic Zone Ltd | B8: 2016 | C8: =MAX(MIN(1, (Fuzzy_Parameters!$C$4 - Fuzzy_Inputs_10!K2)/(Fuzzy_Parameters!$C$4 - Fuzzy_Parameters!$C$3)), 0) -> 0.58862876
A9: Adani Ports and Special Economic Zone Ltd | B9: 2015 | C9: =MAX(MIN(1, (Fuzzy_Parameters!$C$4 - Fuzzy_Inputs_10!L2)/(Fuzzy_Parameters!$C$4 - Fuzzy_Parameters!$C$3)), 0) -> 0.90189521
A10: Adani Ports and Special Economic Zone Ltd | B10: 2014 | C10: =MAX(MIN(1, (Fuzzy_Parameters!$C$4 - Fuzzy_Inputs_10!M2)/(Fuzzy_Parameters!$C$4 - Fuzzy_Parameters!$C$3)), 0) -> 1
A11: Asian Paints Ltd | B11: 2022 | C11: =MAX(MIN(1, (Fuzzy_Parameters!$C$4 - Fuzzy_Inputs_10!E3)/(Fuzzy_Parameters!$C$4 - Fuzzy_Parameters!$C$3)), 0) -> 0
A12: Asian Paints Ltd | B12: 2021 | C12: =MAX(MIN(1, (Fuzzy_Parameters!$C$4 - Fuzzy_Inputs_10!F3)/(Fuzzy_Parameters!$C$4 - Fuzzy_Parameters!$C$3)), 0) -> 0
A13: Asian Paints Ltd | B13: 2020 | C13: =MAX(MIN(1, (Fuzzy_Parameters!$C$4 - Fuzzy_Inputs_10!G3)/(Fuzzy_Parameters!$C$4 - Fuzzy_Parameters!$C$3)), 0) -> 0
A14: Asian Paints Ltd | B14: 2019 | C14: =MAX(MIN(1, (Fuzzy_Parameters!$C$4 - Fuzzy_Inputs_10!H3)/(Fuzzy_Parameters!$C$4 - Fuzzy_Parameters!$C$3)), 0) -> 0
A15: Asian Paints Ltd | B15: 2018 | C15: =MAX(MIN(1, (Fuzzy_Parameters!$C$4 - Fuzzy_Inputs_10!I3)/(Fuzzy_Parameters!$C$4 - Fuzzy_Parameters!$C$3)), 0) -> 0
A16: Asian Paints Ltd | B16: 2017 | C16: =MAX(MIN(1, (Fuzzy_Parameters!$C$4 - Fuzzy_Inputs_10!J3)/(Fuzzy_Parameters!$C$4 - Fuzzy_Parameters!$C$3)), 0) -> 0
A17: Asian Paints Ltd | B17: 2016 | C17: =MAX(MIN(1, (Fuzzy_Parameters!$C$4 - Fuzzy_Inputs_10!K3)/(Fuzzy_Parameters!$C$4 - Fuzzy_Parameters!$C$3)), 0) -> 0.12040134
A18: Asian Paints Ltd | B18: 2015 | C18: =MAX(MIN(1, (Fuzzy_Parameters!$C$4 - Fuzzy_Inputs_10!L3)/(Fuzzy_Parameters!$C$4 - Fuzzy_Parameters!$C$3)), 0) -> 0.52731327
A19: Asian Paints Ltd | B19: 2014 | C19: =MAX(MIN(1, (Fuzzy_Parameters!$C$4 - Fuzzy_Inputs_10!M3)/(Fuzzy_Parameters!$C$4 - Fuzzy_Parameters!$C$3)), 0) -> 0.73132664
A20: AXIS Bank Ltd | B20: 2022
A21: AXIS Bank Ltd | B21: 2021
A22: AXIS Bank Ltd | B22: 2020
A23: AXIS Bank Ltd | B23: 2019
A24: AXIS Bank Ltd | B24: 2018
A25: AXIS Bank Ltd | B25: 2017
A26: AXIS Bank Ltd | B26: 2016
A27: AXIS Bank Ltd | B27: 2015
A28: AXIS Bank Ltd | B28: 2014
A29: Bajaj Finserv Ltd | B29: 2022
A30: Bajaj Finserv Ltd | B30: 2021
A31: Bajaj Finserv Ltd | B31: 2020
... A262: UltraTech Cement Ltd | B262: 2014

Sheet Sheet6
A1: Stock | B1: Year | C1: DILUTED EPS | D1: PAYOUT RATIO | E1: PROFIT MARGIN | F1: DEBT TO EQUITY
A2: Adani Ports and Special Economic Zone Ltd | B2: 2022
A3: Adani Ports and Special Economic Zone Ltd | B3: 2021
A4: Adani Ports and Special Economic Zone Ltd | B4: 2020
A5: Adani Ports and Special Economic Zone Ltd | B5: 2019
A6: Adani Ports and Special Economic Zone Ltd | B6: 2018
A7: Adani Ports and Special Economic Zone Ltd | B7: 2017
A8: Adani Ports and Special Economic Zone Ltd | B8: 2016
A9: Adani Ports and Special Economic Zone Ltd | B9: 2015
A10: Adani Ports and Special Economic Zone Ltd | B10: 2014
A11: Asian Paints Ltd | B11: 2022
A12: Asian Paints Ltd | B12: 2021
A13: Asian Paints Ltd | B13: 2020
... A262: UltraTech Cement Ltd | B262: 2014
