Workbook

Sheet Sheet1
B1: (P/E)2025 | C1: (P/E)2024 | D1: (P/E)2023 | E1: (P/E)2022 | F1: (P/E)2021 | G1: (P/E)2020 | H1: (P/E)2019 | I1: (P/E)2018 | J1: (P/E)2017 | K1: (P/E)2016 | L1: (P/E)2015 | M1: (P/E)2014 | N1: (P/E)2013 | P1: flattened
A2: Adani Ports and Special Economic Zone Ltd | B2: 23.0195 | C2: 35.731 | D2: 25.7038 | E2: 34.5735 | F2: 28.5903 | G2: 13.6948 | H2: 19.616 | I2: 19.9915 | J2: 17.9884 | K2: 17.7055 | L2: 27.5537 | M2: 22.1893 | N2: 18.0664 | P2: =IFERROR(__xludf.DUMMYFUNCTION("FLATTEN(B2:M30)"),23.0195) -> 23.0195
A3: Asian Paints Ltd | B3: 34.9725 | C3: 49.9737 | D3: 64.4793 | E3: 97.5546 | F3: 77.5053 | G3: 59.1028 | H3: 66.3657 | I3: 52.714 | J3: 52.9773 | K3: 47.757 | L3: 55.6224 | M3: 42.9976 | N3: 42.3181 | P3: =IFERROR(__xludf.DUMMYFUNCTION("""COMPUTED_VALUE"""),35.731) -> 35.731
A4: AXIS Bank Ltd | B4: 12.1462 | C4: 12.2436 | D4: 24.3878 | E4: 16.5215 | F4: 28.8342 | G4: 55.5344 | H4: 39.5767 | I4: 273.871 | J4: 29.6735 | K4: 12.658 | L4: 17.7567 | M4: 10.8559 | N4: 10.7586 | P4: =IFERROR(__xludf.DUMMYFUNCTION("""COMPUTED_VALUE"""),25.7038) -> 25.7038
A5: Bajaj Finserv Ltd | B5: 160.9487 | C5: 141.4131 | D5: 139.34 | E5: 25.3549 | F5: 18.33 | G5: 10.4679 | H5: 14.9523 | I5: 10.6291 | J5: 8.2625 | K5: 59.1734 | L5: 38.5711 | M5: 18.4541 | N5: 11.2073 | P5: =IFERROR(__xludf.DUMMYFUNCTION("""COMPUTED_VALUE"""),34.5735) -> 34.5735
A6: Bajaj Finance Ltd | B6: 7.4587 | C6: 6.9385 | D6: 6.6465 | E6: 146.1947 | F6: 131.3917 | G6: 51.1279 | H6: 101.4777 | I6: 108.9304 | J6: 120.1941 | K6: 7.031 | L6: 7.7217 | M6: 5.4576 | N6: 5.6609 | P6: =IFERROR(__xludf.DUMMYFUNCTION("""COMPUTED_VALUE"""),28.5903) -> 28.5903
A7: Bharat Electronics Ltd | B7: 41.3736 | C7: 36.9633 | D7: 23.8509 | E7: 21.4061 | F7: 14.5128 | G7: 9.9266 | H7: 12.0543 | I7: 24.3654 | J7: 26.3215 | K7: 218.9408 | L7: 22.3672 | M7: 9.6262 | N7: 10.0935 | P7: =IFERROR(__xludf.DUMMYFUNCTION("""COMPUTED_VALUE"""),13.6948) -> 13.6948
A8: Bharti Airtel Ltd | B8: 29.844 | C8: 93.8923 | D8: 50.6081 | E8: 98.4876 | F8: -18.7089 | G8: -6.9484 | H8: 346.7708 | I8: 145.0545 | J8: 36.7981 | K8: 23.0703 | L8: 34.0744 | M8: 45.4274 | N8: 48.6333 | P8: =IFERROR(__xludf.DUMMYFUNCTION("""COMPUTED_VALUE"""),19.616) -> 19.616
A9: HCL Technologies Ltd | B9: 24.7966 | C9: 26.6132 | D9: 19.8031 | E9: 23.3745 | F9: 23.9457 | G9: 10.7178 | H9: 14.7866 | I9: 15.5793 | J9: 14.4712 | K9: 20.4612 | L9: 18.8069 | M9: 14.9227 | N9: 13.6879 | P9: =IFERROR(__xludf.DUMMYFUNCTION("""COMPUTED_VALUE"""),19.9915) -> 19.9915
A10: HDFC Bank Ltd | B10: 20.7102 | C10: 16.8729 | D10: 20.3123 | E10: 22.0052 | F10: 26.3971 | G10: 17.9546 | H10: 29.4533 | I10: 27.914 | J10: 25.2239 | K10: 21.9328 | L10: 24.2669 | M10: 21.1122 | N10: 21.9059 | P10: =IFERROR(__xludf.DUMMYFUNCTION("""COMPUTED_VALUE"""),17.9884) -> 17.9884
A11: Hindustan Unilever Ltd | B11: 49.8533 | C11: 51.8576 | D11: 59.4091 | E11: 54.2167 | F11: 71.4311 | G11: 73.7295 | H11: 61.0583 | I11: 55.4545 | J11: 43.9918 | K11: 45.5236 | L11: 43.2771 | M11: 33.0948 | N11: 26.3185 | P11: =IFERROR(__xludf.DUMMYFUNCTION("""COMPUTED_VALUE"""),17.7055) -> 17.7055
A12: ICICI Bank Ltd | B12: 18.6217 | C12: 17.3421 | D12: 17.9533 | E12: 20.1671 | F12: 21.3225 | G12: 21.9109 | H12: 60.3404 | I12: 23.1614 | J12: 17.4167 | K12: 13.494 | L12: 14.8937 | M12: 13.0209 | N12: 12.5507 | P12: =IFERROR(__xludf.DUMMYFUNCTION("""COMPUTED_VALUE"""),27.5537) -> 27.5537
A13: Infosys Ltd | B13: 24.3473 | C13: 23.6441 | D13: 23.9007 | E13: 36.3138 | F13: 29.9879 | G13: 16.4306 | H13: 20.9453 | I13: 15.9617 | J13: 16.2548 | K13: 20.6362 | L13: 20.4748 | M13: 17.5819 | N13: 17.5135 | P13: =IFERROR(__xludf.DUMMYFUNCTION("""COMPUTED_VALUE"""),22.1893) -> 22.1893
A14: ITC Ltd | B14: 14.7463 | C14: 26.0993 | D14: 24.7387 | E14: 20.2749 | F14: 20.4206 | G14: 13.7931 | H14: 28.8058 | I14: 27.635 | J14: 32.9941 | K14: 42.329 | L14: 26.8745 | M14: 31.4572 | N14: 31.8989 | P14: =IFERROR(__xludf.DUMMYFUNCTION("""COMPUTED_VALUE"""),34.9725) -> 34.9725
A15: Kotak Mahindra Bank Ltd | B15: 19.5103 | C15: 19.5276 | D15: 23.1257 | E15: 28.8792 | F15: 34.7121 | G15: 28.9817 | H15: 35.356 | I15: 32.0673 | J15: 32.4321 | K15: 36.0127 | L15: 33.2527 | M15: 24.169 | N15: 22.1264 | P15: =IFERROR(__xludf.DUMMYFUNCTION("""COMPUTED_VALUE"""),49.9737) -> 49.9737
A16: Larsen & Toubro Ltd | B16: 31.9221 | C16: 40.1671 | D16: 29.0531 | E16: 28.6412 | F16: 17.1942 | G16: 11.8585 | H16: 21.7926 | I16: 24.9316 | J16: 36.5185 | K16: 26.7414 | L16: 33.4892 | M16: 24.0259 | N16: 16.0974 | P16: =IFERROR(__xludf.DUMMYFUNCTION("""COMPUTED_VALUE"""),64.4793) -> 64.4793
A17: Mahindra & Mahindra Ltd | B17: 23.0036 | C17: 18.9969 | D17: 12.5371 | E17: 13.6115 | F17: 48.6895 | G17: -247.8261 | H17: 13.7354 | I17: 10.6965 | J17: 37.6083 | K17: 21.3079 | L17: 22.3485 | M17: 12.4039 | N17: 12.3889 | P17: =IFERROR(__xludf.DUMMYFUNCTION("""COMPUTED_VALUE"""),97.5546) -> 97.5546
A18: Maruti Suzuki India Ltd | B18: 24.9815 | C18: 29.4005 | D18: 30.5079 | E18: 58.864 | F18: 47.2109 | G18: 22.8132 | H18: 26.3433 | I18: 33.974 | J18: 24.229 | K18: 20.4369 | L18: 29.3498 | M18: 20.8746 | N18: 15.6557 | P18: =IFERROR(__xludf.DUMMYFUNCTION("""COMPUTED_VALUE"""),77.5053) -> 77.5053
A19: NTPC Ltd | B19: 17.5836 | C19: 15.6547 | D19: 10.0487 | E19: 7.8459 | F19: 7.1587 | G19: 7.1843 | H19: 9.7514 | I19: 15.9193 | J19: 12.7654 | K19: 9.8321 | L19: 12.1676 | M19: 8.6732 | N19: 9.2993 | P19: =IFERROR(__xludf.DUMMYFUNCTION("""COMPUTED_VALUE"""),59.1028) -> 59.1028
A20: Power Grid Corporation of India Ltd | B20: 17.4026 | C20: 15.9591 | D20: 10.2127 | E20: 8.9905 | F20: 9.372 | G20: 7.5213 | H20: 10.3285 | I20: 12.3629 | J20: 13.8483 | K20: 12.2125 | L20: 15.0622 | M20: 11.0929 | N20: 11.368 | P20: =IFERROR(__xludf.DUMMYFUNCTION("""COMPUTED_VALUE"""),66.3657) -> 66.3657
A21: Reliance Industries Ltd | B21: 24.7717 | C21: 28.9291 | D21: 23.6439 | E21: 28.6299 | F21: 26.2302 | G21: 17.6383 | H21: 20.3988 | I21: 14.4864 | J21: 13.0188 | K21: 10.3521 | L21: 10.2946 | M21: 12.1424 | N21: 10.9512 | P21: =IFERROR(__xludf.DUMMYFUNCTION("""COMPUTED_VALUE"""),52.714) -> 52.714
A22: State Bank of India | B22: 8.8781 | C22: 10.012 | D22: 8.3994 | E22: 12.447 | F22: 14.5102 | G22: 8.8916 | H22: 124.3411 | I22: -46.8352 | J22: 943.871 | K22: 12.1818 | L22: 11.7311 | M22: 10.1043 | N22: 0.9373 | P22: =IFERROR(__xludf.DUMMYFUNCTION("""COMPUTED_VALUE"""),52.9773) -> 52.9773
A23: Sun Pharmaceutical Industries Ltd | B23: 38.0581 | C23: 40.614 | D23: 27.8499 | E23: 67.2647 | F23: 49.3884 | G23: 22.4331 | H23: 43.1757 | I23: 55.0444 | J23: 23.7138 | K23: 43.3571 | L23: 30.336 | M23: 37.7204 | N23: 28.4149 | P23: =IFERROR(__xludf.DUMMYFUNCTION("""COMPUTED_VALUE"""),47.757) -> 47.757
A24: Tata Motors Ltd | B24: 8.5539 | C24: 12.1171 | D24: 66.868 | E24: -14.508 | F24: -8.1603 | G24: -2.037 | H24: -2.0532 | I24: 12.3753 | J24: 21.2375 | K24: 11.2788 | L24: 12.66 | M24: 9.1554 | N24: 8.6815 | P24: =IFERROR(__xludf.DUMMYFUNCTION("""COMPUTED_VALUE"""),55.6224) -> 55.6224
A25: Tata Steel Ltd | B25: 56.2956 | C25: -43.0663 | D25: 14.5746 | E25: 3.9328 | F25: 12.7305 | G25: 22.7445 | H25: 5.9356 | I25: 4.456 | J25: -11.2532 | K25: -46.1705 | L25: -7.5012 | M25: 11.1921 | N25: -4.1897 | P25: =IFERROR(__xludf.DUMMYFUNCTION("""COMPUTED_VALUE"""),42.9976) -> 42.9976
A26: Tata Consultancy Services Ltd | B26: 26.8608 | C26: 30.8512 | D26: 27.8305 | E26: 36.0818 | F26: 36.6463 | G26: 21.1515 | H26: 24.0867 | I26: 21.2333 | J26: 18.2228 | K26: 20.4258 | L26: 25.1312 | M26: 21.7902 | N26: 22.1411 | P26: =IFERROR(__xludf.DUMMYFUNCTION("""COMPUTED_VALUE"""),12.1462) -> 12.1462
A27: Tech Mahindra Ltd | B27: 29.5417 | C27: 46.9017 | D27: 20.1214 | E27: 23.6781 | F27: 19.5744 | G27: 12.2257 | H27: 16.014 | I27: 14.8373 | J27: 14.2999 | K27: 13.7772 | L27: 22.9224 | M27: 13.7777 | N27: 10.5022 | P27: =IFERROR(__xludf.DUMMYFUNCTION("""COMPUTED_VALUE"""),12.2436) -> 12.2436
A28: Titan Company Ltd | B28: 81.4407 | C28: 96.5673 | D28: 68.6998 | E28: 103.559 | F28: 142.099 | G28: 55.204 | H28: 71.9027 | I28: 73.8196 | J28: 56.4627 | K28: 44.5789 | L28: 42.6551 | M28: 31.6969 | N28: 31.3953 | P28: =IFERROR(__xludf.DUMMYFUNCTION("""COMPUTED_VALUE"""),24.3878) -> 24.3878
A29: Trent Ltd | B29: 122.065 | C29: 94.4154 | D29: 109.92 | E29: 428.322 | F29: -182.847 | G29: 135.751 | H29: 123.236 | I29: 132.118 | J29: 104.177 | K29: 961.242 | L29: 37.7274 | M29: -183.566 | N29: -113.533 | P29: =IFERROR(__xludf.DUMMYFUNCTION("""COMPUTED_VALUE"""),16.5215) -> 16.5215
A30: UltraTech Cement Ltd | B30: 56.0375 | C30: 40.0948 | D30: 43.3867 | E30: 25.9274 | F30: 35.5718 | G30: 16.3079 | H30: 47.5964 | I30: 48.775 | J30: 40.3351 | K30: 35.7364 | L30: 37.5915 | M30: 27.2082 | N30: 19.1217 | P30: =IFERROR(__xludf.DUMMYFUNCTION("""COMPUTED_VALUE"""),28.8342) -> 28.8342
P31: =IFERROR(__xludf.DUMMYFUNCTION("""COMPUTED_VALUE"""),55.5344) -> 55.5344
P32: =IFERROR(__xludf.DUMMYFUNCTION("""COMPUTED_VALUE"""),39.5767) -> 39.5767
P33: =IFERROR(__xludf.DUMMYFUNCTION("""COMPUTED_VALUE"""),273.871) -> 273.871
A34: Global min | B34: =MIN(B2:N30) -> -247.8261 | P34: =IFERROR(__xludf.DUMMYFUNCTION("""COMPUTED_VALUE"""),29.6735) -> 29.6735
A35: Global Max | B35: =MAX(B2:N30) -> 961.242 | P35: =IFERROR(__xludf.DUMMYFUNCTION("""COMPUTED_VALUE"""),12.658) -> 12.658
P36: =IFERROR(__xludf.DUMMYFUNCTION("""COMPUTED_VALUE"""),17.7567) -> 17.7567
P37: =IFERROR(__xludf.DUMMYFUNCTION("""COMPUTED_VALUE"""),10.8559) -> 10.8559
P38: =IFERROR(__xludf.DUMMYFUNCTION("""COMPUTED_VALUE"""),160.9487) -> 160.9487
P39: =IFERROR(__xludf.DUMMYFUNCTION("""COMPUTED_VALUE"""),141.4131) -> 141.4131
P40: =IFERROR(__xludf.DUMMYFUNCTION("""COMPUTED_VALUE"""),139.34) -> 139.34
...

Sheet Normalised
B1: (P/E)2025 | C1: (P/E)2024 | D1: (P/E)2023 | E1: (P/E)2022 | F1: (P/E)2021 | G1: (P/E)2020 | H1: (P/E)2019 | I1: (P/E)2018 | J1: (P/E)2017 | K1: (P/E)2016 | L1: (P/E)2015 | M1: (P/E)2014 | N1: (P/E)2013
A2: Adani Ports and Special Economic Zone Ltd | B2: =(Sheet1!$B$35 - Sheet1!B2) / (Sheet1!$B$35 - Sheet1!$B$34) -> 0.77598813 | C2: =(Sheet1!$B$35 - Sheet1!C2) / (Sheet1!$B$35 - Sheet1!$B$34) -> 0.76547467 | D2: =(Sheet1!$B$35 - Sheet1!D2) / (Sheet1!$B$35 - Sheet1!$B$34) -> 0.773768 | E2: =(Sheet1!$B$35 - Sheet1!E2) / (Sheet1!$B$35 - Sheet1!$B$34) -> 0.76643201 | F2: =(Sheet1!$B$35 - Sheet1!F2) / (Sheet1!$B$35 - Sheet1!$B$34) -> 0.77138062 | G2: =(Sheet1!$B$35 - Sheet1!G2) / (Sheet1!$B$35 - Sheet1!$B$34) -> 0.78370044 | H2: =(Sheet1!$B$35 - Sheet1!H2) / (Sheet1!$B$35 - Sheet1!$B$34) -> 0.77880311 | I2: =(Sheet1!$B$35 - Sheet1!I2) / (Sheet1!$B$35 - Sheet1!$B$34) -> 0.77849254 | ... N2: =(Sheet1!$B$35 - Sheet1!N2) / (Sheet1!$B$35 - Sheet1!$B$34) -> 0.78008476
A3: Asian Paints Ltd | B3: =(Sheet1!$B$35 - Sheet1!B3) / (Sheet1!$B$35 - Sheet1!$B$34) -> 0.76610201 | C3: =(Sheet1!$B$35 - Sheet1!C3) / (Sheet1!$B$35 - Sheet1!$B$34) -> 0.75369477 | D3: =(Sheet1!$B$35 - Sheet1!D3) / (Sheet1!$B$35 - Sheet1!$B$34) -> 0.74169743 | E3: =(Sheet1!$B$35 - Sheet1!E3) / (Sheet1!$B$35 - Sheet1!$B$34) -> 0.7143414 | F3: =(Sheet1!$B$35 - Sheet1!F3) / (Sheet1!$B$35 - Sheet1!$B$34) -> 0.73092384 | G3: =(Sheet1!$B$35 - Sheet1!G3) / (Sheet1!$B$35 - Sheet1!$B$34) -> 0.74614424 | H3: =(Sheet1!$B$35 - Sheet1!H3) / (Sheet1!$B$35 - Sheet1!$B$34) -> 0.74013722 | I3: =(Sheet1!$B$35 - Sheet1!I3) / (Sheet1!$B$35 - Sheet1!$B$34) -> 0.75142831 | ... N3: =(Sheet1!$B$35 - Sheet1!N3) / (Sheet1!$B$35 - Sheet1!$B$34) -> 0.76002659
A4: AXIS Bank Ltd | B4: =(Sheet1!$B$35 - Sheet1!B4) / (Sheet1!$B$35 - Sheet1!$B$34) -> 0.78498126 | C4: =(Sheet1!$B$35 - Sheet1!C4) / (Sheet1!$B$35 - Sheet1!$B$34) -> 0.7849007 | D4: =(Sheet1!$B$35 - Sheet1!D4) / (Sheet1!$B$35 - Sheet1!$B$34) -> 0.77485644 | E4: =(Sheet1!$B$35 - Sheet1!E4) / (Sheet1!$B$35 - Sheet1!$B$34) -> 0.78136252 | F4: =(Sheet1!$B$35 - Sheet1!F4) / (Sheet1!$B$35 - Sheet1!$B$34) -> 0.77117889 | G4: =(Sheet1!$B$35 - Sheet1!G4) / (Sheet1!$B$35 - Sheet1!$B$34) -> 0.74909561 | H4: =(Sheet1!$B$35 - Sheet1!H4) / (Sheet1!$B$35 - Sheet1!$B$34) -> 0.76229395 | I4: =(Sheet1!$B$35 - Sheet1!I4) / (Sheet1!$B$35 - Sheet1!$B$34) -> 0.56851306 | ... N4: =(Sheet1!$B$35 - Sheet1!N4) / (Sheet1!$B$35 - Sheet1!$B$34) -> 0.78612892
A5: Bajaj Finserv Ltd | B5: =(Sheet1!$B$35 - Sheet1!B5) / (Sheet1!$B$35 - Sheet1!$B$34) -> 0.6619092 | C5: =(Sheet1!$B$35 - Sheet1!C5) / (Sheet1!$B$35 - Sheet1!$B$34) -> 0.67806677 | D5: =(Sheet1!$B$35 - Sheet1!D5) / (Sheet1!$B$35 - Sheet1!$B$34) -> 0.6797814 | E5: =(Sheet1!$B$35 - Sheet1!E5) / (Sheet1!$B$35 - Sheet1!$B$34) -> 0.77405656 | F5: =(Sheet1!$B$35 - Sheet1!F5) / (Sheet1!$B$35 - Sheet1!$B$34) -> 0.77986674 | G5: =(Sheet1!$B$35 - Sheet1!G5) / (Sheet1!$B$35 - Sheet1!$B$34) -> 0.78636935 | H5: =(Sheet1!$B$35 - Sheet1!H5) / (Sheet1!$B$35 - Sheet1!$B$34) -> 0.78266038 | I5: =(Sheet1!$B$35 - Sheet1!I5) / (Sheet1!$B$35 - Sheet1!$B$34) -> 0.78623603 | ... N5: =(Sheet1!$B$35 - Sheet1!N5) / (Sheet1!$B$35 - Sheet1!$B$34) -> 0.78575781
A6: Bajaj Finance Ltd | B6: =(Sheet1!$B$35 - Sheet1!B6) / (Sheet1!$B$35 - Sheet1!$B$34) -> 0.78885821 | C6: =(Sheet1!$B$35 - Sheet1!C6) / (Sheet1!$B$35 - Sheet1!$B$34) -> 0.78928846 | D6: =(Sheet1!$B$35 - Sheet1!D6) / (Sheet1!$B$35 - Sheet1!$B$34) -> 0.78952997 | E6: =(Sheet1!$B$35 - Sheet1!E6) / (Sheet1!$B$35 - Sheet1!$B$34) -> 0.67411199 | F6: =(Sheet1!$B$35 - Sheet1!F6) / (Sheet1!$B$35 - Sheet1!$B$34) -> 0.6863553 | G6: =(Sheet1!$B$35 - Sheet1!G6) / (Sheet1!$B$35 - Sheet1!$B$34) -> 0.75274015 | H6: =(Sheet1!$B$35 - Sheet1!H6) / (Sheet1!$B$35 - Sheet1!$B$34) -> 0.71109667 | I6: =(Sheet1!$B$35 - Sheet1!I6) / (Sheet1!$B$35 - Sheet1!$B$34) -> 0.70493267 | ... N6: =(Sheet1!$B$35 - Sheet1!N6) / (Sheet1!$B$35 - Sheet1!$B$34) -> 0.79034514
A7: Bharat Electronics Ltd | B7: =(Sheet1!$B$35 - Sheet1!B7) / (Sheet1!$B$35 - Sheet1!$B$34) -> 0.76080777 | C7: =(Sheet1!$B$35 - Sheet1!C7) / (Sheet1!$B$35 - Sheet1!$B$34) -> 0.76445545 | D7: =(Sheet1!$B$35 - Sheet1!D7) / (Sheet1!$B$35 - Sheet1!$B$34) -> 0.7753005 | E7: =(Sheet1!$B$35 - Sheet1!E7) / (Sheet1!$B$35 - Sheet1!$B$34) -> 0.77732255 | F7: =(Sheet1!$B$35 - Sheet1!F7) / (Sheet1!$B$35 - Sheet1!$B$34) -> 0.78302388 | G7: =(Sheet1!$B$35 - Sheet1!G7) / (Sheet1!$B$35 - Sheet1!$B$34) -> 0.78681705 | H7: =(Sheet1!$B$35 - Sheet1!H7) / (Sheet1!$B$35 - Sheet1!$B$34) -> 0.78505727 | I7: =(Sheet1!$B$35 - Sheet1!I7) / (Sheet1!$B$35 - Sheet1!$B$34) -> 0.77487496 | ... N7: =(Sheet1!$B$35 - Sheet1!N7) / (Sheet1!$B$35 - Sheet1!$B$34) -> 0.78667901
A8: Bharti Airtel Ltd | B8: =(Sheet1!$B$35 - Sheet1!B8) / (Sheet1!$B$35 - Sheet1!$B$34) -> 0.77034371 | C8: =(Sheet1!$B$35 - Sheet1!C8) / (Sheet1!$B$35 - Sheet1!$B$34) -> 0.71737043 | D8: =(Sheet1!$B$35 - Sheet1!D8) / (Sheet1!$B$35 - Sheet1!$B$34) -> 0.75317007 | E8: =(Sheet1!$B$35 - Sheet1!E8) / (Sheet1!$B$35 - Sheet1!$B$34) -> 0.71356973 | F8: =(Sheet1!$B$35 - Sheet1!F8) / (Sheet1!$B$35 - Sheet1!$B$34) -> 0.810501 | G8: =(Sheet1!$B$35 - Sheet1!G8) / (Sheet1!$B$35 - Sheet1!$B$34) -> 0.80077408 | H8: =(Sheet1!$B$35 - Sheet1!H8) / (Sheet1!$B$35 - Sheet1!$B$34) -> 0.50821885 | I8: =(Sheet1!$B$35 - Sheet1!I8) / (Sheet1!$B$35 - Sheet1!$B$34) -> 0.67505503 | ... N8: =(Sheet1!$B$35 - Sheet1!N8) / (Sheet1!$B$35 - Sheet1!$B$34) -> 0.75480339
A9: HCL Technologies Ltd | B9: =(Sheet1!$B$35 - Sheet1!B9) / (Sheet1!$B$35 - Sheet1!$B$34) -> 0.77451833 | C9: =(Sheet1!$B$35 - Sheet1!C9) / (Sheet1!$B$35 - Sheet1!$B$34) -> 0.77301585 | D9: =(Sheet1!$B$35 - Sheet1!D9) / (Sheet1!$B$35 - Sheet1!$B$34) -> 0.77864837 | E9: =(Sheet1!$B$35 - Sheet1!E9) / (Sheet1!$B$35 - Sheet1!$B$34) -> 0.77569452 | F9: =(Sheet1!$B$35 - Sheet1!F9) / (Sheet1!$B$35 - Sheet1!$B$34) -> 0.77522209 | G9: =(Sheet1!$B$35 - Sheet1!G9) / (Sheet1!$B$35 - Sheet1!$B$34) -> 0.78616267 | H9: =(Sheet1!$B$35 - Sheet1!H9) / (Sheet1!$B$35 - Sheet1!$B$34) -> 0.78279743 | I9: =(Sheet1!$B$35 - Sheet1!I9) / (Sheet1!$B$35 - Sheet1!$B$34) -> 0.7821418 | ... N9: =(Sheet1!$B$35 - Sheet1!N9) / (Sheet1!$B$35 - Sheet1!$B$34) -> 0.78370615
A10: HDFC Bank Ltd | B10: =(Sheet1!$B$35 - Sheet1!B10) / (Sheet1!$B$35 - Sheet1!$B$34) -> 0.77789812 | C10: =(Sheet1!$B$35 - Sheet1!C10) / (Sheet1!$B$35 - Sheet1!$B$34) -> 0.78107189 | D10: =(Sheet1!$B$35 - Sheet1!D10) / (Sheet1!$B$35 - Sheet1!$B$34) -> 0.77822721 | E10: =(Sheet1!$B$35 - Sheet1!E10) / (Sheet1!$B$35 - Sheet1!$B$34) -> 0.77682705 | F10: =(Sheet1!$B$35 - Sheet1!F10) / (Sheet1!$B$35 - Sheet1!$B$34) -> 0.77319458 | G10: =(Sheet1!$B$35 - Sheet1!G10) / (Sheet1!$B$35 - Sheet1!$B$34) -> 0.78017723 | H10: =(Sheet1!$B$35 - Sheet1!H10) / (Sheet1!$B$35 - Sheet1!$B$34) -> 0.77066685 | I10: =(Sheet1!$B$35 - Sheet1!I10) / (Sheet1!$B$35 - Sheet1!$B$34) -> 0.77193998 | ... N10: =(Sheet1!$B$35 - Sheet1!N10) / (Sheet1!$B$35 - Sheet1!$B$34) -> 0.77690917
A11: Hindustan Unilever Ltd | B11: =(Sheet1!$B$35 - Sheet1!B11) / (Sheet1!$B$35 - Sheet1!$B$34) -> 0.75379435 | C11: =(Sheet1!$B$35 - Sheet1!C11) / (Sheet1!$B$35 - Sheet1!$B$34) -> 0.75213662 | D11: =(Sheet1!$B$35 - Sheet1!D11) / (Sheet1!$B$35 - Sheet1!$B$34) -> 0.74589091 | E11: =(Sheet1!$B$35 - Sheet1!E11) / (Sheet1!$B$35 - Sheet1!$B$34) -> 0.75018545 | F11: =(Sheet1!$B$35 - Sheet1!F11) / (Sheet1!$B$35 - Sheet1!$B$34) -> 0.73594771 | G11: =(Sheet1!$B$35 - Sheet1!G11) / (Sheet1!$B$35 - Sheet1!$B$34) -> 0.73404674 | H11: =(Sheet1!$B$35 - Sheet1!H11) / (Sheet1!$B$35 - Sheet1!$B$34) -> 0.74452688 | I11: =(Sheet1!$B$35 - Sheet1!I11) / (Sheet1!$B$35 - Sheet1!$B$34) -> 0.74916169 | ... N11: =(Sheet1!$B$35 - Sheet1!N11) / (Sheet1!$B$35 - Sheet1!$B$34) -> 0.77325959
A12: ICICI Bank Ltd | B12: =(Sheet1!$B$35 - Sheet1!B12) / (Sheet1!$B$35 - Sheet1!$B$34) -> 0.77962548 | C12: =(Sheet1!$B$35 - Sheet1!C12) / (Sheet1!$B$35 - Sheet1!$B$34) -> 0.78068382 | D12: =(Sheet1!$B$35 - Sheet1!D12) / (Sheet1!$B$35 - Sheet1!$B$34) -> 0.7801783 | E12: =(Sheet1!$B$35 - Sheet1!E12) / (Sheet1!$B$35 - Sheet1!$B$34) -> 0.77834731 | F12: =(Sheet1!$B$35 - Sheet1!F12) / (Sheet1!$B$35 - Sheet1!$B$34) -> 0.7773917 | G12: =(Sheet1!$B$35 - Sheet1!G12) / (Sheet1!$B$35 - Sheet1!$B$34) -> 0.77690504 | H12: =(Sheet1!$B$35 - Sheet1!H12) / (Sheet1!$B$35 - Sheet1!$B$34) -> 0.74512064 | I12: =(Sheet1!$B$35 - Sheet1!I12) / (Sheet1!$B$35 - Sheet1!$B$34) -> 0.77587077 | ... N12: =(Sheet1!$B$35 - Sheet1!N12) / (Sheet1!$B$35 - Sheet1!$B$34) -> 0.7846467
A13: Infosys Ltd | B13: =(Sheet1!$B$35 - Sheet1!B13) / (Sheet1!$B$35 - Sheet1!$B$34) -> 0.77488993 | C13: =(Sheet1!$B$35 - Sheet1!C13) / (Sheet1!$B$35 - Sheet1!$B$34) -> 0.77547154 | D13: =(Sheet1!$B$35 - Sheet1!D13) / (Sheet1!$B$35 - Sheet1!$B$34) -> 0.77525931 | E13: =(Sheet1!$B$35 - Sheet1!E13) / (Sheet1!$B$35 - Sheet1!$B$34) -> 0.76499264 | F13: =(Sheet1!$B$35 - Sheet1!F13) / (Sheet1!$B$35 - Sheet1!$B$34) -> 0.77022469 | G13: =(Sheet1!$B$35 - Sheet1!G13) / (Sheet1!$B$35 - Sheet1!$B$34) -> 0.7814377 | H13: =(Sheet1!$B$35 - Sheet1!H13) / (Sheet1!$B$35 - Sheet1!$B$34) -> 0.77770367 | I13: =(Sheet1!$B$35 - Sheet1!I13) / (Sheet1!$B$35 - Sheet1!$B$34) -> 0.78182552 | ... N13: =(Sheet1!$B$35 - Sheet1!N13) / (Sheet1!$B$35 - Sheet1!$B$34) -> 0.78054206
... A30: UltraTech Cement Ltd | B30: =(Sheet1!$B$35 - Sheet1!B30) / (Sheet1!$B$35 - Sheet1!$B$34) -> 0.7486795 | C30: =(Sheet1!$B$35 - Sheet1!C30) / (Sheet1!$B$35 - Sheet1!$B$34) -> 0.76186544 | D30: =(Sheet1!$B$35 - Sheet1!D30) / (Sheet1!$B$35 - Sheet1!$B$34) -> 0.75914276 | E30: =(Sheet1!$B$35 - Sheet1!E30) / (Sheet1!$B$35 - Sheet1!$B$34) -> 0.77358306 | F30: =(Sheet1!$B$35 - Sheet1!F30) / (Sheet1!$B$35 - Sheet1!$B$34) -> 0.76560634 | G30: =(Sheet1!$B$35 - Sheet1!G30) / (Sheet1!$B$35 - Sheet1!$B$34) -> 0.78153919 | H30: =(Sheet1!$B$35 - Sheet1!H30) / (Sheet1!$B$35 - Sheet1!$B$34) -> 0.75566099 | I30: =(Sheet1!$B$35 - Sheet1!I30) / (Sheet1!$B$35 - Sheet1!$B$34) -> 0.75468619 | ... N30: =(Sheet1!$B$35 - Sheet1!N30) / (Sheet1!$B$35 - Sheet1!$B$34) -> 0.77921194
A34: Global min | B34: =MIN(B2:N30) -> 0
A35: Global Max | B35: =MAX(B2:N30) -> 1
