Workbook

Sheet Sheet1
B1: 2025 | C1: 2024 | D1: 2023 | E1: 2022 | F1: 2021 | G1: 2020 | H1: 2019 | I1: 2018 | J1: 2017 | K1: 2016 | L1: 2015 | M1: 2014 | N1: 2013
A2: Adani Ports and Special Economic Zone Ltd | B2: 51.35 | C2: 37.55 | D2: 24.58 | E2: 22.39 | F2: 24.58 | G2: 18.35 | H2: 19.27 | I2: 17.74 | J2: 18.89 | K2: 13.99 | L2: 11.18 | M2: 8.45 | N2: 7.68
A3: Asian Paints Ltd | B3: 38.25 | C3: 56.94 | D3: 42.82 | E3: 31.59 | F3: 32.73 | G3: 28.2 | H3: 22.48 | I3: 21.26 | J3: 20.22 | K3: 18.19 | L3: 14.54 | M3: 12.71 | N3: 116.13
A4: AXIS Bank Ltd | B4: 90.18 | C4: 85.01 | D4: 35.04 | E4: 45.91 | F4: 24.19 | G4: 6.8 | H4: 19.49 | I4: 1.86 | J4: 16.48 | K4: 34.93 | L4: 31.23 | M4: 134.2 | N4: 120.12
A5: Bajaj Finserv Ltd | B5: 9.7 | C5: 7.3 | D5: 4.6 | E5: 26.6 | F5: 11.2 | G5: 41.9 | H5: 19.3 | I5: 8.9 | J5: 4.4 | K5: 10.3 | L5: 7.9 | M5: 5.2 | N5: 3.3
A6: Bajaj Finance Ltd | B6: 268.94 | C6: 235.98 | D6: 189.57 | E6: 115.79 | F6: 73 | G6: 89.07 | H6: 68.75 | I6: 47.05 | J6: 33.67 | K6: 238.85 | L6: 177.7 | M6: 143.65 | N6: 134.56
A7: Bharat Electronics Ltd | B7: 7.28 | C7: 5.45 | D7: 4.09 | E7: 9.85 | F7: 8.62 | G7: 7.49 | H7: 7.74 | I7: 5.83 | J7: 5.94 | K7: 5.57 | L7: 149.65 | M7: 118.91 | N7: 113.85
A8: Bharti Airtel Ltd | B8: 56.04 | C8: 12.8 | D8: 14.57 | E8: 7.63 | F8: -27.65 | G8: -63.41 | H8: 0.96 | I8: 2.75 | J8: 9.51 | K8: 15.2 | L8: 11.56 | M8: 7.01 | N8: 6
A9: HCL Technologies Ltd | B9: 64.09 | C9: 57.86 | D9: 54.79 | E9: 49.77 | F9: 41.07 | G9: 40.75 | H9: 73.55 | I9: 62.19 | J9: 60.27 | K9: 39.69 | L9: 51.79 | M9: 91.93 | N9: 57.2
A10: HDFC Bank Ltd | B10: 92.39 | C10: 90.01 | D10: 82.27 | E10: 68.31 | F10: 57.61 | G10: 49.46 | H10: 82.51 | I10: 70.76 | J10: 59.16 | K10: 50.24 | L10: 43.6 | M10: 36.31 | N10: 28.78
A11: Hindustan Unilever Ltd | B11: 45.32 | C11: 43.74 | D11: 43.07 | E11: 37.79 | F11: 34.03 | G11: 31.17 | H11: 27.96 | I11: 24.08 | J11: 20.67 | K11: 19.09 | L11: 20.16 | M11: 18.23 | N11: 17.7
A12: ICICI Bank Ltd | B12: 71.14 | C12: 61.96 | D12: 47.84 | E12: 35.44 | F12: 26.83 | G12: 14.55 | H12: 6.53 | I12: 11.89 | J12: 15.84 | K12: 17.41 | L12: 21.17 | M12: 95.65 | N12: 83.29
A13: Infosys Ltd | B13: 64.34 | C13: 63.39 | D13: 57.54 | E13: 52.41 | F13: 45.52 | G13: 38.91 | H13: 35.38 | I13: 71 | J13: 62.77 | K13: 59.02 | L13: 108.26 | M13: 186.49 | N13: 165.01
... A30: UltraTech Cement Ltd | B30: 205.13 | C30: 242.87 | D30: 175.54 | E30: 254.53 | F30: 189.33 | G30: 199.49 | H30: 84 | I30: 80.92 | J30: 98.88 | K30: 90.25 | L30: 76.44 | M30: 80.42 | N30: 97.69
A34: Global min | B34: =MIN(B2:N30) -> -84.89
A35: Global Max | B35: =MAX(B2:N30) -> 461.2

Sheet Normalized
B1: 2025 | C1: 2024 | D1: 2023 | E1: 2022 | F1: 2021 | G1: 2020 | H1: 2019 | I1: 2018 | J1: 2017 | K1: 2016 | L1: 2015 | M1: 2014 | N1: 2013 | P1: flattened
A2: Adani Ports and Special Economic Zone Ltd | B2: =(Sheet1!B2 - Sheet1!$B$34) / (Sheet1!$B$35 - Sheet1!$B$34) -> 0.24948269 | C2: =(Sheet1!C2 - Sheet1!$B$34) / (Sheet1!$B$35 - Sheet1!$B$34) -> 0.22421213 | D2: =(Sheet1!D2 - Sheet1!$B$34) / (Sheet1!$B$35 - Sheet1!$B$34) -> 0.20046146 | E2: =(Sheet1!E2 - Sheet1!$B$34) / (Sheet1!$B$35 - Sheet1!$B$34) -> 0.19645113 | F2: =(Sheet1!F2 - Sheet1!$B$34) / (Sheet1!$B$35 - Sheet1!$B$34) -> 0.20046146 | G2: =(Sheet1!G2 - Sheet1!$B$34) / (Sheet1!$B$35 - Sheet1!$B$34) -> 0.18905309 | H2: =(Sheet1!H2 - Sheet1!$B$34) / (Sheet1!$B$35 - Sheet1!$B$34) -> 0.19073779 | I2: =(Sheet1!I2 - Sheet1!$B$34) / (Sheet1!$B$35 - Sheet1!$B$34) -> 0.18793605 | ... N2: =(Sheet1!N2 - Sheet1!$B$34) / (Sheet1!$B$35 - Sheet1!$B$34) -> 0.16951418 | P2: =IFERROR(__xludf.DUMMYFUNCTION("FLATTEN(B2:N30)"),0.2494826860041385) -> 0.24948269
A3: Asian Paints Ltd | B3: =(Sheet1!B3 - Sheet1!$B$34) / (Sheet1!$B$35 - Sheet1!$B$34) -> 0.22549397 | C3: =(Sheet1!C3 - Sheet1!$B$34) / (Sheet1!$B$35 - Sheet1!$B$34) -> 0.25971909 | D3: =(Sheet1!D3 - Sheet1!$B$34) / (Sheet1!$B$35 - Sheet1!$B$34) -> 0.23386255 | E3: =(Sheet1!E3 - Sheet1!$B$34) / (Sheet1!$B$35 - Sheet1!$B$34) -> 0.21329817 | F3: =(Sheet1!F3 - Sheet1!$B$34) / (Sheet1!$B$35 - Sheet1!$B$34) -> 0.21538574 | G3: =(Sheet1!G3 - Sheet1!$B$34) / (Sheet1!$B$35 - Sheet1!$B$34) -> 0.20709041 | H3: =(Sheet1!H3 - Sheet1!$B$34) / (Sheet1!$B$35 - Sheet1!$B$34) -> 0.19661594 | I3: =(Sheet1!I3 - Sheet1!$B$34) / (Sheet1!$B$35 - Sheet1!$B$34) -> 0.19438188 | ... N3: =(Sheet1!N3 - Sheet1!$B$34) / (Sheet1!$B$35 - Sheet1!$B$34) -> 0.36810782 | P3: =IFERROR(__xludf.DUMMYFUNCTION("""COMPUTED_VALUE"""),0.224212126206303) -> 0.22421213
A4: AXIS Bank Ltd | B4: =(Sheet1!B4 - Sheet1!$B$34) / (Sheet1!$B$35 - Sheet1!$B$34) -> 0.32058818 | C4: =(Sheet1!C4 - Sheet1!$B$34) / (Sheet1!$B$35 - Sheet1!$B$34) -> 0.31112088 | D4: =(Sheet1!D4 - Sheet1!$B$34) / (Sheet1!$B$35 - Sheet1!$B$34) -> 0.21961581 | E4: =(Sheet1!E4 - Sheet1!$B$34) / (Sheet1!$B$35 - Sheet1!$B$34) -> 0.23952096 | F4: =(Sheet1!F4 - Sheet1!$B$34) / (Sheet1!$B$35 - Sheet1!$B$34) -> 0.19974729 | G4: =(Sheet1!G4 - Sheet1!$B$34) / (Sheet1!$B$35 - Sheet1!$B$34) -> 0.16790273 | H4: =(Sheet1!H4 - Sheet1!$B$34) / (Sheet1!$B$35 - Sheet1!$B$34) -> 0.19114065 | I4: =(Sheet1!I4 - Sheet1!$B$34) / (Sheet1!$B$35 - Sheet1!$B$34) -> 0.1588566 | ... N4: =(Sheet1!N4 - Sheet1!$B$34) / (Sheet1!$B$35 - Sheet1!$B$34) -> 0.37541431 | P4: =IFERROR(__xludf.DUMMYFUNCTION("""COMPUTED_VALUE"""),0.2004614623963083) -> 0.20046146
A5: Bajaj Finserv Ltd | B5: =(Sheet1!B5 - Sheet1!$B$34) / (Sheet1!$B$35 - Sheet1!$B$34) -> 0.17321321 | C5: =(Sheet1!C5 - Sheet1!$B$34) / (Sheet1!$B$35 - Sheet1!$B$34) -> 0.16881833 | D5: =(Sheet1!D5 - Sheet1!$B$34) / (Sheet1!$B$35 - Sheet1!$B$34) -> 0.16387409 | E5: =(Sheet1!E5 - Sheet1!$B$34) / (Sheet1!$B$35 - Sheet1!$B$34) -> 0.20416049 | F5: =(Sheet1!F5 - Sheet1!$B$34) / (Sheet1!$B$35 - Sheet1!$B$34) -> 0.17596001 | G5: =(Sheet1!G5 - Sheet1!$B$34) / (Sheet1!$B$35 - Sheet1!$B$34) -> 0.23217785 | H5: =(Sheet1!H5 - Sheet1!$B$34) / (Sheet1!$B$35 - Sheet1!$B$34) -> 0.19079273 | I5: =(Sheet1!I5 - Sheet1!$B$34) / (Sheet1!$B$35 - Sheet1!$B$34) -> 0.17174825 | ... N5: =(Sheet1!N5 - Sheet1!$B$34) / (Sheet1!$B$35 - Sheet1!$B$34) -> 0.16149353 | P5: =IFERROR(__xludf.DUMMYFUNCTION("""COMPUTED_VALUE"""),0.1964511344283909) -> 0.19645113
A6: Bajaj Finance Ltd | B6: =(Sheet1!B6 - Sheet1!$B$34) / (Sheet1!$B$35 - Sheet1!$B$34) -> 0.64793349 | C6: =(Sheet1!C6 - Sheet1!$B$34) / (Sheet1!$B$35 - Sheet1!$B$34) -> 0.58757714 | D6: =(Sheet1!D6 - Sheet1!$B$34) / (Sheet1!$B$35 - Sheet1!$B$34) -> 0.50259115 | E6: =(Sheet1!E6 - Sheet1!$B$34) / (Sheet1!$B$35 - Sheet1!$B$34) -> 0.36748521 | F6: =(Sheet1!F6 - Sheet1!$B$34) / (Sheet1!$B$35 - Sheet1!$B$34) -> 0.28912817 | G6: =(Sheet1!G6 - Sheet1!$B$34) / (Sheet1!$B$35 - Sheet1!$B$34) -> 0.31855555 | H6: =(Sheet1!H6 - Sheet1!$B$34) / (Sheet1!$B$35 - Sheet1!$B$34) -> 0.28134557 | I6: =(Sheet1!I6 - Sheet1!$B$34) / (Sheet1!$B$35 - Sheet1!$B$34) -> 0.24160853 | ... N6: =(Sheet1!N6 - Sheet1!$B$34) / (Sheet1!$B$35 - Sheet1!$B$34) -> 0.40185684 | P6: =IFERROR(__xludf.DUMMYFUNCTION("""COMPUTED_VALUE"""),0.2004614623963083) -> 0.20046146
A7: Bharat Electronics Ltd | B7: =(Sheet1!B7 - Sheet1!$B$34) / (Sheet1!$B$35 - Sheet1!$B$34) -> 0.1687817 | C7: =(Sheet1!C7 - Sheet1!$B$34) / (Sheet1!$B$35 - Sheet1!$B$34) -> 0.16543061 | D7: =(Sheet1!D7 - Sheet1!$B$34) / (Sheet1!$B$35 - Sheet1!$B$34) -> 0.16294017 | E7: =(Sheet1!E7 - Sheet1!$B$34) / (Sheet1!$B$35 - Sheet1!$B$34) -> 0.17348789 | F7: =(Sheet1!F7 - Sheet1!$B$34) / (Sheet1!$B$35 - Sheet1!$B$34) -> 0.17123551 | G7: =(Sheet1!G7 - Sheet1!$B$34) / (Sheet1!$B$35 - Sheet1!$B$34) -> 0.16916625 | H7: =(Sheet1!H7 - Sheet1!$B$34) / (Sheet1!$B$35 - Sheet1!$B$34) -> 0.16962405 | I7: =(Sheet1!I7 - Sheet1!$B$34) / (Sheet1!$B$35 - Sheet1!$B$34) -> 0.16612646 | ... N7: =(Sheet1!N7 - Sheet1!$B$34) / (Sheet1!$B$35 - Sheet1!$B$34) -> 0.36393269 | P7: =IFERROR(__xludf.DUMMYFUNCTION("""COMPUTED_VALUE"""),0.18905308648757532) -> 0.18905309
A8: Bharti Airtel Ltd | B8: =(Sheet1!B8 - Sheet1!$B$34) / (Sheet1!$B$35 - Sheet1!$B$34) -> 0.25807101 | C8: =(Sheet1!C8 - Sheet1!$B$34) / (Sheet1!$B$35 - Sheet1!$B$34) -> 0.17888993 | D8: =(Sheet1!D8 - Sheet1!$B$34) / (Sheet1!$B$35 - Sheet1!$B$34) -> 0.18213115 | E8: =(Sheet1!E8 - Sheet1!$B$34) / (Sheet1!$B$35 - Sheet1!$B$34) -> 0.16942262 | F8: =(Sheet1!F8 - Sheet1!$B$34) / (Sheet1!$B$35 - Sheet1!$B$34) -> 0.10481789 | G8: =(Sheet1!G8 - Sheet1!$B$34) / (Sheet1!$B$35 - Sheet1!$B$34) -> 0.039334176 | H8: =(Sheet1!H8 - Sheet1!$B$34) / (Sheet1!$B$35 - Sheet1!$B$34) -> 0.15720852 | I8: =(Sheet1!I8 - Sheet1!$B$34) / (Sheet1!$B$35 - Sheet1!$B$34) -> 0.16048637 | ... N8: =(Sheet1!N8 - Sheet1!$B$34) / (Sheet1!$B$35 - Sheet1!$B$34) -> 0.16643777 | P8: =IFERROR(__xludf.DUMMYFUNCTION("""COMPUTED_VALUE"""),0.19073779047409767) -> 0.19073779
A9: HCL Technologies Ltd | B9: =(Sheet1!B9 - Sheet1!$B$34) / (Sheet1!$B$35 - Sheet1!$B$34) -> 0.27281217 | C9: =(Sheet1!C9 - Sheet1!$B$34) / (Sheet1!$B$35 - Sheet1!$B$34) -> 0.2614038 | D9: =(Sheet1!D9 - Sheet1!$B$34) / (Sheet1!$B$35 - Sheet1!$B$34) -> 0.25578201 | E9: =(Sheet1!E9 - Sheet1!$B$34) / (Sheet1!$B$35 - Sheet1!$B$34) -> 0.24658939 | F9: =(Sheet1!F9 - Sheet1!$B$34) / (Sheet1!$B$35 - Sheet1!$B$34) -> 0.23065795 | G9: =(Sheet1!G9 - Sheet1!$B$34) / (Sheet1!$B$35 - Sheet1!$B$34) -> 0.23007197 | H9: =(Sheet1!H9 - Sheet1!$B$34) / (Sheet1!$B$35 - Sheet1!$B$34) -> 0.29013533 | I9: =(Sheet1!I9 - Sheet1!$B$34) / (Sheet1!$B$35 - Sheet1!$B$34) -> 0.26933289 | ... N9: =(Sheet1!N9 - Sheet1!$B$34) / (Sheet1!$B$35 - Sheet1!$B$34) -> 0.26019521 | P9: =IFERROR(__xludf.DUMMYFUNCTION("""COMPUTED_VALUE"""),0.18793605449651155) -> 0.18793605
A10: HDFC Bank Ltd | B10: =(Sheet1!B10 - Sheet1!$B$34) / (Sheet1!$B$35 - Sheet1!$B$34) -> 0.32463513 | C10: =(Sheet1!C10 - Sheet1!$B$34) / (Sheet1!$B$35 - Sheet1!$B$34) -> 0.32027688 | D10: =(Sheet1!D10 - Sheet1!$B$34) / (Sheet1!$B$35 - Sheet1!$B$34) -> 0.30610339 | E10: =(Sheet1!E10 - Sheet1!$B$34) / (Sheet1!$B$35 - Sheet1!$B$34) -> 0.28053984 | F10: =(Sheet1!F10 - Sheet1!$B$34) / (Sheet1!$B$35 - Sheet1!$B$34) -> 0.260946 | G10: =(Sheet1!G10 - Sheet1!$B$34) / (Sheet1!$B$35 - Sheet1!$B$34) -> 0.24602172 | H10: =(Sheet1!H10 - Sheet1!$B$34) / (Sheet1!$B$35 - Sheet1!$B$34) -> 0.30654288 | I10: =(Sheet1!I10 - Sheet1!$B$34) / (Sheet1!$B$35 - Sheet1!$B$34) -> 0.28502628 | ... N10: =(Sheet1!N10 - Sheet1!$B$34) / (Sheet1!$B$35 - Sheet1!$B$34) -> 0.2081525 | P10: =IFERROR(__xludf.DUMMYFUNCTION("""COMPUTED_VALUE"""),0.19004193447966453) -> 0.19004193
A11: Hindustan Unilever Ltd | B11: =(Sheet1!B11 - Sheet1!$B$34) / (Sheet1!$B$35 - Sheet1!$B$34) -> 0.23844055 | C11: =(Sheet1!C11 - Sheet1!$B$34) / (Sheet1!$B$35 - Sheet1!$B$34) -> 0.23554725 | D11: =(Sheet1!D11 - Sheet1!$B$34) / (Sheet1!$B$35 - Sheet1!$B$34) -> 0.23432035 | E11: =(Sheet1!E11 - Sheet1!$B$34) / (Sheet1!$B$35 - Sheet1!$B$34) -> 0.22465161 | F11: =(Sheet1!F11 - Sheet1!$B$34) / (Sheet1!$B$35 - Sheet1!$B$34) -> 0.2177663 | G11: =(Sheet1!G11 - Sheet1!$B$34) / (Sheet1!$B$35 - Sheet1!$B$34) -> 0.21252907 | H11: =(Sheet1!H11 - Sheet1!$B$34) / (Sheet1!$B$35 - Sheet1!$B$34) -> 0.20665092 | I11: =(Sheet1!I11 - Sheet1!$B$34) / (Sheet1!$B$35 - Sheet1!$B$34) -> 0.19954586 | ... N11: =(Sheet1!N11 - Sheet1!$B$34) / (Sheet1!$B$35 - Sheet1!$B$34) -> 0.18786281 | P11: =IFERROR(__xludf.DUMMYFUNCTION("""COMPUTED_VALUE"""),0.18106905455144753) -> 0.18106905
A12: ICICI Bank Ltd | B12: =(Sheet1!B12 - Sheet1!$B$34) / (Sheet1!$B$35 - Sheet1!$B$34) -> 0.28572213 | C12: =(Sheet1!C12 - Sheet1!$B$34) / (Sheet1!$B$35 - Sheet1!$B$34) -> 0.26891172 | D12: =(Sheet1!D12 - Sheet1!$B$34) / (Sheet1!$B$35 - Sheet1!$B$34) -> 0.24305517 | E12: =(Sheet1!E12 - Sheet1!$B$34) / (Sheet1!$B$35 - Sheet1!$B$34) -> 0.22034829 | F12: =(Sheet1!F12 - Sheet1!$B$34) / (Sheet1!$B$35 - Sheet1!$B$34) -> 0.20458166 | G12: =(Sheet1!G12 - Sheet1!$B$34) / (Sheet1!$B$35 - Sheet1!$B$34) -> 0.18209453 | H12: =(Sheet1!H12 - Sheet1!$B$34) / (Sheet1!$B$35 - Sheet1!$B$34) -> 0.1674083 | I12: =(Sheet1!I12 - Sheet1!$B$34) / (Sheet1!$B$35 - Sheet1!$B$34) -> 0.17722353 | ... N12: =(Sheet1!N12 - Sheet1!$B$34) / (Sheet1!$B$35 - Sheet1!$B$34) -> 0.30797121 | P12: =IFERROR(__xludf.DUMMYFUNCTION("""COMPUTED_VALUE"""),0.17592338259261292) -> 0.17592338
A13: Infosys Ltd | B13: =(Sheet1!B13 - Sheet1!$B$34) / (Sheet1!$B$35 - Sheet1!$B$34) -> 0.27326997 | C13: =(Sheet1!C13 - Sheet1!$B$34) / (Sheet1!$B$35 - Sheet1!$B$34) -> 0.27153033 | D13: =(Sheet1!D13 - Sheet1!$B$34) / (Sheet1!$B$35 - Sheet1!$B$34) -> 0.26081781 | E13: =(Sheet1!E13 - Sheet1!$B$34) / (Sheet1!$B$35 - Sheet1!$B$34) -> 0.25142376 | F13: =(Sheet1!F13 - Sheet1!$B$34) / (Sheet1!$B$35 - Sheet1!$B$34) -> 0.23880679 | G13: =(Sheet1!G13 - Sheet1!$B$34) / (Sheet1!$B$35 - Sheet1!$B$34) -> 0.22670256 | H13: =(Sheet1!H13 - Sheet1!$B$34) / (Sheet1!$B$35 - Sheet1!$B$34) -> 0.22023842 | I13: =(Sheet1!I13 - Sheet1!$B$34) / (Sheet1!$B$35 - Sheet1!$B$34) -> 0.28546577 | ... N13: =(Sheet1!N13 - Sheet1!$B$34) / (Sheet1!$B$35 - Sheet1!$B$34) -> 0.45761688 | P13: =IFERROR(__xludf.DUMMYFUNCTION("""COMPUTED_VALUE"""),0.17092420663260635) -> 0.17092421
A14: ITC Ltd | B14: =(Sheet1!B14 - Sheet1!$B$34) / (Sheet1!$B$35 - Sheet1!$B$34) -> 0.20626637 | C14: =(Sheet1!C14 - Sheet1!$B$34) / (Sheet1!$B$35 - Sheet1!$B$34) -> 0.18544562 | D14: =(Sheet1!D14 - Sheet1!$B$34) / (Sheet1!$B$35 - Sheet1!$B$34) -> 0.18376092 | E14: =(Sheet1!E14 - Sheet1!$B$34) / (Sheet1!$B$35 - Sheet1!$B$34) -> 0.17810251 | F14: =(Sheet1!F14 - Sheet1!$B$34) / (Sheet1!$B$35 - Sheet1!$B$34) -> 0.17504441 | G14: =(Sheet1!G14 - Sheet1!$B$34) / (Sheet1!$B$35 - Sheet1!$B$34) -> 0.17824901 | H14: =(Sheet1!H14 - Sheet1!$B$34) / (Sheet1!$B$35 - Sheet1!$B$34) -> 0.17420205 | I14: =(Sheet1!I14 - Sheet1!$B$34) / (Sheet1!$B$35 - Sheet1!$B$34) -> 0.17229761 | ... N14: =(Sheet1!N14 - Sheet1!$B$34) / (Sheet1!$B$35 - Sheet1!$B$34) -> 0.17295684 | P14: =IFERROR(__xludf.DUMMYFUNCTION("""COMPUTED_VALUE"""),0.1695141826438865) -> 0.16951418
A15: Kotak Mahindra Bank Ltd | B15: =(Sheet1!B15 - Sheet1!$B$34) / (Sheet1!$B$35 - Sheet1!$B$34) -> 0.35924481 | C15: =(Sheet1!C15 - Sheet1!$B$34) / (Sheet1!$B$35 - Sheet1!$B$34) -> 0.32291381 | D15: =(Sheet1!D15 - Sheet1!$B$34) / (Sheet1!$B$35 - Sheet1!$B$34) -> 0.29268069 | E15: =(Sheet1!E15 - Sheet1!$B$34) / (Sheet1!$B$35 - Sheet1!$B$34) -> 0.26665934 | F15: =(Sheet1!F15 - Sheet1!$B$34) / (Sheet1!$B$35 - Sheet1!$B$34) -> 0.24790785 | G15: =(Sheet1!G15 - Sheet1!$B$34) / (Sheet1!$B$35 - Sheet1!$B$34) -> 0.23726858 | H15: =(Sheet1!H15 - Sheet1!$B$34) / (Sheet1!$B$35 - Sheet1!$B$34) -> 0.22456005 | I15: =(Sheet1!I15 - Sheet1!$B$34) / (Sheet1!$B$35 - Sheet1!$B$34) -> 0.21525756 | ... N15: =(Sheet1!N15 - Sheet1!$B$34) / (Sheet1!$B$35 - Sheet1!$B$34) -> 0.20915966 | P15: =IFERROR(__xludf.DUMMYFUNCTION("""COMPUTED_VALUE"""),0.22549396619604825) -> 0.22549397
A16: Larsen & Toubro Ltd | B16: =(Sheet1!B16 - Sheet1!$B$34) / (Sheet1!$B$35 - Sheet1!$B$34) -> 0.3555641 | C16: =(Sheet1!C16 - Sheet1!$B$34) / (Sheet1!$B$35 - Sheet1!$B$34) -> 0.32736362 | D16: =(Sheet1!D16 - Sheet1!$B$34) / (Sheet1!$B$35 - Sheet1!$B$34) -> 0.29178341 | E16: =(Sheet1!E16 - Sheet1!$B$34) / (Sheet1!$B$35 - Sheet1!$B$34) -> 0.26834405 | F16: =(Sheet1!F16 - Sheet1!$B$34) / (Sheet1!$B$35 - Sheet1!$B$34) -> 0.30635976 | G16: =(Sheet1!G16 - Sheet1!$B$34) / (Sheet1!$B$35 - Sheet1!$B$34) -> 0.27988061 | H16: =(Sheet1!H16 - Sheet1!$B$34) / (Sheet1!$B$35 - Sheet1!$B$34) -> 0.27154865 | I16: =(Sheet1!I16 - Sheet1!$B$34) / (Sheet1!$B$35 - Sheet1!$B$34) -> 0.25157025 | ... N16: =(Sheet1!N16 - Sheet1!$B$34) / (Sheet1!$B$35 - Sheet1!$B$34) -> 0.30945449 | P16: =IFERROR(__xludf.DUMMYFUNCTION("""COMPUTED_VALUE"""),0.2597190939222472) -> 0.25971909
A17: Mahindra & Mahindra Ltd | B17: =(Sheet1!B17 - Sheet1!$B$34) / (Sheet1!$B$35 - Sheet1!$B$34) -> 0.36614844 | C17: =(Sheet1!C17 - Sheet1!$B$34) / (Sheet1!$B$35 - Sheet1!$B$34) -> 0.33985241 | D17: =(Sheet1!D17 - Sheet1!$B$34) / (Sheet1!$B$35 - Sheet1!$B$34) -> 0.32384772 | E17: =(Sheet1!E17 - Sheet1!$B$34) / (Sheet1!$B$35 - Sheet1!$B$34) -> 0.26318006 | F17: =(Sheet1!F17 - Sheet1!$B$34) / (Sheet1!$B$35 - Sheet1!$B$34) -> 0.18502445 | G17: =(Sheet1!G17 - Sheet1!$B$34) / (Sheet1!$B$35 - Sheet1!$B$34) -> 0.15354612 | H17: =(Sheet1!H17 - Sheet1!$B$34) / (Sheet1!$B$35 - Sheet1!$B$34) -> 0.24463001 | I17: =(Sheet1!I17 - Sheet1!$B$34) / (Sheet1!$B$35 - Sheet1!$B$34) -> 0.281547 | ... N17: =(Sheet1!N17 - Sheet1!$B$34) / (Sheet1!$B$35 - Sheet1!$B$34) -> 0.27770148 | P17: =IFERROR(__xludf.DUMMYFUNCTION("""COMPUTED_VALUE"""),0.2338625501290996) -> 0.23386255
A18: Maruti Suzuki India Ltd | B18: =(Sheet1!B18 - Sheet1!$B$34) / (Sheet1!$B$35 - Sheet1!$B$34) -> 1 | C18: =(Sheet1!C18 - Sheet1!$B$34) / (Sheet1!$B$35 - Sheet1!$B$34) -> 0.94105367 | D18: =(Sheet1!D18 - Sheet1!$B$34) / (Sheet1!$B$35 - Sheet1!$B$34) -> 0.65320735 | E18: =(Sheet1!E18 - Sheet1!$B$34) / (Sheet1!$B$35 - Sheet1!$B$34) -> 0.39063158 | F18: =(Sheet1!F18 - Sheet1!$B$34) / (Sheet1!$B$35 - Sheet1!$B$34) -> 0.42152392 | G18: =(Sheet1!G18 - Sheet1!$B$34) / (Sheet1!$B$35 - Sheet1!$B$34) -> 0.4996246 | H18: =(Sheet1!H18 - Sheet1!$B$34) / (Sheet1!$B$35 - Sheet1!$B$34) -> 0.61922027 | I18: =(Sheet1!I18 - Sheet1!$B$34) / (Sheet1!$B$35 - Sheet1!$B$34) -> 0.63317402 | ... N18: =(Sheet1!N18 - Sheet1!$B$34) / (Sheet1!$B$35 - Sheet1!$B$34) -> 0.30513285 | P18: =IFERROR(__xludf.DUMMYFUNCTION("""COMPUTED_VALUE"""),0.2132981742936146) -> 0.21329817
A19: NTPC Ltd | B19: =(Sheet1!B19 - Sheet1!$B$34) / (Sheet1!$B$35 - Sheet1!$B$34) -> 0.19269717 | C19: =(Sheet1!C19 - Sheet1!$B$34) / (Sheet1!$B$35 - Sheet1!$B$34) -> 0.19474812 | D19: =(Sheet1!D19 - Sheet1!$B$34) / (Sheet1!$B$35 - Sheet1!$B$34) -> 0.18817411 | E19: =(Sheet1!E19 - Sheet1!$B$34) / (Sheet1!$B$35 - Sheet1!$B$34) -> 0.18412716 | F19: =(Sheet1!F19 - Sheet1!$B$34) / (Sheet1!$B$35 - Sheet1!$B$34) -> 0.18268051 | G19: =(Sheet1!G19 - Sheet1!$B$34) / (Sheet1!$B$35 - Sheet1!$B$34) -> 0.17691223 | H19: =(Sheet1!H19 - Sheet1!$B$34) / (Sheet1!$B$35 - Sheet1!$B$34) -> 0.18086762 | I19: =(Sheet1!I19 - Sheet1!$B$34) / (Sheet1!$B$35 - Sheet1!$B$34) -> 0.17497116 | ... N19: =(Sheet1!N19 - Sheet1!$B$34) / (Sheet1!$B$35 - Sheet1!$B$34) -> 0.18341299 | P19: =IFERROR(__xludf.DUMMYFUNCTION("""COMPUTED_VALUE"""),0.21538574227691407) -> 0.21538574
A20: Power Grid Corporation of India Ltd | B20: =(Sheet1!B20 - Sheet1!$B$34) / (Sheet1!$B$35 - Sheet1!$B$34) -> 0.18601329 | C20: =(Sheet1!C20 - Sheet1!$B$34) / (Sheet1!$B$35 - Sheet1!$B$34) -> 0.1872402 | D20: =(Sheet1!D20 - Sheet1!$B$34) / (Sheet1!$B$35 - Sheet1!$B$34) -> 0.19592009 | E20: =(Sheet1!E20 - Sheet1!$B$34) / (Sheet1!$B$35 - Sheet1!$B$34) -> 0.19961911 | F20: =(Sheet1!F20 - Sheet1!$B$34) / (Sheet1!$B$35 - Sheet1!$B$34) -> 0.19758648 | G20: =(Sheet1!G20 - Sheet1!$B$34) / (Sheet1!$B$35 - Sheet1!$B$34) -> 0.19416213 | H20: =(Sheet1!H20 - Sheet1!$B$34) / (Sheet1!$B$35 - Sheet1!$B$34) -> 0.19057298 | I20: =(Sheet1!I20 - Sheet1!$B$34) / (Sheet1!$B$35 - Sheet1!$B$34) -> 0.18416378 | ... N20: =(Sheet1!N20 - Sheet1!$B$34) / (Sheet1!$B$35 - Sheet1!$B$34) -> 0.17251735 | P20: =IFERROR(__xludf.DUMMYFUNCTION("""COMPUTED_VALUE"""),0.20709040634327675) -> 0.20709041
A21: Reliance Industries Ltd | B21: =(Sheet1!B21 - Sheet1!$B$34) / (Sheet1!$B$35 - Sheet1!$B$34) -> 0.24970243 | C21: =(Sheet1!C21 - Sheet1!$B$34) / (Sheet1!$B$35 - Sheet1!$B$34) -> 0.34388105 | D21: =(Sheet1!D21 - Sheet1!$B$34) / (Sheet1!$B$35 - Sheet1!$B$34) -> 0.33598857 | E21: =(Sheet1!E21 - Sheet1!$B$34) / (Sheet1!$B$35 - Sheet1!$B$34) -> 0.32181509 | F21: =(Sheet1!F21 - Sheet1!$B$34) / (Sheet1!$B$35 - Sheet1!$B$34) -> 0.29317512 | G21: =(Sheet1!G21 - Sheet1!$B$34) / (Sheet1!$B$35 - Sheet1!$B$34) -> 0.27092604 | H21: =(Sheet1!H21 - Sheet1!$B$34) / (Sheet1!$B$35 - Sheet1!$B$34) -> 0.27777473 | I21: =(Sheet1!I21 - Sheet1!$B$34) / (Sheet1!$B$35 - Sheet1!$B$34) -> 0.26695233 | ... N21: =(Sheet1!N21 - Sheet1!$B$34) / (Sheet1!$B$35 - Sheet1!$B$34) -> 0.28482485 | P21: =IFERROR(__xludf.DUMMYFUNCTION("""COMPUTED_VALUE"""),0.19661594242707245) -> 0.19661594
A22: State Bank of India | B22: =(Sheet1!B22 - Sheet1!$B$34) / (Sheet1!$B$35 - Sheet1!$B$34) -> 0.31460016 | C22: =(Sheet1!C22 - Sheet1!$B$34) / (Sheet1!$B$35 - Sheet1!$B$34) -> 0.29310187 | D22: =(Sheet1!D22 - Sheet1!$B$34) / (Sheet1!$B$35 - Sheet1!$B$34) -> 0.26962589 | E22: =(Sheet1!E22 - Sheet1!$B$34) / (Sheet1!$B$35 - Sheet1!$B$34) -> 0.22803933 | F22: =(Sheet1!F22 - Sheet1!$B$34) / (Sheet1!$B$35 - Sheet1!$B$34) -> 0.201432 | G22: =(Sheet1!G22 - Sheet1!$B$34) / (Sheet1!$B$35 - Sheet1!$B$34) -> 0.19601165 | H22: =(Sheet1!H22 - Sheet1!$B$34) / (Sheet1!$B$35 - Sheet1!$B$34) -> 0.16017506 | I22: =(Sheet1!I22 - Sheet1!$B$34) / (Sheet1!$B$35 - Sheet1!$B$34) -> 0.14567196 | ... N22: =(Sheet1!N22 - Sheet1!$B$34) / (Sheet1!$B$35 - Sheet1!$B$34) -> 0.64405135 | P22: =IFERROR(__xludf.DUMMYFUNCTION("""COMPUTED_VALUE"""),0.19438187844494498) -> 0.19438188
A23: Sun Pharmaceutical Industries Ltd | B23: =(Sheet1!B23 - Sheet1!$B$34) / (Sheet1!$B$35 - Sheet1!$B$34) -> 0.23895329 | C23: =(Sheet1!C23 - Sheet1!$B$34) / (Sheet1!$B$35 - Sheet1!$B$34) -> 0.22851545 | D23: =(Sheet1!D23 - Sheet1!$B$34) / (Sheet1!$B$35 - Sheet1!$B$34) -> 0.22009193 | E23: =(Sheet1!E23 - Sheet1!$B$34) / (Sheet1!$B$35 - Sheet1!$B$34) -> 0.18035489 | F23: =(Sheet1!F23 - Sheet1!$B$34) / (Sheet1!$B$35 - Sheet1!$B$34) -> 0.17760809 | G23: =(Sheet1!G23 - Sheet1!$B$34) / (Sheet1!$B$35 - Sheet1!$B$34) -> 0.18420041 | H23: =(Sheet1!H23 - Sheet1!$B$34) / (Sheet1!$B$35 - Sheet1!$B$34) -> 0.17577689 | I23: =(Sheet1!I23 - Sheet1!$B$34) / (Sheet1!$B$35 - Sheet1!$B$34) -> 0.17193137 | ... N23: =(Sheet1!N23 - Sheet1!$B$34) / (Sheet1!$B$35 - Sheet1!$B$34) -> 0.20818913 | P23: =IFERROR(__xludf.DUMMYFUNCTION("""COMPUTED_VALUE"""),0.19247743046018054) -> 0.19247743
A24: Tata Motors Ltd | B24: =(Sheet1!B24 - Sheet1!$B$34) / (Sheet1!$B$35 - Sheet1!$B$34) -> 0.29965757 | C24: =(Sheet1!C24 - Sheet1!$B$34) / (Sheet1!$B$35 - Sheet1!$B$34) -> 0.30538922 | D24: =(Sheet1!D24 - Sheet1!$B$34) / (Sheet1!$B$35 - Sheet1!$B$34) -> 0.16696881 | E24: =(Sheet1!E24 - Sheet1!$B$34) / (Sheet1!$B$35 - Sheet1!$B$34) -> 0.10073431 | F24: =(Sheet1!F24 - Sheet1!$B$34) / (Sheet1!$B$35 - Sheet1!$B$34) -> 0.087714479 | G24: =(Sheet1!G24 - Sheet1!$B$34) / (Sheet1!$B$35 - Sheet1!$B$34) -> 0.091578311 | H24: =(Sheet1!H24 - Sheet1!$B$34) / (Sheet1!$B$35 - Sheet1!$B$34) -> 0 | I24: =(Sheet1!I24 - Sheet1!$B$34) / (Sheet1!$B$35 - Sheet1!$B$34) -> 0.20388581 | ... N24: =(Sheet1!N24 - Sheet1!$B$34) / (Sheet1!$B$35 - Sheet1!$B$34) -> 0.21210789 | P24: =IFERROR(__xludf.DUMMYFUNCTION("""COMPUTED_VALUE"""),0.18876009448991923) -> 0.18876009
A25: Tata Steel Ltd | B25: =(Sheet1!B25 - Sheet1!$B$34) / (Sheet1!$B$35 - Sheet1!$B$34) -> 0.16046805 | C25: =(Sheet1!C25 - Sheet1!$B$34) / (Sheet1!$B$35 - Sheet1!$B$34) -> 0.14882162 | D25: =(Sheet1!D25 - Sheet1!$B$34) / (Sheet1!$B$35 - Sheet1!$B$34) -> 0.16858027 | E25: =(Sheet1!E25 - Sheet1!$B$34) / (Sheet1!$B$35 - Sheet1!$B$34) -> 0.76357377 | F25: =(Sheet1!F25 - Sheet1!$B$34) / (Sheet1!$B$35 - Sheet1!$B$34) -> 0.2722445 | G25: =(Sheet1!G25 - Sheet1!$B$34) / (Sheet1!$B$35 - Sheet1!$B$34) -> 0.1771686 | H25: =(Sheet1!H25 - Sheet1!$B$34) / (Sheet1!$B$35 - Sheet1!$B$34) -> 0.31612005 | I25: =(Sheet1!I25 - Sheet1!$B$34) / (Sheet1!$B$35 - Sheet1!$B$34) -> 0.39002728 | ... N25: =(Sheet1!N25 - Sheet1!$B$34) / (Sheet1!$B$35 - Sheet1!$B$34) -> 0.01895292 | P25: =IFERROR(__xludf.DUMMYFUNCTION("""COMPUTED_VALUE"""),0.1820762145433903) -> 0.18207621
A26: Tata Consultancy Services Ltd | B26: =(Sheet1!B26 - Sheet1!$B$34) / (Sheet1!$B$35 - Sheet1!$B$34) -> 0.40117929 | C26: =(Sheet1!C26 - Sheet1!$B$34) / (Sheet1!$B$35 - Sheet1!$B$34) -> 0.38596202 | D26: =(Sheet1!D26 - Sheet1!$B$34) / (Sheet1!$B$35 - Sheet1!$B$34) -> 0.36638649 | E26: =(Sheet1!E26 - Sheet1!$B$34) / (Sheet1!$B$35 - Sheet1!$B$34) -> 0.34519951 | F26: =(Sheet1!F26 - Sheet1!$B$34) / (Sheet1!$B$35 - Sheet1!$B$34) -> 0.31423392 | G26: =(Sheet1!G26 - Sheet1!$B$34) / (Sheet1!$B$35 - Sheet1!$B$34) -> 0.31328169 | H26: =(Sheet1!H26 - Sheet1!$B$34) / (Sheet1!$B$35 - Sheet1!$B$34) -> 0.30753173 | I26: =(Sheet1!I26 - Sheet1!$B$34) / (Sheet1!$B$35 - Sheet1!$B$34) -> 0.40117929 | ... N26: =(Sheet1!N26 - Sheet1!$B$34) / (Sheet1!$B$35 - Sheet1!$B$34) -> 0.28544745 | P26: =IFERROR(__xludf.DUMMYFUNCTION("""COMPUTED_VALUE"""),0.17872511857019904) -> 0.17872512
A27: Tech Mahindra Ltd | B27: =(Sheet1!B27 - Sheet1!$B$34) / (Sheet1!$B$35 - Sheet1!$B$34) -> 0.24318336 | C27: =(Sheet1!C27 - Sheet1!$B$34) / (Sheet1!$B$35 - Sheet1!$B$34) -> 0.20412386 | D27: =(Sheet1!D27 - Sheet1!$B$34) / (Sheet1!$B$35 - Sheet1!$B$34) -> 0.25572708 | E27: =(Sheet1!E27 - Sheet1!$B$34) / (Sheet1!$B$35 - Sheet1!$B$34) -> 0.27046824 | F27: =(Sheet1!F27 - Sheet1!$B$34) / (Sheet1!$B$35 - Sheet1!$B$34) -> 0.24735849 | G27: =(Sheet1!G27 - Sheet1!$B$34) / (Sheet1!$B$35 - Sheet1!$B$34) -> 0.23941109 | H27: =(Sheet1!H27 - Sheet1!$B$34) / (Sheet1!$B$35 - Sheet1!$B$34) -> 0.24283543 | I27: =(Sheet1!I27 - Sheet1!$B$34) / (Sheet1!$B$35 - Sheet1!$B$34) -> 0.23356956 | ... N27: =(Sheet1!N27 - Sheet1!$B$34) / (Sheet1!$B$35 - Sheet1!$B$34) -> 0.33249098 | P27: =IFERROR(__xludf.DUMMYFUNCTION("""COMPUTED_VALUE"""),0.3681078210551374) -> 0.36810782
A28: Titan Company Ltd | B28: =(Sheet1!B28 - Sheet1!$B$34) / (Sheet1!$B$35 - Sheet1!$B$34) -> 0.224322 | C28: =(Sheet1!C28 - Sheet1!$B$34) / (Sheet1!$B$35 - Sheet1!$B$34) -> 0.22756322 | D28: =(Sheet1!D28 - Sheet1!$B$34) / (Sheet1!$B$35 - Sheet1!$B$34) -> 0.2224908 | E28: =(Sheet1!E28 - Sheet1!$B$34) / (Sheet1!$B$35 - Sheet1!$B$34) -> 0.20029665 | F28: =(Sheet1!F28 - Sheet1!$B$34) / (Sheet1!$B$35 - Sheet1!$B$34) -> 0.17552052 | G28: =(Sheet1!G28 - Sheet1!$B$34) / (Sheet1!$B$35 - Sheet1!$B$34) -> 0.18641616 | H28: =(Sheet1!H28 - Sheet1!$B$34) / (Sheet1!$B$35 - Sheet1!$B$34) -> 0.18442015 | I28: =(Sheet1!I28 - Sheet1!$B$34) / (Sheet1!$B$35 - Sheet1!$B$34) -> 0.17879837 | ... N28: =(Sheet1!N28 - Sheet1!$B$34) / (Sheet1!$B$35 - Sheet1!$B$34) -> 0.17041147 | P28: =IFERROR(__xludf.DUMMYFUNCTION("""COMPUTED_VALUE"""),0.3205881814352945) -> 0.32058818
A29: Trent Ltd | B29: =(Sheet1!B29 - Sheet1!$B$34) / (Sheet1!$B$35 - Sheet1!$B$34) -> 0.23512608 | C29: =(Sheet1!C29 - Sheet1!$B$34) / (Sheet1!$B$35 - Sheet1!$B$34) -> 0.23203135 | D29: =(Sheet1!D29 - Sheet1!$B$34) / (Sheet1!$B$35 - Sheet1!$B$34) -> 0.17835888 | E29: =(Sheet1!E29 - Sheet1!$B$34) / (Sheet1!$B$35 - Sheet1!$B$34) -> 0.16090754 | F29: =(Sheet1!F29 - Sheet1!$B$34) / (Sheet1!$B$35 - Sheet1!$B$34) -> 0.14792433 | G29: =(Sheet1!G29 - Sheet1!$B$34) / (Sheet1!$B$35 - Sheet1!$B$34) -> 0.1619147 | H29: =(Sheet1!H29 - Sheet1!$B$34) / (Sheet1!$B$35 - Sheet1!$B$34) -> 0.16079767 | I29: =(Sheet1!I29 - Sheet1!$B$34) / (Sheet1!$B$35 - Sheet1!$B$34) -> 0.16024831 | ... N29: =(Sheet1!N29 - Sheet1!$B$34) / (Sheet1!$B$35 - Sheet1!$B$34) -> 0.13988537 | P29: =IFERROR(__xludf.DUMMYFUNCTION("""COMPUTED_VALUE"""),0.31112087751103296) -> 0.31112088
A30: UltraTech Cement Ltd | B30: =(Sheet1!B30 - Sheet1!$B$34) / (Sheet1!$B$35 - Sheet1!$B$34) -> 0.53108462 | C30: =(Sheet1!C30 - Sheet1!$B$34) / (Sheet1!$B$35 - Sheet1!$B$34) -> 0.60019411 | D30: =(Sheet1!D30 - Sheet1!$B$34) / (Sheet1!$B$35 - Sheet1!$B$34) -> 0.47689941 | E30: =(Sheet1!E30 - Sheet1!$B$34) / (Sheet1!$B$35 - Sheet1!$B$34) -> 0.6215459 | F30: =(Sheet1!F30 - Sheet1!$B$34) / (Sheet1!$B$35 - Sheet1!$B$34) -> 0.50215166 | G30: =(Sheet1!G30 - Sheet1!$B$34) / (Sheet1!$B$35 - Sheet1!$B$34) -> 0.52075665 | H30: =(Sheet1!H30 - Sheet1!$B$34) / (Sheet1!$B$35 - Sheet1!$B$34) -> 0.30927137 | I30: =(Sheet1!I30 - Sheet1!$B$34) / (Sheet1!$B$35 - Sheet1!$B$34) -> 0.30363127 | ... N30: =(Sheet1!N30 - Sheet1!$B$34) / (Sheet1!$B$35 - Sheet1!$B$34) -> 0.33434049 | P30: =IFERROR(__xludf.DUMMYFUNCTION("""COMPUTED_VALUE"""),0.2196158142430735) -> 0.21961581
P31: =IFERROR(__xludf.DUMMYFUNCTION("""COMPUTED_VALUE"""),0.23952095808383234) -> 0.23952096
P32: =IFERROR(__xludf.DUMMYFUNCTION("""COMPUTED_VALUE"""),0.19974729440202163) -> 0.19974729
P33: =IFERROR(__xludf.DUMMYFUNCTION("""COMPUTED_VALUE"""),0.16790272665677816) -> 0.16790273
A34: Global min | B34: =MIN(B2:N30) -> 0 | P34: =IFERROR(__xludf.DUMMYFUNCTION("""COMPUTED_VALUE"""),0.19114065447087475) -> 0.19114065
A35: Global Max | B35: =MAX(B2:N30) -> 1 | P35: =IFERROR(__xludf.DUMMYFUNCTION("""COMPUTED_VALUE"""),0.1588565987291472) -> 0.1588566
P36: =IFERROR(__xludf.DUMMYFUNCTION("""COMPUTED_VALUE"""),0.18562874251497005) -> 0.18562874
P37: =IFERROR(__xludf.DUMMYFUNCTION("""COMPUTED_VALUE"""),0.21941438224468493) -> 0.21941438
P38: =IFERROR(__xludf.DUMMYFUNCTION("""COMPUTED_VALUE"""),0.21263894229888847) -> 0.21263894
P39: =IFERROR(__xludf.DUMMYFUNCTION("""COMPUTED_VALUE"""),0.4011976047904191) -> 0.4011976
P40: =IFERROR(__xludf.DUMMYFUNCTION("""COMPUTED_VALUE"""),0.3754143089966855) -> 0.37541431
...
