Workbook

Sheet Annual_return_and_ratios
A1: Annual Return | B1: 2025 | C1: 2024 | D1: 2023 | E1: 2022 | F1: 2021 | G1: 2020 | H1: 2019 | I1: 2018 | J1: 2017 | K1: 2016 | L1: 2015 | M1: 2014 | O1: Annual Return | P1: Diluted EPS | Q1: Current Ratio
A2: Adani Ports and Special Economic Zone Ltd | B2: -0.018388853 | C2: 0.064866104 | D2: -0.013411015 | E2: 0.004794169 | F2: 0.097112015 | G2: -0.02803944 | H2: 0.0081405251 | I2: 0.0034890724 | J2: 0.028748929 | K2: -0.013624531 | L2: 0.045516874 | M2: 0.027678695 | O2: =IFERROR(__xludf.DUMMYFUNCTION("Flatten(B2:M30)"),-0.01838885255621591) -> -0.018388853 | P2: =IFERROR(__xludf.DUMMYFUNCTION("Flatten(B35:M63)"),0.2657233426) -> 0.26572334 | Q2: =IFERROR(__xludf.DUMMYFUNCTION("Flatten(B233:M261)"),0.6883852691) -> 0.68838527
A3: Asian Paints Ltd | B3: -0.015508059 | C3: 0.0034231375 | D3: -0.0044897477 | E3: 0.017684069 | F3: 0.03472095 | G3: 0.009850388 | H3: 0.02510981 | I3: 0.0024750057 | J3: 0.018412948 | K3: 0.0057830479 | L3: 0.035916925 | M3: 0.014119278 | O3: =IFERROR(__xludf.DUMMYFUNCTION("""COMPUTED_VALUE"""),0.06486610376095205) -> 0.064866104 | P3: =IFERROR(__xludf.DUMMYFUNCTION("""COMPUTED_VALUE"""),0.1912645849) -> 0.19126458 | Q3: =IFERROR(__xludf.DUMMYFUNCTION("""COMPUTED_VALUE"""),0.7337110482) -> 0.73371105
A4: AXIS Bank Ltd | B4: 0.0031449812 | C4: 0.015642564 | D4: 0.016450513 | E4: 0.005847556 | F4: 0.054840008 | G4: -0.043748563 | H4: 0.037541142 | I4: 0.0035987805 | J4: 0.0072456263 | K4: -0.018288142 | L4: 0.050253859 | M4: 0.020824255 | O4: =IFERROR(__xludf.DUMMYFUNCTION("""COMPUTED_VALUE"""),-0.01341101462370109) -> -0.013411015 | P4: =IFERROR(__xludf.DUMMYFUNCTION("""COMPUTED_VALUE"""),0.1212841438) -> 0.12128414 | Q4: =IFERROR(__xludf.DUMMYFUNCTION("""COMPUTED_VALUE"""),0.8158640227) -> 0.81586402
A5: Bajaj Finserv Ltd | B5: 0.013268901 | C5: 0.021027313 | D5: -0.01579449 | E5: 0.049937612 | F5: 0.074710705 | G5: -0.013627338 | H5: 0.026467161 | I5: 0.021593213 | J5: 0.074197429 | K5: 0.016304197 | L5: 0.054265082 | M5: 0.0057696166 | O5: =IFERROR(__xludf.DUMMYFUNCTION("""COMPUTED_VALUE"""),0.004794169009003115) -> 0.004794169 | P5: =IFERROR(__xludf.DUMMYFUNCTION("""COMPUTED_VALUE"""),0.1094678627) -> 0.10946786 | Q5: =IFERROR(__xludf.DUMMYFUNCTION("""COMPUTED_VALUE"""),0.8866855524) -> 0.88668555
A6: Bajaj Finance Ltd | B6: 0.016012116 | C6: 0.021363854 | D6: -0.013425761 | E6: 0.030882716 | F6: 0.085722308 | G6: -0.0044409445 | H6: 0.047675208 | I6: 0.033765903 | J6: 0.044848665 | K6: 0.043550629 | L6: 0.061872866 | M6: 0.043106995 | O6: =IFERROR(__xludf.DUMMYFUNCTION("""COMPUTED_VALUE"""),0.09711201496689581) -> 0.097112015 | P6: =IFERROR(__xludf.DUMMYFUNCTION("""COMPUTED_VALUE"""),0.1212841438) -> 0.12128414 | Q6: =IFERROR(__xludf.DUMMYFUNCTION("""COMPUTED_VALUE"""),0.9376770538) -> 0.93767705
A7: Bharat Electronics Ltd | B7: 0.027854067 | C7: 0.060032519 | D7: 0.028760919 | E7: 0.043856665 | F7: 0.051465264 | G7: -0.0065329825 | H7: -0.03212618 | I7: -0.0033593882 | J7: 0.021688596 | K7: 0.013684397 | L7: 0.10420563 | M7: 0.0061107392 | O7: =IFERROR(__xludf.DUMMYFUNCTION("""COMPUTED_VALUE"""),-0.02803943999678881) -> -0.02803944 | P7: =IFERROR(__xludf.DUMMYFUNCTION("""COMPUTED_VALUE"""),0.0876697916) -> 0.087669792 | Q7: =IFERROR(__xludf.DUMMYFUNCTION("""COMPUTED_VALUE"""),0.9801699717) -> 0.98016997
A8: Bharti Airtel Ltd | B8: 0.026702653 | C8: 0.046051621 | D8: -0.00065184027 | E8: 0.032532989 | F8: 0.012751318 | G8: 0.028987966 | H8: -0.015063661 | I8: 0.012324354 | J8: 0.0028883304 | K8: -0.0028876544 | L8: 0.019992274 | M8: 0.013501463 | O8: =IFERROR(__xludf.DUMMYFUNCTION("""COMPUTED_VALUE"""),0.008140525116234972) -> 0.0081405251 | P8: =IFERROR(__xludf.DUMMYFUNCTION("""COMPUTED_VALUE"""),0.09263370877) -> 0.092633709 | Q8: =IFERROR(__xludf.DUMMYFUNCTION("""COMPUTED_VALUE"""),0.8328611898) -> 0.83286119
A9: HCL Technologies Ltd | B9: 0.0059402318 | C9: 0.033035712 | D9: 0.00050588316 | E9: 0.017730025 | F9: 0.075759107 | G9: -0.016076783 | H9: 0.010918662 | I9: 0.010621993 | J9: 0.0062164689 | K9: 0.0049023095 | L9: 0.028270595 | M9: 0.051797648 | O9: =IFERROR(__xludf.DUMMYFUNCTION("""COMPUTED_VALUE"""),0.003489072436931193) -> 0.0034890724 | P9: =IFERROR(__xludf.DUMMYFUNCTION("""COMPUTED_VALUE"""),0.08437849868) -> 0.084378499 | Q9: =IFERROR(__xludf.DUMMYFUNCTION("""COMPUTED_VALUE"""),0.5580736544) -> 0.55807365
A10: HDFC Bank Ltd | B10: 0.016101132 | C10: -0.0058276044 | D10: 0.010052314 | E10: 0.0018512656 | F10: 0.046435038 | G10: -0.019558332 | H10: 0.017925707 | I10: 0.02310927 | J10: 0.025591428 | K10: 0.0051465079 | L10: 0.02696064 | M10: 0.016349853 | O10: =IFERROR(__xludf.DUMMYFUNCTION("""COMPUTED_VALUE"""),0.0287489292939952) -> 0.028748929 | P10: =IFERROR(__xludf.DUMMYFUNCTION("""COMPUTED_VALUE"""),0.09058339516) -> 0.090583395 | Q10: =IFERROR(__xludf.DUMMYFUNCTION("""COMPUTED_VALUE"""),0.9490084986) -> 0.9490085
A11: Hindustan Unilever Ltd | B11: 0.0021438945 | C11: -0.010169015 | D11: 0.019518438 | E11: -0.013631594 | F11: 0.0064105839 | G11: 0.025133487 | H11: 0.021783993 | I11: 0.033005659 | J11: 0.0033624168 | K11: 0.0020781671 | L11: 0.033479572 | M11: 0.027625274 | O11: =IFERROR(__xludf.DUMMYFUNCTION("""COMPUTED_VALUE"""),-0.01362453114351661) -> -0.013624531 | P11: =IFERROR(__xludf.DUMMYFUNCTION("""COMPUTED_VALUE"""),0.06414514062) -> 0.064145141 | Q11: =IFERROR(__xludf.DUMMYFUNCTION("""COMPUTED_VALUE"""),0.6855524079) -> 0.68555241
A12: ICICI Bank Ltd | B12: 0.015304241 | C12: 0.017928119 | D12: 0.019352031 | E12: 0.022089283 | F12: 0.04656278 | G12: -0.0081086488 | H12: 0.031910416 | I12: 0.0093822508 | J12: 0.021300104 | K12: -0.020895898 | L12: 0.020279245 | M12: 0.02113549 | O12: =IFERROR(__xludf.DUMMYFUNCTION("""COMPUTED_VALUE"""),0.04551687424786283) -> 0.045516874 | P12: =IFERROR(__xludf.DUMMYFUNCTION("""COMPUTED_VALUE"""),0.04898361098) -> 0.048983611 | Q12: =IFERROR(__xludf.DUMMYFUNCTION("""COMPUTED_VALUE"""),0.7875354108) -> 0.78753541
A13: Infosys Ltd | B13: 0.0071915879 | C13: 0.0075726879 | D13: -0.019672524 | E13: 0.02912291 | F13: 0.071033761 | G13: -0.0089107377 | H13: 0.023217617 | I13: 0.010325168 | J13: -0.011950934 | K13: 0.010477373 | L13: 0.02741054 | M13: 0.015127996 | O13: =IFERROR(__xludf.DUMMYFUNCTION("""COMPUTED_VALUE"""),0.02767869517985113) -> 0.027678695 | P13: =IFERROR(__xludf.DUMMYFUNCTION("""COMPUTED_VALUE"""),0.03425372631) -> 0.034253726 | Q13: =IFERROR(__xludf.DUMMYFUNCTION("""COMPUTED_VALUE"""),0.9433427762) -> 0.94334278
A14: ITC Ltd | B14: 0.00080016843 | C14: 0.01218268 | D14: 0.040903903 | E14: 0.016986342 | F14: 0.023694266 | G14: -0.03640857 | H14: 0.013125397 | I14: -0.012879023 | J14: 0.023501273 | K14: 0.0028203458 | L14: 0.0028571705 | M14: 0.013988984 | O14: =IFERROR(__xludf.DUMMYFUNCTION("""COMPUTED_VALUE"""),-0.01550805906788396) -> -0.015508059 | P14: =IFERROR(__xludf.DUMMYFUNCTION("""COMPUTED_VALUE"""),0.1950414784) -> 0.19504148 | Q14: =IFERROR(__xludf.DUMMYFUNCTION("""COMPUTED_VALUE"""),0.9745042493) -> 0.97450425
A15: Kotak Mahindra Bank Ltd | B15: 0.017714023 | C15: 0.0065065588 | D15: 0.0038693461 | E15: -0.00041895223 | F15: 0.030733862 | G15: 0.0035122161 | H15: 0.024913189 | I15: 0.015169472 | J15: 0.019291035 | K15: 0.0080234666 | L15: 0.041615059 | M15: 0.019368773 | O15: =IFERROR(__xludf.DUMMYFUNCTION("""COMPUTED_VALUE"""),0.003423137479009528) -> 0.0034231375 | P15: =IFERROR(__xludf.DUMMYFUNCTION("""COMPUTED_VALUE"""),0.295884535) -> 0.29588454 | Q15: =IFERROR(__xludf.DUMMYFUNCTION("""COMPUTED_VALUE"""),0.9830028329) -> 0.98300283
A16: Larsen & Toubro Ltd | B16: -0.0074579983 | C16: 0.045849857 | D16: 0.020977232 | E16: 0.020735118 | F16: 0.048978805 | G16: -0.032551731 | H16: 0.0012700295 | I16: 0.018037568 | J16: 0.024065207 | K16: -0.025941129 | L16: 0.025079873 | M16: 0.036673697 | O16: =IFERROR(__xludf.DUMMYFUNCTION("""COMPUTED_VALUE"""),-0.004489747690076594) -> -0.0044897477 | P16: =IFERROR(__xludf.DUMMYFUNCTION("""COMPUTED_VALUE"""),0.2196991974) -> 0.2196992 | Q16: =IFERROR(__xludf.DUMMYFUNCTION("""COMPUTED_VALUE"""),0.9745042493) -> 0.97450425
A17: Mahindra & Mahindra Ltd | B17: 0.024294356 | C17: 0.041173611 | D17: 0.032385582 | E17: 0.0034884913 | F17: 0.093507229 | G17: -0.05388821 | H17: -0.01230839 | I17: 0.0092316108 | J17: 0.0056745011 | K17: 0.0049285533 | L17: 0.020900993 | M17: 0.017918085 | O17: =IFERROR(__xludf.DUMMYFUNCTION("""COMPUTED_VALUE"""),0.01768406932126746) -> 0.017684069 | P17: =IFERROR(__xludf.DUMMYFUNCTION("""COMPUTED_VALUE"""),0.1591070345) -> 0.15910703 | Q17: =IFERROR(__xludf.DUMMYFUNCTION("""COMPUTED_VALUE"""),1.0) -> 1
A18: Maruti Suzuki India Ltd | B18: -0.0085739182 | C18: 0.035676248 | D18: 0.0078403336 | E18: 0.010815818 | F18: 0.039310232 | G18: -0.024544869 | H18: -0.024855082 | I18: 0.02802177 | J18: 0.038272362 | K18: 0.0018332969 | L18: 0.056533506 | M18: 0.047620216 | O18: =IFERROR(__xludf.DUMMYFUNCTION("""COMPUTED_VALUE"""),0.03472094963678952) -> 0.03472095 | P18: =IFERROR(__xludf.DUMMYFUNCTION("""COMPUTED_VALUE"""),0.1652579753) -> 0.16525798 | Q18: =IFERROR(__xludf.DUMMYFUNCTION("""COMPUTED_VALUE"""),0.9915014164) -> 0.99150142
A19: NTPC Ltd | B19: -0.0002763521 | C19: 0.059375032 | D19: 0.025799576 | E19: 0.024615434 | F19: 0.029208582 | G19: -0.03518133 | H19: 0.0013279555 | I19: 0.0044575562 | J19: 0.024293236 | K19: -0.0060716406 | L19: 0.02320403 | M19: -0.0077007392 | O19: =IFERROR(__xludf.DUMMYFUNCTION("""COMPUTED_VALUE"""),0.009850388008809675) -> 0.009850388 | P19: =IFERROR(__xludf.DUMMYFUNCTION("""COMPUTED_VALUE"""),0.1408160788) -> 0.14081608 | Q19: =IFERROR(__xludf.DUMMYFUNCTION("""COMPUTED_VALUE"""),0.9235127479) -> 0.92351275
A20: Power Grid Corporation of India Ltd | B20: 0.00083146406 | C20: 0.046396075 | D20: 0.0076339248 | E20: 0.030461605 | F20: 0.029017078 | G20: -0.014306376 | H20: 0.0076670342 | I20: -0.00046367097 | J20: 0.0300338 | K20: -0.0025886874 | L20: 0.030680866 | M20: 0.0083611295 | O20: =IFERROR(__xludf.DUMMYFUNCTION("""COMPUTED_VALUE"""),0.0251098098275308) -> 0.02510981 | P20: =IFERROR(__xludf.DUMMYFUNCTION("""COMPUTED_VALUE"""),0.1099534633) -> 0.10995346 | Q20: =IFERROR(__xludf.DUMMYFUNCTION("""COMPUTED_VALUE"""),0.8498583569) -> 0.84985836
A21: Reliance Industries Ltd | B21: -0.015457557 | C21: 0.026691237 | D21: -0.0098398948 | E21: 0.023888633 | F21: 0.054133944 | G21: -0.015057342 | H21: 0.037318771 | I21: 0.02311088 | J21: 0.021421743 | K21: 0.023274431 | L21: -0.0092202545 | M21: 0.018471682 | O21: =IFERROR(__xludf.DUMMYFUNCTION("""COMPUTED_VALUE"""),0.002475005739429222) -> 0.0024750057 | P21: =IFERROR(__xludf.DUMMYFUNCTION("""COMPUTED_VALUE"""),0.1033708775) -> 0.10337088 | Q21: =IFERROR(__xludf.DUMMYFUNCTION("""COMPUTED_VALUE"""),0.8725212465) -> 0.87252125
A22: State Bank of India | B22: -9.1539287e-06 | C22: 0.0327997 | D22: 0.0088733531 | E22: 0.028159527 | F22: 0.059749205 | G22: -0.027804186 | H22: 0.020200127 | I22: -0.011748359 | J22: 0.034051401 | K22: -0.025147216 | L22: 0.029377404 | M22: -0.00056298714 | O22: =IFERROR(__xludf.DUMMYFUNCTION("""COMPUTED_VALUE"""),0.01841294789589839) -> 0.018412948 | P22: =IFERROR(__xludf.DUMMYFUNCTION("""COMPUTED_VALUE"""),0.09775949282) -> 0.097759493 | Q22: =IFERROR(__xludf.DUMMYFUNCTION("""COMPUTED_VALUE"""),0.940509915) -> 0.94050992
A23: Sun Pharmaceutical Industries Ltd | B23: 0.0045864804 | C23: 0.043070164 | D23: 0.0072399436 | E23: 0.035430654 | F23: 0.043769361 | G23: -0.020543748 | H23: 0.0044766526 | I23: -0.024611496 | J23: -0.017114299 | K23: -0.010636672 | L23: 0.046259989 | M23: 0.032498627 | O23: =IFERROR(__xludf.DUMMYFUNCTION("""COMPUTED_VALUE"""),0.005783047936699363) -> 0.0057830479 | P23: =IFERROR(__xludf.DUMMYFUNCTION("""COMPUTED_VALUE"""),0.08680650165) -> 0.086806502 | Q23: =IFERROR(__xludf.DUMMYFUNCTION("""COMPUTED_VALUE"""),0.9490084986) -> 0.9490085
A24: Tata Motors Ltd | B24: 0.079588178 | C24: 0.30103891 | D24: 0.11795617 | E24: 0.17929265 | F24: 0.54952967 | G24: 0.043888312 | H24: 0.060301175 | I24: 0.082742311 | J24: 0.1490187 | K24: 0.082698866 | L24: 0.17197631 | M24: 0.18496169 | O24: =IFERROR(__xludf.DUMMYFUNCTION("""COMPUTED_VALUE"""),0.03591692511264611) -> 0.035916925 | P24: =IFERROR(__xludf.DUMMYFUNCTION("""COMPUTED_VALUE"""),0.0671126998) -> 0.0671127 | Q24: =IFERROR(__xludf.DUMMYFUNCTION("""COMPUTED_VALUE"""),0.8640226629) -> 0.86402266
A25: Tata Steel Ltd | B25: -0.0034763223 | C25: 0.033861143 | D25: -0.010399398 | E25: 0.044060292 | F25: 0.10341164 | G25: -0.040818871 | H25: -0.01175668 | I25: 0.019238304 | J25: 0.035967264 | K25: 0.0098082016 | L25: -0.013443551 | M25: 0.029121528 | O25: =IFERROR(__xludf.DUMMYFUNCTION("""COMPUTED_VALUE"""),0.01411927848446944) -> 0.014119278 | P25: =IFERROR(__xludf.DUMMYFUNCTION("""COMPUTED_VALUE"""),0.05723882107) -> 0.057238821 | Q25: =IFERROR(__xludf.DUMMYFUNCTION("""COMPUTED_VALUE"""),0.8526912181) -> 0.85269122
A26: Tata Consultancy Services Ltd | B26: -0.0022352864 | C26: 0.016157167 | D26: -0.010560826 | E26: 0.013763541 | F26: 0.048628352 | G26: -0.0068496008 | H26: 0.030186658 | I26: 0.017171977 | J26: -0.0017700173 | K26: 9.5428579e-05 | L26: 0.016667754 | M26: 0.033187095 | O26: =IFERROR(__xludf.DUMMYFUNCTION("""COMPUTED_VALUE"""),0.003144981180246767) -> 0.0031449812 | P26: =IFERROR(__xludf.DUMMYFUNCTION("""COMPUTED_VALUE"""),0.4752330208) -> 0.47523302 | Q26: =IFERROR(__xludf.DUMMYFUNCTION("""COMPUTED_VALUE"""),0.7518413598) -> 0.75184136
A27: Tech Mahindra Ltd | B27: 0.012174951 | C27: 0.012972896 | D27: -0.018545439 | E27: 0.040224667 | F27: 0.053068331 | G27: -0.02242105 | H27: 0.018453096 | I27: 0.02798524 | J27: 0.0033047456 | K27: -0.019150687 | L27: 0.032876523 | M27: 0.047723765 | O27: =IFERROR(__xludf.DUMMYFUNCTION("""COMPUTED_VALUE"""),0.0156425637222698) -> 0.015642564 | P27: =IFERROR(__xludf.DUMMYFUNCTION("""COMPUTED_VALUE"""),0.4473379645) -> 0.44733796 | Q27: =IFERROR(__xludf.DUMMYFUNCTION("""COMPUTED_VALUE"""),0.7487252125) -> 0.74872521
A28: Titan Company Ltd | B28: -0.018857025 | C28: 0.032481438 | D28: 0.0029580187 | E28: 0.039459912 | F28: 0.045578973 | G28: -0.0083747091 | H28: 0.014850575 | I28: 0.061094544 | J28: 0.025111101 | K28: -0.00054904764 | L28: 0.032579019 | M28: 0.012014397 | O28: =IFERROR(__xludf.DUMMYFUNCTION("""COMPUTED_VALUE"""),0.01645051331551754) -> 0.016450513 | P28: =IFERROR(__xludf.DUMMYFUNCTION("""COMPUTED_VALUE"""),0.1777217239) -> 0.17772172 | Q28: =IFERROR(__xludf.DUMMYFUNCTION("""COMPUTED_VALUE"""),0.7456090652) -> 0.74560907
A29: Trent Ltd | B29: 0.025242339 | C29: 0.092310144 | D29: 0.0080962239 | E29: 0.045613628 | F29: 0.042659575 | G29: 0.033918567 | H29: 0.005211067 | I29: 0.014549981 | J29: 0.040263331 | K29: 0.0089241564 | L29: 0.035042438 | M29: 0.0057484694 | O29: =IFERROR(__xludf.DUMMYFUNCTION("""COMPUTED_VALUE"""),0.005847555985461925) -> 0.005847556 | P29: =IFERROR(__xludf.DUMMYFUNCTION("""COMPUTED_VALUE"""),0.2363714845) -> 0.23637148 | Q29: =IFERROR(__xludf.DUMMYFUNCTION("""COMPUTED_VALUE"""),0.7464589235) -> 0.74645892
A30: UltraTech Cement Ltd | B30: 0.011267776 | C30: 0.019115597 | D30: 0.014258521 | E30: -0.0027189614 | F30: 0.062923229 | G30: -0.010341532 | H30: -0.0021300429 | I30: -0.0032286041 | J30: 0.017915268 | K30: 0.011674742 | L30: 0.021949111 | M30: 0.017814461 | O30: =IFERROR(__xludf.DUMMYFUNCTION("""COMPUTED_VALUE"""),0.05484000762334306) -> 0.054840008 | P30: =IFERROR(__xludf.DUMMYFUNCTION("""COMPUTED_VALUE"""),0.1191798746) -> 0.11917987 | Q30: =IFERROR(__xludf.DUMMYFUNCTION("""COMPUTED_VALUE"""),0.747592068) -> 0.74759207
O31: =IFERROR(__xludf.DUMMYFUNCTION("""COMPUTED_VALUE"""),-0.04374856333401774) -> -0.043748563 | P31: =IFERROR(__xludf.DUMMYFUNCTION("""COMPUTED_VALUE"""),0.02535104876) -> 0.025351049 | Q31: =IFERROR(__xludf.DUMMYFUNCTION("""COMPUTED_VALUE"""),0.7441926346) -> 0.74419263
O32: =IFERROR(__xludf.DUMMYFUNCTION("""COMPUTED_VALUE"""),0.0375411415132909) -> 0.037541142 | P32: =IFERROR(__xludf.DUMMYFUNCTION("""COMPUTED_VALUE"""),0.09382073245) -> 0.093820732 | Q32: =IFERROR(__xludf.DUMMYFUNCTION("""COMPUTED_VALUE"""),0.7407932011) -> 0.7407932
O33: =IFERROR(__xludf.DUMMYFUNCTION("""COMPUTED_VALUE"""),0.003598780509103944) -> 0.0035987805 | P33: =IFERROR(__xludf.DUMMYFUNCTION("""COMPUTED_VALUE"""),0.0) -> 0 | Q33: =IFERROR(__xludf.DUMMYFUNCTION("""COMPUTED_VALUE"""),0.7433427762) -> 0.74334278
A34: Diluted EPS | B34: 2025 | C34: 2024 | D34: 2023 | E34: 2022 | F34: 2021 | G34: 2020 | H34: 2019 | I34: 2018 | J34: 2017 | K34: 2016 | L34: 2015 | M34: 2014 | O34: =IFERROR(__xludf.DUMMYFUNCTION("""COMPUTED_VALUE"""),0.007245626328476344) -> 0.0072456263 | P34: =IFERROR(__xludf.DUMMYFUNCTION("""COMPUTED_VALUE"""),0.07758009038) -> 0.07758009 | Q34: =IFERROR(__xludf.DUMMYFUNCTION("""COMPUTED_VALUE"""),0.7436260623) -> 0.74362606
A35: Adani Ports and Special Economic Zone Ltd | B35: 0.26572334 | C35: 0.19126458 | D35: 0.12128414 | E35: 0.10946786 | F35: 0.12128414 | G35: 0.087669792 | H35: 0.092633709 | I35: 0.084378499 | J35: 0.090583395 | K35: 0.064145141 | L35: 0.048983611 | M35: 0.034253726 | O35: =IFERROR(__xludf.DUMMYFUNCTION("""COMPUTED_VALUE"""),-0.01828814174192833) -> -0.018288142 | P35: =IFERROR(__xludf.DUMMYFUNCTION("""COMPUTED_VALUE"""),0.177128212) -> 0.17712821 | Q35: =IFERROR(__xludf.DUMMYFUNCTION("""COMPUTED_VALUE"""),0.7461756374) -> 0.74617564
A36: Asian Paints Ltd | B36: 0.19504148 | C36: 0.29588454 | D36: 0.2196992 | E36: 0.15910703 | F36: 0.16525798 | G36: 0.14081608 | H36: 0.10995346 | I36: 0.10337088 | J36: 0.097759493 | K36: 0.086806502 | L36: 0.0671127 | M36: 0.057238821 | O36: =IFERROR(__xludf.DUMMYFUNCTION("""COMPUTED_VALUE"""),0.05025385912291375) -> 0.050253859 | P36: =IFERROR(__xludf.DUMMYFUNCTION("""COMPUTED_VALUE"""),0.1571646321) -> 0.15716463 | Q36: =IFERROR(__xludf.DUMMYFUNCTION("""COMPUTED_VALUE"""),0.745325779) -> 0.74532578
A37: AXIS Bank Ltd | B37: 0.47523302 | C37: 0.44733796 | D37: 0.17772172 | E37: 0.23637148 | F37: 0.11917987 | G37: 0.025351049 | H37: 0.093820732 | I37: 0 | J37: 0.07758009 | K37: 0.17712821 | L37: 0.15716463 | M37: 0.71274567 | O37: =IFERROR(__xludf.DUMMYFUNCTION("""COMPUTED_VALUE"""),0.02082425450500124) -> 0.020824255 | P37: =IFERROR(__xludf.DUMMYFUNCTION("""COMPUTED_VALUE"""),0.7127456667) -> 0.71274567 | Q37: =IFERROR(__xludf.DUMMYFUNCTION("""COMPUTED_VALUE"""),0.7458923513) -> 0.74589235
A38: Bajaj Finserv Ltd | B38: 0.040998179 | C38: 0.02804883 | D38: 0.013480812 | E38: 0.13218318 | F38: 0.049091522 | G38: 0.21473528 | H38: 0.092795576 | I38: 0.036681729 | J38: 0.0124017 | K38: 0.044235516 | L38: 0.031286167 | M38: 0.016718149 | O38: =IFERROR(__xludf.DUMMYFUNCTION("""COMPUTED_VALUE"""),0.01326890111153658) -> 0.013268901 | P38: =IFERROR(__xludf.DUMMYFUNCTION("""COMPUTED_VALUE"""),0.040998179) -> 0.040998179 | Q38: =IFERROR(__xludf.DUMMYFUNCTION("""COMPUTED_VALUE"""),0.7847025496) -> 0.78470255
A39: Bajaj Finance Ltd | B39: 1 | C39: 1 | D39: 1 | E39: 0.61341337 | F39: 0.38253726 | G39: 0.46924395 | H39: 0.35960612 | I39: 0.24252243 | J39: 0.1703298 | K39: 1 | L39: 0.94745262 | M39: 0.76373373 | O39: =IFERROR(__xludf.DUMMYFUNCTION("""COMPUTED_VALUE"""),0.02102731258654204) -> 0.021027313 | P39: =IFERROR(__xludf.DUMMYFUNCTION("""COMPUTED_VALUE"""),0.02804882984) -> 0.02804883 | Q39: =IFERROR(__xludf.DUMMYFUNCTION("""COMPUTED_VALUE"""),0.9716713881) -> 0.97167139
A40: Bharat Electronics Ltd | B40: 0.027940919 | C40: 0.01806704 | D40: 0.010729075 | E40: 0.041807513 | F40: 0.035170972 | G40: 0.029073987 | H40: 0.030422877 | I40: 0.020117353 | J40: 0.020710865 | K40: 0.018714507 | L40: 0.7961071 | M40: 0.63024752 | O40: =IFERROR(__xludf.DUMMYFUNCTION("""COMPUTED_VALUE"""),-0.0157944904480797) -> -0.01579449 | P40: =IFERROR(__xludf.DUMMYFUNCTION("""COMPUTED_VALUE"""),0.01348081203) -> 0.013480812 | Q40: =IFERROR(__xludf.DUMMYFUNCTION("""COMPUTED_VALUE"""),0.9830028329) -> 0.98300283
...

Sheet Deviation_sequence
A1: Diluted EPS | B1: 2025 | C1: 2024 | D1: 2023 | E1: 2022 | F1: 2021 | G1: 2020 | H1: 2019 | I1: 2018 | J1: 2017 | K1: 2016 | L1: 2015 | M1: 2014
A2: Adani Ports and Special Economic Zone Ltd | B2: =ABS(Annual_return_and_ratios!B2 - Annual_return_and_ratios!B35) -> 0.2841122 | C2: =ABS(Annual_return_and_ratios!C2 - Annual_return_and_ratios!C35) -> 0.12639848 | D2: =ABS(Annual_return_and_ratios!D2 - Annual_return_and_ratios!D35) -> 0.13469516 | E2: =ABS(Annual_return_and_ratios!E2 - Annual_return_and_ratios!E35) -> 0.10467369 | F2: =ABS(Annual_return_and_ratios!F2 - Annual_return_and_ratios!F35) -> 0.024172129 | G2: =ABS(Annual_return_and_ratios!G2 - Annual_return_and_ratios!G35) -> 0.11570923 | H2: =ABS(Annual_return_and_ratios!H2 - Annual_return_and_ratios!H35) -> 0.084493184 | I2: =ABS(Annual_return_and_ratios!I2 - Annual_return_and_ratios!I35) -> 0.080889426 | ... M2: =ABS(Annual_return_and_ratios!M2 - Annual_return_and_ratios!M35) -> 0.0065750311
A3: Asian Paints Ltd | B3: =ABS(Annual_return_and_ratios!B3 - Annual_return_and_ratios!B36) -> 0.21054954 | C3: =ABS(Annual_return_and_ratios!C3 - Annual_return_and_ratios!C36) -> 0.2924614 | D3: =ABS(Annual_return_and_ratios!D3 - Annual_return_and_ratios!D36) -> 0.22418895 | E3: =ABS(Annual_return_and_ratios!E3 - Annual_return_and_ratios!E36) -> 0.14142297 | F3: =ABS(Annual_return_and_ratios!F3 - Annual_return_and_ratios!F36) -> 0.13053703 | G3: =ABS(Annual_return_and_ratios!G3 - Annual_return_and_ratios!G36) -> 0.13096569 | H3: =ABS(Annual_return_and_ratios!H3 - Annual_return_and_ratios!H36) -> 0.084843653 | I3: =ABS(Annual_return_and_ratios!I3 - Annual_return_and_ratios!I36) -> 0.10089587 | ... M3: =ABS(Annual_return_and_ratios!M3 - Annual_return_and_ratios!M36) -> 0.043119543
A4: AXIS Bank Ltd | B4: =ABS(Annual_return_and_ratios!B4 - Annual_return_and_ratios!B37) -> 0.47208804 | C4: =ABS(Annual_return_and_ratios!C4 - Annual_return_and_ratios!C37) -> 0.4316954 | D4: =ABS(Annual_return_and_ratios!D4 - Annual_return_and_ratios!D37) -> 0.16127121 | E4: =ABS(Annual_return_and_ratios!E4 - Annual_return_and_ratios!E37) -> 0.23052393 | F4: =ABS(Annual_return_and_ratios!F4 - Annual_return_and_ratios!F37) -> 0.064339867 | G4: =ABS(Annual_return_and_ratios!G4 - Annual_return_and_ratios!G37) -> 0.069099612 | H4: =ABS(Annual_return_and_ratios!H4 - Annual_return_and_ratios!H37) -> 0.056279591 | I4: =ABS(Annual_return_and_ratios!I4 - Annual_return_and_ratios!I37) -> 0.0035987805 | ... M4: =ABS(Annual_return_and_ratios!M4 - Annual_return_and_ratios!M37) -> 0.69192141
A5: Bajaj Finserv Ltd | B5: =ABS(Annual_return_and_ratios!B5 - Annual_return_and_ratios!B38) -> 0.027729278 | C5: =ABS(Annual_return_and_ratios!C5 - Annual_return_and_ratios!C38) -> 0.0070215173 | D5: =ABS(Annual_return_and_ratios!D5 - Annual_return_and_ratios!D38) -> 0.029275302 | E5: =ABS(Annual_return_and_ratios!E5 - Annual_return_and_ratios!E38) -> 0.082245567 | F5: =ABS(Annual_return_and_ratios!F5 - Annual_return_and_ratios!F38) -> 0.025619183 | G5: =ABS(Annual_return_and_ratios!G5 - Annual_return_and_ratios!G38) -> 0.22836262 | H5: =ABS(Annual_return_and_ratios!H5 - Annual_return_and_ratios!H38) -> 0.066328414 | I5: =ABS(Annual_return_and_ratios!I5 - Annual_return_and_ratios!I38) -> 0.015088516 | ... M5: =ABS(Annual_return_and_ratios!M5 - Annual_return_and_ratios!M38) -> 0.010948533
A6: Bajaj Finance Ltd | B6: =ABS(Annual_return_and_ratios!B6 - Annual_return_and_ratios!B39) -> 0.98398788 | C6: =ABS(Annual_return_and_ratios!C6 - Annual_return_and_ratios!C39) -> 0.97863615 | D6: =ABS(Annual_return_and_ratios!D6 - Annual_return_and_ratios!D39) -> 1.0134258 | E6: =ABS(Annual_return_and_ratios!E6 - Annual_return_and_ratios!E39) -> 0.58253065 | F6: =ABS(Annual_return_and_ratios!F6 - Annual_return_and_ratios!F39) -> 0.29681496 | G6: =ABS(Annual_return_and_ratios!G6 - Annual_return_and_ratios!G39) -> 0.47368489 | H6: =ABS(Annual_return_and_ratios!H6 - Annual_return_and_ratios!H39) -> 0.31193092 | I6: =ABS(Annual_return_and_ratios!I6 - Annual_return_and_ratios!I39) -> 0.20875652 | ... M6: =ABS(Annual_return_and_ratios!M6 - Annual_return_and_ratios!M39) -> 0.72062673
A7: Bharat Electronics Ltd | B7: =ABS(Annual_return_and_ratios!B7 - Annual_return_and_ratios!B40) -> 8.6851477e-05 | C7: =ABS(Annual_return_and_ratios!C7 - Annual_return_and_ratios!C40) -> 0.041965479 | D7: =ABS(Annual_return_and_ratios!D7 - Annual_return_and_ratios!D40) -> 0.018031844 | E7: =ABS(Annual_return_and_ratios!E7 - Annual_return_and_ratios!E40) -> 0.0020491513 | F7: =ABS(Annual_return_and_ratios!F7 - Annual_return_and_ratios!F40) -> 0.016294292 | G7: =ABS(Annual_return_and_ratios!G7 - Annual_return_and_ratios!G40) -> 0.035606969 | H7: =ABS(Annual_return_and_ratios!H7 - Annual_return_and_ratios!H40) -> 0.062549057 | I7: =ABS(Annual_return_and_ratios!I7 - Annual_return_and_ratios!I40) -> 0.023476742 | ... M7: =ABS(Annual_return_and_ratios!M7 - Annual_return_and_ratios!M40) -> 0.62413678
A8: Bharti Airtel Ltd | B8: =ABS(Annual_return_and_ratios!B8 - Annual_return_and_ratios!B41) -> 0.26432588 | C8: =ABS(Annual_return_and_ratios!C8 - Annual_return_and_ratios!C41) -> 0.0116728 | D8: =ABS(Annual_return_and_ratios!D8 - Annual_return_and_ratios!D41) -> 0.067926407 | E8: =ABS(Annual_return_and_ratios!E8 - Annual_return_and_ratios!E41) -> 0.0027036238 | F8: =ABS(Annual_return_and_ratios!F8 - Annual_return_and_ratios!F41) -> 0.012751318 | G8: =ABS(Annual_return_and_ratios!G8 - Annual_return_and_ratios!G41) -> 0.028987966 | H8: =ABS(Annual_return_and_ratios!H8 - Annual_return_and_ratios!H41) -> 0.015063661 | I8: =ABS(Annual_return_and_ratios!I8 - Annual_return_and_ratios!I41) -> 0.0088253318 | ... M8: =ABS(Annual_return_and_ratios!M8 - Annual_return_and_ratios!M41) -> 0.012982654
A9: HCL Technologies Ltd | B9: =ABS(Annual_return_and_ratios!B9 - Annual_return_and_ratios!B42) -> 0.32852257 | C9: =ABS(Annual_return_and_ratios!C9 - Annual_return_and_ratios!C42) -> 0.26781274 | D9: =ABS(Annual_return_and_ratios!D9 - Annual_return_and_ratios!D42) -> 0.28377819 | E9: =ABS(Annual_return_and_ratios!E9 - Annual_return_and_ratios!E42) -> 0.23946833 | F9: =ABS(Annual_return_and_ratios!F9 - Annual_return_and_ratios!F42) -> 0.13449786 | G9: =ABS(Annual_return_and_ratios!G9 - Annual_return_and_ratios!G42) -> 0.22460717 | H9: =ABS(Annual_return_and_ratios!H9 - Annual_return_and_ratios!H42) -> 0.37458616 | I9: =ABS(Annual_return_and_ratios!I9 - Annual_return_and_ratios!I42) -> 0.31358924 | ... M9: =ABS(Annual_return_and_ratios!M9 - Annual_return_and_ratios!M42) -> 0.43287761
A10: HDFC Bank Ltd | B10: =ABS(Annual_return_and_ratios!B10 - Annual_return_and_ratios!B43) -> 0.47105608 | C10: =ABS(Annual_return_and_ratios!C10 - Annual_return_and_ratios!C43) -> 0.48014338 | D10: =ABS(Annual_return_and_ratios!D10 - Annual_return_and_ratios!D43) -> 0.42250181 | E10: =ABS(Annual_return_and_ratios!E10 - Annual_return_and_ratios!E43) -> 0.35538081 | F10: =ABS(Annual_return_and_ratios!F10 - Annual_return_and_ratios!F43) -> 0.25306452 | G10: =ABS(Annual_return_and_ratios!G10 - Annual_return_and_ratios!G43) -> 0.27508406 | H10: =ABS(Annual_return_and_ratios!H10 - Annual_return_and_ratios!H43) -> 0.41592335 | I10: =ABS(Annual_return_and_ratios!I10 - Annual_return_and_ratios!I43) -> 0.34734193 | ... M10: =ABS(Annual_return_and_ratios!M10 - Annual_return_and_ratios!M43) -> 0.16822423
A11: Hindustan Unilever Ltd | B11: =ABS(Annual_return_and_ratios!B11 - Annual_return_and_ratios!B44) -> 0.23104421 | C11: =ABS(Annual_return_and_ratios!C11 - Annual_return_and_ratios!C44) -> 0.23483213 | D11: =ABS(Annual_return_and_ratios!D11 - Annual_return_and_ratios!D44) -> 0.20152965 | E11: =ABS(Annual_return_and_ratios!E11 - Annual_return_and_ratios!E44) -> 0.20619111 | F11: =ABS(Annual_return_and_ratios!F11 - Annual_return_and_ratios!F44) -> 0.16586162 | G11: =ABS(Annual_return_and_ratios!G11 - Annual_return_and_ratios!G44) -> 0.13170741 | H11: =ABS(Annual_return_and_ratios!H11 - Annual_return_and_ratios!H44) -> 0.11773715 | I11: =ABS(Annual_return_and_ratios!I11 - Annual_return_and_ratios!I44) -> 0.085580704 | ... M11: =ABS(Annual_return_and_ratios!M11 - Annual_return_and_ratios!M44) -> 0.05939705
A12: ICICI Bank Ltd | B12: =ABS(Annual_return_and_ratios!B12 - Annual_return_and_ratios!B45) -> 0.35719728 | C12: =ABS(Annual_return_and_ratios!C12 - Annual_return_and_ratios!C45) -> 0.30504214 | D12: =ABS(Annual_return_and_ratios!D12 - Annual_return_and_ratios!D45) -> 0.22743289 | E12: =ABS(Annual_return_and_ratios!E12 - Annual_return_and_ratios!E45) -> 0.15779067 | F12: =ABS(Annual_return_and_ratios!F12 - Annual_return_and_ratios!F45) -> 0.086861379 | G12: =ABS(Annual_return_and_ratios!G12 - Annual_return_and_ratios!G45) -> 0.075275304 | H12: =ABS(Annual_return_and_ratios!H12 - Annual_return_and_ratios!H45) -> 0.0080161693 | I12: =ABS(Annual_return_and_ratios!I12 - Annual_return_and_ratios!I45) -> 0.043432209 | ... M12: =ABS(Annual_return_and_ratios!M12 - Annual_return_and_ratios!M45) -> 0.48361126
A13: Infosys Ltd | B13: =ABS(Annual_return_and_ratios!B13 - Annual_return_and_ratios!B46) -> 0.32862011 | C13: =ABS(Annual_return_and_ratios!C13 - Annual_return_and_ratios!C46) -> 0.32311322 | D13: =ABS(Annual_return_and_ratios!D13 - Annual_return_and_ratios!D46) -> 0.3187944 | E13: =ABS(Annual_return_and_ratios!E13 - Annual_return_and_ratios!E46) -> 0.24231973 | F13: =ABS(Annual_return_and_ratios!F13 - Annual_return_and_ratios!F46) -> 0.16323345 | G13: =ABS(Annual_return_and_ratios!G13 - Annual_return_and_ratios!G46) -> 0.20751329 | H13: =ABS(Annual_return_and_ratios!H13 - Annual_return_and_ratios!H46) -> 0.1563386 | I13: =ABS(Annual_return_and_ratios!I13 - Annual_return_and_ratios!I46) -> 0.36142097 | ... M13: =ABS(Annual_return_and_ratios!M13 - Annual_return_and_ratios!M46) -> 0.97975162
... A30: UltraTech Cement Ltd | B30: =ABS(Annual_return_and_ratios!B30 - Annual_return_and_ratios!B63) -> 0.98873222 | C30: =ABS(Annual_return_and_ratios!C30 - Annual_return_and_ratios!C63) -> 0.9808844 | D30: =ABS(Annual_return_and_ratios!D30 - Annual_return_and_ratios!D63) -> 0.92153968 | E30: =ABS(Annual_return_and_ratios!E30 - Annual_return_and_ratios!E63) -> 1.002719 | F30: =ABS(Annual_return_and_ratios!F30 - Annual_return_and_ratios!F63) -> 0.93707677 | G30: =ABS(Annual_return_and_ratios!G30 - Annual_return_and_ratios!G63) -> 1.0103415 | H30: =ABS(Annual_return_and_ratios!H30 - Annual_return_and_ratios!H63) -> 0.44401849 | I30: =ABS(Annual_return_and_ratios!I30 - Annual_return_and_ratios!I63) -> 0.42849872 | ... M30: =ABS(Annual_return_and_ratios!M30 - Annual_return_and_ratios!M63) -> 0.40475787
A34: payout ratio | B34: (PR)2025 | C34: (PR)2024 | D34: (PR)2023 | E34: (PR)2022 | F34: (PR)2021 | G34: (PR)2020 | H34: (PR)2019 | I34: (PR)2018 | J34: (PR)2017 | K34: (PR)2016 | L34: (PR)2015 | M34: (PR)2014
A35: Adani Ports and Special Economic Zone Ltd | B35: =ABS(Annual_return_and_ratios!B2 - Annual_return_and_ratios!B68) -> 0.15114479 | C35: =ABS(Annual_return_and_ratios!C2 - Annual_return_and_ratios!C68) -> 0.08641656 | D35: =ABS(Annual_return_and_ratios!D2 - Annual_return_and_ratios!D68) -> 0.23936889 | E35: =ABS(Annual_return_and_ratios!E2 - Annual_return_and_ratios!E68) -> 0.24059972 | F35: =ABS(Annual_return_and_ratios!F2 - Annual_return_and_ratios!F68) -> 0.097112015 | G35: =ABS(Annual_return_and_ratios!G2 - Annual_return_and_ratios!G68) -> 0.23683452 | H35: =ABS(Annual_return_and_ratios!H2 - Annual_return_and_ratios!H68) -> 0.10983949 | I35: =ABS(Annual_return_and_ratios!I2 - Annual_return_and_ratios!I68) -> 0.079710709 | ... M35: =ABS(Annual_return_and_ratios!M2 - Annual_return_and_ratios!M68) -> 0.11189689
A36: Asian Paints Ltd | B36: =ABS(Annual_return_and_ratios!B3 - Annual_return_and_ratios!B69) -> 0.97867056 | C36: =ABS(Annual_return_and_ratios!C3 - Annual_return_and_ratios!C69) -> 0.52362247 | D36: =ABS(Annual_return_and_ratios!D3 - Annual_return_and_ratios!D69) -> 0.53278563 | E36: =ABS(Annual_return_and_ratios!E3 - Annual_return_and_ratios!E69) -> 0.63518416 | F36: =ABS(Annual_return_and_ratios!F3 - Annual_return_and_ratios!F69) -> 0.081554155 | G36: =ABS(Annual_return_and_ratios!G3 - Annual_return_and_ratios!G69) -> 0.72155753 | H36: =ABS(Annual_return_and_ratios!H3 - Annual_return_and_ratios!H69) -> 0.42487371 | I36: =ABS(Annual_return_and_ratios!I3 - Annual_return_and_ratios!I69) -> 0.54821207 | ... M36: =ABS(Annual_return_and_ratios!M3 - Annual_return_and_ratios!M69) -> 0.45996035
A37: AXIS Bank Ltd | B37: =ABS(Annual_return_and_ratios!B4 - Annual_return_and_ratios!B70) -> 0.010380666 | C37: =ABS(Annual_return_and_ratios!C4 - Annual_return_and_ratios!C70) -> 0.0014349507 | D37: =ABS(Annual_return_and_ratios!D4 - Annual_return_and_ratios!D70) -> 0.02048928 | E37: =ABS(Annual_return_and_ratios!E4 - Annual_return_and_ratios!E70) -> 0.0082463961 | F37: =ABS(Annual_return_and_ratios!F4 - Annual_return_and_ratios!F70) -> 0.03756355 | G37: =ABS(Annual_return_and_ratios!G4 - Annual_return_and_ratios!G70) -> 0.057956176 | H37: =ABS(Annual_return_and_ratios!H4 - Annual_return_and_ratios!H70) -> 0.011058151 | I37: =ABS(Annual_return_and_ratios!I4 - Annual_return_and_ratios!I70) -> 0.012200085 | ... M37: =ABS(Annual_return_and_ratios!M4 - Annual_return_and_ratios!M70) -> 0.0058210152
A38: Bajaj Finserv Ltd | B38: =ABS(Annual_return_and_ratios!B5 - Annual_return_and_ratios!B71) -> 0.0070764007 | C38: =ABS(Annual_return_and_ratios!C5 - Annual_return_and_ratios!C71) -> 0.0032962116 | D38: =ABS(Annual_return_and_ratios!D5 - Annual_return_and_ratios!D71) -> 0.02704692 | E38: =ABS(Annual_return_and_ratios!E5 - Annual_return_and_ratios!E71) -> 0.038116878 | F38: =ABS(Annual_return_and_ratios!F5 - Annual_return_and_ratios!F71) -> 0.074710705 | G38: =ABS(Annual_return_and_ratios!G5 - Annual_return_and_ratios!G71) -> 0.053863298 | H38: =ABS(Annual_return_and_ratios!H5 - Annual_return_and_ratios!H71) -> 0.016692324 | I38: =ABS(Annual_return_and_ratios!I5 - Annual_return_and_ratios!I71) -> 0.0096588179 | ... M38: =ABS(Annual_return_and_ratios!M5 - Annual_return_and_ratios!M71) -> 0.014689346
A39: Bajaj Finance Ltd | B39: =ABS(Annual_return_and_ratios!B6 - Annual_return_and_ratios!B72) -> 0.13606617 | C39: =ABS(Annual_return_and_ratios!C6 - Annual_return_and_ratios!C72) -> 0.12139424 | D39: =ABS(Annual_return_and_ratios!D6 - Annual_return_and_ratios!D72) -> 0.13265605 | E39: =ABS(Annual_return_and_ratios!E6 - Annual_return_and_ratios!E72) -> 0.066524679 | F39: =ABS(Annual_return_and_ratios!F6 - Annual_return_and_ratios!F72) -> 0.085722308 | G39: =ABS(Annual_return_and_ratios!G6 - Annual_return_and_ratios!G72) -> 0.20948522 | H39: =ABS(Annual_return_and_ratios!H6 - Annual_return_and_ratios!H72) -> 0.018020795 | I39: =ABS(Annual_return_and_ratios!I6 - Annual_return_and_ratios!I72) -> 0.050343166 | ... M39: =ABS(Annual_return_and_ratios!M6 - Annual_return_and_ratios!M72) -> 0.083624913
A40: Bharat Electronics Ltd | B40: =ABS(Annual_return_and_ratios!B7 - Annual_return_and_ratios!B73) -> 0.33120073 | C40: =ABS(Annual_return_and_ratios!C7 - Annual_return_and_ratios!C73) -> 0.35698934 | D40: =ABS(Annual_return_and_ratios!D7 - Annual_return_and_ratios!D73) -> 0.44440942 | E40: =ABS(Annual_return_and_ratios!E7 - Annual_return_and_ratios!E73) -> 0.44090709 | F40: =ABS(Annual_return_and_ratios!F7 - Annual_return_and_ratios!F73) -> 0.50263164 | G40: =ABS(Annual_return_and_ratios!G7 - Annual_return_and_ratios!G73) -> 0.47720279 | H40: =ABS(Annual_return_and_ratios!H7 - Annual_return_and_ratios!H73) -> 0.34037455 | I40: =ABS(Annual_return_and_ratios!I7 - Annual_return_and_ratios!I73) -> 0.50153513 | ... M40: =ABS(Annual_return_and_ratios!M7 - Annual_return_and_ratios!M73) -> 0.21655097
A41: Bharti Airtel Ltd | B41: =ABS(Annual_return_and_ratios!B8 - Annual_return_and_ratios!B74) -> 0.13003573 | C41: =ABS(Annual_return_and_ratios!C8 - Annual_return_and_ratios!C74) -> 0.30027315 | D41: =ABS(Annual_return_and_ratios!D8 - Annual_return_and_ratios!D74) -> 0.23183812 | E41: =ABS(Annual_return_and_ratios!E8 - Annual_return_and_ratios!E74) -> 0.032532989 | F41: =ABS(Annual_return_and_ratios!F8 - Annual_return_and_ratios!F74) -> 0.012751318 | G41: =ABS(Annual_return_and_ratios!G8 - Annual_return_and_ratios!G74) -> 0.028987966 | H41: =ABS(Annual_return_and_ratios!H8 - Annual_return_and_ratios!H74) -> 1.0150637 | I41: =ABS(Annual_return_and_ratios!I8 - Annual_return_and_ratios!I74) -> 0.98767565 | ... M41: =ABS(Annual_return_and_ratios!M8 - Annual_return_and_ratios!M74) -> 0.013501463
A42: HCL Technologies Ltd | B42: =ABS(Annual_return_and_ratios!B9 - Annual_return_and_ratios!B75) -> 0.99405977 | C42: =ABS(Annual_return_and_ratios!C9 - Annual_return_and_ratios!C75) -> 0.96696429 | D42: =ABS(Annual_return_and_ratios!D9 - Annual_return_and_ratios!D75) -> 0.99402703 | E42: =ABS(Annual_return_and_ratios!E9 - Annual_return_and_ratios!E75) -> 0.94134068 | F42: =ABS(Annual_return_and_ratios!F9 - Annual_return_and_ratios!F75) -> 0.25635805 | G42: =ABS(Annual_return_and_ratios!G9 - Annual_return_and_ratios!G75) -> 0.15553871 | H42: =ABS(Annual_return_and_ratios!H9 - Annual_return_and_ratios!H75) -> 0.11240342 | I42: =ABS(Annual_return_and_ratios!I9 - Annual_return_and_ratios!I75) -> 0.20988016 | ... M42: =ABS(Annual_return_and_ratios!M9 - Annual_return_and_ratios!M75) -> 0.070387824
A43: HDFC Bank Ltd | B43: =ABS(Annual_return_and_ratios!B10 - Annual_return_and_ratios!B76) -> 0.26861943 | C43: =ABS(Annual_return_and_ratios!C10 - Annual_return_and_ratios!C76) -> 0.28293289 | D43: =ABS(Annual_return_and_ratios!D10 - Annual_return_and_ratios!D76) -> 0.26352948 | E43: =ABS(Annual_return_and_ratios!E10 - Annual_return_and_ratios!E76) -> 0.26275132 | F43: =ABS(Annual_return_and_ratios!F10 - Annual_return_and_ratios!F76) -> 0.084729645 | G43: =ABS(Annual_return_and_ratios!G10 - Annual_return_and_ratios!G76) -> 0.019558332 | H43: =ABS(Annual_return_and_ratios!H10 - Annual_return_and_ratios!H76) -> 0.19382456 | I43: =ABS(Annual_return_and_ratios!I10 - Annual_return_and_ratios!I76) -> 0.1964836 | ... M43: =ABS(Annual_return_and_ratios!M10 - Annual_return_and_ratios!M76) -> 0.016349853
A44: Hindustan Unilever Ltd | B44: =ABS(Annual_return_and_ratios!B11 - Annual_return_and_ratios!B77) -> 0.99785611 | C44: =ABS(Annual_return_and_ratios!C11 - Annual_return_and_ratios!C77) -> 1.010169 | D44: =ABS(Annual_return_and_ratios!D11 - Annual_return_and_ratios!D77) -> 0.9304594 | E44: =ABS(Annual_return_and_ratios!E11 - Annual_return_and_ratios!E77) -> 0.97611213 | F44: =ABS(Annual_return_and_ratios!F11 - Annual_return_and_ratios!F77) -> 0.99358942 | G44: =ABS(Annual_return_and_ratios!G11 - Annual_return_and_ratios!G77) -> 0.85005547 | H44: =ABS(Annual_return_and_ratios!H11 - Annual_return_and_ratios!H77) -> 0.83169574 | I44: =ABS(Annual_return_and_ratios!I11 - Annual_return_and_ratios!I77) -> 0.81626862 | ... M44: =ABS(Annual_return_and_ratios!M11 - Annual_return_and_ratios!M77) -> 0.78220867
A45: ICICI Bank Ltd | B45: =ABS(Annual_return_and_ratios!B12 - Annual_return_and_ratios!B78) -> 0.15973355 | C45: =ABS(Annual_return_and_ratios!C12 - Annual_return_and_ratios!C78) -> 0.16279272 | D45: =ABS(Annual_return_and_ratios!D12 - Annual_return_and_ratios!D78) -> 0.16705185 | E45: =ABS(Annual_return_and_ratios!E12 - Annual_return_and_ratios!E78) -> 0.13476276 | F45: =ABS(Annual_return_and_ratios!F12 - Annual_return_and_ratios!F78) -> 0.038682898 | G45: =ABS(Annual_return_and_ratios!G12 - Annual_return_and_ratios!G78) -> 0.0081086488 | H45: =ABS(Annual_return_and_ratios!H12 - Annual_return_and_ratios!H78) -> 0.13858094 | I45: =ABS(Annual_return_and_ratios!I12 - Annual_return_and_ratios!I78) -> 0.12701083 | ... M45: =ABS(Annual_return_and_ratios!M12 - Annual_return_and_ratios!M78) -> 0.25165068
A46: Infosys Ltd | B46: =ABS(Annual_return_and_ratios!B13 - Annual_return_and_ratios!B79) -> 0.8562903 | C46: =ABS(Annual_return_and_ratios!C13 - Annual_return_and_ratios!C79) -> 0.62892837 | D46: =ABS(Annual_return_and_ratios!D13 - Annual_return_and_ratios!D79) -> 0.66265226 | E46: =ABS(Annual_return_and_ratios!E13 - Annual_return_and_ratios!E79) -> 0.62135844 | F46: =ABS(Annual_return_and_ratios!F13 - Annual_return_and_ratios!F79) -> 0.46453642 | G46: =ABS(Annual_return_and_ratios!G13 - Annual_return_and_ratios!G79) -> 0.66075602 | H46: =ABS(Annual_return_and_ratios!H13 - Annual_return_and_ratios!H79) -> 0.97678238 | I46: =ABS(Annual_return_and_ratios!I13 - Annual_return_and_ratios!I79) -> 0.51922098 | ... M46: =ABS(Annual_return_and_ratios!M13 - Annual_return_and_ratios!M79) -> 0.36938684
... A63: UltraTech Cement Ltd | B63: =ABS(Annual_return_and_ratios!B30 - Annual_return_and_ratios!B96) -> 0.36835964 | C63: =ABS(Annual_return_and_ratios!C30 - Annual_return_and_ratios!C96) -> 0.1585364 | D63: =ABS(Annual_return_and_ratios!D30 - Annual_return_and_ratios!D96) -> 0.23090805 | E63: =ABS(Annual_return_and_ratios!E30 - Annual_return_and_ratios!E96) -> 0.16775459 | F63: =ABS(Annual_return_and_ratios!F30 - Annual_return_and_ratios!F96) -> 0.015048151 | G63: =ABS(Annual_return_and_ratios!G30 - Annual_return_and_ratios!G96) -> 0.08547139 | H63: =ABS(Annual_return_and_ratios!H30 - Annual_return_and_ratios!H96) -> 0.16648371 | I63: =ABS(Annual_return_and_ratios!I30 - Annual_return_and_ratios!I96) -> 0.17212871 | ... M63: =ABS(Annual_return_and_ratios!M30 - Annual_return_and_ratios!M96) -> 0.10925843
A67: Profit margin | B67: (PM)2025 | C67: (PM)2024 | D67: (PM)2023 | E67: (PM)2022 | F67: (PM)2021 | G67: (PM)2020 | H67: (PM)2019 | I67: (PM)2018 | J67: (PM)2017 | K67: (PM)2016 | L67: (PM)2015 | M67: (PM)2014
A68: Adani Ports and Special Economic Zone Ltd | B68: =ABS(Annual_return_and_ratios!B2 - Annual_return_and_ratios!B101) -> 1.0183889 | C68: =ABS(Annual_return_and_ratios!C2 - Annual_return_and_ratios!C101) -> 0.90308005 | D68: =ABS(Annual_return_and_ratios!D2 - Annual_return_and_ratios!D101) -> 0.81157571 | E68: =ABS(Annual_return_and_ratios!E2 - Annual_return_and_ratios!E101) -> 0.89728573 | F68: =ABS(Annual_return_and_ratios!F2 - Annual_return_and_ratios!F101) -> 0.90288799 | G68: =ABS(Annual_return_and_ratios!G2 - Annual_return_and_ratios!G101) -> 1.0270003 | H68: =ABS(Annual_return_and_ratios!H2 - Annual_return_and_ratios!H101) -> 0.99185947 | I68: =ABS(Annual_return_and_ratios!I2 - Annual_return_and_ratios!I101) -> 0.99651093 | ... M68: =ABS(Annual_return_and_ratios!M2 - Annual_return_and_ratios!M101) -> 0.9723213
A69: Asian Paints Ltd | B69: =ABS(Annual_return_and_ratios!B3 - Annual_return_and_ratios!B102) -> 0.33054699 | C69: =ABS(Annual_return_and_ratios!C3 - Annual_return_and_ratios!C102) -> 0.4638116 | D69: =ABS(Annual_return_and_ratios!D3 - Annual_return_and_ratios!D102) -> 0.36333293 | E69: =ABS(Annual_return_and_ratios!E3 - Annual_return_and_ratios!E102) -> 0.29639564 | F69: =ABS(Annual_return_and_ratios!F3 - Annual_return_and_ratios!F102) -> 0.41173075 | G69: =ABS(Annual_return_and_ratios!G3 - Annual_return_and_ratios!G102) -> 0.39951157 | H69: =ABS(Annual_return_and_ratios!H3 - Annual_return_and_ratios!H102) -> 0.31358981 | I69: =ABS(Annual_return_and_ratios!I3 - Annual_return_and_ratios!I102) -> 0.36596035 | ... M69: =ABS(Annual_return_and_ratios!M3 - Annual_return_and_ratios!M102) -> 0.28205504
A70: AXIS Bank Ltd | B70: =ABS(Annual_return_and_ratios!B4 - Annual_return_and_ratios!B103) -> 0.6811926 | C70: =ABS(Annual_return_and_ratios!C4 - Annual_return_and_ratios!C103) -> 0.71217953 | D70: =ABS(Annual_return_and_ratios!D4 - Annual_return_and_ratios!D103) -> 0.3590191 | E70: =ABS(Annual_return_and_ratios!E4 - Annual_return_and_ratios!E103) -> 0.63052916 | F70: =ABS(Annual_return_and_ratios!F4 - Annual_return_and_ratios!F103) -> 0.28194118 | G70: =ABS(Annual_return_and_ratios!G4 - Annual_return_and_ratios!G103) -> 0.11642526 | H70: =ABS(Annual_return_and_ratios!H4 - Annual_return_and_ratios!H103) -> 0.22889744 | I70: =ABS(Annual_return_and_ratios!I4 - Annual_return_and_ratios!I103) -> 0.0067287922 | ... M70: =ABS(Annual_return_and_ratios!M4 - Annual_return_and_ratios!M103) -> 0.61395377
A71: Bajaj Finserv Ltd | B71: =ABS(Annual_return_and_ratios!B5 - Annual_return_and_ratios!B104) -> 0.38426271 | C71: =ABS(Annual_return_and_ratios!C5 - Annual_return_and_ratios!C104) -> 0.40911769 | D71: =ABS(Annual_return_and_ratios!D5 - Annual_return_and_ratios!D104) -> 0.46991992 | E71: =ABS(Annual_return_and_ratios!E5 - Annual_return_and_ratios!E104) -> 0.31721879 | F71: =ABS(Annual_return_and_ratios!F5 - Annual_return_and_ratios!F104) -> 0.2924457 | G71: =ABS(Annual_return_and_ratios!G5 - Annual_return_and_ratios!G104) -> 0.34465322 | H71: =ABS(Annual_return_and_ratios!H5 - Annual_return_and_ratios!H104) -> 0.35539724 | I71: =ABS(Annual_return_and_ratios!I5 - Annual_return_and_ratios!I104) -> 0.36314884 | ... M71: =ABS(Annual_return_and_ratios!M5 - Annual_return_and_ratios!M104) -> 0.99423038
A72: Bajaj Finance Ltd | B72: =ABS(Annual_return_and_ratios!B6 - Annual_return_and_ratios!B105) -> 0.7316338 | C72: =ABS(Annual_return_and_ratios!C6 - Annual_return_and_ratios!C105) -> 0.79726415 | D72: =ABS(Annual_return_and_ratios!D6 - Annual_return_and_ratios!D105) -> 0.8806541 | E72: =ABS(Annual_return_and_ratios!E6 - Annual_return_and_ratios!E105) -> 0.65793121 | F72: =ABS(Annual_return_and_ratios!F6 - Annual_return_and_ratios!F105) -> 0.42275877 | G72: =ABS(Annual_return_and_ratios!G6 - Annual_return_and_ratios!G105) -> 0.62099384 | H72: =ABS(Annual_return_and_ratios!H6 - Annual_return_and_ratios!H105) -> 0.62163464 | I72: =ABS(Annual_return_and_ratios!I6 - Annual_return_and_ratios!I105) -> 0.58086856 | ... M72: =ABS(Annual_return_and_ratios!M6 - Annual_return_and_ratios!M105) -> 0.49990591
A73: Bharat Electronics Ltd | B73: =ABS(Annual_return_and_ratios!B7 - Annual_return_and_ratios!B106) -> 0.66191908 | C73: =ABS(Annual_return_and_ratios!C7 - Annual_return_and_ratios!C106) -> 0.54053342 | D73: =ABS(Annual_return_and_ratios!D7 - Annual_return_and_ratios!D106) -> 0.47972016 | E73: =ABS(Annual_return_and_ratios!E7 - Annual_return_and_ratios!E106) -> 0.42465703 | F73: =ABS(Annual_return_and_ratios!F7 - Annual_return_and_ratios!F106) -> 0.39594565 | G73: =ABS(Annual_return_and_ratios!G7 - Annual_return_and_ratios!G106) -> 0.42708581 | H73: =ABS(Annual_return_and_ratios!H7 - Annual_return_and_ratios!H106) -> 0.49648326 | I73: =ABS(Annual_return_and_ratios!I7 - Annual_return_and_ratios!I106) -> 0.41463978 | ... M73: =ABS(Annual_return_and_ratios!M7 - Annual_return_and_ratios!M106) -> 0.43938174
A74: Bharti Airtel Ltd | B74: =ABS(Annual_return_and_ratios!B8 - Annual_return_and_ratios!B107) -> 0.57610146 | C74: =ABS(Annual_return_and_ratios!C8 - Annual_return_and_ratios!C107) -> 0.057000288 | D74: =ABS(Annual_return_and_ratios!D8 - Annual_return_and_ratios!D107) -> 0.24438895 | E74: =ABS(Annual_return_and_ratios!E8 - Annual_return_and_ratios!E107) -> 0.10728892 | F74: =ABS(Annual_return_and_ratios!F8 - Annual_return_and_ratios!F107) -> 0.012751318 | G74: =ABS(Annual_return_and_ratios!G8 - Annual_return_and_ratios!G107) -> 0.028987966 | H74: =ABS(Annual_return_and_ratios!H8 - Annual_return_and_ratios!H107) -> 0.046174275 | I74: =ABS(Annual_return_and_ratios!I8 - Annual_return_and_ratios!I107) -> 0.008874348 | ... M74: =ABS(Annual_return_and_ratios!M8 - Annual_return_and_ratios!M107) -> 0.077400361
A75: HCL Technologies Ltd | B75: =ABS(Annual_return_and_ratios!B9 - Annual_return_and_ratios!B108) -> 0.44786546 | C75: =ABS(Annual_return_and_ratios!C9 - Annual_return_and_ratios!C108) -> 0.40254485 | D75: =ABS(Annual_return_and_ratios!D9 - Annual_return_and_ratios!D108) -> 0.44594581 | E75: =ABS(Annual_return_and_ratios!E9 - Annual_return_and_ratios!E108) -> 0.46549167 | F75: =ABS(Annual_return_and_ratios!F9 - Annual_return_and_ratios!F108) -> 0.37644789 | G75: =ABS(Annual_return_and_ratios!G9 - Annual_return_and_ratios!G108) -> 0.49482213 | H75: =ABS(Annual_return_and_ratios!H9 - Annual_return_and_ratios!H108) -> 0.50299798 | I75: =ABS(Annual_return_and_ratios!I9 - Annual_return_and_ratios!I108) -> 0.51864213 | ... M75: =ABS(Annual_return_and_ratios!M9 - Annual_return_and_ratios!M108) -> 0.57402768
A76: HDFC Bank Ltd | B76: =ABS(Annual_return_and_ratios!B10 - Annual_return_and_ratios!B109) -> 0.67910758 | C76: =ABS(Annual_return_and_ratios!C10 - Annual_return_and_ratios!C109) -> 0.73684709 | D76: =ABS(Annual_return_and_ratios!D10 - Annual_return_and_ratios!D109) -> 0.84118907 | E76: =ABS(Annual_return_and_ratios!E10 - Annual_return_and_ratios!E109) -> 0.90182733 | F76: =ABS(Annual_return_and_ratios!F10 - Annual_return_and_ratios!F109) -> 0.75524679 | G76: =ABS(Annual_return_and_ratios!G10 - Annual_return_and_ratios!G109) -> 0.7291553 | H76: =ABS(Annual_return_and_ratios!H10 - Annual_return_and_ratios!H109) -> 0.64147222 | I76: =ABS(Annual_return_and_ratios!I10 - Annual_return_and_ratios!I109) -> 0.65227562 | ... M76: =ABS(Annual_return_and_ratios!M10 - Annual_return_and_ratios!M109) -> 0.62130582
A77: Hindustan Unilever Ltd | B77: =ABS(Annual_return_and_ratios!B11 - Annual_return_and_ratios!B110) -> 0.51720831 | C77: =ABS(Annual_return_and_ratios!C11 - Annual_return_and_ratios!C110) -> 0.51992905 | D77: =ABS(Annual_return_and_ratios!D11 - Annual_return_and_ratios!D110) -> 0.49439821 | E77: =ABS(Annual_return_and_ratios!E11 - Annual_return_and_ratios!E110) -> 0.53426276 | F77: =ABS(Annual_return_and_ratios!F11 - Annual_return_and_ratios!F110) -> 0.51581928 | G77: =ABS(Annual_return_and_ratios!G11 - Annual_return_and_ratios!G110) -> 0.49645689 | H77: =ABS(Annual_return_and_ratios!H11 - Annual_return_and_ratios!H110) -> 0.44960735 | I77: =ABS(Annual_return_and_ratios!I11 - Annual_return_and_ratios!I110) -> 0.41568421 | ... M77: =ABS(Annual_return_and_ratios!M11 - Annual_return_and_ratios!M110) -> 0.38365512
A78: ICICI Bank Ltd | B78: =ABS(Annual_return_and_ratios!B12 - Annual_return_and_ratios!B111) -> 0.89700731 | C78: =ABS(Annual_return_and_ratios!C12 - Annual_return_and_ratios!C111) -> 0.86272926 | D78: =ABS(Annual_return_and_ratios!D12 - Annual_return_and_ratios!D111) -> 0.86929883 | E78: =ABS(Annual_return_and_ratios!E12 - Annual_return_and_ratios!E111) -> 0.82051915 | F78: =ABS(Annual_return_and_ratios!F12 - Annual_return_and_ratios!F111) -> 0.65695915 | G78: =ABS(Annual_return_and_ratios!G12 - Annual_return_and_ratios!G111) -> 0.40979687 | H78: =ABS(Annual_return_and_ratios!H12 - Annual_return_and_ratios!H111) -> 0.19935687 | I78: =ABS(Annual_return_and_ratios!I12 - Annual_return_and_ratios!I111) -> 0.43706944 | ... M78: =ABS(Annual_return_and_ratios!M12 - Annual_return_and_ratios!M111) -> 0.71212217
...

Sheet GRC
A1: Diluted EPS | B1: 2025 | C1: 2024 | D1: 2023 | E1: 2022 | F1: 2021 | G1: 2020 | H1: 2019 | I1: 2018 | J1: 2017 | K1: 2016 | L1: 2015 | M1: 2014 | O1: Company mean
A2: Adani Ports and Special Economic Zone Ltd | B2: =(Deviation_sequence!$B$233 + 0.5 *Deviation_sequence!$B$232) / (Deviation_sequence!B2 + 0.5 * Deviation_sequence!$B$232) -> 0.6498081 | C2: =(Deviation_sequence!$B$233 + 0.5 *Deviation_sequence!$B$232) / (Deviation_sequence!C2 + 0.5 * Deviation_sequence!$B$232) -> 0.80666861 | D2: =(Deviation_sequence!$B$233 + 0.5 *Deviation_sequence!$B$232) / (Deviation_sequence!D2 + 0.5 * Deviation_sequence!$B$232) -> 0.79655333 | E2: =(Deviation_sequence!$B$233 + 0.5 *Deviation_sequence!$B$232) / (Deviation_sequence!E2 + 0.5 * Deviation_sequence!$B$232) -> 0.83441435 | F2: =(Deviation_sequence!$B$233 + 0.5 *Deviation_sequence!$B$232) / (Deviation_sequence!F2 + 0.5 * Deviation_sequence!$B$232) -> 0.95629728 | G2: =(Deviation_sequence!$B$233 + 0.5 *Deviation_sequence!$B$232) / (Deviation_sequence!G2 + 0.5 * Deviation_sequence!$B$232) -> 0.82008593 | H2: =(Deviation_sequence!$B$233 + 0.5 *Deviation_sequence!$B$232) / (Deviation_sequence!H2 + 0.5 * Deviation_sequence!$B$232) -> 0.86195423 | I2: =(Deviation_sequence!$B$233 + 0.5 *Deviation_sequence!$B$232) / (Deviation_sequence!I2 + 0.5 * Deviation_sequence!$B$232) -> 0.86706463 | ... M2: =(Deviation_sequence!$B$233 + 0.5 *Deviation_sequence!$B$232) / (Deviation_sequence!M2 + 0.5 * Deviation_sequence!$B$232) -> 0.9878389 | O2: =AVERAGE(B2:M2) -> 0.86174808
A3: Asian Paints Ltd | B3: =(Deviation_sequence!$B$233 + 0.5 *Deviation_sequence!$B$232) / (Deviation_sequence!B3 + 0.5 * Deviation_sequence!$B$232) -> 0.71462441 | C3: =(Deviation_sequence!$B$233 + 0.5 *Deviation_sequence!$B$232) / (Deviation_sequence!C3 + 0.5 * Deviation_sequence!$B$232) -> 0.64318699 | D3: =(Deviation_sequence!$B$233 + 0.5 *Deviation_sequence!$B$232) / (Deviation_sequence!D3 + 0.5 * Deviation_sequence!$B$232) -> 0.70164794 | E3: =(Deviation_sequence!$B$233 + 0.5 *Deviation_sequence!$B$232) / (Deviation_sequence!E3 + 0.5 * Deviation_sequence!$B$232) -> 0.78853519 | F3: =(Deviation_sequence!$B$233 + 0.5 *Deviation_sequence!$B$232) / (Deviation_sequence!F3 + 0.5 * Deviation_sequence!$B$232) -> 0.801591 | G3: =(Deviation_sequence!$B$233 + 0.5 *Deviation_sequence!$B$232) / (Deviation_sequence!G3 + 0.5 * Deviation_sequence!$B$232) -> 0.80106872 | H3: =(Deviation_sequence!$B$233 + 0.5 *Deviation_sequence!$B$232) / (Deviation_sequence!H3 + 0.5 * Deviation_sequence!$B$232) -> 0.86146045 | I3: =(Deviation_sequence!$B$233 + 0.5 *Deviation_sequence!$B$232) / (Deviation_sequence!I3 + 0.5 * Deviation_sequence!$B$232) -> 0.83943517 | ... M3: =(Deviation_sequence!$B$233 + 0.5 *Deviation_sequence!$B$232) / (Deviation_sequence!M3 + 0.5 * Deviation_sequence!$B$232) -> 0.92451248 | O3: =AVERAGE(B3:M3) -> 0.81303918
A4: AXIS Bank Ltd | B4: =(Deviation_sequence!$B$233 + 0.5 *Deviation_sequence!$B$232) / (Deviation_sequence!B4 + 0.5 * Deviation_sequence!$B$232) -> 0.52754154 | C4: =(Deviation_sequence!$B$233 + 0.5 *Deviation_sequence!$B$232) / (Deviation_sequence!C4 + 0.5 * Deviation_sequence!$B$232) -> 0.5497697 | D4: =(Deviation_sequence!$B$233 + 0.5 *Deviation_sequence!$B$232) / (Deviation_sequence!D4 + 0.5 * Deviation_sequence!$B$232) -> 0.76579371 | E4: =(Deviation_sequence!$B$233 + 0.5 *Deviation_sequence!$B$232) / (Deviation_sequence!E4 + 0.5 * Deviation_sequence!$B$232) -> 0.6957798 | F4: =(Deviation_sequence!$B$233 + 0.5 *Deviation_sequence!$B$232) / (Deviation_sequence!F4 + 0.5 * Deviation_sequence!$B$232) -> 0.89133307 | G4: =(Deviation_sequence!$B$233 + 0.5 *Deviation_sequence!$B$232) / (Deviation_sequence!G4 + 0.5 * Deviation_sequence!$B$232) -> 0.88421527 | H4: =(Deviation_sequence!$B$233 + 0.5 *Deviation_sequence!$B$232) / (Deviation_sequence!H4 + 0.5 * Deviation_sequence!$B$232) -> 0.90365148 | I4: =(Deviation_sequence!$B$233 + 0.5 *Deviation_sequence!$B$232) / (Deviation_sequence!I4 + 0.5 * Deviation_sequence!$B$232) -> 0.9933805 | ... M4: =(Deviation_sequence!$B$233 + 0.5 *Deviation_sequence!$B$232) / (Deviation_sequence!M4 + 0.5 * Deviation_sequence!$B$232) -> 0.43239467 | O4: =AVERAGE(B4:M4) -> 0.75727599
A5: Bajaj Finserv Ltd | B5: =(Deviation_sequence!$B$233 + 0.5 *Deviation_sequence!$B$232) / (Deviation_sequence!B5 + 0.5 * Deviation_sequence!$B$232) -> 0.9501645 | C5: =(Deviation_sequence!$B$233 + 0.5 *Deviation_sequence!$B$232) / (Deviation_sequence!C5 + 0.5 * Deviation_sequence!$B$232) -> 0.9870129 | D5: =(Deviation_sequence!$B$233 + 0.5 *Deviation_sequence!$B$232) / (Deviation_sequence!D5 + 0.5 * Deviation_sequence!$B$232) -> 0.94752349 | E5: =(Deviation_sequence!$B$233 + 0.5 *Deviation_sequence!$B$232) / (Deviation_sequence!E5 + 0.5 * Deviation_sequence!$B$232) -> 0.86513442 | F5: =(Deviation_sequence!$B$233 + 0.5 *Deviation_sequence!$B$232) / (Deviation_sequence!F5 + 0.5 * Deviation_sequence!$B$232) -> 0.95379293 | G5: =(Deviation_sequence!$B$233 + 0.5 *Deviation_sequence!$B$232) / (Deviation_sequence!G5 + 0.5 * Deviation_sequence!$B$232) -> 0.69777077 | H5: =(Deviation_sequence!$B$233 + 0.5 *Deviation_sequence!$B$232) / (Deviation_sequence!H5 + 0.5 * Deviation_sequence!$B$232) -> 0.88834547 | I5: =(Deviation_sequence!$B$233 + 0.5 *Deviation_sequence!$B$232) / (Deviation_sequence!I5 + 0.5 * Deviation_sequence!$B$232) -> 0.97232332 | ... M5: =(Deviation_sequence!$B$233 + 0.5 *Deviation_sequence!$B$232) / (Deviation_sequence!M5 + 0.5 * Deviation_sequence!$B$232) -> 0.97980697 | O5: =AVERAGE(B5:M5) -> 0.92043753
A6: Bajaj Finance Ltd | B6: =(Deviation_sequence!$B$233 + 0.5 *Deviation_sequence!$B$232) / (Deviation_sequence!B6 + 0.5 * Deviation_sequence!$B$232) -> 0.34881183 | C6: =(Deviation_sequence!$B$233 + 0.5 *Deviation_sequence!$B$232) / (Deviation_sequence!C6 + 0.5 * Deviation_sequence!$B$232) -> 0.35005172 | D6: =(Deviation_sequence!$B$233 + 0.5 *Deviation_sequence!$B$232) / (Deviation_sequence!D6 + 0.5 * Deviation_sequence!$B$232) -> 0.34214572 | E6: =(Deviation_sequence!$B$233 + 0.5 *Deviation_sequence!$B$232) / (Deviation_sequence!E6 + 0.5 * Deviation_sequence!$B$232) -> 0.47502744 | F6: =(Deviation_sequence!$B$233 + 0.5 *Deviation_sequence!$B$232) / (Deviation_sequence!F6 + 0.5 * Deviation_sequence!$B$232) -> 0.63978775 | G6: =(Deviation_sequence!$B$233 + 0.5 *Deviation_sequence!$B$232) / (Deviation_sequence!G6 + 0.5 * Deviation_sequence!$B$232) -> 0.52669966 | H6: =(Deviation_sequence!$B$233 + 0.5 *Deviation_sequence!$B$232) / (Deviation_sequence!H6 + 0.5 * Deviation_sequence!$B$232) -> 0.62825921 | I6: =(Deviation_sequence!$B$233 + 0.5 *Deviation_sequence!$B$232) / (Deviation_sequence!I6 + 0.5 * Deviation_sequence!$B$232) -> 0.71636606 | ... M6: =(Deviation_sequence!$B$233 + 0.5 *Deviation_sequence!$B$232) / (Deviation_sequence!M6 + 0.5 * Deviation_sequence!$B$232) -> 0.42244572 | O6: =AVERAGE(B6:M6) -> 0.49881652
A7: Bharat Electronics Ltd | B7: =(Deviation_sequence!$B$233 + 0.5 *Deviation_sequence!$B$232) / (Deviation_sequence!B7 + 0.5 * Deviation_sequence!$B$232) -> 1 | C7: =(Deviation_sequence!$B$233 + 0.5 *Deviation_sequence!$B$232) / (Deviation_sequence!C7 + 0.5 * Deviation_sequence!$B$232) -> 0.9263879 | D7: =(Deviation_sequence!$B$233 + 0.5 *Deviation_sequence!$B$232) / (Deviation_sequence!D7 + 0.5 * Deviation_sequence!$B$232) -> 0.96707196 | E7: =(Deviation_sequence!$B$233 + 0.5 *Deviation_sequence!$B$232) / (Deviation_sequence!E7 + 0.5 * Deviation_sequence!$B$232) -> 0.9962905 | F7: =(Deviation_sequence!$B$233 + 0.5 *Deviation_sequence!$B$232) / (Deviation_sequence!F7 + 0.5 * Deviation_sequence!$B$232) -> 0.97016514 | G7: =(Deviation_sequence!$B$233 + 0.5 *Deviation_sequence!$B$232) / (Deviation_sequence!G7 + 0.5 * Deviation_sequence!$B$232) -> 0.93685886 | H7: =(Deviation_sequence!$B$233 + 0.5 *Deviation_sequence!$B$232) / (Deviation_sequence!H7 + 0.5 * Deviation_sequence!$B$232) -> 0.89404083 | I7: =(Deviation_sequence!$B$233 + 0.5 *Deviation_sequence!$B$232) / (Deviation_sequence!I7 + 0.5 * Deviation_sequence!$B$232) -> 0.95750544 | ... M7: =(Deviation_sequence!$B$233 + 0.5 *Deviation_sequence!$B$232) / (Deviation_sequence!M7 + 0.5 * Deviation_sequence!$B$232) -> 0.45785745 | O7: =AVERAGE(B7:M7) -> 0.8773
A8: Bharti Airtel Ltd | B8: =(Deviation_sequence!$B$233 + 0.5 *Deviation_sequence!$B$232) / (Deviation_sequence!B8 + 0.5 * Deviation_sequence!$B$232) -> 0.66605706 | C8: =(Deviation_sequence!$B$233 + 0.5 *Deviation_sequence!$B$232) / (Deviation_sequence!C8 + 0.5 * Deviation_sequence!$B$232) -> 0.97848944 | D8: =(Deviation_sequence!$B$233 + 0.5 *Deviation_sequence!$B$232) / (Deviation_sequence!D8 + 0.5 * Deviation_sequence!$B$232) -> 0.88595912 | E8: =(Deviation_sequence!$B$233 + 0.5 *Deviation_sequence!$B$232) / (Deviation_sequence!E8 + 0.5 * Deviation_sequence!$B$232) -> 0.99505941 | F8: =(Deviation_sequence!$B$233 + 0.5 *Deviation_sequence!$B$232) / (Deviation_sequence!F8 + 0.5 * Deviation_sequence!$B$232) -> 0.97653405 | G8: =(Deviation_sequence!$B$233 + 0.5 *Deviation_sequence!$B$232) / (Deviation_sequence!G8 + 0.5 * Deviation_sequence!$B$232) -> 0.94801323 | H8: =(Deviation_sequence!$B$233 + 0.5 *Deviation_sequence!$B$232) / (Deviation_sequence!H8 + 0.5 * Deviation_sequence!$B$232) -> 0.97236791 | I8: =(Deviation_sequence!$B$233 + 0.5 *Deviation_sequence!$B$232) / (Deviation_sequence!I8 + 0.5 * Deviation_sequence!$B$232) -> 0.98368985 | ... M8: =(Deviation_sequence!$B$233 + 0.5 *Deviation_sequence!$B$232) / (Deviation_sequence!M8 + 0.5 * Deviation_sequence!$B$232) -> 0.97611565 | O8: =AVERAGE(B8:M8) -> 0.9282383
