Workbook

Sheet Sheet1
B1: (P/E)2025 | C1: (P/E)2024 | D1: (P/E)2023 | E1: (P/E)2022 | F1: (P/E)2021 | G1: (P/E)2020 | H1: (P/E)2019 | I1: (P/E)2018 | J1: (P/E)2017 | K1: (P/E)2016 | L1: (P/E)2015 | M1: (P/E)2014
A2: Adani Ports and Special Economic Zone Ltd | B2: 23.0195 | C2: 35.731 | D2: 25.7038 | E2: 34.5735 | F2: 28.5903 | G2: 13.6948 | H2: 19.616 | I2: 19.9915 | J2: 17.9884 | K2: 17.7055 | L2: 27.5537 | M2: 22.1893 | N2: 63.7973
A3: Asian Paints Ltd | B3: 34.9725 | C3: 49.9737 | D3: 64.4793 | E3: 97.5546 | F3: 77.5053 | G3: 59.1028 | H3: 66.3657 | I3: 52.714 | J3: 52.9773 | K3: 47.757 | L3: 55.6224 | M3: 42.9976 | N3: 63.7973
A4: AXIS Bank Ltd | B4: 12.1462 | C4: 12.2436 | D4: 24.3878 | E4: 16.5215 | F4: 28.8342 | G4: 55.5344 | H4: 39.5767 | I4: 121.41018 | J4: 29.6735 | K4: 12.658 | L4: 17.7567 | M4: 10.8559 | N4: 63.7973
A5: Bajaj Finserv Ltd | B5: 121.41018 | C5: 121.41018 | D5: 121.41018 | E5: 25.3549 | F5: 18.33 | G5: 10.4679 | H5: 14.9523 | I5: 10.6291 | J5: 8.2625 | K5: 59.1734 | L5: 38.5711 | M5: 18.4541 | N5: 63.7973
A6: Bajaj Finance Ltd | B6: 7.4587 | C6: 6.9385 | D6: 6.6465 | E6: 121.41018 | F6: 121.41018 | G6: 51.1279 | H6: 101.4777 | I6: 108.9304 | J6: 120.1941 | K6: 7.031 | L6: 7.7217 | M6: 6.184415 | N6: 63.7973
A7: Bharat Electronics Ltd | B7: 41.3736 | C7: 36.9633 | D7: 23.8509 | E7: 21.4061 | F7: 14.5128 | G7: 9.9266 | H7: 12.0543 | I7: 24.3654 | J7: 26.3215 | K7: 121.41018 | L7: 22.3672 | M7: 9.6262 | N7: 63.7973
A8: Bharti Airtel Ltd | B8: 29.844 | C8: 93.8923 | D8: 50.6081 | E8: 98.4876 | F8: 6.184415 | G8: 6.184415 | H8: 121.41018 | I8: 121.41018 | J8: 36.7981 | K8: 23.0703 | L8: 34.0744 | M8: 45.4274 | N8: 63.7973
A9: HCL Technologies Ltd | B9: 24.7966 | C9: 26.6132 | D9: 19.8031 | E9: 23.3745 | F9: 23.9457 | G9: 10.7178 | H9: 14.7866 | I9: 15.5793 | J9: 14.4712 | K9: 20.4612 | L9: 18.8069 | M9: 14.9227 | N9: 63.7973
A10: HDFC Bank Ltd | B10: 20.7102 | C10: 16.8729 | D10: 20.3123 | E10: 22.0052 | F10: 26.3971 | G10: 17.9546 | H10: 29.4533 | I10: 27.914 | J10: 25.2239 | K10: 21.9328 | L10: 24.2669 | M10: 21.1122 | N10: 63.7973
A11: Hindustan Unilever Ltd | B11: 49.8533 | C11: 51.8576 | D11: 59.4091 | E11: 54.2167 | F11: 71.4311 | G11: 73.7295 | H11: 61.0583 | I11: 55.4545 | J11: 43.9918 | K11: 45.5236 | L11: 43.2771 | M11: 33.0948 | N11: 63.7973
A12: ICICI Bank Ltd | B12: 18.6217 | C12: 17.3421 | D12: 17.9533 | E12: 20.1671 | F12: 21.3225 | G12: 21.9109 | H12: 60.3404 | I12: 23.1614 | J12: 17.4167 | K12: 13.494 | L12: 14.8937 | M12: 13.0209 | N12: 63.7973
A13: Infosys Ltd | B13: 24.3473 | C13: 23.6441 | D13: 23.9007 | E13: 36.3138 | F13: 29.9879 | G13: 16.4306 | H13: 20.9453 | I13: 15.9617 | J13: 16.2548 | K13: 20.6362 | L13: 20.4748 | M13: 17.5819 | N13: 63.7973
... A30: UltraTech Cement Ltd | B30: 56.0375 | C30: 40.0948 | D30: 43.3867 | E30: 25.9274 | F30: 35.5718 | G30: 16.3079 | H30: 47.5964 | I30: 48.775 | J30: 40.3351 | K30: 35.7364 | L30: 37.5915 | M30: 27.2082 | N30: 63.7973
A34: Global min | B34: =MIN(B2:N30) -> 6.184415
A35: Global Max | B35: =MAX(B2:N30) -> 121.41018
A38: percentile min | B38: =PERCENTILE(B2:M30, 0.05) -> 6.3461447
A39: percentile max | B39: =PERCENTILE(B2:M30, 0.95) -> 120.98456
B42: =MEDIAN(B2, $B$38, $B$39) -> 23.0195 | C42: =MEDIAN(C2, $B$38, $B$39) -> 35.731 | D42: =MEDIAN(D2, $B$38, $B$39) -> 25.7038 | E42: =MEDIAN(E2, $B$38, $B$39) -> 34.5735 | F42: =MEDIAN(F2, $B$38, $B$39) -> 28.5903 | G42: =MEDIAN(G2, $B$38, $B$39) -> 13.6948 | H42: =MEDIAN(H2, $B$38, $B$39) -> 19.616 | I42: =MEDIAN(I2, $B$38, $B$39) -> 19.9915 | ... N42: =MEDIAN(N2, $B$38, $B$39) -> 63.7973
B43: =MEDIAN(B3, $B$38, $B$39) -> 34.9725 | C43: =MEDIAN(C3, $B$38, $B$39) -> 49.9737 | D43: =MEDIAN(D3, $B$38, $B$39) -> 64.4793 | E43: =MEDIAN(E3, $B$38, $B$39) -> 97.5546 | F43: =MEDIAN(F3, $B$38, $B$39) -> 77.5053 | G43: =MEDIAN(G3, $B$38, $B$39) -> 59.1028 | H43: =MEDIAN(H3, $B$38, $B$39) -> 66.3657 | I43: =MEDIAN(I3, $B$38, $B$39) -> 52.714 | ... N43: =MEDIAN(N3, $B$38, $B$39) -> 63.7973
B44: =MEDIAN(B4, $B$38, $B$39) -> 12.1462 | C44: =MEDIAN(C4, $B$38, $B$39) -> 12.2436 | D44: =MEDIAN(D4, $B$38, $B$39) -> 24.3878 | E44: =MEDIAN(E4, $B$38, $B$39) -> 16.5215 | F44: =MEDIAN(F4, $B$38, $B$39) -> 28.8342 | G44: =MEDIAN(G4, $B$38, $B$39) -> 55.5344 | H44: =MEDIAN(H4, $B$38, $B$39) -> 39.5767 | I44: =MEDIAN(I4, $B$38, $B$39) -> 120.98456 | ... N44: =MEDIAN(N4, $B$38, $B$39) -> 63.7973
B45: =MEDIAN(B5, $B$38, $B$39) -> 120.98456 | C45: =MEDIAN(C5, $B$38, $B$39) -> 120.98456 | D45: =MEDIAN(D5, $B$38, $B$39) -> 120.98456 | E45: =MEDIAN(E5, $B$38, $B$39) -> 25.3549 | F45: =MEDIAN(F5, $B$38, $B$39) -> 18.33 | G45: =MEDIAN(G5, $B$38, $B$39) -> 10.4679 | H45: =MEDIAN(H5, $B$38, $B$39) -> 14.9523 | I45: =MEDIAN(I5, $B$38, $B$39) -> 10.6291 | ... N45: =MEDIAN(N5, $B$38, $B$39) -> 63.7973
B46: =MEDIAN(B6, $B$38, $B$39) -> 7.4587 | C46: =MEDIAN(C6, $B$38, $B$39) -> 6.9385 | D46: =MEDIAN(D6, $B$38, $B$39) -> 6.6465 | E46: =MEDIAN(E6, $B$38, $B$39) -> 120.98456 | F46: =MEDIAN(F6, $B$38, $B$39) -> 120.98456 | G46: =MEDIAN(G6, $B$38, $B$39) -> 51.1279 | H46: =MEDIAN(H6, $B$38, $B$39) -> 101.4777 | I46: =MEDIAN(I6, $B$38, $B$39) -> 108.9304 | ... N46: =MEDIAN(N6, $B$38, $B$39) -> 63.7973
B47: =MEDIAN(B7, $B$38, $B$39) -> 41.3736 | C47: =MEDIAN(C7, $B$38, $B$39) -> 36.9633 | D47: =MEDIAN(D7, $B$38, $B$39) -> 23.8509 | E47: =MEDIAN(E7, $B$38, $B$39) -> 21.4061 | F47: =MEDIAN(F7, $B$38, $B$39) -> 14.5128 | G47: =MEDIAN(G7, $B$38, $B$39) -> 9.9266 | H47: =MEDIAN(H7, $B$38, $B$39) -> 12.0543 | I47: =MEDIAN(I7, $B$38, $B$39) -> 24.3654 | ... N47: =MEDIAN(N7, $B$38, $B$39) -> 63.7973
B48: =MEDIAN(B8, $B$38, $B$39) -> 29.844 | C48: =MEDIAN(C8, $B$38, $B$39) -> 93.8923 | D48: =MEDIAN(D8, $B$38, $B$39) -> 50.6081 | E48: =MEDIAN(E8, $B$38, $B$39) -> 98.4876 | F48: =MEDIAN(F8, $B$38, $B$39) -> 6.3461447 | G48: =MEDIAN(G8, $B$38, $B$39) -> 6.3461447 | H48: =MEDIAN(H8, $B$38, $B$39) -> 120.98456 | I48: =MEDIAN(I8, $B$38, $B$39) -> 120.98456 | ... N48: =MEDIAN(N8, $B$38, $B$39) -> 63.7973
B49: =MEDIAN(B9, $B$38, $B$39) -> 24.7966 | C49: =MEDIAN(C9, $B$38, $B$39) -> 26.6132 | D49: =MEDIAN(D9, $B$38, $B$39) -> 19.8031 | E49: =MEDIAN(E9, $B$38, $B$39) -> 23.3745 | F49: =MEDIAN(F9, $B$38, $B$39) -> 23.9457 | G49: =MEDIAN(G9, $B$38, $B$39) -> 10.7178 | H49: =MEDIAN(H9, $B$38, $B$39) -> 14.7866 | I49: =MEDIAN(I9, $B$38, $B$39) -> 15.5793 | ... N49: =MEDIAN(N9, $B$38, $B$39) -> 63.7973
B50: =MEDIAN(B10, $B$38, $B$39) -> 20.7102 | C50: =MEDIAN(C10, $B$38, $B$39) -> 16.8729 | D50: =MEDIAN(D10, $B$38, $B$39) -> 20.3123 | E50: =MEDIAN(E10, $B$38, $B$39) -> 22.0052 | F50: =MEDIAN(F10, $B$38, $B$39) -> 26.3971 | G50: =MEDIAN(G10, $B$38, $B$39) -> 17.9546 | H50: =MEDIAN(H10, $B$38, $B$39) -> 29.4533 | I50: =MEDIAN(I10, $B$38, $B$39) -> 27.914 | ... N50: =MEDIAN(N10, $B$38, $B$39) -> 63.7973
B51: =MEDIAN(B11, $B$38, $B$39) -> 49.8533 | C51: =MEDIAN(C11, $B$38, $B$39) -> 51.8576 | D51: =MEDIAN(D11, $B$38, $B$39) -> 59.4091 | E51: =MEDIAN(E11, $B$38, $B$39) -> 54.2167 | F51: =MEDIAN(F11, $B$38, $B$39) -> 71.4311 | G51: =MEDIAN(G11, $B$38, $B$39) -> 73.7295 | H51: =MEDIAN(H11, $B$38, $B$39) -> 61.0583 | I51: =MEDIAN(I11, $B$38, $B$39) -> 55.4545 | ... N51: =MEDIAN(N11, $B$38, $B$39) -> 63.7973
B52: =MEDIAN(B12, $B$38, $B$39) -> 18.6217 | C52: =MEDIAN(C12, $B$38, $B$39) -> 17.3421 | D52: =MEDIAN(D12, $B$38, $B$39) -> 17.9533 | E52: =MEDIAN(E12, $B$38, $B$39) -> 20.1671 | F52: =MEDIAN(F12, $B$38, $B$39) -> 21.3225 | G52: =MEDIAN(G12, $B$38, $B$39) -> 21.9109 | H52: =MEDIAN(H12, $B$38, $B$39) -> 60.3404 | I52: =MEDIAN(I12, $B$38, $B$39) -> 23.1614 | ... N52: =MEDIAN(N12, $B$38, $B$39) -> 63.7973
B53: =MEDIAN(B13, $B$38, $B$39) -> 24.3473 | C53: =MEDIAN(C13, $B$38, $B$39) -> 23.6441 | D53: =MEDIAN(D13, $B$38, $B$39) -> 23.9007 | E53: =MEDIAN(E13, $B$38, $B$39) -> 36.3138 | F53: =MEDIAN(F13, $B$38, $B$39) -> 29.9879 | G53: =MEDIAN(G13, $B$38, $B$39) -> 16.4306 | H53: =MEDIAN(H13, $B$38, $B$39) -> 20.9453 | I53: =MEDIAN(I13, $B$38, $B$39) -> 15.9617 | ... N53: =MEDIAN(N13, $B$38, $B$39) -> 63.7973
... B70: =MEDIAN(B30, $B$38, $B$39) -> 56.0375 | C70: =MEDIAN(C30, $B$38, $B$39) -> 40.0948 | D70: =MEDIAN(D30, $B$38, $B$39) -> 43.3867 | E70: =MEDIAN(E30, $B$38, $B$39) -> 25.9274 | F70: =MEDIAN(F30, $B$38, $B$39) -> 35.5718 | G70: =MEDIAN(G30, $B$38, $B$39) -> 16.3079 | H70: =MEDIAN(H30, $B$38, $B$39) -> 47.5964 | I70: =MEDIAN(I30, $B$38, $B$39) -> 48.775 | ... N70: =MEDIAN(N30, $B$38, $B$39) -> 63.7973

Sheet Normalised
B1: (P/E)2025 | C1: (P/E)2024 | D1: (P/E)2023 | E1: (P/E)2022 | F1: (P/E)2021 | G1: (P/E)2020 | H1: (P/E)2019 | I1: (P/E)2018 | J1: (P/E)2017 | K1: (P/E)2016 | L1: (P/E)2015 | M1: (P/E)2014 | P1: flattened
A2: Adani Ports and Special Economic Zone Ltd | B2: =(Sheet1!$B$35 - Sheet1!B2) / (Sheet1!$B$35 - Sheet1!$B$34) -> 0.85389479 | C2: =(Sheet1!$B$35 - Sheet1!C2) / (Sheet1!$B$35 - Sheet1!$B$34) -> 0.74357659 | D2: =(Sheet1!$B$35 - Sheet1!D2) / (Sheet1!$B$35 - Sheet1!$B$34) -> 0.83059879 | E2: =(Sheet1!$B$35 - Sheet1!E2) / (Sheet1!$B$35 - Sheet1!$B$34) -> 0.75362208 | F2: =(Sheet1!$B$35 - Sheet1!F2) / (Sheet1!$B$35 - Sheet1!$B$34) -> 0.80554797 | G2: =(Sheet1!$B$35 - Sheet1!G2) / (Sheet1!$B$35 - Sheet1!$B$34) -> 0.93482027 | H2: =(Sheet1!$B$35 - Sheet1!H2) / (Sheet1!$B$35 - Sheet1!$B$34) -> 0.88343246 | I2: =(Sheet1!$B$35 - Sheet1!I2) / (Sheet1!$B$35 - Sheet1!$B$34) -> 0.88017364 | ... M2: =(Sheet1!$B$35 - Sheet1!M2) / (Sheet1!$B$35 - Sheet1!$B$34) -> 0.86109978 | P2: =IFERROR(__xludf.DUMMYFUNCTION("FLATTEN(B2:M30)"),0.8538947928054635) -> 0.85389479
A3: Asian Paints Ltd | B3: =(Sheet1!$B$35 - Sheet1!B3) / (Sheet1!$B$35 - Sheet1!$B$34) -> 0.75015932 | C3: =(Sheet1!$B$35 - Sheet1!C3) / (Sheet1!$B$35 - Sheet1!$B$34) -> 0.61996969 | D3: =(Sheet1!$B$35 - Sheet1!D3) / (Sheet1!$B$35 - Sheet1!$B$34) -> 0.49408119 | E3: =(Sheet1!$B$35 - Sheet1!E3) / (Sheet1!$B$35 - Sheet1!$B$34) -> 0.20703342 | F3: =(Sheet1!$B$35 - Sheet1!F3) / (Sheet1!$B$35 - Sheet1!$B$34) -> 0.38103356 | G3: =(Sheet1!$B$35 - Sheet1!G3) / (Sheet1!$B$35 - Sheet1!$B$34) -> 0.54074175 | H3: =(Sheet1!$B$35 - Sheet1!H3) / (Sheet1!$B$35 - Sheet1!$B$34) -> 0.47770985 | I3: =(Sheet1!$B$35 - Sheet1!I3) / (Sheet1!$B$35 - Sheet1!$B$34) -> 0.59618768 | ... M3: =(Sheet1!$B$35 - Sheet1!M3) / (Sheet1!$B$35 - Sheet1!$B$34) -> 0.68051257 | P3: =IFERROR(__xludf.DUMMYFUNCTION("""COMPUTED_VALUE"""),0.7435765888134225) -> 0.74357659
A4: AXIS Bank Ltd | B4: =(Sheet1!$B$35 - Sheet1!B4) / (Sheet1!$B$35 - Sheet1!$B$34) -> 0.94825997 | C4: =(Sheet1!$B$35 - Sheet1!C4) / (Sheet1!$B$35 - Sheet1!$B$34) -> 0.94741467 | D4: =(Sheet1!$B$35 - Sheet1!D4) / (Sheet1!$B$35 - Sheet1!$B$34) -> 0.84201985 | E4: =(Sheet1!$B$35 - Sheet1!E4) / (Sheet1!$B$35 - Sheet1!$B$34) -> 0.91028843 | F4: =(Sheet1!$B$35 - Sheet1!F4) / (Sheet1!$B$35 - Sheet1!$B$34) -> 0.80343126 | G4: =(Sheet1!$B$35 - Sheet1!G4) / (Sheet1!$B$35 - Sheet1!$B$34) -> 0.57171052 | H4: =(Sheet1!$B$35 - Sheet1!H4) / (Sheet1!$B$35 - Sheet1!$B$34) -> 0.71020124 | I4: =(Sheet1!$B$35 - Sheet1!I4) / (Sheet1!$B$35 - Sheet1!$B$34) -> 0 | ... M4: =(Sheet1!$B$35 - Sheet1!M4) / (Sheet1!$B$35 - Sheet1!$B$34) -> 0.95945798 | P4: =IFERROR(__xludf.DUMMYFUNCTION("""COMPUTED_VALUE"""),0.8305987887952495) -> 0.83059879
A5: Bajaj Finserv Ltd | B5: =(Sheet1!$B$35 - Sheet1!B5) / (Sheet1!$B$35 - Sheet1!$B$34) -> 0 | C5: =(Sheet1!$B$35 - Sheet1!C5) / (Sheet1!$B$35 - Sheet1!$B$34) -> 0 | D5: =(Sheet1!$B$35 - Sheet1!D5) / (Sheet1!$B$35 - Sheet1!$B$34) -> 0 | E5: =(Sheet1!$B$35 - Sheet1!E5) / (Sheet1!$B$35 - Sheet1!$B$34) -> 0.83362676 | F5: =(Sheet1!$B$35 - Sheet1!F5) / (Sheet1!$B$35 - Sheet1!$B$34) -> 0.89459315 | G5: =(Sheet1!$B$35 - Sheet1!G5) / (Sheet1!$B$35 - Sheet1!$B$34) -> 0.96282529 | H5: =(Sheet1!$B$35 - Sheet1!H5) / (Sheet1!$B$35 - Sheet1!$B$34) -> 0.92390691 | I5: =(Sheet1!$B$35 - Sheet1!I5) / (Sheet1!$B$35 - Sheet1!$B$34) -> 0.96142629 | ... M5: =(Sheet1!$B$35 - Sheet1!M5) / (Sheet1!$B$35 - Sheet1!$B$34) -> 0.89351614 | P5: =IFERROR(__xludf.DUMMYFUNCTION("""COMPUTED_VALUE"""),0.7536220847124736) -> 0.75362208
A6: Bajaj Finance Ltd | B6: =(Sheet1!$B$35 - Sheet1!B6) / (Sheet1!$B$35 - Sheet1!$B$34) -> 0.98894097 | C6: =(Sheet1!$B$35 - Sheet1!C6) / (Sheet1!$B$35 - Sheet1!$B$34) -> 0.99345559 | D6: =(Sheet1!$B$35 - Sheet1!D6) / (Sheet1!$B$35 - Sheet1!$B$34) -> 0.99598974 | E6: =(Sheet1!$B$35 - Sheet1!E6) / (Sheet1!$B$35 - Sheet1!$B$34) -> 0 | F6: =(Sheet1!$B$35 - Sheet1!F6) / (Sheet1!$B$35 - Sheet1!$B$34) -> 0 | G6: =(Sheet1!$B$35 - Sheet1!G6) / (Sheet1!$B$35 - Sheet1!$B$34) -> 0.60995283 | H6: =(Sheet1!$B$35 - Sheet1!H6) / (Sheet1!$B$35 - Sheet1!$B$34) -> 0.17298635 | I6: =(Sheet1!$B$35 - Sheet1!I6) / (Sheet1!$B$35 - Sheet1!$B$34) -> 0.10830724 | ... M6: =(Sheet1!$B$35 - Sheet1!M6) / (Sheet1!$B$35 - Sheet1!$B$34) -> 1 | P6: =IFERROR(__xludf.DUMMYFUNCTION("""COMPUTED_VALUE"""),0.8055479690003373) -> 0.80554797
A7: Bharat Electronics Ltd | B7: =(Sheet1!$B$35 - Sheet1!B7) / (Sheet1!$B$35 - Sheet1!$B$34) -> 0.69460664 | C7: =(Sheet1!$B$35 - Sheet1!C7) / (Sheet1!$B$35 - Sheet1!$B$34) -> 0.73288193 | D7: =(Sheet1!$B$35 - Sheet1!D7) / (Sheet1!$B$35 - Sheet1!$B$34) -> 0.84667939 | E7: =(Sheet1!$B$35 - Sheet1!E7) / (Sheet1!$B$35 - Sheet1!$B$34) -> 0.86789687 | F7: =(Sheet1!$B$35 - Sheet1!F7) / (Sheet1!$B$35 - Sheet1!$B$34) -> 0.92772116 | G7: =(Sheet1!$B$35 - Sheet1!G7) / (Sheet1!$B$35 - Sheet1!$B$34) -> 0.96752302 | H7: =(Sheet1!$B$35 - Sheet1!H7) / (Sheet1!$B$35 - Sheet1!$B$34) -> 0.94905753 | I7: =(Sheet1!$B$35 - Sheet1!I7) / (Sheet1!$B$35 - Sheet1!$B$34) -> 0.84221425 | ... M7: =(Sheet1!$B$35 - Sheet1!M7) / (Sheet1!$B$35 - Sheet1!$B$34) -> 0.97013008 | P7: =IFERROR(__xludf.DUMMYFUNCTION("""COMPUTED_VALUE"""),0.9348202663345188) -> 0.93482027
A8: Bharti Airtel Ltd | B8: =(Sheet1!$B$35 - Sheet1!B8) / (Sheet1!$B$35 - Sheet1!$B$34) -> 0.79466759 | C8: =(Sheet1!$B$35 - Sheet1!C8) / (Sheet1!$B$35 - Sheet1!$B$34) -> 0.23881711 | D8: =(Sheet1!$B$35 - Sheet1!D8) / (Sheet1!$B$35 - Sheet1!$B$34) -> 0.61446398 | E8: =(Sheet1!$B$35 - Sheet1!E8) / (Sheet1!$B$35 - Sheet1!$B$34) -> 0.19893627 | F8: =(Sheet1!$B$35 - Sheet1!F8) / (Sheet1!$B$35 - Sheet1!$B$34) -> 1 | G8: =(Sheet1!$B$35 - Sheet1!G8) / (Sheet1!$B$35 - Sheet1!$B$34) -> 1 | H8: =(Sheet1!$B$35 - Sheet1!H8) / (Sheet1!$B$35 - Sheet1!$B$34) -> 0 | I8: =(Sheet1!$B$35 - Sheet1!I8) / (Sheet1!$B$35 - Sheet1!$B$34) -> 0 | ... M8: =(Sheet1!$B$35 - Sheet1!M8) / (Sheet1!$B$35 - Sheet1!$B$34) -> 0.65942527 | P8: =IFERROR(__xludf.DUMMYFUNCTION("""COMPUTED_VALUE"""),0.8834324561250491) -> 0.88343246
A9: HCL Technologies Ltd | B9: =(Sheet1!$B$35 - Sheet1!B9) / (Sheet1!$B$35 - Sheet1!$B$34) -> 0.83847203 | C9: =(Sheet1!$B$35 - Sheet1!C9) / (Sheet1!$B$35 - Sheet1!$B$34) -> 0.82270646 | D9: =(Sheet1!$B$35 - Sheet1!D9) / (Sheet1!$B$35 - Sheet1!$B$34) -> 0.88180869 | E9: =(Sheet1!$B$35 - Sheet1!E9) / (Sheet1!$B$35 - Sheet1!$B$34) -> 0.85081388 | F9: =(Sheet1!$B$35 - Sheet1!F9) / (Sheet1!$B$35 - Sheet1!$B$34) -> 0.84585666 | G9: =(Sheet1!$B$35 - Sheet1!G9) / (Sheet1!$B$35 - Sheet1!$B$34) -> 0.9606565 | H9: =(Sheet1!$B$35 - Sheet1!H9) / (Sheet1!$B$35 - Sheet1!$B$34) -> 0.92534496 | I9: =(Sheet1!$B$35 - Sheet1!I9) / (Sheet1!$B$35 - Sheet1!$B$34) -> 0.91846542 | ... M9: =(Sheet1!$B$35 - Sheet1!M9) / (Sheet1!$B$35 - Sheet1!$B$34) -> 0.9241638 | P9: =IFERROR(__xludf.DUMMYFUNCTION("""COMPUTED_VALUE"""),0.8801736365050977) -> 0.88017364
A10: HDFC Bank Ltd | B10: =(Sheet1!$B$35 - Sheet1!B10) / (Sheet1!$B$35 - Sheet1!$B$34) -> 0.87393632 | C10: =(Sheet1!$B$35 - Sheet1!C10) / (Sheet1!$B$35 - Sheet1!$B$34) -> 0.90723876 | D10: =(Sheet1!$B$35 - Sheet1!D10) / (Sheet1!$B$35 - Sheet1!$B$34) -> 0.87738954 | E10: =(Sheet1!$B$35 - Sheet1!E10) / (Sheet1!$B$35 - Sheet1!$B$34) -> 0.86269751 | F10: =(Sheet1!$B$35 - Sheet1!F10) / (Sheet1!$B$35 - Sheet1!$B$34) -> 0.82458191 | G10: =(Sheet1!$B$35 - Sheet1!G10) / (Sheet1!$B$35 - Sheet1!$B$34) -> 0.89785111 | H10: =(Sheet1!$B$35 - Sheet1!H10) / (Sheet1!$B$35 - Sheet1!$B$34) -> 0.79805832 | I10: =(Sheet1!$B$35 - Sheet1!I10) / (Sheet1!$B$35 - Sheet1!$B$34) -> 0.81141732 | ... M10: =(Sheet1!$B$35 - Sheet1!M10) / (Sheet1!$B$35 - Sheet1!$B$34) -> 0.87044751 | P10: =IFERROR(__xludf.DUMMYFUNCTION("""COMPUTED_VALUE"""),0.8975577685443109) -> 0.89755777
A11: Hindustan Unilever Ltd | B11: =(Sheet1!$B$35 - Sheet1!B11) / (Sheet1!$B$35 - Sheet1!$B$34) -> 0.6210146 | C11: =(Sheet1!$B$35 - Sheet1!C11) / (Sheet1!$B$35 - Sheet1!$B$34) -> 0.60362005 | D11: =(Sheet1!$B$35 - Sheet1!D11) / (Sheet1!$B$35 - Sheet1!$B$34) -> 0.53808349 | E11: =(Sheet1!$B$35 - Sheet1!E11) / (Sheet1!$B$35 - Sheet1!$B$34) -> 0.58314633 | F11: =(Sheet1!$B$35 - Sheet1!F11) / (Sheet1!$B$35 - Sheet1!$B$34) -> 0.4337492 | G11: =(Sheet1!$B$35 - Sheet1!G11) / (Sheet1!$B$35 - Sheet1!$B$34) -> 0.41380227 | H11: =(Sheet1!$B$35 - Sheet1!H11) / (Sheet1!$B$35 - Sheet1!$B$34) -> 0.52377072 | I11: =(Sheet1!$B$35 - Sheet1!I11) / (Sheet1!$B$35 - Sheet1!$B$34) -> 0.57240394 | ... M11: =(Sheet1!$B$35 - Sheet1!M11) / (Sheet1!$B$35 - Sheet1!$B$34) -> 0.76645515 | P11: =IFERROR(__xludf.DUMMYFUNCTION("""COMPUTED_VALUE"""),0.9000129484923381) -> 0.90001295
A12: ICICI Bank Ltd | B12: =(Sheet1!$B$35 - Sheet1!B12) / (Sheet1!$B$35 - Sheet1!$B$34) -> 0.8920616 | C12: =(Sheet1!$B$35 - Sheet1!C12) / (Sheet1!$B$35 - Sheet1!$B$34) -> 0.90316676 | D12: =(Sheet1!$B$35 - Sheet1!D12) / (Sheet1!$B$35 - Sheet1!$B$34) -> 0.89786239 | E12: =(Sheet1!$B$35 - Sheet1!E12) / (Sheet1!$B$35 - Sheet1!$B$34) -> 0.87864967 | F12: =(Sheet1!$B$35 - Sheet1!F12) / (Sheet1!$B$35 - Sheet1!$B$34) -> 0.8686224 | G12: =(Sheet1!$B$35 - Sheet1!G12) / (Sheet1!$B$35 - Sheet1!$B$34) -> 0.8635159 | H12: =(Sheet1!$B$35 - Sheet1!H12) / (Sheet1!$B$35 - Sheet1!$B$34) -> 0.5300011 | I12: =(Sheet1!$B$35 - Sheet1!I12) / (Sheet1!$B$35 - Sheet1!$B$34) -> 0.8526633 | ... M12: =(Sheet1!$B$35 - Sheet1!M12) / (Sheet1!$B$35 - Sheet1!$B$34) -> 0.94066878 | P12: =IFERROR(__xludf.DUMMYFUNCTION("""COMPUTED_VALUE"""),0.8145442204465199) -> 0.81454422
A13: Infosys Ltd | B13: =(Sheet1!$B$35 - Sheet1!B13) / (Sheet1!$B$35 - Sheet1!$B$34) -> 0.84237133 | C13: =(Sheet1!$B$35 - Sheet1!C13) / (Sheet1!$B$35 - Sheet1!$B$34) -> 0.84847413 | D13: =(Sheet1!$B$35 - Sheet1!D13) / (Sheet1!$B$35 - Sheet1!$B$34) -> 0.8462472 | E13: =(Sheet1!$B$35 - Sheet1!E13) / (Sheet1!$B$35 - Sheet1!$B$34) -> 0.73851869 | F13: =(Sheet1!$B$35 - Sheet1!F13) / (Sheet1!$B$35 - Sheet1!$B$34) -> 0.79341874 | G13: =(Sheet1!$B$35 - Sheet1!G13) / (Sheet1!$B$35 - Sheet1!$B$34) -> 0.91107731 | H13: =(Sheet1!$B$35 - Sheet1!H13) / (Sheet1!$B$35 - Sheet1!$B$34) -> 0.87189597 | I13: =(Sheet1!$B$35 - Sheet1!I13) / (Sheet1!$B$35 - Sheet1!$B$34) -> 0.91514672 | ... M13: =(Sheet1!$B$35 - Sheet1!M13) / (Sheet1!$B$35 - Sheet1!$B$34) -> 0.90108563 | P13: =IFERROR(__xludf.DUMMYFUNCTION("""COMPUTED_VALUE"""),0.8610997782874438) -> 0.86109978
A14: ITC Ltd | B14: =(Sheet1!$B$35 - Sheet1!B14) / (Sheet1!$B$35 - Sheet1!$B$34) -> 0.9256947 | C14: =(Sheet1!$B$35 - Sheet1!C14) / (Sheet1!$B$35 - Sheet1!$B$34) -> 0.8271664 | D14: =(Sheet1!$B$35 - Sheet1!D14) / (Sheet1!$B$35 - Sheet1!$B$34) -> 0.83897452 | E14: =(Sheet1!$B$35 - Sheet1!E14) / (Sheet1!$B$35 - Sheet1!$B$34) -> 0.87771412 | F14: =(Sheet1!$B$35 - Sheet1!F14) / (Sheet1!$B$35 - Sheet1!$B$34) -> 0.87644964 | G14: =(Sheet1!$B$35 - Sheet1!G14) / (Sheet1!$B$35 - Sheet1!$B$34) -> 0.93396716 | H14: =(Sheet1!$B$35 - Sheet1!H14) / (Sheet1!$B$35 - Sheet1!$B$34) -> 0.80367773 | I14: =(Sheet1!$B$35 - Sheet1!I14) / (Sheet1!$B$35 - Sheet1!$B$34) -> 0.81383865 | ... M14: =(Sheet1!$B$35 - Sheet1!M14) / (Sheet1!$B$35 - Sheet1!$B$34) -> 0.78066725 | P14: =IFERROR(__xludf.DUMMYFUNCTION("""COMPUTED_VALUE"""),0.7501593176595825) -> 0.75015932
A15: Kotak Mahindra Bank Ltd | B15: =(Sheet1!$B$35 - Sheet1!B15) / (Sheet1!$B$35 - Sheet1!$B$34) -> 0.88434979 | C15: =(Sheet1!$B$35 - Sheet1!C15) / (Sheet1!$B$35 - Sheet1!$B$34) -> 0.88419965 | D15: =(Sheet1!$B$35 - Sheet1!D15) / (Sheet1!$B$35 - Sheet1!$B$34) -> 0.85297312 | E15: =(Sheet1!$B$35 - Sheet1!E15) / (Sheet1!$B$35 - Sheet1!$B$34) -> 0.80304072 | F15: =(Sheet1!$B$35 - Sheet1!F15) / (Sheet1!$B$35 - Sheet1!$B$34) -> 0.75241923 | G15: =(Sheet1!$B$35 - Sheet1!G15) / (Sheet1!$B$35 - Sheet1!$B$34) -> 0.80215116 | H15: =(Sheet1!$B$35 - Sheet1!H15) / (Sheet1!$B$35 - Sheet1!$B$34) -> 0.74683107 | I15: =(Sheet1!$B$35 - Sheet1!I15) / (Sheet1!$B$35 - Sheet1!$B$34) -> 0.77537243 | ... M15: =(Sheet1!$B$35 - Sheet1!M15) / (Sheet1!$B$35 - Sheet1!$B$34) -> 0.84391873 | P15: =IFERROR(__xludf.DUMMYFUNCTION("""COMPUTED_VALUE"""),0.6199696908078807) -> 0.61996969
A16: Larsen & Toubro Ltd | B16: =(Sheet1!$B$35 - Sheet1!B16) / (Sheet1!$B$35 - Sheet1!$B$34) -> 0.77663256 | C16: =(Sheet1!$B$35 - Sheet1!C16) / (Sheet1!$B$35 - Sheet1!$B$34) -> 0.70507739 | D16: =(Sheet1!$B$35 - Sheet1!D16) / (Sheet1!$B$35 - Sheet1!$B$34) -> 0.80153151 | E16: =(Sheet1!$B$35 - Sheet1!E16) / (Sheet1!$B$35 - Sheet1!$B$34) -> 0.80510623 | F16: =(Sheet1!$B$35 - Sheet1!F16) / (Sheet1!$B$35 - Sheet1!$B$34) -> 0.90445032 | G16: =(Sheet1!$B$35 - Sheet1!G16) / (Sheet1!$B$35 - Sheet1!$B$34) -> 0.95075681 | H16: =(Sheet1!$B$35 - Sheet1!H16) / (Sheet1!$B$35 - Sheet1!$B$34) -> 0.86454258 | I16: =(Sheet1!$B$35 - Sheet1!I16) / (Sheet1!$B$35 - Sheet1!$B$34) -> 0.83730041 | ... M16: =(Sheet1!$B$35 - Sheet1!M16) / (Sheet1!$B$35 - Sheet1!$B$34) -> 0.84516064 | P16: =IFERROR(__xludf.DUMMYFUNCTION("""COMPUTED_VALUE"""),0.4940811851376648) -> 0.49408119
A17: Mahindra & Mahindra Ltd | B17: =(Sheet1!$B$35 - Sheet1!B17) / (Sheet1!$B$35 - Sheet1!$B$34) -> 0.85403278 | C17: =(Sheet1!$B$35 - Sheet1!C17) / (Sheet1!$B$35 - Sheet1!$B$34) -> 0.88880539 | D17: =(Sheet1!$B$35 - Sheet1!D17) / (Sheet1!$B$35 - Sheet1!$B$34) -> 0.9448675 | E17: =(Sheet1!$B$35 - Sheet1!E17) / (Sheet1!$B$35 - Sheet1!$B$34) -> 0.93554319 | F17: =(Sheet1!$B$35 - Sheet1!F17) / (Sheet1!$B$35 - Sheet1!$B$34) -> 0.63111477 | G17: =(Sheet1!$B$35 - Sheet1!G17) / (Sheet1!$B$35 - Sheet1!$B$34) -> 1 | H17: =(Sheet1!$B$35 - Sheet1!H17) / (Sheet1!$B$35 - Sheet1!$B$34) -> 0.93446791 | I17: =(Sheet1!$B$35 - Sheet1!I17) / (Sheet1!$B$35 - Sheet1!$B$34) -> 0.96084136 | ... M17: =(Sheet1!$B$35 - Sheet1!M17) / (Sheet1!$B$35 - Sheet1!$B$34) -> 0.94602349 | P17: =IFERROR(__xludf.DUMMYFUNCTION("""COMPUTED_VALUE"""),0.20703341795849983) -> 0.20703342
A18: Maruti Suzuki India Ltd | B18: =(Sheet1!$B$35 - Sheet1!B18) / (Sheet1!$B$35 - Sheet1!$B$34) -> 0.83686735 | C18: =(Sheet1!$B$35 - Sheet1!C18) / (Sheet1!$B$35 - Sheet1!$B$34) -> 0.79851656 | D18: =(Sheet1!$B$35 - Sheet1!D18) / (Sheet1!$B$35 - Sheet1!$B$34) -> 0.78890586 | E18: =(Sheet1!$B$35 - Sheet1!E18) / (Sheet1!$B$35 - Sheet1!$B$34) -> 0.54281421 | F18: =(Sheet1!$B$35 - Sheet1!F18) / (Sheet1!$B$35 - Sheet1!$B$34) -> 0.64394697 | G18: =(Sheet1!$B$35 - Sheet1!G18) / (Sheet1!$B$35 - Sheet1!$B$34) -> 0.85568519 | H18: =(Sheet1!$B$35 - Sheet1!H18) / (Sheet1!$B$35 - Sheet1!$B$34) -> 0.82504882 | I18: =(Sheet1!$B$35 - Sheet1!I18) / (Sheet1!$B$35 - Sheet1!$B$34) -> 0.75882491 | ... M18: =(Sheet1!$B$35 - Sheet1!M18) / (Sheet1!$B$35 - Sheet1!$B$34) -> 0.87250955 | P18: =IFERROR(__xludf.DUMMYFUNCTION("""COMPUTED_VALUE"""),0.38103355698989877) -> 0.38103356
A19: NTPC Ltd | B19: =(Sheet1!$B$35 - Sheet1!B19) / (Sheet1!$B$35 - Sheet1!$B$34) -> 0.90107087 | C19: =(Sheet1!$B$35 - Sheet1!C19) / (Sheet1!$B$35 - Sheet1!$B$34) -> 0.91781105 | D19: =(Sheet1!$B$35 - Sheet1!D19) / (Sheet1!$B$35 - Sheet1!$B$34) -> 0.96646336 | E19: =(Sheet1!$B$35 - Sheet1!E19) / (Sheet1!$B$35 - Sheet1!$B$34) -> 0.98558061 | F19: =(Sheet1!$B$35 - Sheet1!F19) / (Sheet1!$B$35 - Sheet1!$B$34) -> 0.99154456 | G19: =(Sheet1!$B$35 - Sheet1!G19) / (Sheet1!$B$35 - Sheet1!$B$34) -> 0.99132238 | H19: =(Sheet1!$B$35 - Sheet1!H19) / (Sheet1!$B$35 - Sheet1!$B$34) -> 0.96904351 | I19: =(Sheet1!$B$35 - Sheet1!I19) / (Sheet1!$B$35 - Sheet1!$B$34) -> 0.91551469 | ... M19: =(Sheet1!$B$35 - Sheet1!M19) / (Sheet1!$B$35 - Sheet1!$B$34) -> 0.9784008 | P19: =IFERROR(__xludf.DUMMYFUNCTION("""COMPUTED_VALUE"""),0.5407417542100172) -> 0.54074175
A20: Power Grid Corporation of India Ltd | B20: =(Sheet1!$B$35 - Sheet1!B20) / (Sheet1!$B$35 - Sheet1!$B$34) -> 0.9026417 | C20: =(Sheet1!$B$35 - Sheet1!C20) / (Sheet1!$B$35 - Sheet1!$B$34) -> 0.91516928 | D20: =(Sheet1!$B$35 - Sheet1!D20) / (Sheet1!$B$35 - Sheet1!$B$34) -> 0.96504007 | E20: =(Sheet1!$B$35 - Sheet1!E20) / (Sheet1!$B$35 - Sheet1!$B$34) -> 0.97564707 | F20: =(Sheet1!$B$35 - Sheet1!F20) / (Sheet1!$B$35 - Sheet1!$B$34) -> 0.97233618 | G20: =(Sheet1!$B$35 - Sheet1!G20) / (Sheet1!$B$35 - Sheet1!$B$34) -> 0.98839769 | H20: =(Sheet1!$B$35 - Sheet1!H20) / (Sheet1!$B$35 - Sheet1!$B$34) -> 0.96403509 | I20: =(Sheet1!$B$35 - Sheet1!I20) / (Sheet1!$B$35 - Sheet1!$B$34) -> 0.94637931 | ... M20: =(Sheet1!$B$35 - Sheet1!M20) / (Sheet1!$B$35 - Sheet1!$B$34) -> 0.95740115 | P20: =IFERROR(__xludf.DUMMYFUNCTION("""COMPUTED_VALUE"""),0.477709847371816) -> 0.47770985
A21: Reliance Industries Ltd | B21: =(Sheet1!$B$35 - Sheet1!B21) / (Sheet1!$B$35 - Sheet1!$B$34) -> 0.83868813 | C21: =(Sheet1!$B$35 - Sheet1!C21) / (Sheet1!$B$35 - Sheet1!$B$34) -> 0.80260765 | D21: =(Sheet1!$B$35 - Sheet1!D21) / (Sheet1!$B$35 - Sheet1!$B$34) -> 0.84847587 | E21: =(Sheet1!$B$35 - Sheet1!E21) / (Sheet1!$B$35 - Sheet1!$B$34) -> 0.8052043 | F21: =(Sheet1!$B$35 - Sheet1!F21) / (Sheet1!$B$35 - Sheet1!$B$34) -> 0.82603037 | G21: =(Sheet1!$B$35 - Sheet1!G21) / (Sheet1!$B$35 - Sheet1!$B$34) -> 0.90059615 | H21: =(Sheet1!$B$35 - Sheet1!H21) / (Sheet1!$B$35 - Sheet1!$B$34) -> 0.87663884 | I21: =(Sheet1!$B$35 - Sheet1!I21) / (Sheet1!$B$35 - Sheet1!$B$34) -> 0.92795028 | ... M21: =(Sheet1!$B$35 - Sheet1!M21) / (Sheet1!$B$35 - Sheet1!$B$34) -> 0.94829295 | P21: =IFERROR(__xludf.DUMMYFUNCTION("""COMPUTED_VALUE"""),0.5961876844042785) -> 0.59618768
A22: State Bank of India | B22: =(Sheet1!$B$35 - Sheet1!B22) / (Sheet1!$B$35 - Sheet1!$B$34) -> 0.97662255 | C22: =(Sheet1!$B$35 - Sheet1!C22) / (Sheet1!$B$35 - Sheet1!$B$34) -> 0.96678187 | D22: =(Sheet1!$B$35 - Sheet1!D22) / (Sheet1!$B$35 - Sheet1!$B$34) -> 0.980777 | E22: =(Sheet1!$B$35 - Sheet1!E22) / (Sheet1!$B$35 - Sheet1!$B$34) -> 0.94564944 | F22: =(Sheet1!$B$35 - Sheet1!F22) / (Sheet1!$B$35 - Sheet1!$B$34) -> 0.92774372 | G22: =(Sheet1!$B$35 - Sheet1!G22) / (Sheet1!$B$35 - Sheet1!$B$34) -> 0.97650539 | H22: =(Sheet1!$B$35 - Sheet1!H22) / (Sheet1!$B$35 - Sheet1!$B$34) -> 0 | I22: =(Sheet1!$B$35 - Sheet1!I22) / (Sheet1!$B$35 - Sheet1!$B$34) -> 1 | ... M22: =(Sheet1!$B$35 - Sheet1!M22) / (Sheet1!$B$35 - Sheet1!$B$34) -> 0.96598083 | P22: =IFERROR(__xludf.DUMMYFUNCTION("""COMPUTED_VALUE"""),0.5939026052939371) -> 0.59390261
A23: Sun Pharmaceutical Industries Ltd | B23: =(Sheet1!$B$35 - Sheet1!B23) / (Sheet1!$B$35 - Sheet1!$B$34) -> 0.72338059 | C23: =(Sheet1!$B$35 - Sheet1!C23) / (Sheet1!$B$35 - Sheet1!$B$34) -> 0.70119892 | D23: =(Sheet1!$B$35 - Sheet1!D23) / (Sheet1!$B$35 - Sheet1!$B$34) -> 0.81197361 | E23: =(Sheet1!$B$35 - Sheet1!E23) / (Sheet1!$B$35 - Sheet1!$B$34) -> 0.46990777 | F23: =(Sheet1!$B$35 - Sheet1!F23) / (Sheet1!$B$35 - Sheet1!$B$34) -> 0.62504928 | G23: =(Sheet1!$B$35 - Sheet1!G23) / (Sheet1!$B$35 - Sheet1!$B$34) -> 0.85898393 | H23: =(Sheet1!$B$35 - Sheet1!H23) / (Sheet1!$B$35 - Sheet1!$B$34) -> 0.67896691 | I23: =(Sheet1!$B$35 - Sheet1!I23) / (Sheet1!$B$35 - Sheet1!$B$34) -> 0.57596304 | ... M23: =(Sheet1!$B$35 - Sheet1!M23) / (Sheet1!$B$35 - Sheet1!$B$34) -> 0.72631135 | P23: =IFERROR(__xludf.DUMMYFUNCTION("""COMPUTED_VALUE"""),0.6392075748333031) -> 0.63920757
A24: Tata Motors Ltd | B24: =(Sheet1!$B$35 - Sheet1!B24) / (Sheet1!$B$35 - Sheet1!$B$34) -> 0.97943615 | C24: =(Sheet1!$B$35 - Sheet1!C24) / (Sheet1!$B$35 - Sheet1!$B$34) -> 0.94851252 | D24: =(Sheet1!$B$35 - Sheet1!D24) / (Sheet1!$B$35 - Sheet1!$B$34) -> 0.47335058 | E24: =(Sheet1!$B$35 - Sheet1!E24) / (Sheet1!$B$35 - Sheet1!$B$34) -> 1 | F24: =(Sheet1!$B$35 - Sheet1!F24) / (Sheet1!$B$35 - Sheet1!$B$34) -> 1 | G24: =(Sheet1!$B$35 - Sheet1!G24) / (Sheet1!$B$35 - Sheet1!$B$34) -> 1 | H24: =(Sheet1!$B$35 - Sheet1!H24) / (Sheet1!$B$35 - Sheet1!$B$34) -> 1 | I24: =(Sheet1!$B$35 - Sheet1!I24) / (Sheet1!$B$35 - Sheet1!$B$34) -> 0.9462717 | ... M24: =(Sheet1!$B$35 - Sheet1!M24) / (Sheet1!$B$35 - Sheet1!$B$34) -> 0.97421597 | P24: =IFERROR(__xludf.DUMMYFUNCTION("""COMPUTED_VALUE"""),0.5709468029590948) -> 0.5709468
A25: Tata Steel Ltd | B25: =(Sheet1!$B$35 - Sheet1!B25) / (Sheet1!$B$35 - Sheet1!$B$34) -> 0.56510436 | C25: =(Sheet1!$B$35 - Sheet1!C25) / (Sheet1!$B$35 - Sheet1!$B$34) -> 1 | D25: =(Sheet1!$B$35 - Sheet1!D25) / (Sheet1!$B$35 - Sheet1!$B$34) -> 0.92718482 | E25: =(Sheet1!$B$35 - Sheet1!E25) / (Sheet1!$B$35 - Sheet1!$B$34) -> 1 | F25: =(Sheet1!$B$35 - Sheet1!F25) / (Sheet1!$B$35 - Sheet1!$B$34) -> 0.94318905 | G25: =(Sheet1!$B$35 - Sheet1!G25) / (Sheet1!$B$35 - Sheet1!$B$34) -> 0.85628141 | H25: =(Sheet1!$B$35 - Sheet1!H25) / (Sheet1!$B$35 - Sheet1!$B$34) -> 1 | I25: =(Sheet1!$B$35 - Sheet1!I25) / (Sheet1!$B$35 - Sheet1!$B$34) -> 1 | ... M25: =(Sheet1!$B$35 - Sheet1!M25) / (Sheet1!$B$35 - Sheet1!$B$34) -> 0.95654023 | P25: =IFERROR(__xludf.DUMMYFUNCTION("""COMPUTED_VALUE"""),0.6805125711028008) -> 0.68051257
A26: Tata Consultancy Services Ltd | B26: =(Sheet1!$B$35 - Sheet1!B26) / (Sheet1!$B$35 - Sheet1!$B$34) -> 0.82055763 | C26: =(Sheet1!$B$35 - Sheet1!C26) / (Sheet1!$B$35 - Sheet1!$B$34) -> 0.78592649 | D26: =(Sheet1!$B$35 - Sheet1!D26) / (Sheet1!$B$35 - Sheet1!$B$34) -> 0.81214198 | E26: =(Sheet1!$B$35 - Sheet1!E26) / (Sheet1!$B$35 - Sheet1!$B$34) -> 0.74053213 | F26: =(Sheet1!$B$35 - Sheet1!F26) / (Sheet1!$B$35 - Sheet1!$B$34) -> 0.73563305 | G26: =(Sheet1!$B$35 - Sheet1!G26) / (Sheet1!$B$35 - Sheet1!$B$34) -> 0.87010644 | H26: =(Sheet1!$B$35 - Sheet1!H26) / (Sheet1!$B$35 - Sheet1!$B$34) -> 0.84463298 | I26: =(Sheet1!$B$35 - Sheet1!I26) / (Sheet1!$B$35 - Sheet1!$B$34) -> 0.86939653 | ... M26: =(Sheet1!$B$35 - Sheet1!M26) / (Sheet1!$B$35 - Sheet1!$B$34) -> 0.86456341 | P26: =IFERROR(__xludf.DUMMYFUNCTION("""COMPUTED_VALUE"""),0.9482599682345365) -> 0.94825997
A27: Tech Mahindra Ltd | B27: =(Sheet1!$B$35 - Sheet1!B27) / (Sheet1!$B$35 - Sheet1!$B$34) -> 0.79729114 | C27: =(Sheet1!$B$35 - Sheet1!C27) / (Sheet1!$B$35 - Sheet1!$B$34) -> 0.64663039 | D27: =(Sheet1!$B$35 - Sheet1!D27) / (Sheet1!$B$35 - Sheet1!$B$34) -> 0.87904628 | E27: =(Sheet1!$B$35 - Sheet1!E27) / (Sheet1!$B$35 - Sheet1!$B$34) -> 0.84817906 | F27: =(Sheet1!$B$35 - Sheet1!F27) / (Sheet1!$B$35 - Sheet1!$B$34) -> 0.88379349 | G27: =(Sheet1!$B$35 - Sheet1!G27) / (Sheet1!$B$35 - Sheet1!$B$34) -> 0.94757002 | H27: =(Sheet1!$B$35 - Sheet1!H27) / (Sheet1!$B$35 - Sheet1!$B$34) -> 0.91469282 | I27: =(Sheet1!$B$35 - Sheet1!I27) / (Sheet1!$B$35 - Sheet1!$B$34) -> 0.92490495 | ... M27: =(Sheet1!$B$35 - Sheet1!M27) / (Sheet1!$B$35 - Sheet1!$B$34) -> 0.93410081 | P27: =IFERROR(__xludf.DUMMYFUNCTION("""COMPUTED_VALUE"""),0.9474146712146077) -> 0.94741467
A28: Titan Company Ltd | B28: =(Sheet1!$B$35 - Sheet1!B28) / (Sheet1!$B$35 - Sheet1!$B$34) -> 0.34687974 | C28: =(Sheet1!$B$35 - Sheet1!C28) / (Sheet1!$B$35 - Sheet1!$B$34) -> 0.21560181 | D28: =(Sheet1!$B$35 - Sheet1!D28) / (Sheet1!$B$35 - Sheet1!$B$34) -> 0.45745309 | E28: =(Sheet1!$B$35 - Sheet1!E28) / (Sheet1!$B$35 - Sheet1!$B$34) -> 0.15492355 | F28: =(Sheet1!$B$35 - Sheet1!F28) / (Sheet1!$B$35 - Sheet1!$B$34) -> 0 | G28: =(Sheet1!$B$35 - Sheet1!G28) / (Sheet1!$B$35 - Sheet1!$B$34) -> 0.57457794 | H28: =(Sheet1!$B$35 - Sheet1!H28) / (Sheet1!$B$35 - Sheet1!$B$34) -> 0.42965636 | I28: =(Sheet1!$B$35 - Sheet1!I28) / (Sheet1!$B$35 - Sheet1!$B$34) -> 0.41302033 | ... M28: =(Sheet1!$B$35 - Sheet1!M28) / (Sheet1!$B$35 - Sheet1!$B$34) -> 0.77858699 | P28: =IFERROR(__xludf.DUMMYFUNCTION("""COMPUTED_VALUE"""),0.8420198450398726) -> 0.84201985
A29: Trent Ltd | B29: =(Sheet1!$B$35 - Sheet1!B29) / (Sheet1!$B$35 - Sheet1!$B$34) -> 0 | C29: =(Sheet1!$B$35 - Sheet1!C29) / (Sheet1!$B$35 - Sheet1!$B$34) -> 0.23427732 | D29: =(Sheet1!$B$35 - Sheet1!D29) / (Sheet1!$B$35 - Sheet1!$B$34) -> 0.099718882 | E29: =(Sheet1!$B$35 - Sheet1!E29) / (Sheet1!$B$35 - Sheet1!$B$34) -> 0 | F29: =(Sheet1!$B$35 - Sheet1!F29) / (Sheet1!$B$35 - Sheet1!$B$34) -> 1 | G29: =(Sheet1!$B$35 - Sheet1!G29) / (Sheet1!$B$35 - Sheet1!$B$34) -> 0 | H29: =(Sheet1!$B$35 - Sheet1!H29) / (Sheet1!$B$35 - Sheet1!$B$34) -> 0 | I29: =(Sheet1!$B$35 - Sheet1!I29) / (Sheet1!$B$35 - Sheet1!$B$34) -> 0 | ... M29: =(Sheet1!$B$35 - Sheet1!M29) / (Sheet1!$B$35 - Sheet1!$B$34) -> 1 | P29: =IFERROR(__xludf.DUMMYFUNCTION("""COMPUTED_VALUE"""),0.9102884276668318) -> 0.91028843
A30: UltraTech Cement Ltd | B30: =(Sheet1!$B$35 - Sheet1!B30) / (Sheet1!$B$35 - Sheet1!$B$34) -> 0.56734431 | C30: =(Sheet1!$B$35 - Sheet1!C30) / (Sheet1!$B$35 - Sheet1!$B$34) -> 0.70570485 | D30: =(Sheet1!$B$35 - Sheet1!D30) / (Sheet1!$B$35 - Sheet1!$B$34) -> 0.67713572 | E30: =(Sheet1!$B$35 - Sheet1!E30) / (Sheet1!$B$35 - Sheet1!$B$34) -> 0.82865825 | F30: =(Sheet1!$B$35 - Sheet1!F30) / (Sheet1!$B$35 - Sheet1!$B$34) -> 0.74495822 | G30: =(Sheet1!$B$35 - Sheet1!G30) / (Sheet1!$B$35 - Sheet1!$B$34) -> 0.91214218 | H30: =(Sheet1!$B$35 - Sheet1!H30) / (Sheet1!$B$35 - Sheet1!$B$34) -> 0.64060136 | I30: =(Sheet1!$B$35 - Sheet1!I30) / (Sheet1!$B$35 - Sheet1!$B$34) -> 0.63037275 | ... M30: =(Sheet1!$B$35 - Sheet1!M30) / (Sheet1!$B$35 - Sheet1!$B$34) -> 0.81754268 | P30: =IFERROR(__xludf.DUMMYFUNCTION("""COMPUTED_VALUE"""),0.8034312550048482) -> 0.80343126
P31: =IFERROR(__xludf.DUMMYFUNCTION("""COMPUTED_VALUE"""),0.5717105210058477) -> 0.57171052
P32: =IFERROR(__xludf.DUMMYFUNCTION("""COMPUTED_VALUE"""),0.7102012423089035) -> 0.71020124
P33: =IFERROR(__xludf.DUMMYFUNCTION("""COMPUTED_VALUE"""),0.0) -> 0
A34: Global min | B34: =MIN(B2:N30) -> 0 | P34: =IFERROR(__xludf.DUMMYFUNCTION("""COMPUTED_VALUE"""),0.7961472941339424) -> 0.79614729
A35: Global Max | B35: =MAX(B2:N30) -> 1 | P35: =IFERROR(__xludf.DUMMYFUNCTION("""COMPUTED_VALUE"""),0.9438182535035349) -> 0.94381825
P36: =IFERROR(__xludf.DUMMYFUNCTION("""COMPUTED_VALUE"""),0.8995686034469547) -> 0.8995686
P37: =IFERROR(__xludf.DUMMYFUNCTION("""COMPUTED_VALUE"""),0.9594579840950509) -> 0.95945798
P38: =IFERROR(__xludf.DUMMYFUNCTION("""COMPUTED_VALUE"""),0.0) -> 0
P39: =IFERROR(__xludf.DUMMYFUNCTION("""COMPUTED_VALUE"""),0.0) -> 0
P40: =IFERROR(__xludf.DUMMYFUNCTION("""COMPUTED_VALUE"""),0.0) -> 0
...
