Workbook

Sheet Sheet1
B1: 2025 | C1: 2024 | D1: 2023 | E1: 2022 | F1: 2021 | G1: 2020 | H1: 2019 | I1: 2018 | J1: 2017 | K1: 2016 | L1: 2015 | M1: 2014
A2: Adani Ports and Special Economic Zone Ltd | B2: 0.73 | C2: 0.87 | D2: 1.09 | E2: 1.19 | F2: 1.13 | G2: 1.09 | H2: 1.07 | I2: 1.01 | J2: 1.2 | K2: 1.4 | L2: 1.41 | M2: 1.33
A3: Asian Paints Ltd | B3: 0.04 | C3: 0.06 | D3: 0.06 | E3: 0.06 | F3: 0.03 | G3: 0.03 | H3: 0.07 | I3: 0.06 | J3: 0.07 | K3: 0.05 | L3: 0.09 | M3: 0.06
A4: AXIS Bank Ltd | B4: 7.88 | C4: 8.69 | D4: 9.39 | E4: 9.12 | F4: 8.66 | G4: 8 | H4: 10.99 | I4: 9.72 | J4: 9.79 | K4: 8.88 | L4: 9.33 | M4: 9.06
A5: Bajaj Finserv Ltd | B5: 4.89 | C5: 4.77 | D5: 4.56 | E5: 3.99 | F5: 3.57 | G5: 4.04 | H5: 4.2 | I5: 3.21 | J5: 2.99 | K5: 2.65 | L5: 2.01 | M5: 1.66
A6: Bajaj Finance Ltd | B6: 3.74 | C6: 3.82 | D6: 3.99 | E6: 3.78 | F6: 3.57 | G6: 4.02 | H6: 5.16 | I6: 3.42 | J6: 4.38 | K6: 4.99 | L6: 4.71 | M6: 5.17
A7: Bharat Electronics Ltd | B7: 1.2 | C7: 1.13 | D7: 1.1 | E7: 0.93 | F7: 0.82 | G7: 1.41 | H7: 1.26 | I7: 0.63 | J7: 0.73 | K7: 0.56 | L7: 0.7 | M7: 0.78
A8: Bharti Airtel Ltd | B8: 1.13 | C8: 1.5 | D8: 1.82 | E8: 2 | F8: 2.2 | G8: 1.52 | H8: 1.69 | I8: 1.41 | J8: 1.52 | K8: 1.5 | L8: 1.76 | M8: 1.27
A9: HCL Technologies Ltd | B9: 0.03 | C9: 0.03 | D9: 0.03 | E9: 0.06 | F9: 0.06 | G9: 0.09 | H9: 0.09 | I9: 0.01 | J9: 0.01 | K9: 0.03 | L9: 0.02 | M9: 0.02
A10: HDFC Bank Ltd | B10: 6.27 | C10: 7.12 | D10: 7.8 | E10: 7.58 | F10: 7.58 | G10: 7.92 | H10: 7.43 | I10: 9.17 | J10: 8.02 | K10: 7.89 | L10: 8.61 | M10: 10.36
A11: Hindustan Unilever Ltd | B11: 0.56 | C11: 0.57 | D11: 0.54 | E11: 0.52 | F11: 0.49 | G11: 1.64 | H11: 1.38 | I11: 1.41 | J11: 1.57 | K11: 1.34 | L11: 1.94 | M11: 2.36
A12: ICICI Bank Ltd | B12: 8.87 | C12: 8.92 | D12: 7.67 | E12: 8.13 | F12: 8.31 | G12: 9.38 | H12: 9.13 | I12: 8.63 | J12: 8.2 | K12: 8.19 | L12: 8.35 | M12: 8.29
A13: Infosys Ltd | B13: 0.47 | C13: 0.49 | D13: 0.57 | E13: 0.56 | F13: 0.43 | G13: 0.42 | H13: 0.28 | I13: 0.23 | J13: 0.19 | K13: 0.2 | L13: 0.2 | M13: 0.26
... A30: UltraTech Cement Ltd | B30: 0.33 | C30: 0.17 | D30: 0.18 | E30: 0.2 | F30: 0.4 | G30: 0.55 | H30: 0.86 | I30: 0.71 | J30: 0.31 | K30: 0.34 | L30: 0.4 | M30: 0.41

Sheet LOG_DE
B1: 2025 | C1: 2024 | D1: 2023 | E1: 2022 | F1: 2021 | G1: 2020 | H1: 2019 | I1: 2018 | J1: 2017 | K1: 2016 | L1: 2015 | M1: 2014
A2: Adani Ports and Special Economic Zone Ltd | B2: =LN(Sheet1!B2 + 1) -> 0.54812141 | C2: =LN(Sheet1!C2 + 1) -> 0.62593843 | D2: =LN(Sheet1!D2 + 1) -> 0.73716407 | E2: =LN(Sheet1!E2 + 1) -> 0.78390154 | F2: =LN(Sheet1!F2 + 1) -> 0.75612198 | G2: =LN(Sheet1!G2 + 1) -> 0.73716407 | H2: =LN(Sheet1!H2 + 1) -> 0.72754861 | I2: =LN(Sheet1!I2 + 1) -> 0.69813472 | ... M2: =LN(Sheet1!M2 + 1) -> 0.84586827
A3: Asian Paints Ltd | B3: =LN(Sheet1!B3 + 1) -> 0.039220713 | C3: =LN(Sheet1!C3 + 1) -> 0.058268908 | D3: =LN(Sheet1!D3 + 1) -> 0.058268908 | E3: =LN(Sheet1!E3 + 1) -> 0.058268908 | F3: =LN(Sheet1!F3 + 1) -> 0.029558802 | G3: =LN(Sheet1!G3 + 1) -> 0.029558802 | H3: =LN(Sheet1!H3 + 1) -> 0.067658648 | I3: =LN(Sheet1!I3 + 1) -> 0.058268908 | ... M3: =LN(Sheet1!M3 + 1) -> 0.058268908
A4: AXIS Bank Ltd | B4: =LN(Sheet1!B4 + 1) -> 2.1838016 | C4: =LN(Sheet1!C4 + 1) -> 2.2710944 | D4: =LN(Sheet1!D4 + 1) -> 2.3408438 | E4: =LN(Sheet1!E4 + 1) -> 2.3145137 | F4: =LN(Sheet1!F4 + 1) -> 2.2679936 | G4: =LN(Sheet1!G4 + 1) -> 2.1972246 | H4: =LN(Sheet1!H4 + 1) -> 2.484073 | I4: =LN(Sheet1!I4 + 1) -> 2.3721112 | ... M4: =LN(Sheet1!M4 + 1) -> 2.3085672
A5: Bajaj Finserv Ltd | B5: =LN(Sheet1!B5 + 1) -> 1.773256 | C5: =LN(Sheet1!C5 + 1) -> 1.7526721 | D5: =LN(Sheet1!D5 + 1) -> 1.7155981 | E5: =LN(Sheet1!E5 + 1) -> 1.6074359 | F5: =LN(Sheet1!F5 + 1) -> 1.5195132 | G5: =LN(Sheet1!G5 + 1) -> 1.6174061 | H5: =LN(Sheet1!H5 + 1) -> 1.6486586 | I5: =LN(Sheet1!I5 + 1) -> 1.4374626 | ... M5: =LN(Sheet1!M5 + 1) -> 0.97832612
A6: Bajaj Finance Ltd | B6: =LN(Sheet1!B6 + 1) -> 1.5560371 | C6: =LN(Sheet1!C6 + 1) -> 1.5727739 | D6: =LN(Sheet1!D6 + 1) -> 1.6074359 | E6: =LN(Sheet1!E6 + 1) -> 1.5644405 | F6: =LN(Sheet1!F6 + 1) -> 1.5195132 | G6: =LN(Sheet1!G6 + 1) -> 1.6134299 | H6: =LN(Sheet1!H6 + 1) -> 1.8180768 | I6: =LN(Sheet1!I6 + 1) -> 1.4861397 | ... M6: =LN(Sheet1!M6 + 1) -> 1.8196988
A7: Bharat Electronics Ltd | B7: =LN(Sheet1!B7 + 1) -> 0.78845736 | C7: =LN(Sheet1!C7 + 1) -> 0.75612198 | D7: =LN(Sheet1!D7 + 1) -> 0.74193734 | E7: =LN(Sheet1!E7 + 1) -> 0.65752 | F7: =LN(Sheet1!F7 + 1) -> 0.5988365 | G7: =LN(Sheet1!G7 + 1) -> 0.87962675 | H7: =LN(Sheet1!H7 + 1) -> 0.81536481 | I7: =LN(Sheet1!I7 + 1) -> 0.48858001 | ... M7: =LN(Sheet1!M7 + 1) -> 0.57661336
A8: Bharti Airtel Ltd | B8: =LN(Sheet1!B8 + 1) -> 0.75612198 | C8: =LN(Sheet1!C8 + 1) -> 0.91629073 | D8: =LN(Sheet1!D8 + 1) -> 1.0367369 | E8: =LN(Sheet1!E8 + 1) -> 1.0986123 | F8: =LN(Sheet1!F8 + 1) -> 1.1631508 | G8: =LN(Sheet1!G8 + 1) -> 0.9242589 | H8: =LN(Sheet1!H8 + 1) -> 0.98954119 | I8: =LN(Sheet1!I8 + 1) -> 0.87962675 | ... M8: =LN(Sheet1!M8 + 1) -> 0.81977983
A9: HCL Technologies Ltd | B9: =LN(Sheet1!B9 + 1) -> 0.029558802 | C9: =LN(Sheet1!C9 + 1) -> 0.029558802 | D9: =LN(Sheet1!D9 + 1) -> 0.029558802 | E9: =LN(Sheet1!E9 + 1) -> 0.058268908 | F9: =LN(Sheet1!F9 + 1) -> 0.058268908 | G9: =LN(Sheet1!G9 + 1) -> 0.086177696 | H9: =LN(Sheet1!H9 + 1) -> 0.086177696 | I9: =LN(Sheet1!I9 + 1) -> 0.0099503309 | ... M9: =LN(Sheet1!M9 + 1) -> 0.019802627
A10: HDFC Bank Ltd | B10: =LN(Sheet1!B10 + 1) -> 1.9837563 | C10: =LN(Sheet1!C10 + 1) -> 2.0943302 | D10: =LN(Sheet1!D10 + 1) -> 2.1747517 | E10: =LN(Sheet1!E10 + 1) -> 2.1494339 | F10: =LN(Sheet1!F10 + 1) -> 2.1494339 | G10: =LN(Sheet1!G10 + 1) -> 2.1882959 | H10: =LN(Sheet1!H10 + 1) -> 2.1317968 | I10: =LN(Sheet1!I10 + 1) -> 2.3194422 | ... M10: =LN(Sheet1!M10 + 1) -> 2.4300984
A11: Hindustan Unilever Ltd | B11: =LN(Sheet1!B11 + 1) -> 0.44468582 | C11: =LN(Sheet1!C11 + 1) -> 0.45107562 | D11: =LN(Sheet1!D11 + 1) -> 0.43178242 | E11: =LN(Sheet1!E11 + 1) -> 0.41871033 | F11: =LN(Sheet1!F11 + 1) -> 0.39877612 | G11: =LN(Sheet1!G11 + 1) -> 0.97077892 | H11: =LN(Sheet1!H11 + 1) -> 0.86710049 | I11: =LN(Sheet1!I11 + 1) -> 0.87962675 | ... M11: =LN(Sheet1!M11 + 1) -> 1.211941
A12: ICICI Bank Ltd | B12: =LN(Sheet1!B12 + 1) -> 2.2894999 | C12: =LN(Sheet1!C12 + 1) -> 2.2945529 | D12: =LN(Sheet1!D12 + 1) -> 2.1598688 | E12: =LN(Sheet1!E12 + 1) -> 2.2115657 | F12: =LN(Sheet1!F12 + 1) -> 2.2310891 | G12: =LN(Sheet1!G12 + 1) -> 2.3398809 | H12: =LN(Sheet1!H12 + 1) -> 2.3155013 | I12: =LN(Sheet1!I12 + 1) -> 2.2648832 | ... M12: =LN(Sheet1!M12 + 1) -> 2.2289386
A13: Infosys Ltd | B13: =LN(Sheet1!B13 + 1) -> 0.3852624 | C13: =LN(Sheet1!C13 + 1) -> 0.39877612 | D13: =LN(Sheet1!D13 + 1) -> 0.45107562 | E13: =LN(Sheet1!E13 + 1) -> 0.44468582 | F13: =LN(Sheet1!F13 + 1) -> 0.35767444 | G13: =LN(Sheet1!G13 + 1) -> 0.35065687 | H13: =LN(Sheet1!H13 + 1) -> 0.24686008 | I13: =LN(Sheet1!I13 + 1) -> 0.20701417 | ... M13: =LN(Sheet1!M13 + 1) -> 0.23111172
... A30: UltraTech Cement Ltd | B30: =LN(Sheet1!B30 + 1) -> 0.28517894 | C30: =LN(Sheet1!C30 + 1) -> 0.15700375 | D30: =LN(Sheet1!D30 + 1) -> 0.16551444 | E30: =LN(Sheet1!E30 + 1) -> 0.18232156 | F30: =LN(Sheet1!F30 + 1) -> 0.33647224 | G30: =LN(Sheet1!G30 + 1) -> 0.43825493 | H30: =LN(Sheet1!H30 + 1) -> 0.62057649 | I30: =LN(Sheet1!I30 + 1) -> 0.53649337 | ... M30: =LN(Sheet1!M30 + 1) -> 0.3435897

Sheet non_bank
B1: 2025 | C1: 2024 | D1: 2023 | E1: 2022 | F1: 2021 | G1: 2020 | H1: 2019 | I1: 2018 | J1: 2017 | K1: 2016 | L1: 2015 | M1: 2014
A2: Adani Ports and Special Economic Zone Ltd | B2: 0.54812141 | C2: 0.62593843 | D2: 0.73716407 | E2: 0.78390154 | F2: 0.75612198 | G2: 0.73716407 | H2: 0.72754861 | I2: 0.69813472 | J2: 0.78845736 | K2: 0.87546874 | L2: 0.87962675 | M2: 0.84586827
A3: Asian Paints Ltd | B3: 0.039220713 | C3: 0.058268908 | D3: 0.058268908 | E3: 0.058268908 | F3: 0.029558802 | G3: 0.029558802 | H3: 0.067658648 | I3: 0.058268908 | J3: 0.067658648 | K3: 0.048790164 | L3: 0.086177696 | M3: 0.058268908
A4: Bharat Electronics Ltd | B4: 0.78845736 | C4: 0.75612198 | D4: 0.74193734 | E4: 0.65752 | F4: 0.5988365 | G4: 0.87962675 | H4: 0.81536481 | I4: 0.48858001 | J4: 0.54812141 | K4: 0.44468582 | L4: 0.53062825 | M4: 0.57661336
A5: Bharti Airtel Ltd | B5: 0.75612198 | C5: 0.91629073 | D5: 1.0367369 | E5: 1.0986123 | F5: 1.1391037 | G5: 0.9242589 | H5: 0.98954119 | I5: 0.87962675 | J5: 0.9242589 | K5: 0.91629073 | L5: 1.0152307 | M5: 0.81977983
A6: HCL Technologies Ltd | B6: 0.029558802 | C6: 0.029558802 | D6: 0.029558802 | E6: 0.058268908 | F6: 0.058268908 | G6: 0.086177696 | H6: 0.086177696 | I6: 0.029558802 | J6: 0.029558802 | K6: 0.029558802 | L6: 0.029558802 | M6: 0.029558802
A7: Hindustan Unilever Ltd | B7: 0.44468582 | C7: 0.45107562 | D7: 0.43178242 | E7: 0.41871033 | F7: 0.39877612 | G7: 0.97077892 | H7: 0.86710049 | I7: 0.87962675 | J7: 0.9439059 | K7: 0.85015093 | L7: 1.0784096 | M7: 1.1391037
A8: Infosys Ltd | B8: 0.3852624 | C8: 0.39877612 | D8: 0.45107562 | E8: 0.44468582 | F8: 0.35767444 | G8: 0.35065687 | H8: 0.24686008 | I8: 0.20701417 | J8: 0.17395331 | K8: 0.18232156 | L8: 0.18232156 | M8: 0.23111172
A9: ITC Ltd | B9: 0.12221763 | C9: 0.13102826 | D9: 0.20701417 | E9: 0.21511138 | F9: 0.20701417 | G9: 0.19062036 | H9: 0.21511138 | I9: 0.20701417 | J9: 0.22314355 | K9: 0.35065687 | L9: 0.36464311 | M9: 0.37843644
A10: Larsen & Toubro Ltd | B10: 0.84586827 | C10: 0.84156719 | D10: 0.84586827 | E10: 0.91629073 | F10: 1.0043016 | G10: 1.1281711 | H10: 1.1052568 | I10: 0.97832612 | J10: 0.98581679 | K10: 1.0952734 | L10: 1.1019401 | M10: 1.1391037
A11: Mahindra & Mahindra Ltd | B11: 0.9439059 | C11: 0.94000726 | D11: 0.9439059 | E11: 0.9477894 | F11: 0.88789126 | G11: 0.94000726 | H11: 0.85441533 | I11: 0.80200159 | J11: 0.85441533 | K11: 0.77010822 | L11: 0.76080583 | M11: 0.79299252
A12: Maruti Suzuki India Ltd | B12: 0.26236426 | C12: 0.3074847 | D12: 0.3074847 | E12: 0.29266961 | F12: 0.28517894 | G12: 0.2390169 | H12: 0.27002714 | I12: 0.29266961 | J12: 0.30010459 | K12: 0.3435897 | L12: 0.43178242 | M12: 0.48242615
A13: NTPC Ltd | B13: 0.76546784 | C13: 0.80647587 | D13: 0.84586827 | E13: 0.84586827 | F13: 0.86710049 | G13: 0.87962675 | H13: 0.81536481 | I13: 0.75612198 | J13: 0.71294981 | K13: 0.66782937 | L13: 0.67294447 | M13: 0.54812141
... A23: UltraTech Cement Ltd | B23: 0.28517894 | C23: 0.15700375 | D23: 0.16551444 | E23: 0.18232156 | F23: 0.33647224 | G23: 0.43825493 | H23: 0.62057649 | I23: 0.53649337 | J23: 0.27002714 | K23: 0.29266961 | L23: 0.33647224 | M23: 0.3435897
A27: min | B27: =MIN(B2:M23) -> 0.029558802
A28: max | B28: =MAX(B2:M23) -> 1.1391037
A30: percentile min | B30: =PERCENTILE(B2:M23, 0.05) -> 0.029558802
A31: percentile max | B31: =PERCENTILE(B2:M23, 0.95) -> 1.1374638
B33: =MEDIAN(B2, $B$30, $B$31) -> 0.54812141 | C33: =MEDIAN(C2, $B$30, $B$31) -> 0.62593843 | D33: =MEDIAN(D2, $B$30, $B$31) -> 0.73716407 | E33: =MEDIAN(E2, $B$30, $B$31) -> 0.78390154 | F33: =MEDIAN(F2, $B$30, $B$31) -> 0.75612198 | G33: =MEDIAN(G2, $B$30, $B$31) -> 0.73716407 | H33: =MEDIAN(H2, $B$30, $B$31) -> 0.72754861 | I33: =MEDIAN(I2, $B$30, $B$31) -> 0.69813472 | ... M33: =MEDIAN(M2, $B$30, $B$31) -> 0.84586827
B34: =MEDIAN(B3, $B$30, $B$31) -> 0.039220713 | C34: =MEDIAN(C3, $B$30, $B$31) -> 0.058268908 | D34: =MEDIAN(D3, $B$30, $B$31) -> 0.058268908 | E34: =MEDIAN(E3, $B$30, $B$31) -> 0.058268908 | F34: =MEDIAN(F3, $B$30, $B$31) -> 0.029558802 | G34: =MEDIAN(G3, $B$30, $B$31) -> 0.029558802 | H34: =MEDIAN(H3, $B$30, $B$31) -> 0.067658648 | I34: =MEDIAN(I3, $B$30, $B$31) -> 0.058268908 | ... M34: =MEDIAN(M3, $B$30, $B$31) -> 0.058268908
B35: =MEDIAN(B4, $B$30, $B$31) -> 0.78845736 | C35: =MEDIAN(C4, $B$30, $B$31) -> 0.75612198 | D35: =MEDIAN(D4, $B$30, $B$31) -> 0.74193734 | E35: =MEDIAN(E4, $B$30, $B$31) -> 0.65752 | F35: =MEDIAN(F4, $B$30, $B$31) -> 0.5988365 | G35: =MEDIAN(G4, $B$30, $B$31) -> 0.87962675 | H35: =MEDIAN(H4, $B$30, $B$31) -> 0.81536481 | I35: =MEDIAN(I4, $B$30, $B$31) -> 0.48858001 | ... M35: =MEDIAN(M4, $B$30, $B$31) -> 0.57661336
B36: =MEDIAN(B5, $B$30, $B$31) -> 0.75612198 | C36: =MEDIAN(C5, $B$30, $B$31) -> 0.91629073 | D36: =MEDIAN(D5, $B$30, $B$31) -> 1.0367369 | E36: =MEDIAN(E5, $B$30, $B$31) -> 1.0986123 | F36: =MEDIAN(F5, $B$30, $B$31) -> 1.1374638 | G36: =MEDIAN(G5, $B$30, $B$31) -> 0.9242589 | H36: =MEDIAN(H5, $B$30, $B$31) -> 0.98954119 | I36: =MEDIAN(I5, $B$30, $B$31) -> 0.87962675 | ... M36: =MEDIAN(M5, $B$30, $B$31) -> 0.81977983
B37: =MEDIAN(B6, $B$30, $B$31) -> 0.029558802 | C37: =MEDIAN(C6, $B$30, $B$31) -> 0.029558802 | D37: =MEDIAN(D6, $B$30, $B$31) -> 0.029558802 | E37: =MEDIAN(E6, $B$30, $B$31) -> 0.058268908 | F37: =MEDIAN(F6, $B$30, $B$31) -> 0.058268908 | G37: =MEDIAN(G6, $B$30, $B$31) -> 0.086177696 | H37: =MEDIAN(H6, $B$30, $B$31) -> 0.086177696 | I37: =MEDIAN(I6, $B$30, $B$31) -> 0.029558802 | ... M37: =MEDIAN(M6, $B$30, $B$31) -> 0.029558802
B38: =MEDIAN(B7, $B$30, $B$31) -> 0.44468582 | C38: =MEDIAN(C7, $B$30, $B$31) -> 0.45107562 | D38: =MEDIAN(D7, $B$30, $B$31) -> 0.43178242 | E38: =MEDIAN(E7, $B$30, $B$31) -> 0.41871033 | F38: =MEDIAN(F7, $B$30, $B$31) -> 0.39877612 | G38: =MEDIAN(G7, $B$30, $B$31) -> 0.97077892 | H38: =MEDIAN(H7, $B$30, $B$31) -> 0.86710049 | I38: =MEDIAN(I7, $B$30, $B$31) -> 0.87962675 | ... M38: =MEDIAN(M7, $B$30, $B$31) -> 1.1374638
B39: =MEDIAN(B8, $B$30, $B$31) -> 0.3852624 | C39: =MEDIAN(C8, $B$30, $B$31) -> 0.39877612 | D39: =MEDIAN(D8, $B$30, $B$31) -> 0.45107562 | E39: =MEDIAN(E8, $B$30, $B$31) -> 0.44468582 | F39: =MEDIAN(F8, $B$30, $B$31) -> 0.35767444 | G39: =MEDIAN(G8, $B$30, $B$31) -> 0.35065687 | H39: =MEDIAN(H8, $B$30, $B$31) -> 0.24686008 | I39: =MEDIAN(I8, $B$30, $B$31) -> 0.20701417 | ... M39: =MEDIAN(M8, $B$30, $B$31) -> 0.23111172
B40: =MEDIAN(B9, $B$30, $B$31) -> 0.12221763 | C40: =MEDIAN(C9, $B$30, $B$31) -> 0.13102826 | D40: =MEDIAN(D9, $B$30, $B$31) -> 0.20701417 | E40: =MEDIAN(E9, $B$30, $B$31) -> 0.21511138 | F40: =MEDIAN(F9, $B$30, $B$31) -> 0.20701417 | G40: =MEDIAN(G9, $B$30, $B$31) -> 0.19062036 | H40: =MEDIAN(H9, $B$30, $B$31) -> 0.21511138 | I40: =MEDIAN(I9, $B$30, $B$31) -> 0.20701417 | ... M40: =MEDIAN(M9, $B$30, $B$31) -> 0.37843644
B41: =MEDIAN(B10, $B$30, $B$31) -> 0.84586827 | C41: =MEDIAN(C10, $B$30, $B$31) -> 0.84156719 | D41: =MEDIAN(D10, $B$30, $B$31) -> 0.84586827 | E41: =MEDIAN(E10, $B$30, $B$31) -> 0.91629073 | F41: =MEDIAN(F10, $B$30, $B$31) -> 1.0043016 | G41: =MEDIAN(G10, $B$30, $B$31) -> 1.1281711 | H41: =MEDIAN(H10, $B$30, $B$31) -> 1.1052568 | I41: =MEDIAN(I10, $B$30, $B$31) -> 0.97832612 | ... M41: =MEDIAN(M10, $B$30, $B$31) -> 1.1374638
B42: =MEDIAN(B11, $B$30, $B$31) -> 0.9439059 | C42: =MEDIAN(C11, $B$30, $B$31) -> 0.94000726 | D42: =MEDIAN(D11, $B$30, $B$31) -> 0.9439059 | E42: =MEDIAN(E11, $B$30, $B$31) -> 0.9477894 | F42: =MEDIAN(F11, $B$30, $B$31) -> 0.88789126 | G42: =MEDIAN(G11, $B$30, $B$31) -> 0.94000726 | H42: =MEDIAN(H11, $B$30, $B$31) -> 0.85441533 | I42: =MEDIAN(I11, $B$30, $B$31) -> 0.80200159 | ... M42: =MEDIAN(M11, $B$30, $B$31) -> 0.79299252
B43: =MEDIAN(B12, $B$30, $B$31) -> 0.26236426 | C43: =MEDIAN(C12, $B$30, $B$31) -> 0.3074847 | D43: =MEDIAN(D12, $B$30, $B$31) -> 0.3074847 | E43: =MEDIAN(E12, $B$30, $B$31) -> 0.29266961 | F43: =MEDIAN(F12, $B$30, $B$31) -> 0.28517894 | G43: =MEDIAN(G12, $B$30, $B$31) -> 0.2390169 | H43: =MEDIAN(H12, $B$30, $B$31) -> 0.27002714 | I43: =MEDIAN(I12, $B$30, $B$31) -> 0.29266961 | ... M43: =MEDIAN(M12, $B$30, $B$31) -> 0.48242615
B44: =MEDIAN(B13, $B$30, $B$31) -> 0.76546784 | C44: =MEDIAN(C13, $B$30, $B$31) -> 0.80647587 | D44: =MEDIAN(D13, $B$30, $B$31) -> 0.84586827 | E44: =MEDIAN(E13, $B$30, $B$31) -> 0.84586827 | F44: =MEDIAN(F13, $B$30, $B$31) -> 0.86710049 | G44: =MEDIAN(G13, $B$30, $B$31) -> 0.87962675 | H44: =MEDIAN(H13, $B$30, $B$31) -> 0.81536481 | I44: =MEDIAN(I13, $B$30, $B$31) -> 0.75612198 | ... M44: =MEDIAN(M13, $B$30, $B$31) -> 0.54812141
... B54: =MEDIAN(B23, $B$30, $B$31) -> 0.28517894 | C54: =MEDIAN(C23, $B$30, $B$31) -> 0.15700375 | D54: =MEDIAN(D23, $B$30, $B$31) -> 0.16551444 | E54: =MEDIAN(E23, $B$30, $B$31) -> 0.18232156 | F54: =MEDIAN(F23, $B$30, $B$31) -> 0.33647224 | G54: =MEDIAN(G23, $B$30, $B$31) -> 0.43825493 | H54: =MEDIAN(H23, $B$30, $B$31) -> 0.62057649 | I54: =MEDIAN(I23, $B$30, $B$31) -> 0.53649337 | ... M54: =MEDIAN(M23, $B$30, $B$31) -> 0.3435897

Sheet bank
B1: 2025 | C1: 2024 | D1: 2023 | E1: 2022 | F1: 2021 | G1: 2020 | H1: 2019 | I1: 2018 | J1: 2017 | K1: 2016 | L1: 2015 | M1: 2014
A2: AXIS Bank Ltd | B2: 2.1838016 | C2: 2.2710944 | D2: 2.3408438 | E2: 2.3145137 | F2: 2.2679936 | G2: 2.1972246 | H2: 2.484073 | I2: 2.3721112 | J2: 2.3786198 | K2: 2.2905125 | L2: 2.3350523 | M2: 2.3085672
A3: Bajaj Finserv Ltd | B3: 1.773256 | C3: 1.7526721 | D3: 1.7155981 | E3: 1.6074359 | F3: 1.5195132 | G3: 1.6174061 | H3: 1.6486586 | I3: 1.4447642 | J3: 1.4447642 | K3: 1.4447642 | L3: 1.4447642 | M3: 1.4447642
A4: Bajaj Finance Ltd | B4: 1.5560371 | C4: 1.5727739 | D4: 1.6074359 | E4: 1.5644405 | F4: 1.5195132 | G4: 1.6134299 | H4: 1.8180768 | I4: 1.4861397 | J4: 1.6826884 | K4: 1.7900914 | L4: 1.742219 | M4: 1.8196988
A5: HDFC Bank Ltd | B5: 1.9837563 | C5: 2.0943302 | D5: 2.1747517 | E5: 2.1494339 | F5: 2.1494339 | G5: 2.1882959 | H5: 2.1317968 | I5: 2.3194422 | J5: 2.1994443 | K5: 2.184927 | L5: 2.2628042 | M5: 2.4300984
A6: ICICI Bank Ltd | B6: 2.2894999 | C6: 2.2945529 | D6: 2.1598688 | E6: 2.2115657 | F6: 2.2310891 | G6: 2.3398809 | H6: 2.3155013 | I6: 2.2648832 | J6: 2.2192035 | K6: 2.2181159 | L6: 2.2353763 | M6: 2.2289386
A7: Kotak Mahindra Bank Ltd | B7: 1.6882491 | C7: 1.7766458 | D7: 1.7119945 | E7: 1.7119945 | F7: 1.7351891 | G7: 1.8437192 | H7: 1.9110229 | I7: 1.9257074 | J7: 1.9712994 | K7: 1.9933388 | L7: 1.9586853 | M7: 2.0215476
A8: State Bank of India | B8: 2.706716 | C8: 2.7843938 | D8: 2.8063861 | E8: 2.8068995 | F8: 2.8068995 | G8: 2.8068995 | H8: 2.8068995 | I8: 2.752386 | J8: 2.7619069 | K8: 2.7985001 | L8: 2.8068995 | M8: 2.7868614
A12: min | B12: =MIN(B2:M8) -> 1.4447642
A13: max | B13: =MAX(B3:M9) -> 2.8068995
A15: percentile min | B15: =PERCENTILE(B2:M8, 0.05) -> 1.4509705
A16: percentile max | B16: =PERCENTILE(B2:M8, 0.95) -> 2.8068225
B19: =MEDIAN(B2, $B$15, $B$16) -> 2.1838016 | C19: =MEDIAN(C2, $B$15, $B$16) -> 2.2710944 | D19: =MEDIAN(D2, $B$15, $B$16) -> 2.3408438 | E19: =MEDIAN(E2, $B$15, $B$16) -> 2.3145137 | F19: =MEDIAN(F2, $B$15, $B$16) -> 2.2679936 | G19: =MEDIAN(G2, $B$15, $B$16) -> 2.1972246 | H19: =MEDIAN(H2, $B$15, $B$16) -> 2.484073 | I19: =MEDIAN(I2, $B$15, $B$16) -> 2.3721112 | ... M19: =MEDIAN(M2, $B$15, $B$16) -> 2.3085672
B20: =MEDIAN(B3, $B$15, $B$16) -> 1.773256 | C20: =MEDIAN(C3, $B$15, $B$16) -> 1.7526721 | D20: =MEDIAN(D3, $B$15, $B$16) -> 1.7155981 | E20: =MEDIAN(E3, $B$15, $B$16) -> 1.6074359 | F20: =MEDIAN(F3, $B$15, $B$16) -> 1.5195132 | G20: =MEDIAN(G3, $B$15, $B$16) -> 1.6174061 | H20: =MEDIAN(H3, $B$15, $B$16) -> 1.6486586 | I20: =MEDIAN(I3, $B$15, $B$16) -> 1.4509705 | ... M20: =MEDIAN(M3, $B$15, $B$16) -> 1.4509705
B21: =MEDIAN(B4, $B$15, $B$16) -> 1.5560371 | C21: =MEDIAN(C4, $B$15, $B$16) -> 1.5727739 | D21: =MEDIAN(D4, $B$15, $B$16) -> 1.6074359 | E21: =MEDIAN(E4, $B$15, $B$16) -> 1.5644405 | F21: =MEDIAN(F4, $B$15, $B$16) -> 1.5195132 | G21: =MEDIAN(G4, $B$15, $B$16) -> 1.6134299 | H21: =MEDIAN(H4, $B$15, $B$16) -> 1.8180768 | I21: =MEDIAN(I4, $B$15, $B$16) -> 1.4861397 | ... M21: =MEDIAN(M4, $B$15, $B$16) -> 1.8196988
B22: =MEDIAN(B5, $B$15, $B$16) -> 1.9837563 | C22: =MEDIAN(C5, $B$15, $B$16) -> 2.0943302 | D22: =MEDIAN(D5, $B$15, $B$16) -> 2.1747517 | E22: =MEDIAN(E5, $B$15, $B$16) -> 2.1494339 | F22: =MEDIAN(F5, $B$15, $B$16) -> 2.1494339 | G22: =MEDIAN(G5, $B$15, $B$16) -> 2.1882959 | H22: =MEDIAN(H5, $B$15, $B$16) -> 2.1317968 | I22: =MEDIAN(I5, $B$15, $B$16) -> 2.3194422 | ... M22: =MEDIAN(M5, $B$15, $B$16) -> 2.4300984
B23: =MEDIAN(B6, $B$15, $B$16) -> 2.2894999 | C23: =MEDIAN(C6, $B$15, $B$16) -> 2.2945529 | D23: =MEDIAN(D6, $B$15, $B$16) -> 2.1598688 | E23: =MEDIAN(E6, $B$15, $B$16) -> 2.2115657 | F23: =MEDIAN(F6, $B$15, $B$16) -> 2.2310891 | G23: =MEDIAN(G6, $B$15, $B$16) -> 2.3398809 | H23: =MEDIAN(H6, $B$15, $B$16) -> 2.3155013 | I23: =MEDIAN(I6, $B$15, $B$16) -> 2.2648832 | ... M23: =MEDIAN(M6, $B$15, $B$16) -> 2.2289386
B24: =MEDIAN(B7, $B$15, $B$16) -> 1.6882491 | C24: =MEDIAN(C7, $B$15, $B$16) -> 1.7766458 | D24: =MEDIAN(D7, $B$15, $B$16) -> 1.7119945 | E24: =MEDIAN(E7, $B$15, $B$16) -> 1.7119945 | F24: =MEDIAN(F7, $B$15, $B$16) -> 1.7351891 | G24: =MEDIAN(G7, $B$15, $B$16) -> 1.8437192 | H24: =MEDIAN(H7, $B$15, $B$16) -> 1.9110229 | I24: =MEDIAN(I7, $B$15, $B$16) -> 1.9257074 | ... M24: =MEDIAN(M7, $B$15, $B$16) -> 2.0215476
B25: =MEDIAN(B8, $B$15, $B$16) -> 2.706716 | C25: =MEDIAN(C8, $B$15, $B$16) -> 2.7843938 | D25: =MEDIAN(D8, $B$15, $B$16) -> 2.8063861 | E25: =MEDIAN(E8, $B$15, $B$16) -> 2.8068225 | F25: =MEDIAN(F8, $B$15, $B$16) -> 2.8068225 | G25: =MEDIAN(G8, $B$15, $B$16) -> 2.8068225 | H25: =MEDIAN(H8, $B$15, $B$16) -> 2.8068225 | I25: =MEDIAN(I8, $B$15, $B$16) -> 2.752386 | ... M25: =MEDIAN(M8, $B$15, $B$16) -> 2.7868614

Sheet non_bank_normalise
B1: 2025 | C1: 2024 | D1: 2023 | E1: 2022 | F1: 2021 | G1: 2020 | H1: 2019 | I1: 2018 | J1: 2017 | K1: 2016 | L1: 2015 | M1: 2014
A2: Adani Ports and Special Economic Zone Ltd | B2: =(non_bank!$B$28 - non_bank!B2) / (non_bank!$B$28 - non_bank!$B$27) -> 0.53263487 | C2: =(non_bank!$B$28 - non_bank!C2) / (non_bank!$B$28 - non_bank!$B$27) -> 0.46250069 | D2: =(non_bank!$B$28 - non_bank!D2) / (non_bank!$B$28 - non_bank!$B$27) -> 0.36225631 | E2: =(non_bank!$B$28 - non_bank!E2) / (non_bank!$B$28 - non_bank!$B$27) -> 0.32013321 | F2: =(non_bank!$B$28 - non_bank!F2) / (non_bank!$B$28 - non_bank!$B$27) -> 0.34517011 | G2: =(non_bank!$B$28 - non_bank!G2) / (non_bank!$B$28 - non_bank!$B$27) -> 0.36225631 | H2: =(non_bank!$B$28 - non_bank!H2) / (non_bank!$B$28 - non_bank!$B$27) -> 0.37092244 | I2: =(non_bank!$B$28 - non_bank!I2) / (non_bank!$B$28 - non_bank!$B$27) -> 0.39743231 | ... M2: =(non_bank!$B$28 - non_bank!M2) / (non_bank!$B$28 - non_bank!$B$27) -> 0.26428443
A3: Asian Paints Ltd | B3: =(non_bank!$B$28 - non_bank!B3) / (non_bank!$B$28 - non_bank!$B$27) -> 0.99129201 | C3: =(non_bank!$B$28 - non_bank!C3) / (non_bank!$B$28 - non_bank!$B$27) -> 0.97412443 | D3: =(non_bank!$B$28 - non_bank!D3) / (non_bank!$B$28 - non_bank!$B$27) -> 0.97412443 | E3: =(non_bank!$B$28 - non_bank!E3) / (non_bank!$B$28 - non_bank!$B$27) -> 0.97412443 | F3: =(non_bank!$B$28 - non_bank!F3) / (non_bank!$B$28 - non_bank!$B$27) -> 1 | G3: =(non_bank!$B$28 - non_bank!G3) / (non_bank!$B$28 - non_bank!$B$27) -> 1 | H3: =(non_bank!$B$28 - non_bank!H3) / (non_bank!$B$28 - non_bank!$B$27) -> 0.96566174 | I3: =(non_bank!$B$28 - non_bank!I3) / (non_bank!$B$28 - non_bank!$B$27) -> 0.97412443 | ... M3: =(non_bank!$B$28 - non_bank!M3) / (non_bank!$B$28 - non_bank!$B$27) -> 0.97412443
A4: Bharat Electronics Ltd | B4: =(non_bank!$B$28 - non_bank!B4) / (non_bank!$B$28 - non_bank!$B$27) -> 0.31602719 | C4: =(non_bank!$B$28 - non_bank!C4) / (non_bank!$B$28 - non_bank!$B$27) -> 0.34517011 | D4: =(non_bank!$B$28 - non_bank!D4) / (non_bank!$B$28 - non_bank!$B$27) -> 0.3579543 | E4: =(non_bank!$B$28 - non_bank!E4) / (non_bank!$B$28 - non_bank!$B$27) -> 0.43403715 | F4: =(non_bank!$B$28 - non_bank!F4) / (non_bank!$B$28 - non_bank!$B$27) -> 0.48692686 | G4: =(non_bank!$B$28 - non_bank!G4) / (non_bank!$B$28 - non_bank!$B$27) -> 0.23385892 | H4: =(non_bank!$B$28 - non_bank!H4) / (non_bank!$B$28 - non_bank!$B$27) -> 0.29177629 | I4: =(non_bank!$B$28 - non_bank!I4) / (non_bank!$B$28 - non_bank!$B$27) -> 0.58629776 | ... M4: =(non_bank!$B$28 - non_bank!M4) / (non_bank!$B$28 - non_bank!$B$27) -> 0.50695591
A5: Bharti Airtel Ltd | B5: =(non_bank!$B$28 - non_bank!B5) / (non_bank!$B$28 - non_bank!$B$27) -> 0.34517011 | C5: =(non_bank!$B$28 - non_bank!C5) / (non_bank!$B$28 - non_bank!$B$27) -> 0.20081475 | D5: =(non_bank!$B$28 - non_bank!D5) / (non_bank!$B$28 - non_bank!$B$27) -> 0.092260197 | E5: =(non_bank!$B$28 - non_bank!E5) / (non_bank!$B$28 - non_bank!$B$27) -> 0.036493727 | F5: =(non_bank!$B$28 - non_bank!F5) / (non_bank!$B$28 - non_bank!$B$27) -> 0 | G5: =(non_bank!$B$28 - non_bank!G5) / (non_bank!$B$28 - non_bank!$B$27) -> 0.19363328 | H5: =(non_bank!$B$28 - non_bank!H5) / (non_bank!$B$28 - non_bank!$B$27) -> 0.13479628 | I5: =(non_bank!$B$28 - non_bank!I5) / (non_bank!$B$28 - non_bank!$B$27) -> 0.23385892 | ... M5: =(non_bank!$B$28 - non_bank!M5) / (non_bank!$B$28 - non_bank!$B$27) -> 0.28779717
A6: HCL Technologies Ltd | B6: =(non_bank!$B$28 - non_bank!B6) / (non_bank!$B$28 - non_bank!$B$27) -> 1 | C6: =(non_bank!$B$28 - non_bank!C6) / (non_bank!$B$28 - non_bank!$B$27) -> 1 | D6: =(non_bank!$B$28 - non_bank!D6) / (non_bank!$B$28 - non_bank!$B$27) -> 1 | E6: =(non_bank!$B$28 - non_bank!E6) / (non_bank!$B$28 - non_bank!$B$27) -> 0.97412443 | F6: =(non_bank!$B$28 - non_bank!F6) / (non_bank!$B$28 - non_bank!$B$27) -> 0.97412443 | G6: =(non_bank!$B$28 - non_bank!G6) / (non_bank!$B$28 - non_bank!$B$27) -> 0.94897107 | H6: =(non_bank!$B$28 - non_bank!H6) / (non_bank!$B$28 - non_bank!$B$27) -> 0.94897107 | I6: =(non_bank!$B$28 - non_bank!I6) / (non_bank!$B$28 - non_bank!$B$27) -> 1 | ... M6: =(non_bank!$B$28 - non_bank!M6) / (non_bank!$B$28 - non_bank!$B$27) -> 1
A7: Hindustan Unilever Ltd | B7: =(non_bank!$B$28 - non_bank!B7) / (non_bank!$B$28 - non_bank!$B$27) -> 0.6258583 | C7: =(non_bank!$B$28 - non_bank!C7) / (non_bank!$B$28 - non_bank!$B$27) -> 0.62009937 | D7: =(non_bank!$B$28 - non_bank!D7) / (non_bank!$B$28 - non_bank!$B$27) -> 0.63748776 | E7: =(non_bank!$B$28 - non_bank!E7) / (non_bank!$B$28 - non_bank!$B$27) -> 0.64926924 | F7: =(non_bank!$B$28 - non_bank!F7) / (non_bank!$B$28 - non_bank!$B$27) -> 0.66723536 | G7: =(non_bank!$B$28 - non_bank!G7) / (non_bank!$B$28 - non_bank!$B$27) -> 0.15170616 | H7: =(non_bank!$B$28 - non_bank!H7) / (non_bank!$B$28 - non_bank!$B$27) -> 0.24514846 | I7: =(non_bank!$B$28 - non_bank!I7) / (non_bank!$B$28 - non_bank!$B$27) -> 0.23385892 | ... M7: =(non_bank!$B$28 - non_bank!M7) / (non_bank!$B$28 - non_bank!$B$27) -> 0
A8: Infosys Ltd | B8: =(non_bank!$B$28 - non_bank!B8) / (non_bank!$B$28 - non_bank!$B$27) -> 0.67941487 | C8: =(non_bank!$B$28 - non_bank!C8) / (non_bank!$B$28 - non_bank!$B$27) -> 0.66723536 | D8: =(non_bank!$B$28 - non_bank!D8) / (non_bank!$B$28 - non_bank!$B$27) -> 0.62009937 | E8: =(non_bank!$B$28 - non_bank!E8) / (non_bank!$B$28 - non_bank!$B$27) -> 0.6258583 | F8: =(non_bank!$B$28 - non_bank!F8) / (non_bank!$B$28 - non_bank!$B$27) -> 0.70427908 | G8: =(non_bank!$B$28 - non_bank!G8) / (non_bank!$B$28 - non_bank!$B$27) -> 0.71060381 | H8: =(non_bank!$B$28 - non_bank!H8) / (non_bank!$B$28 - non_bank!$B$27) -> 0.80415279 | I8: =(non_bank!$B$28 - non_bank!I8) / (non_bank!$B$28 - non_bank!$B$27) -> 0.84006473 | ... M8: =(non_bank!$B$28 - non_bank!M8) / (non_bank!$B$28 - non_bank!$B$27) -> 0.81834632
A9: ITC Ltd | B9: =(non_bank!$B$28 - non_bank!B9) / (non_bank!$B$28 - non_bank!$B$27) -> 0.91648934 | C9: =(non_bank!$B$28 - non_bank!C9) / (non_bank!$B$28 - non_bank!$B$27) -> 0.90854858 | D9: =(non_bank!$B$28 - non_bank!D9) / (non_bank!$B$28 - non_bank!$B$27) -> 0.84006473 | E9: =(non_bank!$B$28 - non_bank!E9) / (non_bank!$B$28 - non_bank!$B$27) -> 0.83276695 | F9: =(non_bank!$B$28 - non_bank!F9) / (non_bank!$B$28 - non_bank!$B$27) -> 0.84006473 | G9: =(non_bank!$B$28 - non_bank!G9) / (non_bank!$B$28 - non_bank!$B$27) -> 0.85483998 | H9: =(non_bank!$B$28 - non_bank!H9) / (non_bank!$B$28 - non_bank!$B$27) -> 0.83276695 | I9: =(non_bank!$B$28 - non_bank!I9) / (non_bank!$B$28 - non_bank!$B$27) -> 0.84006473 | ... M9: =(non_bank!$B$28 - non_bank!M9) / (non_bank!$B$28 - non_bank!$B$27) -> 0.68556691
A10: Larsen & Toubro Ltd | B10: =(non_bank!$B$28 - non_bank!B10) / (non_bank!$B$28 - non_bank!$B$27) -> 0.26428443 | C10: =(non_bank!$B$28 - non_bank!C10) / (non_bank!$B$28 - non_bank!$B$27) -> 0.26816087 | D10: =(non_bank!$B$28 - non_bank!D10) / (non_bank!$B$28 - non_bank!$B$27) -> 0.26428443 | E10: =(non_bank!$B$28 - non_bank!E10) / (non_bank!$B$28 - non_bank!$B$27) -> 0.20081475 | F10: =(non_bank!$B$28 - non_bank!F10) / (non_bank!$B$28 - non_bank!$B$27) -> 0.12149315 | G10: =(non_bank!$B$28 - non_bank!G10) / (non_bank!$B$28 - non_bank!$B$27) -> 0.0098532528 | H10: =(non_bank!$B$28 - non_bank!H10) / (non_bank!$B$28 - non_bank!$B$27) -> 0.030505197 | I10: =(non_bank!$B$28 - non_bank!I10) / (non_bank!$B$28 - non_bank!$B$27) -> 0.14490409 | ... M10: =(non_bank!$B$28 - non_bank!M10) / (non_bank!$B$28 - non_bank!$B$27) -> 0
A11: Mahindra & Mahindra Ltd | B11: =(non_bank!$B$28 - non_bank!B11) / (non_bank!$B$28 - non_bank!$B$27) -> 0.17592602 | C11: =(non_bank!$B$28 - non_bank!C11) / (non_bank!$B$28 - non_bank!$B$27) -> 0.17943975 | D11: =(non_bank!$B$28 - non_bank!D11) / (non_bank!$B$28 - non_bank!$B$27) -> 0.17592602 | E11: =(non_bank!$B$28 - non_bank!E11) / (non_bank!$B$28 - non_bank!$B$27) -> 0.17242593 | F11: =(non_bank!$B$28 - non_bank!F11) / (non_bank!$B$28 - non_bank!$B$27) -> 0.22641036 | G11: =(non_bank!$B$28 - non_bank!G11) / (non_bank!$B$28 - non_bank!$B$27) -> 0.17943975 | H11: =(non_bank!$B$28 - non_bank!H11) / (non_bank!$B$28 - non_bank!$B$27) -> 0.25658122 | I11: =(non_bank!$B$28 - non_bank!I11) / (non_bank!$B$28 - non_bank!$B$27) -> 0.30382018 | ... M11: =(non_bank!$B$28 - non_bank!M11) / (non_bank!$B$28 - non_bank!$B$27) -> 0.31193978
A12: Maruti Suzuki India Ltd | B12: =(non_bank!$B$28 - non_bank!B12) / (non_bank!$B$28 - non_bank!$B$27) -> 0.79017933 | C12: =(non_bank!$B$28 - non_bank!C12) / (non_bank!$B$28 - non_bank!$B$27) -> 0.74951361 | D12: =(non_bank!$B$28 - non_bank!D12) / (non_bank!$B$28 - non_bank!$B$27) -> 0.74951361 | E12: =(non_bank!$B$28 - non_bank!E12) / (non_bank!$B$28 - non_bank!$B$27) -> 0.76286601 | F12: =(non_bank!$B$28 - non_bank!F12) / (non_bank!$B$28 - non_bank!$B$27) -> 0.76961713 | G12: =(non_bank!$B$28 - non_bank!G12) / (non_bank!$B$28 - non_bank!$B$27) -> 0.81122161 | H12: =(non_bank!$B$28 - non_bank!H12) / (non_bank!$B$28 - non_bank!$B$27) -> 0.78327301 | I12: =(non_bank!$B$28 - non_bank!I12) / (non_bank!$B$28 - non_bank!$B$27) -> 0.76286601 | ... M12: =(non_bank!$B$28 - non_bank!M12) / (non_bank!$B$28 - non_bank!$B$27) -> 0.59184406
A13: NTPC Ltd | B13: =(non_bank!$B$28 - non_bank!B13) / (non_bank!$B$28 - non_bank!$B$27) -> 0.33674696 | C13: =(non_bank!$B$28 - non_bank!C13) / (non_bank!$B$28 - non_bank!$B$27) -> 0.29978764 | D13: =(non_bank!$B$28 - non_bank!D13) / (non_bank!$B$28 - non_bank!$B$27) -> 0.26428443 | E13: =(non_bank!$B$28 - non_bank!E13) / (non_bank!$B$28 - non_bank!$B$27) -> 0.26428443 | F13: =(non_bank!$B$28 - non_bank!F13) / (non_bank!$B$28 - non_bank!$B$27) -> 0.24514846 | G13: =(non_bank!$B$28 - non_bank!G13) / (non_bank!$B$28 - non_bank!$B$27) -> 0.23385892 | H13: =(non_bank!$B$28 - non_bank!H13) / (non_bank!$B$28 - non_bank!$B$27) -> 0.29177629 | I13: =(non_bank!$B$28 - non_bank!I13) / (non_bank!$B$28 - non_bank!$B$27) -> 0.34517011 | ... M13: =(non_bank!$B$28 - non_bank!M13) / (non_bank!$B$28 - non_bank!$B$27) -> 0.53263487
... A23: UltraTech Cement Ltd | B23: =(non_bank!$B$28 - non_bank!B23) / (non_bank!$B$28 - non_bank!$B$27) -> 0.76961713 | C23: =(non_bank!$B$28 - non_bank!C23) / (non_bank!$B$28 - non_bank!$B$27) -> 0.88513764 | D23: =(non_bank!$B$28 - non_bank!D23) / (non_bank!$B$28 - non_bank!$B$27) -> 0.87746721 | E23: =(non_bank!$B$28 - non_bank!E23) / (non_bank!$B$28 - non_bank!$B$27) -> 0.86231945 | F23: =(non_bank!$B$28 - non_bank!F23) / (non_bank!$B$28 - non_bank!$B$27) -> 0.723388 | G23: =(non_bank!$B$28 - non_bank!G23) / (non_bank!$B$28 - non_bank!$B$27) -> 0.63165427 | H23: =(non_bank!$B$28 - non_bank!H23) / (non_bank!$B$28 - non_bank!$B$27) -> 0.46733325 | I23: =(non_bank!$B$28 - non_bank!I23) / (non_bank!$B$28 - non_bank!$B$27) -> 0.54311487 | ... M23: =(non_bank!$B$28 - non_bank!M23) / (non_bank!$B$28 - non_bank!$B$27) -> 0.71697324
A27: min | B27: =MIN(B2:M23) -> 0
A28: max | B28: =MAX(B2:M23) -> 1

Sheet bank_normalise
B1: 2025 | C1: 2024 | D1: 2023 | E1: 2022 | F1: 2021 | G1: 2020 | H1: 2019 | I1: 2018 | J1: 2017 | K1: 2016 | L1: 2015 | M1: 2014
A2: AXIS Bank Ltd | B2: =(bank!$B$13 - bank!B2) / (bank!$B$13 - bank!$B$12) -> 0.45744205 | C2: =(bank!$B$13 - bank!C2) / (bank!$B$13 - bank!$B$12) -> 0.39335674 | D2: =(bank!$B$13 - bank!D2) / (bank!$B$13 - bank!$B$12) -> 0.34215083 | E2: =(bank!$B$13 - bank!E2) / (bank!$B$13 - bank!$B$12) -> 0.36148088 | F2: =(bank!$B$13 - bank!F2) / (bank!$B$13 - bank!$B$12) -> 0.39563315 | G2: =(bank!$B$13 - bank!G2) / (bank!$B$13 - bank!$B$12) -> 0.44758766 | H2: =(bank!$B$13 - bank!H2) / (bank!$B$13 - bank!$B$12) -> 0.23700037 | I2: =(bank!$B$13 - bank!I2) / (bank!$B$13 - bank!$B$12) -> 0.31919617 | ... M2: =(bank!$B$13 - bank!M2) / (bank!$B$13 - bank!$B$12) -> 0.36584645
A3: Bajaj Finserv Ltd | B3: =(bank!$B$13 - bank!B3) / (bank!$B$13 - bank!$B$12) -> 0.75884056 | C3: =(bank!$B$13 - bank!C3) / (bank!$B$13 - bank!$B$12) -> 0.77395207 | D3: =(bank!$B$13 - bank!D3) / (bank!$B$13 - bank!$B$12) -> 0.80116961 | E3: =(bank!$B$13 - bank!E3) / (bank!$B$13 - bank!$B$12) -> 0.88057596 | F3: =(bank!$B$13 - bank!F3) / (bank!$B$13 - bank!$B$12) -> 0.94512366 | G3: =(bank!$B$13 - bank!G3) / (bank!$B$13 - bank!$B$12) -> 0.87325644 | H3: =(bank!$B$13 - bank!H3) / (bank!$B$13 - bank!$B$12) -> 0.85031266 | I3: =(bank!$B$13 - bank!I3) / (bank!$B$13 - bank!$B$12) -> 1 | ... M3: =(bank!$B$13 - bank!M3) / (bank!$B$13 - bank!$B$12) -> 1
A4: Bajaj Finance Ltd | B4: =(bank!$B$13 - bank!B4) / (bank!$B$13 - bank!$B$12) -> 0.91830993 | C4: =(bank!$B$13 - bank!C4) / (bank!$B$13 - bank!$B$12) -> 0.90602276 | D4: =(bank!$B$13 - bank!D4) / (bank!$B$13 - bank!$B$12) -> 0.88057596 | E4: =(bank!$B$13 - bank!E4) / (bank!$B$13 - bank!$B$12) -> 0.91214064 | F4: =(bank!$B$13 - bank!F4) / (bank!$B$13 - bank!$B$12) -> 0.94512366 | G4: =(bank!$B$13 - bank!G4) / (bank!$B$13 - bank!$B$12) -> 0.8761755 | H4: =(bank!$B$13 - bank!H4) / (bank!$B$13 - bank!$B$12) -> 0.72593577 | I4: =(bank!$B$13 - bank!I4) / (bank!$B$13 - bank!$B$12) -> 0.96962454 | ... M4: =(bank!$B$13 - bank!M4) / (bank!$B$13 - bank!$B$12) -> 0.72474495
A5: HDFC Bank Ltd | B5: =(bank!$B$13 - bank!B5) / (bank!$B$13 - bank!$B$12) -> 0.60430357 | C5: =(bank!$B$13 - bank!C5) / (bank!$B$13 - bank!$B$12) -> 0.52312672 | D5: =(bank!$B$13 - bank!D5) / (bank!$B$13 - bank!$B$12) -> 0.46408591 | E5: =(bank!$B$13 - bank!E5) / (bank!$B$13 - bank!$B$12) -> 0.48267276 | F5: =(bank!$B$13 - bank!F5) / (bank!$B$13 - bank!$B$12) -> 0.48267276 | G5: =(bank!$B$13 - bank!G5) / (bank!$B$13 - bank!$B$12) -> 0.45414254 | H5: =(bank!$B$13 - bank!H5) / (bank!$B$13 - bank!$B$12) -> 0.49562092 | I5: =(bank!$B$13 - bank!I5) / (bank!$B$13 - bank!$B$12) -> 0.35786263 | ... M5: =(bank!$B$13 - bank!M5) / (bank!$B$13 - bank!$B$12) -> 0.27662532
A6: ICICI Bank Ltd | B6: =(bank!$B$13 - bank!B6) / (bank!$B$13 - bank!$B$12) -> 0.37984455 | C6: =(bank!$B$13 - bank!C6) / (bank!$B$13 - bank!$B$12) -> 0.37613489 | D6: =(bank!$B$13 - bank!D6) / (bank!$B$13 - bank!$B$12) -> 0.47501209 | E6: =(bank!$B$13 - bank!E6) / (bank!$B$13 - bank!$B$12) -> 0.43705925 | F6: =(bank!$B$13 - bank!F6) / (bank!$B$13 - bank!$B$12) -> 0.42272631 | G6: =(bank!$B$13 - bank!G6) / (bank!$B$13 - bank!$B$12) -> 0.34285776 | H6: =(bank!$B$13 - bank!H6) / (bank!$B$13 - bank!$B$12) -> 0.3607558 | I6: =(bank!$B$13 - bank!I6) / (bank!$B$13 - bank!$B$12) -> 0.39791664 | ... M6: =(bank!$B$13 - bank!M6) / (bank!$B$13 - bank!$B$12) -> 0.42430511
A7: Kotak Mahindra Bank Ltd | B7: =(bank!$B$13 - bank!B7) / (bank!$B$13 - bank!$B$12) -> 0.82124765 | C7: =(bank!$B$13 - bank!C7) / (bank!$B$13 - bank!$B$12) -> 0.75635194 | D7: =(bank!$B$13 - bank!D7) / (bank!$B$13 - bank!$B$12) -> 0.80381517 | E7: =(bank!$B$13 - bank!E7) / (bank!$B$13 - bank!$B$12) -> 0.80381517 | F7: =(bank!$B$13 - bank!F7) / (bank!$B$13 - bank!$B$12) -> 0.78678704 | G7: =(bank!$B$13 - bank!G7) / (bank!$B$13 - bank!$B$12) -> 0.7071106 | H7: =(bank!$B$13 - bank!H7) / (bank!$B$13 - bank!$B$12) -> 0.65770018 | I7: =(bank!$B$13 - bank!I7) / (bank!$B$13 - bank!$B$12) -> 0.64691964 | ... M7: =(bank!$B$13 - bank!M7) / (bank!$B$13 - bank!$B$12) -> 0.57655943
A8: State Bank of India | B8: =(bank!$B$13 - bank!B8) / (bank!$B$13 - bank!$B$12) -> 0.073548906 | C8: =(bank!$B$13 - bank!C8) / (bank!$B$13 - bank!$B$12) -> 0.016522422 | D8: =(bank!$B$13 - bank!D8) / (bank!$B$13 - bank!$B$12) -> 0.00037693763 | E8: =(bank!$B$13 - bank!E8) / (bank!$B$13 - bank!$B$12) -> 0 | F8: =(bank!$B$13 - bank!F8) / (bank!$B$13 - bank!$B$12) -> 0 | G8: =(bank!$B$13 - bank!G8) / (bank!$B$13 - bank!$B$12) -> 0 | H8: =(bank!$B$13 - bank!H8) / (bank!$B$13 - bank!$B$12) -> 0 | I8: =(bank!$B$13 - bank!I8) / (bank!$B$13 - bank!$B$12) -> 0.040020639 | ... M8: =(bank!$B$13 - bank!M8) / (bank!$B$13 - bank!$B$12) -> 0.014710844
A12: min | B12: =MIN(B2:M8) -> 0
A13: max | B13: =MAX(B3:M9) -> 1

Sheet combined_normalised
B1: 2025 | C1: 2024 | D1: 2023 | E1: 2022 | F1: 2021 | G1: 2020 | H1: 2019 | I1: 2018 | J1: 2017 | K1: 2016 | L1: 2015 | M1: 2014 | P1: flattened
A2: Adani Ports and Special Economic Zone Ltd | B2: 0.53263487 | C2: 0.46250069 | D2: 0.36225631 | E2: 0.32013321 | F2: 0.34517011 | G2: 0.36225631 | H2: 0.37092244 | I2: 0.39743231 | J2: 0.31602719 | K2: 0.23760641 | L2: 0.23385891 | M2: 0.26428443 | P2: =IFERROR(__xludf.DUMMYFUNCTION("FLATTEN(B2:M30)"),0.532634867562179) -> 0.53263487
A3: Asian Paints Ltd | B3: 0.99129201 | C3: 0.97412443 | D3: 0.97412443 | E3: 0.97412443 | F3: 1 | G3: 1 | H3: 0.96566174 | I3: 0.97412443 | J3: 0.96566174 | K3: 0.98266734 | L3: 0.94897107 | M3: 0.97412443 | P3: =IFERROR(__xludf.DUMMYFUNCTION("""COMPUTED_VALUE"""),0.4625006879663207) -> 0.46250069
A4: AXIS Bank Ltd | B4: 0.45744205 | C4: 0.39335674 | D4: 0.34215083 | E4: 0.36148088 | F4: 0.39563315 | G4: 0.44758766 | H4: 0.23700037 | I4: 0.31919617 | J4: 0.31441792 | K4: 0.37910112 | L4: 0.34640263 | M4: 0.36584645 | P4: =IFERROR(__xludf.DUMMYFUNCTION("""COMPUTED_VALUE"""),0.3622563142775422) -> 0.36225631
A5: Bajaj Finserv Ltd | B5: 0.75884056 | C5: 0.77395207 | D5: 0.80116961 | E5: 0.88057596 | F5: 0.94512366 | G5: 0.87325644 | H5: 0.85031266 | I5: 1 | J5: 1 | K5: 1 | L5: 1 | M5: 1 | P5: =IFERROR(__xludf.DUMMYFUNCTION("""COMPUTED_VALUE"""),0.3201332084809979) -> 0.32013321
A6: Bajaj Finance Ltd | B6: 0.91830993 | C6: 0.90602276 | D6: 0.88057596 | E6: 0.91214064 | F6: 0.94512366 | G6: 0.8761755 | H6: 0.72593577 | I6: 0.96962454 | J6: 0.82533001 | K6: 0.74648099 | L6: 0.78162609 | M6: 0.72474495 | P6: =IFERROR(__xludf.DUMMYFUNCTION("""COMPUTED_VALUE"""),0.34517010759603917) -> 0.34517011
A7: Bharat Electronics Ltd | B7: 0.31602719 | C7: 0.34517011 | D7: 0.3579543 | E7: 0.43403715 | F7: 0.48692686 | G7: 0.23385891 | H7: 0.29177629 | I7: 0.58629776 | J7: 0.53263487 | K7: 0.6258583 | L7: 0.54840093 | M7: 0.50695591 | P7: =IFERROR(__xludf.DUMMYFUNCTION("""COMPUTED_VALUE"""),0.3622563142775422) -> 0.36225631
A8: Bharti Airtel Ltd | B8: 0.34517011 | C8: 0.20081475 | D8: 0.092260197 | E8: 0.036493727 | F8: 0 | G8: 0.19363328 | H8: 0.13479628 | I8: 0.23385891 | J8: 0.19363328 | K8: 0.20081475 | L8: 0.1116431 | M8: 0.28779717 | P8: =IFERROR(__xludf.DUMMYFUNCTION("""COMPUTED_VALUE"""),0.37092244267591573) -> 0.37092244
A9: HCL Technologies Ltd | B9: 1 | C9: 1 | D9: 1 | E9: 0.97412443 | F9: 0.97412443 | G9: 0.94897107 | H9: 0.94897107 | I9: 1 | J9: 1 | K9: 1 | L9: 1 | M9: 1 | P9: =IFERROR(__xludf.DUMMYFUNCTION("""COMPUTED_VALUE"""),0.39743230703709925) -> 0.39743231
A10: HDFC Bank Ltd | B10: 0.60430357 | C10: 0.52312672 | D10: 0.46408591 | E10: 0.48267276 | F10: 0.48267276 | G10: 0.45414254 | H10: 0.49562092 | I10: 0.35786263 | J10: 0.44595804 | K10: 0.45661578 | L10: 0.39944292 | M10: 0.27662532 | P10: =IFERROR(__xludf.DUMMYFUNCTION("""COMPUTED_VALUE"""),0.31602718584668543) -> 0.31602719
A11: Hindustan Unilever Ltd | B11: 0.6258583 | C11: 0.62009937 | D11: 0.63748776 | E11: 0.64926924 | F11: 0.66723536 | G11: 0.15170616 | H11: 0.24514846 | I11: 0.23385891 | J11: 0.17592602 | K11: 0.2604246 | L11: 0.054701829 | M11: 0 | P11: =IFERROR(__xludf.DUMMYFUNCTION("""COMPUTED_VALUE"""),0.2376064064869655) -> 0.23760641
A12: ICICI Bank Ltd | B12: 0.37984455 | C12: 0.37613489 | D12: 0.47501209 | E12: 0.43705925 | F12: 0.42272631 | G12: 0.34285776 | H12: 0.3607558 | I12: 0.39791664 | J12: 0.43145203 | K12: 0.43225044 | L12: 0.41957886 | M12: 0.42430511 | P12: =IFERROR(__xludf.DUMMYFUNCTION("""COMPUTED_VALUE"""),0.23385891497809416) -> 0.23385892
A13: Infosys Ltd | B13: 0.67941487 | C13: 0.66723536 | D13: 0.62009937 | E13: 0.6258583 | F13: 0.70427908 | G13: 0.71060381 | H13: 0.80415279 | I13: 0.84006473 | J13: 0.86986151 | K13: 0.86231945 | L13: 0.86231945 | M13: 0.81834632 | P13: =IFERROR(__xludf.DUMMYFUNCTION("""COMPUTED_VALUE"""),0.26428443399993323) -> 0.26428443
A14: ITC Ltd | B14: 0.91648934 | C14: 0.90854858 | D14: 0.84006473 | E14: 0.83276695 | F14: 0.84006473 | G14: 0.85483998 | H14: 0.83276695 | I14: 0.84006473 | J14: 0.82552779 | K14: 0.71060381 | L14: 0.69799843 | M14: 0.68556691 | P14: =IFERROR(__xludf.DUMMYFUNCTION("""COMPUTED_VALUE"""),0.9912920055972348) -> 0.99129201
A15: Kotak Mahindra Bank Ltd | B15: 0.82124765 | C15: 0.75635194 | D15: 0.80381517 | E15: 0.80381517 | F15: 0.78678704 | G15: 0.7071106 | H15: 0.65770018 | I15: 0.64691964 | J15: 0.61344871 | K15: 0.59726862 | L15: 0.6227092 | M15: 0.57655943 | P15: =IFERROR(__xludf.DUMMYFUNCTION("""COMPUTED_VALUE"""),0.9741244311181435) -> 0.97412443
A16: Larsen & Toubro Ltd | B16: 0.26428443 | C16: 0.26816087 | D16: 0.26428443 | E16: 0.20081475 | F16: 0.12149315 | G16: 0.0098532528 | H16: 0.030505197 | I16: 0.14490409 | J16: 0.13815297 | K16: 0.03950298 | L16: 0.033494488 | M16: 0 | P16: =IFERROR(__xludf.DUMMYFUNCTION("""COMPUTED_VALUE"""),0.9741244311181435) -> 0.97412443
A17: Mahindra & Mahindra Ltd | B17: 0.17592602 | C17: 0.17943975 | D17: 0.17592602 | E17: 0.17242593 | F17: 0.22641036 | G17: 0.17943975 | H17: 0.25658122 | I17: 0.30382018 | J17: 0.25658122 | K17: 0.33256472 | L17: 0.34094869 | M17: 0.31193978 | P17: =IFERROR(__xludf.DUMMYFUNCTION("""COMPUTED_VALUE"""),0.9741244311181435) -> 0.97412443
A18: Maruti Suzuki India Ltd | B18: 0.79017933 | C18: 0.74951361 | D18: 0.74951361 | E18: 0.76286601 | F18: 0.76961713 | G18: 0.81122161 | H18: 0.78327301 | I18: 0.76286601 | J18: 0.75616508 | K18: 0.71697324 | L18: 0.63748776 | M18: 0.59184406 | P18: =IFERROR(__xludf.DUMMYFUNCTION("""COMPUTED_VALUE"""),1.0) -> 1
A19: NTPC Ltd | B19: 0.33674696 | C19: 0.29978764 | D19: 0.26428443 | E19: 0.26428443 | F19: 0.24514846 | G19: 0.23385891 | H19: 0.29177629 | I19: 0.34517011 | J19: 0.38407991 | K19: 0.42474562 | L19: 0.42013553 | M19: 0.53263487 | P19: =IFERROR(__xludf.DUMMYFUNCTION("""COMPUTED_VALUE"""),1.0) -> 1
A20: Power Grid Corporation of India Ltd | B20: 0.23385891 | C20: 0.23012694 | D20: 0.19363328 | E20: 0.10838353 | F20: 0.076420239 | G20: 0 | H20: 0 | I20: 0 | J20: 0 | K20: 0 | L20: 0 | M20: 0 | P20: =IFERROR(__xludf.DUMMYFUNCTION("""COMPUTED_VALUE"""),0.9656617359891198) -> 0.96566174
A21: Reliance Industries Ltd | B21: 0.71697324 | C21: 0.71697324 | D21: 0.69799843 | E21: 0.76286601 | F21: 0.7764192 | G21: 0.57530653 | H21: 0.54840093 | I21: 0.59184406 | J21: 0.54840093 | K21: 0.53785964 | L21: 0.55906698 | M21: 0.55906698 | P21: =IFERROR(__xludf.DUMMYFUNCTION("""COMPUTED_VALUE"""),0.9741244311181435) -> 0.97412443
A22: State Bank of India | B22: =(bank!$B$13 - bank!B22) / (bank!$B$13 - bank!$B$12) -> 0.60430357 | C22: =(bank!$B$13 - bank!C22) / (bank!$B$13 - bank!$B$12) -> 0.52312672 | D22: =(bank!$B$13 - bank!D22) / (bank!$B$13 - bank!$B$12) -> 0.46408591 | E22: =(bank!$B$13 - bank!E22) / (bank!$B$13 - bank!$B$12) -> 0.48267276 | F22: =(bank!$B$13 - bank!F22) / (bank!$B$13 - bank!$B$12) -> 0.48267276 | G22: =(bank!$B$13 - bank!G22) / (bank!$B$13 - bank!$B$12) -> 0.45414254 | H22: =(bank!$B$13 - bank!H22) / (bank!$B$13 - bank!$B$12) -> 0.49562092 | I22: =(bank!$B$13 - bank!I22) / (bank!$B$13 - bank!$B$12) -> 0.35786263 | ... M22: =(bank!$B$13 - bank!M22) / (bank!$B$13 - bank!$B$12) -> 0.27662532 | P22: =IFERROR(__xludf.DUMMYFUNCTION("""COMPUTED_VALUE"""),0.9656617359891198) -> 0.96566174
A23: Sun Pharmaceutical Industries Ltd | B23: 0.81122161 | C23: 0.76286601 | D23: 0.72984875 | E23: 0.72984875 | F23: 0.72984875 | G23: 0.70427908 | H23: 0.723388 | I23: 0.71697324 | J23: 0.76961713 | K23: 0.76961713 | L23: 0.71060381 | M23: 0.79017933 | P23: =IFERROR(__xludf.DUMMYFUNCTION("""COMPUTED_VALUE"""),0.9826673425624152) -> 0.98266734
A24: Tata Motors Ltd | B24: 0.63748776 | C24: 0.33256472 | D24: 0 | E24: 0 | F24: 0.012774715 | G24: 0.17242593 | H24: 0.19721686 | I24: 0.48692686 | J24: 0.28383553 | K24: 0.50695591 | L24: 0.30382018 | M24: 0.47707681 | P24: =IFERROR(__xludf.DUMMYFUNCTION("""COMPUTED_VALUE"""),0.9489710662267077) -> 0.94897107
A25: Tata Steel Ltd | B25: 0.4109855 | C25: 0.45291261 | D25: 0.51713987 | E25: 0.60304011 | F25: 0.3579543 | G25: 0.16893939 | H25: 0.24894329 | I25: 0.19721686 | J25: 0 | K25: 0.054701829 | L25: 0 | M25: 0.13479628 | P25: =IFERROR(__xludf.DUMMYFUNCTION("""COMPUTED_VALUE"""),0.9741244311181435) -> 0.97412443
A26: Tata Consultancy Services Ltd | B26: 0.55371818 | C26: 0.56444771 | D26: 0.60869073 | E26: 0.61437699 | F26: 0.66120677 | G26: 0.71060381 | H26: 0.81834632 | I26: 0.81834632 | J26: 0.86986151 | K26: 0.84742208 | L26: 0.81834632 | M26: 0.81122161 | P26: =IFERROR(__xludf.DUMMYFUNCTION("""COMPUTED_VALUE"""),0.4574420529209024) -> 0.45744205
A27: Tech Mahindra Ltd | B27: 1 | C27: 0.97412443 | D27: 0.97412443 | E27: 0.97412443 | F27: 0.96566174 | G27: 0.93258388 | H27: 0.96566174 | I27: 0.94897107 | J27: 0.96566174 | K27: 0.96566174 | L27: 0.97412443 | M27: 1 | P27: =IFERROR(__xludf.DUMMYFUNCTION("""COMPUTED_VALUE"""),0.39335674030055834) -> 0.39335674
A28: Titan Company Ltd | B28: 0.17943975 | C28: 0.23760641 | D28: 0.58629776 | E28: 0.97412443 | F28: 0.61437699 | G28: 0.75616508 | H28: 0.72984875 | I28: 0.76961713 | J28: 0.69799843 | K28: 1 | L28: 1 | M28: 0.7764192 | P28: =IFERROR(__xludf.DUMMYFUNCTION("""COMPUTED_VALUE"""),0.34215083049317574) -> 0.34215083
A29: Trent Ltd | B29: 0.94897107 | C29: 0.92450068 | D29: 0.86986151 | E29: 0.85483998 | F29: 1 | G29: 0.91648934 | H29: 0.83276695 | I29: 0.82552779 | J29: 0.86986151 | K29: 0.96566174 | L29: 0.95727776 | M29: 0.76961713 | P29: =IFERROR(__xludf.DUMMYFUNCTION("""COMPUTED_VALUE"""),0.3614808783510441) -> 0.36148088
A30: UltraTech Cement Ltd | B30: 0.76961713 | C30: 0.88513764 | D30: 0.87746721 | E30: 0.86231945 | F30: 0.723388 | G30: 0.63165427 | H30: 0.46733325 | I30: 0.54311487 | J30: 0.78327301 | K30: 0.76286601 | L30: 0.723388 | M30: 0.71697324 | P30: =IFERROR(__xludf.DUMMYFUNCTION("""COMPUTED_VALUE"""),0.39563314969555186) -> 0.39563315
P31: =IFERROR(__xludf.DUMMYFUNCTION("""COMPUTED_VALUE"""),0.4475876574227574) -> 0.44758766
P32: =IFERROR(__xludf.DUMMYFUNCTION("""COMPUTED_VALUE"""),0.23700036559830037) -> 0.23700037
P33: =IFERROR(__xludf.DUMMYFUNCTION("""COMPUTED_VALUE"""),0.31919617269690104) -> 0.31919617
A34: min | B34: =MIN(B2:M30) -> 0 | P34: =IFERROR(__xludf.DUMMYFUNCTION("""COMPUTED_VALUE"""),0.314417922363832) -> 0.31441792
A35: max | B35: =MAX(B2:M30) -> 1 | P35: =IFERROR(__xludf.DUMMYFUNCTION("""COMPUTED_VALUE"""),0.3791011187550386) -> 0.37910112
P36: =IFERROR(__xludf.DUMMYFUNCTION("""COMPUTED_VALUE"""),0.3464026267887092) -> 0.34640263
P37: =IFERROR(__xludf.DUMMYFUNCTION("""COMPUTED_VALUE"""),0.3658464498375848) -> 0.36584645
P38: =IFERROR(__xludf.DUMMYFUNCTION("""COMPUTED_VALUE"""),0.758840561724621) -> 0.75884056
P39: =IFERROR(__xludf.DUMMYFUNCTION("""COMPUTED_VALUE"""),0.7739520683314665) -> 0.77395207
P40: =IFERROR(__xludf.DUMMYFUNCTION("""COMPUTED_VALUE"""),0.8011696077728717) -> 0.80116961
...
