Workbook

Sheet Sheet1
B1: (P/S)2025 | C1: (P/S)2024 | D1: (P/S)2023 | E1: (P/S)2022 | F1: (P/S)2021 | G1: (P/S)2020 | H1: (P/S)2019 | I1: (P/S)2018 | J1: (P/S)2017 | K1: (P/S)2016 | L1: (P/S)2015 | M1: (P/S)2014
A2: Adani Ports and Special Economic Zone Ltd | B2: 8.22 | C2: 8.7525 | D2: 6.55 | E2: 8.7525 | F2: 8.7525 | G2: 4.3 | H2: 7.17 | I2: 6.49 | J2: 8.34 | K2: 7.22 | L2: 8.7525 | M2: 8.05
A3: Asian Paints Ltd | B3: 6.61 | C3: 7.69 | D3: 7.68 | E3: 8.7525 | F3: 8.7525 | G3: 7.91 | H3: 7.44 | I3: 6.39 | J3: 6.82 | K3: 5.84 | L3: 5.47 | M3: 4.12
A4: AXIS Bank Ltd | B4: 2.68 | C4: 2.87 | D4: 3.02 | E4: 3.39 | F4: 3.3 | G4: 1.68 | H4: 3.56 | I4: 2.8 | J4: 2.6 | K4: 2.56 | L4: 3.72 | M4: 2.23
A5: Bajaj Finserv Ltd | B5: 2.39 | C5: 2.37 | D5: 2.46 | E5: 3.97 | F5: 2.54 | G5: 1.34 | H5: 2.63 | I5: 2.51 | J5: 2.65 | K5: 2.87 | L5: 2.91 | M5: 2.09
A6: Bajaj Finance Ltd | B6: 7.97 | C6: 8.14 | D6: 8.2 | E6: 8.7525 | F6: 8.7525 | G6: 5.04 | H6: 8.7525 | I6: 7.57 | J6: 6.44 | K6: 5.08 | L6: 3.81 | M6: 2.05
A7: Bharat Electronics Ltd | B7: 8.7525 | C7: 7.27 | D7: 4.02 | E7: 3.34 | F7: 2.16 | G7: 1.4 | H7: 1.87 | I7: 3.33 | J7: 4.03 | K7: 3.98 | L7: 3.78 | M7: 1.4
A8: Bharti Airtel Ltd | B8: 5.8 | C8: 4.71 | D8: 3.05 | E8: 3.62 | F8: 2.82 | G8: 2.75 | H8: 1.65 | I8: 1.9 | J8: 1.46 | K8: 1.45 | L8: 1.64 | M8: 1.46
A9: HCL Technologies Ltd | B9: 3.69 | C9: 3.81 | D9: 2.91 | E9: 3.69 | F9: 3.54 | G9: 1.68 | H9: 2.44 | I9: 2.66 | J9: 2.62 | K9: 3.69 | L9: 3.53 | M9: 3.26
A10: HDFC Bank Ltd | B10: 4.66 | C10: 4.26 | D10: 5.56 | E10: 6.38 | F10: 6.81 | G10: 4.12 | H10: 6.37 | I10: 6.12 | J10: 5.33 | K10: 4.5 | L10: 5.29 | M10: 4.37
A11: Hindustan Unilever Ltd | B11: 8.41 | C11: 8.61 | D11: 8.7525 | E11: 8.7525 | F11: 8.7525 | G11: 8.7525 | H11: 8.7525 | I11: 8.12 | J11: 5.93 | K11: 5.84 | L11: 5.91 | M11: 4.47
A12: ICICI Bank Ltd | B12: 5.15 | C12: 4.82 | D12: 5.06 | E12: 5.32 | F12: 4.51 | G12: 2.48 | H12: 3.57 | I12: 2.88 | J12: 2.65 | K12: 2.32 | L12: 3.33 | M12: 2.91
A13: Infosys Ltd | B13: 3.99 | C13: 4.04 | D13: 4.03 | E13: 6.58 | F13: 5.78 | G13: 2.99 | H13: 3.9 | I13: 3.5 | J13: 3.41 | K13: 4.46 | L13: 4.76 | M13: 3.74
... A30: UltraTech Cement Ltd | B30: 4.46 | C30: 3.97 | D30: 3.48 | E30: 3.62 | F30: 4.35 | G30: 2.21 | H30: 2.64 | I30: 3.5 | J30: 4.32 | K30: 3.52 | L30: 3.24 | M30: 2.77
A34: Global min | B34: =MIN(B2:N30) -> 0.5935
A35: Global Max | B35: =MAX(B2:N30) -> 8.7525
A38: percentile min | B38: =PERCENTILE(B2:M30, 0.05) -> 0.595775
A39: percentile max | B39: =PERCENTILE(B2:M30, 0.95) -> 8.7525
B42: =MEDIAN(B2, $B$38, $B$39) -> 8.22 | C42: =MEDIAN(C2, $B$38, $B$39) -> 8.7525 | D42: =MEDIAN(D2, $B$38, $B$39) -> 6.55 | E42: =MEDIAN(E2, $B$38, $B$39) -> 8.7525 | F42: =MEDIAN(F2, $B$38, $B$39) -> 8.7525 | G42: =MEDIAN(G2, $B$38, $B$39) -> 4.3 | H42: =MEDIAN(H2, $B$38, $B$39) -> 7.17 | I42: =MEDIAN(I2, $B$38, $B$39) -> 6.49 | ... N42: =MEDIAN(N2, $B$38, $B$39) -> 4.6741375
B43: =MEDIAN(B3, $B$38, $B$39) -> 6.61 | C43: =MEDIAN(C3, $B$38, $B$39) -> 7.69 | D43: =MEDIAN(D3, $B$38, $B$39) -> 7.68 | E43: =MEDIAN(E3, $B$38, $B$39) -> 8.7525 | F43: =MEDIAN(F3, $B$38, $B$39) -> 8.7525 | G43: =MEDIAN(G3, $B$38, $B$39) -> 7.91 | H43: =MEDIAN(H3, $B$38, $B$39) -> 7.44 | I43: =MEDIAN(I3, $B$38, $B$39) -> 6.39 | ... N43: =MEDIAN(N3, $B$38, $B$39) -> 4.6741375
B44: =MEDIAN(B4, $B$38, $B$39) -> 2.68 | C44: =MEDIAN(C4, $B$38, $B$39) -> 2.87 | D44: =MEDIAN(D4, $B$38, $B$39) -> 3.02 | E44: =MEDIAN(E4, $B$38, $B$39) -> 3.39 | F44: =MEDIAN(F4, $B$38, $B$39) -> 3.3 | G44: =MEDIAN(G4, $B$38, $B$39) -> 1.68 | H44: =MEDIAN(H4, $B$38, $B$39) -> 3.56 | I44: =MEDIAN(I4, $B$38, $B$39) -> 2.8 | ... N44: =MEDIAN(N4, $B$38, $B$39) -> 4.6741375
B45: =MEDIAN(B5, $B$38, $B$39) -> 2.39 | C45: =MEDIAN(C5, $B$38, $B$39) -> 2.37 | D45: =MEDIAN(D5, $B$38, $B$39) -> 2.46 | E45: =MEDIAN(E5, $B$38, $B$39) -> 3.97 | F45: =MEDIAN(F5, $B$38, $B$39) -> 2.54 | G45: =MEDIAN(G5, $B$38, $B$39) -> 1.34 | H45: =MEDIAN(H5, $B$38, $B$39) -> 2.63 | I45: =MEDIAN(I5, $B$38, $B$39) -> 2.51 | ... N45: =MEDIAN(N5, $B$38, $B$39) -> 4.6741375
B46: =MEDIAN(B6, $B$38, $B$39) -> 7.97 | C46: =MEDIAN(C6, $B$38, $B$39) -> 8.14 | D46: =MEDIAN(D6, $B$38, $B$39) -> 8.2 | E46: =MEDIAN(E6, $B$38, $B$39) -> 8.7525 | F46: =MEDIAN(F6, $B$38, $B$39) -> 8.7525 | G46: =MEDIAN(G6, $B$38, $B$39) -> 5.04 | H46: =MEDIAN(H6, $B$38, $B$39) -> 8.7525 | I46: =MEDIAN(I6, $B$38, $B$39) -> 7.57 | ... N46: =MEDIAN(N6, $B$38, $B$39) -> 4.6741375
B47: =MEDIAN(B7, $B$38, $B$39) -> 8.7525 | C47: =MEDIAN(C7, $B$38, $B$39) -> 7.27 | D47: =MEDIAN(D7, $B$38, $B$39) -> 4.02 | E47: =MEDIAN(E7, $B$38, $B$39) -> 3.34 | F47: =MEDIAN(F7, $B$38, $B$39) -> 2.16 | G47: =MEDIAN(G7, $B$38, $B$39) -> 1.4 | H47: =MEDIAN(H7, $B$38, $B$39) -> 1.87 | I47: =MEDIAN(I7, $B$38, $B$39) -> 3.33 | ... N47: =MEDIAN(N7, $B$38, $B$39) -> 4.6741375
B48: =MEDIAN(B8, $B$38, $B$39) -> 5.8 | C48: =MEDIAN(C8, $B$38, $B$39) -> 4.71 | D48: =MEDIAN(D8, $B$38, $B$39) -> 3.05 | E48: =MEDIAN(E8, $B$38, $B$39) -> 3.62 | F48: =MEDIAN(F8, $B$38, $B$39) -> 2.82 | G48: =MEDIAN(G8, $B$38, $B$39) -> 2.75 | H48: =MEDIAN(H8, $B$38, $B$39) -> 1.65 | I48: =MEDIAN(I8, $B$38, $B$39) -> 1.9 | ... N48: =MEDIAN(N8, $B$38, $B$39) -> 4.6741375
B49: =MEDIAN(B9, $B$38, $B$39) -> 3.69 | C49: =MEDIAN(C9, $B$38, $B$39) -> 3.81 | D49: =MEDIAN(D9, $B$38, $B$39) -> 2.91 | E49: =MEDIAN(E9, $B$38, $B$39) -> 3.69 | F49: =MEDIAN(F9, $B$38, $B$39) -> 3.54 | G49: =MEDIAN(G9, $B$38, $B$39) -> 1.68 | H49: =MEDIAN(H9, $B$38, $B$39) -> 2.44 | I49: =MEDIAN(I9, $B$38, $B$39) -> 2.66 | ... N49: =MEDIAN(N9, $B$38, $B$39) -> 4.6741375
B50: =MEDIAN(B10, $B$38, $B$39) -> 4.66 | C50: =MEDIAN(C10, $B$38, $B$39) -> 4.26 | D50: =MEDIAN(D10, $B$38, $B$39) -> 5.56 | E50: =MEDIAN(E10, $B$38, $B$39) -> 6.38 | F50: =MEDIAN(F10, $B$38, $B$39) -> 6.81 | G50: =MEDIAN(G10, $B$38, $B$39) -> 4.12 | H50: =MEDIAN(H10, $B$38, $B$39) -> 6.37 | I50: =MEDIAN(I10, $B$38, $B$39) -> 6.12 | ... N50: =MEDIAN(N10, $B$38, $B$39) -> 4.6741375
B51: =MEDIAN(B11, $B$38, $B$39) -> 8.41 | C51: =MEDIAN(C11, $B$38, $B$39) -> 8.61 | D51: =MEDIAN(D11, $B$38, $B$39) -> 8.7525 | E51: =MEDIAN(E11, $B$38, $B$39) -> 8.7525 | F51: =MEDIAN(F11, $B$38, $B$39) -> 8.7525 | G51: =MEDIAN(G11, $B$38, $B$39) -> 8.7525 | H51: =MEDIAN(H11, $B$38, $B$39) -> 8.7525 | I51: =MEDIAN(I11, $B$38, $B$39) -> 8.12 | ... N51: =MEDIAN(N11, $B$38, $B$39) -> 4.6741375
B52: =MEDIAN(B12, $B$38, $B$39) -> 5.15 | C52: =MEDIAN(C12, $B$38, $B$39) -> 4.82 | D52: =MEDIAN(D12, $B$38, $B$39) -> 5.06 | E52: =MEDIAN(E12, $B$38, $B$39) -> 5.32 | F52: =MEDIAN(F12, $B$38, $B$39) -> 4.51 | G52: =MEDIAN(G12, $B$38, $B$39) -> 2.48 | H52: =MEDIAN(H12, $B$38, $B$39) -> 3.57 | I52: =MEDIAN(I12, $B$38, $B$39) -> 2.88 | ... N52: =MEDIAN(N12, $B$38, $B$39) -> 4.6741375
B53: =MEDIAN(B13, $B$38, $B$39) -> 3.99 | C53: =MEDIAN(C13, $B$38, $B$39) -> 4.04 | D53: =MEDIAN(D13, $B$38, $B$39) -> 4.03 | E53: =MEDIAN(E13, $B$38, $B$39) -> 6.58 | F53: =MEDIAN(F13, $B$38, $B$39) -> 5.78 | G53: =MEDIAN(G13, $B$38, $B$39) -> 2.99 | H53: =MEDIAN(H13, $B$38, $B$39) -> 3.9 | I53: =MEDIAN(I13, $B$38, $B$39) -> 3.5 | ... N53: =MEDIAN(N13, $B$38, $B$39) -> 4.6741375
... B70: =MEDIAN(B30, $B$38, $B$39) -> 4.46 | C70: =MEDIAN(C30, $B$38, $B$39) -> 3.97 | D70: =MEDIAN(D30, $B$38, $B$39) -> 3.48 | E70: =MEDIAN(E30, $B$38, $B$39) -> 3.62 | F70: =MEDIAN(F30, $B$38, $B$39) -> 4.35 | G70: =MEDIAN(G30, $B$38, $B$39) -> 2.21 | H70: =MEDIAN(H30, $B$38, $B$39) -> 2.64 | I70: =MEDIAN(I30, $B$38, $B$39) -> 3.5 | ... N70: =MEDIAN(N30, $B$38, $B$39) -> 4.6741375

Sheet Normalized
B1: (P/S)2025 | C1: (P/S)2024 | D1: (P/S)2023 | E1: (P/S)2022 | F1: (P/S)2021 | G1: (P/S)2020 | H1: (P/S)2019 | I1: (P/S)2018 | J1: (P/S)2017 | K1: (P/S)2016 | L1: (P/S)2015 | M1: (P/S)2014 | P1: flattened
A2: Adani Ports and Special Economic Zone Ltd | B2: =(Sheet1!$B$35 - Sheet1!B2) / (Sheet1!$B$35 - Sheet1!$B$34) -> 0.065265351 | C2: =(Sheet1!$B$35 - Sheet1!C2) / (Sheet1!$B$35 - Sheet1!$B$34) -> 0 | D2: =(Sheet1!$B$35 - Sheet1!D2) / (Sheet1!$B$35 - Sheet1!$B$34) -> 0.2699473 | E2: =(Sheet1!$B$35 - Sheet1!E2) / (Sheet1!$B$35 - Sheet1!$B$34) -> 0 | F2: =(Sheet1!$B$35 - Sheet1!F2) / (Sheet1!$B$35 - Sheet1!$B$34) -> 0 | G2: =(Sheet1!$B$35 - Sheet1!G2) / (Sheet1!$B$35 - Sheet1!$B$34) -> 0.54571639 | H2: =(Sheet1!$B$35 - Sheet1!H2) / (Sheet1!$B$35 - Sheet1!$B$34) -> 0.19395759 | I2: =(Sheet1!$B$35 - Sheet1!I2) / (Sheet1!$B$35 - Sheet1!$B$34) -> 0.27730114 | ... M2: =(Sheet1!$B$35 - Sheet1!M2) / (Sheet1!$B$35 - Sheet1!$B$34) -> 0.086101238 | P2: =IFERROR(__xludf.DUMMYFUNCTION("FLATTEN(B2:M30)"),0.06526535114597364) -> 0.065265351
A3: Asian Paints Ltd | B3: =(Sheet1!$B$35 - Sheet1!B3) / (Sheet1!$B$35 - Sheet1!$B$34) -> 0.26259346 | C3: =(Sheet1!$B$35 - Sheet1!C3) / (Sheet1!$B$35 - Sheet1!$B$34) -> 0.13022429 | D3: =(Sheet1!$B$35 - Sheet1!D3) / (Sheet1!$B$35 - Sheet1!$B$34) -> 0.13144993 | E3: =(Sheet1!$B$35 - Sheet1!E3) / (Sheet1!$B$35 - Sheet1!$B$34) -> 0 | F3: =(Sheet1!$B$35 - Sheet1!F3) / (Sheet1!$B$35 - Sheet1!$B$34) -> 0 | G3: =(Sheet1!$B$35 - Sheet1!G3) / (Sheet1!$B$35 - Sheet1!$B$34) -> 0.1032602 | H3: =(Sheet1!$B$35 - Sheet1!H3) / (Sheet1!$B$35 - Sheet1!$B$34) -> 0.1608653 | I3: =(Sheet1!$B$35 - Sheet1!I3) / (Sheet1!$B$35 - Sheet1!$B$34) -> 0.28955754 | ... M3: =(Sheet1!$B$35 - Sheet1!M3) / (Sheet1!$B$35 - Sheet1!$B$34) -> 0.56777791 | P3: =IFERROR(__xludf.DUMMYFUNCTION("""COMPUTED_VALUE"""),0.0) -> 0
A4: AXIS Bank Ltd | B4: =(Sheet1!$B$35 - Sheet1!B4) / (Sheet1!$B$35 - Sheet1!$B$34) -> 0.74427013 | C4: =(Sheet1!$B$35 - Sheet1!C4) / (Sheet1!$B$35 - Sheet1!$B$34) -> 0.72098296 | D4: =(Sheet1!$B$35 - Sheet1!D4) / (Sheet1!$B$35 - Sheet1!$B$34) -> 0.70259836 | E4: =(Sheet1!$B$35 - Sheet1!E4) / (Sheet1!$B$35 - Sheet1!$B$34) -> 0.65724966 | F4: =(Sheet1!$B$35 - Sheet1!F4) / (Sheet1!$B$35 - Sheet1!$B$34) -> 0.66828043 | G4: =(Sheet1!$B$35 - Sheet1!G4) / (Sheet1!$B$35 - Sheet1!$B$34) -> 0.86683417 | H4: =(Sheet1!$B$35 - Sheet1!H4) / (Sheet1!$B$35 - Sheet1!$B$34) -> 0.63641378 | I4: =(Sheet1!$B$35 - Sheet1!I4) / (Sheet1!$B$35 - Sheet1!$B$34) -> 0.72956245 | ... M4: =(Sheet1!$B$35 - Sheet1!M4) / (Sheet1!$B$35 - Sheet1!$B$34) -> 0.79942395 | P4: =IFERROR(__xludf.DUMMYFUNCTION("""COMPUTED_VALUE"""),0.2699472974629244) -> 0.2699473
A5: Bajaj Finserv Ltd | B5: =(Sheet1!$B$35 - Sheet1!B5) / (Sheet1!$B$35 - Sheet1!$B$34) -> 0.7798137 | C5: =(Sheet1!$B$35 - Sheet1!C5) / (Sheet1!$B$35 - Sheet1!$B$34) -> 0.78226498 | D5: =(Sheet1!$B$35 - Sheet1!D5) / (Sheet1!$B$35 - Sheet1!$B$34) -> 0.77123422 | E5: =(Sheet1!$B$35 - Sheet1!E5) / (Sheet1!$B$35 - Sheet1!$B$34) -> 0.58616252 | F5: =(Sheet1!$B$35 - Sheet1!F5) / (Sheet1!$B$35 - Sheet1!$B$34) -> 0.7614291 | G5: =(Sheet1!$B$35 - Sheet1!G5) / (Sheet1!$B$35 - Sheet1!$B$34) -> 0.90850594 | H5: =(Sheet1!$B$35 - Sheet1!H5) / (Sheet1!$B$35 - Sheet1!$B$34) -> 0.75039833 | I5: =(Sheet1!$B$35 - Sheet1!I5) / (Sheet1!$B$35 - Sheet1!$B$34) -> 0.76510602 | ... M5: =(Sheet1!$B$35 - Sheet1!M5) / (Sheet1!$B$35 - Sheet1!$B$34) -> 0.81658291 | P5: =IFERROR(__xludf.DUMMYFUNCTION("""COMPUTED_VALUE"""),0.0) -> 0
A6: Bajaj Finance Ltd | B6: =(Sheet1!$B$35 - Sheet1!B6) / (Sheet1!$B$35 - Sheet1!$B$34) -> 0.095906361 | C6: =(Sheet1!$B$35 - Sheet1!C6) / (Sheet1!$B$35 - Sheet1!$B$34) -> 0.075070474 | D6: =(Sheet1!$B$35 - Sheet1!D6) / (Sheet1!$B$35 - Sheet1!$B$34) -> 0.067716632 | E6: =(Sheet1!$B$35 - Sheet1!E6) / (Sheet1!$B$35 - Sheet1!$B$34) -> 0 | F6: =(Sheet1!$B$35 - Sheet1!F6) / (Sheet1!$B$35 - Sheet1!$B$34) -> 0 | G6: =(Sheet1!$B$35 - Sheet1!G6) / (Sheet1!$B$35 - Sheet1!$B$34) -> 0.455019 | H6: =(Sheet1!$B$35 - Sheet1!H6) / (Sheet1!$B$35 - Sheet1!$B$34) -> 0 | I6: =(Sheet1!$B$35 - Sheet1!I6) / (Sheet1!$B$35 - Sheet1!$B$34) -> 0.14493198 | ... M6: =(Sheet1!$B$35 - Sheet1!M6) / (Sheet1!$B$35 - Sheet1!$B$34) -> 0.82148548 | P6: =IFERROR(__xludf.DUMMYFUNCTION("""COMPUTED_VALUE"""),0.0) -> 0
A7: Bharat Electronics Ltd | B7: =(Sheet1!$B$35 - Sheet1!B7) / (Sheet1!$B$35 - Sheet1!$B$34) -> 0 | C7: =(Sheet1!$B$35 - Sheet1!C7) / (Sheet1!$B$35 - Sheet1!$B$34) -> 0.18170119 | D7: =(Sheet1!$B$35 - Sheet1!D7) / (Sheet1!$B$35 - Sheet1!$B$34) -> 0.58003432 | E7: =(Sheet1!$B$35 - Sheet1!E7) / (Sheet1!$B$35 - Sheet1!$B$34) -> 0.66337786 | F7: =(Sheet1!$B$35 - Sheet1!F7) / (Sheet1!$B$35 - Sheet1!$B$34) -> 0.80800343 | G7: =(Sheet1!$B$35 - Sheet1!G7) / (Sheet1!$B$35 - Sheet1!$B$34) -> 0.9011521 | H7: =(Sheet1!$B$35 - Sheet1!H7) / (Sheet1!$B$35 - Sheet1!$B$34) -> 0.843547 | I7: =(Sheet1!$B$35 - Sheet1!I7) / (Sheet1!$B$35 - Sheet1!$B$34) -> 0.66460351 | ... M7: =(Sheet1!$B$35 - Sheet1!M7) / (Sheet1!$B$35 - Sheet1!$B$34) -> 0.9011521 | P7: =IFERROR(__xludf.DUMMYFUNCTION("""COMPUTED_VALUE"""),0.5457163868121093) -> 0.54571639
A8: Bharti Airtel Ltd | B8: =(Sheet1!$B$35 - Sheet1!B8) / (Sheet1!$B$35 - Sheet1!$B$34) -> 0.36187033 | C8: =(Sheet1!$B$35 - Sheet1!C8) / (Sheet1!$B$35 - Sheet1!$B$34) -> 0.49546513 | D8: =(Sheet1!$B$35 - Sheet1!D8) / (Sheet1!$B$35 - Sheet1!$B$34) -> 0.69892144 | E8: =(Sheet1!$B$35 - Sheet1!E8) / (Sheet1!$B$35 - Sheet1!$B$34) -> 0.62905993 | F8: =(Sheet1!$B$35 - Sheet1!F8) / (Sheet1!$B$35 - Sheet1!$B$34) -> 0.72711117 | G8: =(Sheet1!$B$35 - Sheet1!G8) / (Sheet1!$B$35 - Sheet1!$B$34) -> 0.73569065 | H8: =(Sheet1!$B$35 - Sheet1!H8) / (Sheet1!$B$35 - Sheet1!$B$34) -> 0.87051109 | I8: =(Sheet1!$B$35 - Sheet1!I8) / (Sheet1!$B$35 - Sheet1!$B$34) -> 0.83987008 | ... M8: =(Sheet1!$B$35 - Sheet1!M8) / (Sheet1!$B$35 - Sheet1!$B$34) -> 0.89379826 | P8: =IFERROR(__xludf.DUMMYFUNCTION("""COMPUTED_VALUE"""),0.19395759284226005) -> 0.19395759
A9: HCL Technologies Ltd | B9: =(Sheet1!$B$35 - Sheet1!B9) / (Sheet1!$B$35 - Sheet1!$B$34) -> 0.62048045 | C9: =(Sheet1!$B$35 - Sheet1!C9) / (Sheet1!$B$35 - Sheet1!$B$34) -> 0.60577277 | D9: =(Sheet1!$B$35 - Sheet1!D9) / (Sheet1!$B$35 - Sheet1!$B$34) -> 0.7160804 | E9: =(Sheet1!$B$35 - Sheet1!E9) / (Sheet1!$B$35 - Sheet1!$B$34) -> 0.62048045 | F9: =(Sheet1!$B$35 - Sheet1!F9) / (Sheet1!$B$35 - Sheet1!$B$34) -> 0.63886506 | G9: =(Sheet1!$B$35 - Sheet1!G9) / (Sheet1!$B$35 - Sheet1!$B$34) -> 0.86683417 | H9: =(Sheet1!$B$35 - Sheet1!H9) / (Sheet1!$B$35 - Sheet1!$B$34) -> 0.7736855 | I9: =(Sheet1!$B$35 - Sheet1!I9) / (Sheet1!$B$35 - Sheet1!$B$34) -> 0.74672141 | ... M9: =(Sheet1!$B$35 - Sheet1!M9) / (Sheet1!$B$35 - Sheet1!$B$34) -> 0.67318299 | P9: =IFERROR(__xludf.DUMMYFUNCTION("""COMPUTED_VALUE"""),0.27730113984556926) -> 0.27730114
A10: HDFC Bank Ltd | B10: =(Sheet1!$B$35 - Sheet1!B10) / (Sheet1!$B$35 - Sheet1!$B$34) -> 0.50159333 | C10: =(Sheet1!$B$35 - Sheet1!C10) / (Sheet1!$B$35 - Sheet1!$B$34) -> 0.55061895 | D10: =(Sheet1!$B$35 - Sheet1!D10) / (Sheet1!$B$35 - Sheet1!$B$34) -> 0.3912857 | E10: =(Sheet1!$B$35 - Sheet1!E10) / (Sheet1!$B$35 - Sheet1!$B$34) -> 0.29078318 | F10: =(Sheet1!$B$35 - Sheet1!F10) / (Sheet1!$B$35 - Sheet1!$B$34) -> 0.23808065 | G10: =(Sheet1!$B$35 - Sheet1!G10) / (Sheet1!$B$35 - Sheet1!$B$34) -> 0.56777791 | H10: =(Sheet1!$B$35 - Sheet1!H10) / (Sheet1!$B$35 - Sheet1!$B$34) -> 0.29200882 | I10: =(Sheet1!$B$35 - Sheet1!I10) / (Sheet1!$B$35 - Sheet1!$B$34) -> 0.32264983 | ... M10: =(Sheet1!$B$35 - Sheet1!M10) / (Sheet1!$B$35 - Sheet1!$B$34) -> 0.5371369 | P10: =IFERROR(__xludf.DUMMYFUNCTION("""COMPUTED_VALUE"""),0.05055766638068387) -> 0.050557666
A11: Hindustan Unilever Ltd | B11: =(Sheet1!$B$35 - Sheet1!B11) / (Sheet1!$B$35 - Sheet1!$B$34) -> 0.041978184 | C11: =(Sheet1!$B$35 - Sheet1!C11) / (Sheet1!$B$35 - Sheet1!$B$34) -> 0.017465376 | D11: =(Sheet1!$B$35 - Sheet1!D11) / (Sheet1!$B$35 - Sheet1!$B$34) -> 0 | E11: =(Sheet1!$B$35 - Sheet1!E11) / (Sheet1!$B$35 - Sheet1!$B$34) -> 0 | F11: =(Sheet1!$B$35 - Sheet1!F11) / (Sheet1!$B$35 - Sheet1!$B$34) -> 0 | G11: =(Sheet1!$B$35 - Sheet1!G11) / (Sheet1!$B$35 - Sheet1!$B$34) -> 0 | H11: =(Sheet1!$B$35 - Sheet1!H11) / (Sheet1!$B$35 - Sheet1!$B$34) -> 0 | I11: =(Sheet1!$B$35 - Sheet1!I11) / (Sheet1!$B$35 - Sheet1!$B$34) -> 0.077521755 | ... M11: =(Sheet1!$B$35 - Sheet1!M11) / (Sheet1!$B$35 - Sheet1!$B$34) -> 0.5248805 | P11: =IFERROR(__xludf.DUMMYFUNCTION("""COMPUTED_VALUE"""),0.18782939085672262) -> 0.18782939
A12: ICICI Bank Ltd | B12: =(Sheet1!$B$35 - Sheet1!B12) / (Sheet1!$B$35 - Sheet1!$B$34) -> 0.44153695 | C12: =(Sheet1!$B$35 - Sheet1!C12) / (Sheet1!$B$35 - Sheet1!$B$34) -> 0.48198309 | D12: =(Sheet1!$B$35 - Sheet1!D12) / (Sheet1!$B$35 - Sheet1!$B$34) -> 0.45256772 | E12: =(Sheet1!$B$35 - Sheet1!E12) / (Sheet1!$B$35 - Sheet1!$B$34) -> 0.42070107 | F12: =(Sheet1!$B$35 - Sheet1!F12) / (Sheet1!$B$35 - Sheet1!$B$34) -> 0.51997794 | G12: =(Sheet1!$B$35 - Sheet1!G12) / (Sheet1!$B$35 - Sheet1!$B$34) -> 0.76878294 | H12: =(Sheet1!$B$35 - Sheet1!H12) / (Sheet1!$B$35 - Sheet1!$B$34) -> 0.63518814 | I12: =(Sheet1!$B$35 - Sheet1!I12) / (Sheet1!$B$35 - Sheet1!$B$34) -> 0.71975732 | ... M12: =(Sheet1!$B$35 - Sheet1!M12) / (Sheet1!$B$35 - Sheet1!$B$34) -> 0.7160804 | P12: =IFERROR(__xludf.DUMMYFUNCTION("""COMPUTED_VALUE"""),0.0) -> 0
A13: Infosys Ltd | B13: =(Sheet1!$B$35 - Sheet1!B13) / (Sheet1!$B$35 - Sheet1!$B$34) -> 0.58371124 | C13: =(Sheet1!$B$35 - Sheet1!C13) / (Sheet1!$B$35 - Sheet1!$B$34) -> 0.57758304 | D13: =(Sheet1!$B$35 - Sheet1!D13) / (Sheet1!$B$35 - Sheet1!$B$34) -> 0.57880868 | E13: =(Sheet1!$B$35 - Sheet1!E13) / (Sheet1!$B$35 - Sheet1!$B$34) -> 0.26627038 | F13: =(Sheet1!$B$35 - Sheet1!F13) / (Sheet1!$B$35 - Sheet1!$B$34) -> 0.36432161 | G13: =(Sheet1!$B$35 - Sheet1!G13) / (Sheet1!$B$35 - Sheet1!$B$34) -> 0.70627528 | H13: =(Sheet1!$B$35 - Sheet1!H13) / (Sheet1!$B$35 - Sheet1!$B$34) -> 0.594742 | I13: =(Sheet1!$B$35 - Sheet1!I13) / (Sheet1!$B$35 - Sheet1!$B$34) -> 0.64376762 | ... M13: =(Sheet1!$B$35 - Sheet1!M13) / (Sheet1!$B$35 - Sheet1!$B$34) -> 0.61435225 | P13: =IFERROR(__xludf.DUMMYFUNCTION("""COMPUTED_VALUE"""),0.08610123789680094) -> 0.086101238
A14: ITC Ltd | B14: =(Sheet1!$B$35 - Sheet1!B14) / (Sheet1!$B$35 - Sheet1!$B$34) -> 0.23808065 | C14: =(Sheet1!$B$35 - Sheet1!C14) / (Sheet1!$B$35 - Sheet1!$B$34) -> 0.14738326 | D14: =(Sheet1!$B$35 - Sheet1!D14) / (Sheet1!$B$35 - Sheet1!$B$34) -> 0.24911141 | E14: =(Sheet1!$B$35 - Sheet1!E14) / (Sheet1!$B$35 - Sheet1!$B$34) -> 0.4488908 | F14: =(Sheet1!$B$35 - Sheet1!F14) / (Sheet1!$B$35 - Sheet1!$B$34) -> 0.4035421 | G14: =(Sheet1!$B$35 - Sheet1!G14) / (Sheet1!$B$35 - Sheet1!$B$34) -> 0.54816767 | H14: =(Sheet1!$B$35 - Sheet1!H14) / (Sheet1!$B$35 - Sheet1!$B$34) -> 0.15106018 | I14: =(Sheet1!$B$35 - Sheet1!I14) / (Sheet1!$B$35 - Sheet1!$B$34) -> 0.19150631 | ... M14: =(Sheet1!$B$35 - Sheet1!M14) / (Sheet1!$B$35 - Sheet1!$B$34) -> 0.098357642 | P14: =IFERROR(__xludf.DUMMYFUNCTION("""COMPUTED_VALUE"""),0.26259345508027937) -> 0.26259346
A15: Kotak Mahindra Bank Ltd | B15: =(Sheet1!$B$35 - Sheet1!B15) / (Sheet1!$B$35 - Sheet1!$B$34) -> 0.26749602 | C15: =(Sheet1!$B$35 - Sheet1!C15) / (Sheet1!$B$35 - Sheet1!$B$34) -> 0.29936267 | D15: =(Sheet1!$B$35 - Sheet1!D15) / (Sheet1!$B$35 - Sheet1!$B$34) -> 0.071393553 | E15: =(Sheet1!$B$35 - Sheet1!E15) / (Sheet1!$B$35 - Sheet1!$B$34) -> 0 | F15: =(Sheet1!$B$35 - Sheet1!F15) / (Sheet1!$B$35 - Sheet1!$B$34) -> 0 | G15: =(Sheet1!$B$35 - Sheet1!G15) / (Sheet1!$B$35 - Sheet1!$B$34) -> 0.16454222 | H15: =(Sheet1!$B$35 - Sheet1!H15) / (Sheet1!$B$35 - Sheet1!$B$34) -> 0.028496139 | I15: =(Sheet1!$B$35 - Sheet1!I15) / (Sheet1!$B$35 - Sheet1!$B$34) -> 0.098357642 | ... M15: =(Sheet1!$B$35 - Sheet1!M15) / (Sheet1!$B$35 - Sheet1!$B$34) -> 0.45992156 | P15: =IFERROR(__xludf.DUMMYFUNCTION("""COMPUTED_VALUE"""),0.13022429219267057) -> 0.13022429
A16: Larsen & Toubro Ltd | B16: =(Sheet1!$B$35 - Sheet1!B16) / (Sheet1!$B$35 - Sheet1!$B$34) -> 0.84232136 | C16: =(Sheet1!$B$35 - Sheet1!C16) / (Sheet1!$B$35 - Sheet1!$B$34) -> 0.78471626 | D16: =(Sheet1!$B$35 - Sheet1!D16) / (Sheet1!$B$35 - Sheet1!$B$34) -> 0.86928545 | E16: =(Sheet1!$B$35 - Sheet1!E16) / (Sheet1!$B$35 - Sheet1!$B$34) -> 0.87786493 | F16: =(Sheet1!$B$35 - Sheet1!F16) / (Sheet1!$B$35 - Sheet1!$B$34) -> 0.89257262 | G16: =(Sheet1!$B$35 - Sheet1!G16) / (Sheet1!$B$35 - Sheet1!$B$34) -> 0.97714181 | H16: =(Sheet1!$B$35 - Sheet1!H16) / (Sheet1!$B$35 - Sheet1!$B$34) -> 0.89624954 | I16: =(Sheet1!$B$35 - Sheet1!I16) / (Sheet1!$B$35 - Sheet1!$B$34) -> 0.88399314 | ... M16: =(Sheet1!$B$35 - Sheet1!M16) / (Sheet1!$B$35 - Sheet1!$B$34) -> 0.90237774 | P16: =IFERROR(__xludf.DUMMYFUNCTION("""COMPUTED_VALUE"""),0.13144993258977816) -> 0.13144993
A17: Mahindra & Mahindra Ltd | B17: =(Sheet1!$B$35 - Sheet1!B17) / (Sheet1!$B$35 - Sheet1!$B$34) -> 0.843547 | C17: =(Sheet1!$B$35 - Sheet1!C17) / (Sheet1!$B$35 - Sheet1!$B$34) -> 0.8827675 | D17: =(Sheet1!$B$35 - Sheet1!D17) / (Sheet1!$B$35 - Sheet1!$B$34) -> 0.94282388 | E17: =(Sheet1!$B$35 - Sheet1!E17) / (Sheet1!$B$35 - Sheet1!$B$34) -> 0.95140336 | F17: =(Sheet1!$B$35 - Sheet1!F17) / (Sheet1!$B$35 - Sheet1!$B$34) -> 0.92689055 | G17: =(Sheet1!$B$35 - Sheet1!G17) / (Sheet1!$B$35 - Sheet1!$B$34) -> 1 | H17: =(Sheet1!$B$35 - Sheet1!H17) / (Sheet1!$B$35 - Sheet1!$B$34) -> 0.98694693 | I17: =(Sheet1!$B$35 - Sheet1!I17) / (Sheet1!$B$35 - Sheet1!$B$34) -> 0.96611104 | ... M17: =(Sheet1!$B$35 - Sheet1!M17) / (Sheet1!$B$35 - Sheet1!$B$34) -> 0.97714181 | P17: =IFERROR(__xludf.DUMMYFUNCTION("""COMPUTED_VALUE"""),0.0) -> 0
A18: Maruti Suzuki India Ltd | B18: =(Sheet1!$B$35 - Sheet1!B18) / (Sheet1!$B$35 - Sheet1!$B$34) -> 0.78226498 | C18: =(Sheet1!$B$35 - Sheet1!C18) / (Sheet1!$B$35 - Sheet1!$B$34) -> 0.72956245 | D18: =(Sheet1!$B$35 - Sheet1!D18) / (Sheet1!$B$35 - Sheet1!$B$34) -> 0.81168035 | E18: =(Sheet1!$B$35 - Sheet1!E18) / (Sheet1!$B$35 - Sheet1!$B$34) -> 0.75652654 | F18: =(Sheet1!$B$35 - Sheet1!F18) / (Sheet1!$B$35 - Sheet1!$B$34) -> 0.71240348 | G18: =(Sheet1!$B$35 - Sheet1!G18) / (Sheet1!$B$35 - Sheet1!$B$34) -> 0.86315725 | H18: =(Sheet1!$B$35 - Sheet1!H18) / (Sheet1!$B$35 - Sheet1!$B$34) -> 0.7859419 | I18: =(Sheet1!$B$35 - Sheet1!I18) / (Sheet1!$B$35 - Sheet1!$B$34) -> 0.66215222 | ... M18: =(Sheet1!$B$35 - Sheet1!M18) / (Sheet1!$B$35 - Sheet1!$B$34) -> 0.90850594 | P18: =IFERROR(__xludf.DUMMYFUNCTION("""COMPUTED_VALUE"""),0.0) -> 0
A19: NTPC Ltd | B19: =(Sheet1!$B$35 - Sheet1!B19) / (Sheet1!$B$35 - Sheet1!$B$34) -> 0.84722392 | C19: =(Sheet1!$B$35 - Sheet1!C19) / (Sheet1!$B$35 - Sheet1!$B$34) -> 0.84967521 | D19: =(Sheet1!$B$35 - Sheet1!D19) / (Sheet1!$B$35 - Sheet1!$B$34) -> 0.95508028 | E19: =(Sheet1!$B$35 - Sheet1!E19) / (Sheet1!$B$35 - Sheet1!$B$34) -> 0.95140336 | F19: =(Sheet1!$B$35 - Sheet1!F19) / (Sheet1!$B$35 - Sheet1!$B$34) -> 0.9587572 | G19: =(Sheet1!$B$35 - Sheet1!G19) / (Sheet1!$B$35 - Sheet1!$B$34) -> 0.97959309 | H19: =(Sheet1!$B$35 - Sheet1!H19) / (Sheet1!$B$35 - Sheet1!$B$34) -> 0.90850594 | I19: =(Sheet1!$B$35 - Sheet1!I19) / (Sheet1!$B$35 - Sheet1!$B$34) -> 0.87786493 | ... M19: =(Sheet1!$B$35 - Sheet1!M19) / (Sheet1!$B$35 - Sheet1!$B$34) -> 0.91953671 | P19: =IFERROR(__xludf.DUMMYFUNCTION("""COMPUTED_VALUE"""),0.10326020345630585) -> 0.1032602
A20: Power Grid Corporation of India Ltd | B20: =(Sheet1!$B$35 - Sheet1!B20) / (Sheet1!$B$35 - Sheet1!$B$34) -> 0.34961392 | C20: =(Sheet1!$B$35 - Sheet1!C20) / (Sheet1!$B$35 - Sheet1!$B$34) -> 0.38393185 | D20: =(Sheet1!$B$35 - Sheet1!D20) / (Sheet1!$B$35 - Sheet1!$B$34) -> 0.64989582 | E20: =(Sheet1!$B$35 - Sheet1!E20) / (Sheet1!$B$35 - Sheet1!$B$34) -> 0.62783429 | F20: =(Sheet1!$B$35 - Sheet1!F20) / (Sheet1!$B$35 - Sheet1!$B$34) -> 0.72343424 | G20: =(Sheet1!$B$35 - Sheet1!G20) / (Sheet1!$B$35 - Sheet1!$B$34) -> 0.80310087 | H20: =(Sheet1!$B$35 - Sheet1!H20) / (Sheet1!$B$35 - Sheet1!$B$34) -> 0.7099522 | I20: =(Sheet1!$B$35 - Sheet1!I20) / (Sheet1!$B$35 - Sheet1!$B$34) -> 0.65724966 | ... M20: =(Sheet1!$B$35 - Sheet1!M20) / (Sheet1!$B$35 - Sheet1!$B$34) -> 0.64254198 | P20: =IFERROR(__xludf.DUMMYFUNCTION("""COMPUTED_VALUE"""),0.1608653021203578) -> 0.1608653
A21: Reliance Industries Ltd | B21: =(Sheet1!$B$35 - Sheet1!B21) / (Sheet1!$B$35 - Sheet1!$B$34) -> 0.85335213 | C21: =(Sheet1!$B$35 - Sheet1!C21) / (Sheet1!$B$35 - Sheet1!$B$34) -> 0.79819831 | D21: =(Sheet1!$B$35 - Sheet1!D21) / (Sheet1!$B$35 - Sheet1!$B$34) -> 0.85212649 | E21: =(Sheet1!$B$35 - Sheet1!E21) / (Sheet1!$B$35 - Sheet1!$B$34) -> 0.76020346 | F21: =(Sheet1!$B$35 - Sheet1!F21) / (Sheet1!$B$35 - Sheet1!$B$34) -> 0.73323937 | G21: =(Sheet1!$B$35 - Sheet1!G21) / (Sheet1!$B$35 - Sheet1!$B$34) -> 0.92811619 | H21: =(Sheet1!$B$35 - Sheet1!H21) / (Sheet1!$B$35 - Sheet1!$B$34) -> 0.89870082 | I21: =(Sheet1!$B$35 - Sheet1!I21) / (Sheet1!$B$35 - Sheet1!$B$34) -> 0.90973158 | ... M21: =(Sheet1!$B$35 - Sheet1!M21) / (Sheet1!$B$35 - Sheet1!$B$34) -> 0.99552641 | P21: =IFERROR(__xludf.DUMMYFUNCTION("""COMPUTED_VALUE"""),0.2895575438166442) -> 0.28955754
A22: State Bank of India | B22: =(Sheet1!$B$35 - Sheet1!B22) / (Sheet1!$B$35 - Sheet1!$B$34) -> 0.9011521 | C22: =(Sheet1!$B$35 - Sheet1!C22) / (Sheet1!$B$35 - Sheet1!$B$34) -> 0.88521878 | D22: =(Sheet1!$B$35 - Sheet1!D22) / (Sheet1!$B$35 - Sheet1!$B$34) -> 0.90973158 | E22: =(Sheet1!$B$35 - Sheet1!E22) / (Sheet1!$B$35 - Sheet1!$B$34) -> 0.88644442 | F22: =(Sheet1!$B$35 - Sheet1!F22) / (Sheet1!$B$35 - Sheet1!$B$34) -> 0.92934183 | G22: =(Sheet1!$B$35 - Sheet1!G22) / (Sheet1!$B$35 - Sheet1!$B$34) -> 0.99307513 | H22: =(Sheet1!$B$35 - Sheet1!H22) / (Sheet1!$B$35 - Sheet1!$B$34) -> 0.93424439 | I22: =(Sheet1!$B$35 - Sheet1!I22) / (Sheet1!$B$35 - Sheet1!$B$34) -> 0.95385464 | ... M22: =(Sheet1!$B$35 - Sheet1!M22) / (Sheet1!$B$35 - Sheet1!$B$34) -> 0.97959309 | P22: =IFERROR(__xludf.DUMMYFUNCTION("""COMPUTED_VALUE"""),0.2368550067410221) -> 0.23685501
A23: Sun Pharmaceutical Industries Ltd | B23: =(Sheet1!$B$35 - Sheet1!B23) / (Sheet1!$B$35 - Sheet1!$B$34) -> 0.10203456 | C23: =(Sheet1!$B$35 - Sheet1!C23) / (Sheet1!$B$35 - Sheet1!$B$34) -> 0.089778159 | D23: =(Sheet1!$B$35 - Sheet1!D23) / (Sheet1!$B$35 - Sheet1!$B$34) -> 0.41457286 | E23: =(Sheet1!$B$35 - Sheet1!E23) / (Sheet1!$B$35 - Sheet1!$B$34) -> 0.37657801 | F23: =(Sheet1!$B$35 - Sheet1!F23) / (Sheet1!$B$35 - Sheet1!$B$34) -> 0.54816767 | G23: =(Sheet1!$B$35 - Sheet1!G23) / (Sheet1!$B$35 - Sheet1!$B$34) -> 0.75775218 | H23: =(Sheet1!$B$35 - Sheet1!H23) / (Sheet1!$B$35 - Sheet1!$B$34) -> 0.58738816 | I23: =(Sheet1!$B$35 - Sheet1!I23) / (Sheet1!$B$35 - Sheet1!$B$34) -> 0.52120358 | ... M23: =(Sheet1!$B$35 - Sheet1!M23) / (Sheet1!$B$35 - Sheet1!$B$34) -> 0.16821914 | P23: =IFERROR(__xludf.DUMMYFUNCTION("""COMPUTED_VALUE"""),0.35696776565755606) -> 0.35696777
A24: Tata Motors Ltd | B24: =(Sheet1!$B$35 - Sheet1!B24) / (Sheet1!$B$35 - Sheet1!$B$34) -> 1 | C24: =(Sheet1!$B$35 - Sheet1!C24) / (Sheet1!$B$35 - Sheet1!$B$34) -> 0.96611104 | D24: =(Sheet1!$B$35 - Sheet1!D24) / (Sheet1!$B$35 - Sheet1!$B$34) -> 1 | E24: =(Sheet1!$B$35 - Sheet1!E24) / (Sheet1!$B$35 - Sheet1!$B$34) -> 0.99920333 | F24: =(Sheet1!$B$35 - Sheet1!F24) / (Sheet1!$B$35 - Sheet1!$B$34) -> 1 | G24: =(Sheet1!$B$35 - Sheet1!G24) / (Sheet1!$B$35 - Sheet1!$B$34) -> 1 | H24: =(Sheet1!$B$35 - Sheet1!H24) / (Sheet1!$B$35 - Sheet1!$B$34) -> 1 | I24: =(Sheet1!$B$35 - Sheet1!I24) / (Sheet1!$B$35 - Sheet1!$B$34) -> 1 | ... M24: =(Sheet1!$B$35 - Sheet1!M24) / (Sheet1!$B$35 - Sheet1!$B$34) -> 1 | P24: =IFERROR(__xludf.DUMMYFUNCTION("""COMPUTED_VALUE"""),0.4023164603505332) -> 0.40231646
A25: Tata Steel Ltd | B25: =(Sheet1!$B$35 - Sheet1!B25) / (Sheet1!$B$35 - Sheet1!$B$34) -> 0.9648854 | C25: =(Sheet1!$B$35 - Sheet1!C25) / (Sheet1!$B$35 - Sheet1!$B$34) -> 0.96856232 | D25: =(Sheet1!$B$35 - Sheet1!D25) / (Sheet1!$B$35 - Sheet1!$B$34) -> 1 | E25: =(Sheet1!$B$35 - Sheet1!E25) / (Sheet1!$B$35 - Sheet1!$B$34) -> 0.99307513 | F25: =(Sheet1!$B$35 - Sheet1!F25) / (Sheet1!$B$35 - Sheet1!$B$34) -> 0.99675205 | G25: =(Sheet1!$B$35 - Sheet1!G25) / (Sheet1!$B$35 - Sheet1!$B$34) -> 1 | H25: =(Sheet1!$B$35 - Sheet1!H25) / (Sheet1!$B$35 - Sheet1!$B$34) -> 1 | I25: =(Sheet1!$B$35 - Sheet1!I25) / (Sheet1!$B$35 - Sheet1!$B$34) -> 1 | ... M25: =(Sheet1!$B$35 - Sheet1!M25) / (Sheet1!$B$35 - Sheet1!$B$34) -> 1 | P25: =IFERROR(__xludf.DUMMYFUNCTION("""COMPUTED_VALUE"""),0.5677779139600442) -> 0.56777791
A26: Tata Consultancy Services Ltd | B26: =(Sheet1!$B$35 - Sheet1!B26) / (Sheet1!$B$35 - Sheet1!$B$34) -> 0.44643951 | C26: =(Sheet1!$B$35 - Sheet1!C26) / (Sheet1!$B$35 - Sheet1!$B$34) -> 0.35696777 | D26: =(Sheet1!$B$35 - Sheet1!D26) / (Sheet1!$B$35 - Sheet1!$B$34) -> 0.43540875 | E26: =(Sheet1!$B$35 - Sheet1!E26) / (Sheet1!$B$35 - Sheet1!$B$34) -> 0.19763451 | F26: =(Sheet1!$B$35 - Sheet1!F26) / (Sheet1!$B$35 - Sheet1!$B$34) -> 0.19518323 | G26: =(Sheet1!$B$35 - Sheet1!G26) / (Sheet1!$B$35 - Sheet1!$B$34) -> 0.53836254 | H26: =(Sheet1!$B$35 - Sheet1!H26) / (Sheet1!$B$35 - Sheet1!$B$34) -> 0.44521387 | I26: =(Sheet1!$B$35 - Sheet1!I26) / (Sheet1!$B$35 - Sheet1!$B$34) -> 0.5310087 | ... M26: =(Sheet1!$B$35 - Sheet1!M26) / (Sheet1!$B$35 - Sheet1!$B$34) -> 0.44766515 | P26: =IFERROR(__xludf.DUMMYFUNCTION("""COMPUTED_VALUE"""),0.7442701311435226) -> 0.74427013
A27: Tech Mahindra Ltd | B27: =(Sheet1!$B$35 - Sheet1!B27) / (Sheet1!$B$35 - Sheet1!$B$34) -> 0.78226498 | C27: =(Sheet1!$B$35 - Sheet1!C27) / (Sheet1!$B$35 - Sheet1!$B$34) -> 0.81290599 | D27: =(Sheet1!$B$35 - Sheet1!D27) / (Sheet1!$B$35 - Sheet1!$B$34) -> 0.84967521 | E27: =(Sheet1!$B$35 - Sheet1!E27) / (Sheet1!$B$35 - Sheet1!$B$34) -> 0.71117784 | F27: =(Sheet1!$B$35 - Sheet1!F27) / (Sheet1!$B$35 - Sheet1!$B$34) -> 0.79207011 | G27: =(Sheet1!$B$35 - Sheet1!G27) / (Sheet1!$B$35 - Sheet1!$B$34) -> 0.90850594 | H27: =(Sheet1!$B$35 - Sheet1!H27) / (Sheet1!$B$35 - Sheet1!$B$34) -> 0.83006496 | I27: =(Sheet1!$B$35 - Sheet1!I27) / (Sheet1!$B$35 - Sheet1!$B$34) -> 0.84844956 | ... M27: =(Sheet1!$B$35 - Sheet1!M27) / (Sheet1!$B$35 - Sheet1!$B$34) -> 0.79942395 | P27: =IFERROR(__xludf.DUMMYFUNCTION("""COMPUTED_VALUE"""),0.7209829635984802) -> 0.72098296
A28: Titan Company Ltd | B28: =(Sheet1!$B$35 - Sheet1!B28) / (Sheet1!$B$35 - Sheet1!$B$34) -> 0.51997794 | C28: =(Sheet1!$B$35 - Sheet1!C28) / (Sheet1!$B$35 - Sheet1!$B$34) -> 0.26014217 | D28: =(Sheet1!$B$35 - Sheet1!D28) / (Sheet1!$B$35 - Sheet1!$B$34) -> 0.39618826 | E28: =(Sheet1!$B$35 - Sheet1!E28) / (Sheet1!$B$35 - Sheet1!$B$34) -> 0.11183969 | F28: =(Sheet1!$B$35 - Sheet1!F28) / (Sheet1!$B$35 - Sheet1!$B$34) -> 0.2883319 | G28: =(Sheet1!$B$35 - Sheet1!G28) / (Sheet1!$B$35 - Sheet1!$B$34) -> 0.58983944 | H28: =(Sheet1!$B$35 - Sheet1!H28) / (Sheet1!$B$35 - Sheet1!$B$34) -> 0.44643951 | I28: =(Sheet1!$B$35 - Sheet1!I28) / (Sheet1!$B$35 - Sheet1!$B$34) -> 0.43786003 | ... M28: =(Sheet1!$B$35 - Sheet1!M28) / (Sheet1!$B$35 - Sheet1!$B$34) -> 0.81168035 | P28: =IFERROR(__xludf.DUMMYFUNCTION("""COMPUTED_VALUE"""),0.702598357641868) -> 0.70259836
A29: Trent Ltd | B29: =(Sheet1!$B$35 - Sheet1!B29) / (Sheet1!$B$35 - Sheet1!$B$34) -> 0 | C29: =(Sheet1!$B$35 - Sheet1!C29) / (Sheet1!$B$35 - Sheet1!$B$34) -> 0 | D29: =(Sheet1!$B$35 - Sheet1!D29) / (Sheet1!$B$35 - Sheet1!$B$34) -> 0.345937 | E29: =(Sheet1!$B$35 - Sheet1!E29) / (Sheet1!$B$35 - Sheet1!$B$34) -> 0 | F29: =(Sheet1!$B$35 - Sheet1!F29) / (Sheet1!$B$35 - Sheet1!$B$34) -> 0 | G29: =(Sheet1!$B$35 - Sheet1!G29) / (Sheet1!$B$35 - Sheet1!$B$34) -> 0.4734036 | H29: =(Sheet1!$B$35 - Sheet1!H29) / (Sheet1!$B$35 - Sheet1!$B$34) -> 0.51507538 | I29: =(Sheet1!$B$35 - Sheet1!I29) / (Sheet1!$B$35 - Sheet1!$B$34) -> 0.41947543 | ... M29: =(Sheet1!$B$35 - Sheet1!M29) / (Sheet1!$B$35 - Sheet1!$B$34) -> 0.89624954 | P29: =IFERROR(__xludf.DUMMYFUNCTION("""COMPUTED_VALUE"""),0.6572496629488908) -> 0.65724966
A30: UltraTech Cement Ltd | B30: =(Sheet1!$B$35 - Sheet1!B30) / (Sheet1!$B$35 - Sheet1!$B$34) -> 0.52610614 | C30: =(Sheet1!$B$35 - Sheet1!C30) / (Sheet1!$B$35 - Sheet1!$B$34) -> 0.58616252 | D30: =(Sheet1!$B$35 - Sheet1!D30) / (Sheet1!$B$35 - Sheet1!$B$34) -> 0.6462189 | E30: =(Sheet1!$B$35 - Sheet1!E30) / (Sheet1!$B$35 - Sheet1!$B$34) -> 0.62905993 | F30: =(Sheet1!$B$35 - Sheet1!F30) / (Sheet1!$B$35 - Sheet1!$B$34) -> 0.53958818 | G30: =(Sheet1!$B$35 - Sheet1!G30) / (Sheet1!$B$35 - Sheet1!$B$34) -> 0.80187523 | H30: =(Sheet1!$B$35 - Sheet1!H30) / (Sheet1!$B$35 - Sheet1!$B$34) -> 0.74917269 | I30: =(Sheet1!$B$35 - Sheet1!I30) / (Sheet1!$B$35 - Sheet1!$B$34) -> 0.64376762 | ... M30: =(Sheet1!$B$35 - Sheet1!M30) / (Sheet1!$B$35 - Sheet1!$B$34) -> 0.73323937 | P30: =IFERROR(__xludf.DUMMYFUNCTION("""COMPUTED_VALUE"""),0.6682804265228582) -> 0.66828043
P31: =IFERROR(__xludf.DUMMYFUNCTION("""COMPUTED_VALUE"""),0.8668341708542714) -> 0.86683417
P32: =IFERROR(__xludf.DUMMYFUNCTION("""COMPUTED_VALUE"""),0.6364137761980635) -> 0.63641378
P33: =IFERROR(__xludf.DUMMYFUNCTION("""COMPUTED_VALUE"""),0.7295624463782326) -> 0.72956245
A34: Global min | B34: =MIN(B2:N30) -> 0 | P34: =IFERROR(__xludf.DUMMYFUNCTION("""COMPUTED_VALUE"""),0.7540752543203825) -> 0.75407525
A35: Global Max | B35: =MAX(B2:N30) -> 1 | P35: =IFERROR(__xludf.DUMMYFUNCTION("""COMPUTED_VALUE"""),0.7589778159088123) -> 0.75897782
P36: =IFERROR(__xludf.DUMMYFUNCTION("""COMPUTED_VALUE"""),0.6168035298443436) -> 0.61680353
P37: =IFERROR(__xludf.DUMMYFUNCTION("""COMPUTED_VALUE"""),0.7994239490133594) -> 0.79942395
P38: =IFERROR(__xludf.DUMMYFUNCTION("""COMPUTED_VALUE"""),0.7798137026596397) -> 0.7798137
P39: =IFERROR(__xludf.DUMMYFUNCTION("""COMPUTED_VALUE"""),0.7822649834538546) -> 0.78226498
P40: =IFERROR(__xludf.DUMMYFUNCTION("""COMPUTED_VALUE"""),0.7712342198798873) -> 0.77123422
...
