Workbook

Sheet Sheet1
B1: 2025 | C1: 2024 | D1: 2023 | E1: 2022 | F1: 2021 | G1: 2020 | H1: 2019 | I1: 2018 | J1: 2017 | K1: 2016 | L1: 2015 | M1: 2014
A2: Adani Ports and Special Economic Zone Ltd | B2: 51.35 | C2: 37.55 | D2: 24.58 | E2: 22.39 | F2: 24.58 | G2: 18.35 | H2: 19.27 | I2: 17.74 | J2: 18.89 | K2: 13.99 | L2: 11.18 | M2: 8.45
A3: Asian Paints Ltd | B3: 38.25 | C3: 56.94 | D3: 42.82 | E3: 31.59 | F3: 32.73 | G3: 28.2 | H3: 22.48 | I3: 21.26 | J3: 20.22 | K3: 18.19 | L3: 14.54 | M3: 12.71
A4: AXIS Bank Ltd | B4: 90.18 | C4: 85.01 | D4: 35.04 | E4: 45.91 | F4: 24.19 | G4: 6.8 | H4: 19.49 | I4: 2.1015 | J4: 16.48 | K4: 34.93 | L4: 31.23 | M4: 134.2
A5: Bajaj Finserv Ltd | B5: 9.7 | C5: 7.3 | D5: 4.6 | E5: 26.6 | F5: 11.2 | G5: 41.9 | H5: 19.3 | I5: 8.9 | J5: 4.4 | K5: 10.3 | L5: 7.9 | M5: 5.2
A6: Bajaj Finance Ltd | B6: 187.439 | C6: 187.439 | D6: 187.439 | E6: 115.79 | F6: 73 | G6: 89.07 | H6: 68.75 | I6: 47.05 | J6: 33.67 | K6: 187.439 | L6: 177.7 | M6: 143.65
A7: Bharat Electronics Ltd | B7: 7.28 | C7: 5.45 | D7: 4.09 | E7: 9.85 | F7: 8.62 | G7: 7.49 | H7: 7.74 | I7: 5.83 | J7: 5.94 | K7: 5.57 | L7: 149.65 | M7: 118.91
A8: Bharti Airtel Ltd | B8: 56.04 | C8: 12.8 | D8: 14.57 | E8: 7.63 | F8: 2.1015 | G8: 2.1015 | H8: 2.1015 | I8: 2.75 | J8: 9.51 | K8: 15.2 | L8: 11.56 | M8: 7.01
A9: HCL Technologies Ltd | B9: 64.09 | C9: 57.86 | D9: 54.79 | E9: 49.77 | F9: 41.07 | G9: 40.75 | H9: 73.55 | I9: 62.19 | J9: 60.27 | K9: 39.69 | L9: 51.79 | M9: 91.93
A10: HDFC Bank Ltd | B10: 92.39 | C10: 90.01 | D10: 82.27 | E10: 68.31 | F10: 57.61 | G10: 49.46 | H10: 82.51 | I10: 70.76 | J10: 59.16 | K10: 50.24 | L10: 43.6 | M10: 36.31
A11: Hindustan Unilever Ltd | B11: 45.32 | C11: 43.74 | D11: 43.07 | E11: 37.79 | F11: 34.03 | G11: 31.17 | H11: 27.96 | I11: 24.08 | J11: 20.67 | K11: 19.09 | L11: 20.16 | M11: 18.23
A12: ICICI Bank Ltd | B12: 71.14 | C12: 61.96 | D12: 47.84 | E12: 35.44 | F12: 26.83 | G12: 14.55 | H12: 6.53 | I12: 11.89 | J12: 15.84 | K12: 17.41 | L12: 21.17 | M12: 95.65
A13: Infosys Ltd | B13: 64.34 | C13: 63.39 | D13: 57.54 | E13: 52.41 | F13: 45.52 | G13: 38.91 | H13: 35.38 | I13: 71 | J13: 62.77 | K13: 59.02 | L13: 108.26 | M13: 186.49
... A30: UltraTech Cement Ltd | B30: 187.439 | C30: 187.439 | D30: 175.54 | E30: 187.439 | F30: 187.439 | G30: 187.439 | H30: 84 | I30: 80.92 | J30: 98.88 | K30: 90.25 | L30: 76.44 | M30: 80.42
A34: Global min | B34: =MIN(B2:N30) -> 2.1015
A35: Global Max | B35: =MAX(B2:N30) -> 187.439
A37: percentile min | B37: =PERCENTILE(B2:M30, 0.05) -> 2.258475
A38: percentile max | B38: =PERCENTILE(B2:M30, 0.95) -> 187.10685

Sheet Normalized
B1: 2025 | C1: 2024 | D1: 2023 | E1: 2022 | F1: 2021 | G1: 2020 | H1: 2019 | I1: 2018 | J1: 2017 | K1: 2016 | L1: 2015 | M1: 2014 | P1: flattened
A2: Adani Ports and Special Economic Zone Ltd | B2: =(Sheet1!B2 - Sheet1!$B$34) / (Sheet1!$B$35 - Sheet1!$B$34) -> 0.26572334 | C2: =(Sheet1!C2 - Sheet1!$B$34) / (Sheet1!$B$35 - Sheet1!$B$34) -> 0.19126458 | D2: =(Sheet1!D2 - Sheet1!$B$34) / (Sheet1!$B$35 - Sheet1!$B$34) -> 0.12128414 | E2: =(Sheet1!E2 - Sheet1!$B$34) / (Sheet1!$B$35 - Sheet1!$B$34) -> 0.10946786 | F2: =(Sheet1!F2 - Sheet1!$B$34) / (Sheet1!$B$35 - Sheet1!$B$34) -> 0.12128414 | G2: =(Sheet1!G2 - Sheet1!$B$34) / (Sheet1!$B$35 - Sheet1!$B$34) -> 0.087669792 | H2: =(Sheet1!H2 - Sheet1!$B$34) / (Sheet1!$B$35 - Sheet1!$B$34) -> 0.092633709 | I2: =(Sheet1!I2 - Sheet1!$B$34) / (Sheet1!$B$35 - Sheet1!$B$34) -> 0.084378499 | ... M2: =(Sheet1!M2 - Sheet1!$B$34) / (Sheet1!$B$35 - Sheet1!$B$34) -> 0.034253726 | P2: =IFERROR(__xludf.DUMMYFUNCTION("FLATTEN(B2:M30)"),0.26572334255075203) -> 0.26572334
A3: Asian Paints Ltd | B3: =(Sheet1!B3 - Sheet1!$B$34) / (Sheet1!$B$35 - Sheet1!$B$34) -> 0.19504148 | C3: =(Sheet1!C3 - Sheet1!$B$34) / (Sheet1!$B$35 - Sheet1!$B$34) -> 0.29588454 | D3: =(Sheet1!D3 - Sheet1!$B$34) / (Sheet1!$B$35 - Sheet1!$B$34) -> 0.2196992 | E3: =(Sheet1!E3 - Sheet1!$B$34) / (Sheet1!$B$35 - Sheet1!$B$34) -> 0.15910703 | F3: =(Sheet1!F3 - Sheet1!$B$34) / (Sheet1!$B$35 - Sheet1!$B$34) -> 0.16525798 | G3: =(Sheet1!G3 - Sheet1!$B$34) / (Sheet1!$B$35 - Sheet1!$B$34) -> 0.14081608 | H3: =(Sheet1!H3 - Sheet1!$B$34) / (Sheet1!$B$35 - Sheet1!$B$34) -> 0.10995346 | I3: =(Sheet1!I3 - Sheet1!$B$34) / (Sheet1!$B$35 - Sheet1!$B$34) -> 0.10337088 | ... M3: =(Sheet1!M3 - Sheet1!$B$34) / (Sheet1!$B$35 - Sheet1!$B$34) -> 0.057238821 | P3: =IFERROR(__xludf.DUMMYFUNCTION("""COMPUTED_VALUE"""),0.19126458487893708) -> 0.19126458
A4: AXIS Bank Ltd | B4: =(Sheet1!B4 - Sheet1!$B$34) / (Sheet1!$B$35 - Sheet1!$B$34) -> 0.47523302 | C4: =(Sheet1!C4 - Sheet1!$B$34) / (Sheet1!$B$35 - Sheet1!$B$34) -> 0.44733796 | D4: =(Sheet1!D4 - Sheet1!$B$34) / (Sheet1!$B$35 - Sheet1!$B$34) -> 0.17772172 | E4: =(Sheet1!E4 - Sheet1!$B$34) / (Sheet1!$B$35 - Sheet1!$B$34) -> 0.23637148 | F4: =(Sheet1!F4 - Sheet1!$B$34) / (Sheet1!$B$35 - Sheet1!$B$34) -> 0.11917987 | G4: =(Sheet1!G4 - Sheet1!$B$34) / (Sheet1!$B$35 - Sheet1!$B$34) -> 0.025351049 | H4: =(Sheet1!H4 - Sheet1!$B$34) / (Sheet1!$B$35 - Sheet1!$B$34) -> 0.093820732 | I4: =(Sheet1!I4 - Sheet1!$B$34) / (Sheet1!$B$35 - Sheet1!$B$34) -> 0 | ... M4: =(Sheet1!M4 - Sheet1!$B$34) / (Sheet1!$B$35 - Sheet1!$B$34) -> 0.71274567 | P4: =IFERROR(__xludf.DUMMYFUNCTION("""COMPUTED_VALUE"""),0.1212841437917313) -> 0.12128414
A5: Bajaj Finserv Ltd | B5: =(Sheet1!B5 - Sheet1!$B$34) / (Sheet1!$B$35 - Sheet1!$B$34) -> 0.040998179 | C5: =(Sheet1!C5 - Sheet1!$B$34) / (Sheet1!$B$35 - Sheet1!$B$34) -> 0.02804883 | D5: =(Sheet1!D5 - Sheet1!$B$34) / (Sheet1!$B$35 - Sheet1!$B$34) -> 0.013480812 | E5: =(Sheet1!E5 - Sheet1!$B$34) / (Sheet1!$B$35 - Sheet1!$B$34) -> 0.13218318 | F5: =(Sheet1!F5 - Sheet1!$B$34) / (Sheet1!$B$35 - Sheet1!$B$34) -> 0.049091522 | G5: =(Sheet1!G5 - Sheet1!$B$34) / (Sheet1!$B$35 - Sheet1!$B$34) -> 0.21473528 | H5: =(Sheet1!H5 - Sheet1!$B$34) / (Sheet1!$B$35 - Sheet1!$B$34) -> 0.092795576 | I5: =(Sheet1!I5 - Sheet1!$B$34) / (Sheet1!$B$35 - Sheet1!$B$34) -> 0.036681729 | ... M5: =(Sheet1!M5 - Sheet1!$B$34) / (Sheet1!$B$35 - Sheet1!$B$34) -> 0.016718149 | P5: =IFERROR(__xludf.DUMMYFUNCTION("""COMPUTED_VALUE"""),0.10946786268294328) -> 0.10946786
A6: Bajaj Finance Ltd | B6: =(Sheet1!B6 - Sheet1!$B$34) / (Sheet1!$B$35 - Sheet1!$B$34) -> 1 | C6: =(Sheet1!C6 - Sheet1!$B$34) / (Sheet1!$B$35 - Sheet1!$B$34) -> 1 | D6: =(Sheet1!D6 - Sheet1!$B$34) / (Sheet1!$B$35 - Sheet1!$B$34) -> 1 | E6: =(Sheet1!E6 - Sheet1!$B$34) / (Sheet1!$B$35 - Sheet1!$B$34) -> 0.61341337 | F6: =(Sheet1!F6 - Sheet1!$B$34) / (Sheet1!$B$35 - Sheet1!$B$34) -> 0.38253726 | G6: =(Sheet1!G6 - Sheet1!$B$34) / (Sheet1!$B$35 - Sheet1!$B$34) -> 0.46924395 | H6: =(Sheet1!H6 - Sheet1!$B$34) / (Sheet1!$B$35 - Sheet1!$B$34) -> 0.35960612 | I6: =(Sheet1!I6 - Sheet1!$B$34) / (Sheet1!$B$35 - Sheet1!$B$34) -> 0.24252243 | ... M6: =(Sheet1!M6 - Sheet1!$B$34) / (Sheet1!$B$35 - Sheet1!$B$34) -> 0.76373373 | P6: =IFERROR(__xludf.DUMMYFUNCTION("""COMPUTED_VALUE"""),0.1212841437917313) -> 0.12128414
A7: Bharat Electronics Ltd | B7: =(Sheet1!B7 - Sheet1!$B$34) / (Sheet1!$B$35 - Sheet1!$B$34) -> 0.027940919 | C7: =(Sheet1!C7 - Sheet1!$B$34) / (Sheet1!$B$35 - Sheet1!$B$34) -> 0.01806704 | D7: =(Sheet1!D7 - Sheet1!$B$34) / (Sheet1!$B$35 - Sheet1!$B$34) -> 0.010729075 | E7: =(Sheet1!E7 - Sheet1!$B$34) / (Sheet1!$B$35 - Sheet1!$B$34) -> 0.041807513 | F7: =(Sheet1!F7 - Sheet1!$B$34) / (Sheet1!$B$35 - Sheet1!$B$34) -> 0.035170972 | G7: =(Sheet1!G7 - Sheet1!$B$34) / (Sheet1!$B$35 - Sheet1!$B$34) -> 0.029073987 | H7: =(Sheet1!H7 - Sheet1!$B$34) / (Sheet1!$B$35 - Sheet1!$B$34) -> 0.030422877 | I7: =(Sheet1!I7 - Sheet1!$B$34) / (Sheet1!$B$35 - Sheet1!$B$34) -> 0.020117353 | ... M7: =(Sheet1!M7 - Sheet1!$B$34) / (Sheet1!$B$35 - Sheet1!$B$34) -> 0.63024752 | P7: =IFERROR(__xludf.DUMMYFUNCTION("""COMPUTED_VALUE"""),0.08766979159641196) -> 0.087669792
A8: Bharti Airtel Ltd | B8: =(Sheet1!B8 - Sheet1!$B$34) / (Sheet1!$B$35 - Sheet1!$B$34) -> 0.29102853 | C8: =(Sheet1!C8 - Sheet1!$B$34) / (Sheet1!$B$35 - Sheet1!$B$34) -> 0.057724422 | D8: =(Sheet1!D8 - Sheet1!$B$34) / (Sheet1!$B$35 - Sheet1!$B$34) -> 0.067274567 | E8: =(Sheet1!E8 - Sheet1!$B$34) / (Sheet1!$B$35 - Sheet1!$B$34) -> 0.029829365 | F8: =(Sheet1!F8 - Sheet1!$B$34) / (Sheet1!$B$35 - Sheet1!$B$34) -> 0 | G8: =(Sheet1!G8 - Sheet1!$B$34) / (Sheet1!$B$35 - Sheet1!$B$34) -> 0 | H8: =(Sheet1!H8 - Sheet1!$B$34) / (Sheet1!$B$35 - Sheet1!$B$34) -> 0 | I8: =(Sheet1!I8 - Sheet1!$B$34) / (Sheet1!$B$35 - Sheet1!$B$34) -> 0.0034990221 | ... M8: =(Sheet1!M8 - Sheet1!$B$34) / (Sheet1!$B$35 - Sheet1!$B$34) -> 0.026484117 | P8: =IFERROR(__xludf.DUMMYFUNCTION("""COMPUTED_VALUE"""),0.09263370877453295) -> 0.092633709
A9: HCL Technologies Ltd | B9: =(Sheet1!B9 - Sheet1!$B$34) / (Sheet1!$B$35 - Sheet1!$B$34) -> 0.3344628 | C9: =(Sheet1!C9 - Sheet1!$B$34) / (Sheet1!$B$35 - Sheet1!$B$34) -> 0.30084845 | D9: =(Sheet1!D9 - Sheet1!$B$34) / (Sheet1!$B$35 - Sheet1!$B$34) -> 0.28428408 | E9: =(Sheet1!E9 - Sheet1!$B$34) / (Sheet1!$B$35 - Sheet1!$B$34) -> 0.25719835 | F9: =(Sheet1!F9 - Sheet1!$B$34) / (Sheet1!$B$35 - Sheet1!$B$34) -> 0.21025696 | G9: =(Sheet1!G9 - Sheet1!$B$34) / (Sheet1!$B$35 - Sheet1!$B$34) -> 0.20853038 | H9: =(Sheet1!H9 - Sheet1!$B$34) / (Sheet1!$B$35 - Sheet1!$B$34) -> 0.38550482 | I9: =(Sheet1!I9 - Sheet1!$B$34) / (Sheet1!$B$35 - Sheet1!$B$34) -> 0.32421124 | ... M9: =(Sheet1!M9 - Sheet1!$B$34) / (Sheet1!$B$35 - Sheet1!$B$34) -> 0.48467525 | P9: =IFERROR(__xludf.DUMMYFUNCTION("""COMPUTED_VALUE"""),0.08437849868483172) -> 0.084378499
A10: HDFC Bank Ltd | B10: =(Sheet1!B10 - Sheet1!$B$34) / (Sheet1!$B$35 - Sheet1!$B$34) -> 0.48715721 | C10: =(Sheet1!C10 - Sheet1!$B$34) / (Sheet1!$B$35 - Sheet1!$B$34) -> 0.47431578 | D10: =(Sheet1!D10 - Sheet1!$B$34) / (Sheet1!$B$35 - Sheet1!$B$34) -> 0.43255412 | E10: =(Sheet1!E10 - Sheet1!$B$34) / (Sheet1!$B$35 - Sheet1!$B$34) -> 0.35723208 | F10: =(Sheet1!F10 - Sheet1!$B$34) / (Sheet1!$B$35 - Sheet1!$B$34) -> 0.29949956 | G10: =(Sheet1!G10 - Sheet1!$B$34) / (Sheet1!$B$35 - Sheet1!$B$34) -> 0.25552573 | H10: =(Sheet1!H10 - Sheet1!$B$34) / (Sheet1!$B$35 - Sheet1!$B$34) -> 0.43384906 | I10: =(Sheet1!I10 - Sheet1!$B$34) / (Sheet1!$B$35 - Sheet1!$B$34) -> 0.3704512 | ... M10: =(Sheet1!M10 - Sheet1!$B$34) / (Sheet1!$B$35 - Sheet1!$B$34) -> 0.18457409 | P10: =IFERROR(__xludf.DUMMYFUNCTION("""COMPUTED_VALUE"""),0.09058339515748298) -> 0.090583395
A11: Hindustan Unilever Ltd | B11: =(Sheet1!B11 - Sheet1!$B$34) / (Sheet1!$B$35 - Sheet1!$B$34) -> 0.2331881 | C11: =(Sheet1!C11 - Sheet1!$B$34) / (Sheet1!$B$35 - Sheet1!$B$34) -> 0.22466311 | D11: =(Sheet1!D11 - Sheet1!$B$34) / (Sheet1!$B$35 - Sheet1!$B$34) -> 0.22104809 | E11: =(Sheet1!E11 - Sheet1!$B$34) / (Sheet1!$B$35 - Sheet1!$B$34) -> 0.19255952 | F11: =(Sheet1!F11 - Sheet1!$B$34) / (Sheet1!$B$35 - Sheet1!$B$34) -> 0.17227221 | G11: =(Sheet1!G11 - Sheet1!$B$34) / (Sheet1!$B$35 - Sheet1!$B$34) -> 0.1568409 | H11: =(Sheet1!H11 - Sheet1!$B$34) / (Sheet1!$B$35 - Sheet1!$B$34) -> 0.13952114 | I11: =(Sheet1!I11 - Sheet1!$B$34) / (Sheet1!$B$35 - Sheet1!$B$34) -> 0.11858636 | ... M11: =(Sheet1!M11 - Sheet1!$B$34) / (Sheet1!$B$35 - Sheet1!$B$34) -> 0.087022324 | P11: =IFERROR(__xludf.DUMMYFUNCTION("""COMPUTED_VALUE"""),0.06414514062183854) -> 0.064145141
A12: ICICI Bank Ltd | B12: =(Sheet1!B12 - Sheet1!$B$34) / (Sheet1!$B$35 - Sheet1!$B$34) -> 0.37250152 | C12: =(Sheet1!C12 - Sheet1!$B$34) / (Sheet1!$B$35 - Sheet1!$B$34) -> 0.32297026 | D12: =(Sheet1!D12 - Sheet1!$B$34) / (Sheet1!$B$35 - Sheet1!$B$34) -> 0.24678492 | E12: =(Sheet1!E12 - Sheet1!$B$34) / (Sheet1!$B$35 - Sheet1!$B$34) -> 0.17987995 | F12: =(Sheet1!F12 - Sheet1!$B$34) / (Sheet1!$B$35 - Sheet1!$B$34) -> 0.13342416 | G12: =(Sheet1!G12 - Sheet1!$B$34) / (Sheet1!$B$35 - Sheet1!$B$34) -> 0.067166655 | H12: =(Sheet1!H12 - Sheet1!$B$34) / (Sheet1!$B$35 - Sheet1!$B$34) -> 0.023894247 | I12: =(Sheet1!I12 - Sheet1!$B$34) / (Sheet1!$B$35 - Sheet1!$B$34) -> 0.05281446 | ... M12: =(Sheet1!M12 - Sheet1!$B$34) / (Sheet1!$B$35 - Sheet1!$B$34) -> 0.50474675 | P12: =IFERROR(__xludf.DUMMYFUNCTION("""COMPUTED_VALUE"""),0.04898361097996897) -> 0.048983611
A13: Infosys Ltd | B13: =(Sheet1!B13 - Sheet1!$B$34) / (Sheet1!$B$35 - Sheet1!$B$34) -> 0.33581169 | C13: =(Sheet1!C13 - Sheet1!$B$34) / (Sheet1!$B$35 - Sheet1!$B$34) -> 0.33068591 | D13: =(Sheet1!D13 - Sheet1!$B$34) / (Sheet1!$B$35 - Sheet1!$B$34) -> 0.29912187 | E13: =(Sheet1!E13 - Sheet1!$B$34) / (Sheet1!$B$35 - Sheet1!$B$34) -> 0.27144264 | F13: =(Sheet1!F13 - Sheet1!$B$34) / (Sheet1!$B$35 - Sheet1!$B$34) -> 0.23426722 | G13: =(Sheet1!G13 - Sheet1!$B$34) / (Sheet1!$B$35 - Sheet1!$B$34) -> 0.19860255 | H13: =(Sheet1!H13 - Sheet1!$B$34) / (Sheet1!$B$35 - Sheet1!$B$34) -> 0.17955621 | I13: =(Sheet1!I13 - Sheet1!$B$34) / (Sheet1!$B$35 - Sheet1!$B$34) -> 0.37174614 | ... M13: =(Sheet1!M13 - Sheet1!$B$34) / (Sheet1!$B$35 - Sheet1!$B$34) -> 0.99487961 | P13: =IFERROR(__xludf.DUMMYFUNCTION("""COMPUTED_VALUE"""),0.03425372631010993) -> 0.034253726
A14: ITC Ltd | B14: =(Sheet1!B14 - Sheet1!$B$34) / (Sheet1!$B$35 - Sheet1!$B$34) -> 0.13838808 | C14: =(Sheet1!C14 - Sheet1!$B$34) / (Sheet1!$B$35 - Sheet1!$B$34) -> 0.077040534 | D14: =(Sheet1!D14 - Sheet1!$B$34) / (Sheet1!$B$35 - Sheet1!$B$34) -> 0.072076617 | E14: =(Sheet1!E14 - Sheet1!$B$34) / (Sheet1!$B$35 - Sheet1!$B$34) -> 0.05540433 | F14: =(Sheet1!F14 - Sheet1!$B$34) / (Sheet1!$B$35 - Sheet1!$B$34) -> 0.046393741 | G14: =(Sheet1!G14 - Sheet1!$B$34) / (Sheet1!$B$35 - Sheet1!$B$34) -> 0.055835975 | H14: =(Sheet1!H14 - Sheet1!$B$34) / (Sheet1!$B$35 - Sheet1!$B$34) -> 0.043911783 | I14: =(Sheet1!I14 - Sheet1!$B$34) / (Sheet1!$B$35 - Sheet1!$B$34) -> 0.038300398 | ... M14: =(Sheet1!M14 - Sheet1!$B$34) / (Sheet1!$B$35 - Sheet1!$B$34) -> 0.04849801 | P14: =IFERROR(__xludf.DUMMYFUNCTION("""COMPUTED_VALUE"""),0.19504147838402916) -> 0.19504148
A15: Kotak Mahindra Bank Ltd | B15: =(Sheet1!B15 - Sheet1!$B$34) / (Sheet1!$B$35 - Sheet1!$B$34) -> 0.58913334 | C15: =(Sheet1!C15 - Sheet1!$B$34) / (Sheet1!$B$35 - Sheet1!$B$34) -> 0.48208538 | D15: =(Sheet1!D15 - Sheet1!$B$34) / (Sheet1!$B$35 - Sheet1!$B$34) -> 0.39300465 | E15: =(Sheet1!E15 - Sheet1!$B$34) / (Sheet1!$B$35 - Sheet1!$B$34) -> 0.31633372 | F15: =(Sheet1!F15 - Sheet1!$B$34) / (Sheet1!$B$35 - Sheet1!$B$34) -> 0.26108316 | G15: =(Sheet1!G15 - Sheet1!$B$34) / (Sheet1!$B$35 - Sheet1!$B$34) -> 0.22973494 | H15: =(Sheet1!H15 - Sheet1!$B$34) / (Sheet1!$B$35 - Sheet1!$B$34) -> 0.19228974 | I15: =(Sheet1!I15 - Sheet1!$B$34) / (Sheet1!$B$35 - Sheet1!$B$34) -> 0.16488029 | ... M15: =(Sheet1!M15 - Sheet1!$B$34) / (Sheet1!$B$35 - Sheet1!$B$34) -> 0.16207459 | P15: =IFERROR(__xludf.DUMMYFUNCTION("""COMPUTED_VALUE"""),0.2958845349699872) -> 0.29588454
A16: Larsen & Toubro Ltd | B16: =(Sheet1!B16 - Sheet1!$B$34) / (Sheet1!$B$35 - Sheet1!$B$34) -> 0.57828826 | C16: =(Sheet1!C16 - Sheet1!$B$34) / (Sheet1!$B$35 - Sheet1!$B$34) -> 0.4951966 | D16: =(Sheet1!D16 - Sheet1!$B$34) / (Sheet1!$B$35 - Sheet1!$B$34) -> 0.39036083 | E16: =(Sheet1!E16 - Sheet1!$B$34) / (Sheet1!$B$35 - Sheet1!$B$34) -> 0.32129763 | F16: =(Sheet1!F16 - Sheet1!$B$34) / (Sheet1!$B$35 - Sheet1!$B$34) -> 0.4333095 | G16: =(Sheet1!G16 - Sheet1!$B$34) / (Sheet1!$B$35 - Sheet1!$B$34) -> 0.35528967 | H16: =(Sheet1!H16 - Sheet1!$B$34) / (Sheet1!$B$35 - Sheet1!$B$34) -> 0.33073987 | I16: =(Sheet1!I16 - Sheet1!$B$34) / (Sheet1!$B$35 - Sheet1!$B$34) -> 0.27187428 | ... M16: =(Sheet1!M16 - Sheet1!$B$34) / (Sheet1!$B$35 - Sheet1!$B$34) -> 0.27273757 | P16: =IFERROR(__xludf.DUMMYFUNCTION("""COMPUTED_VALUE"""),0.2196991974101302) -> 0.2196992
A17: Mahindra & Mahindra Ltd | B17: =(Sheet1!B17 - Sheet1!$B$34) / (Sheet1!$B$35 - Sheet1!$B$34) -> 0.60947461 | C17: =(Sheet1!C17 - Sheet1!$B$34) / (Sheet1!$B$35 - Sheet1!$B$34) -> 0.53199433 | D17: =(Sheet1!D17 - Sheet1!$B$34) / (Sheet1!$B$35 - Sheet1!$B$34) -> 0.48483712 | E17: =(Sheet1!E17 - Sheet1!$B$34) / (Sheet1!$B$35 - Sheet1!$B$34) -> 0.30608215 | F17: =(Sheet1!F17 - Sheet1!$B$34) / (Sheet1!$B$35 - Sheet1!$B$34) -> 0.075799555 | G17: =(Sheet1!G17 - Sheet1!$B$34) / (Sheet1!$B$35 - Sheet1!$B$34) -> 0 | H17: =(Sheet1!H17 - Sheet1!$B$34) / (Sheet1!$B$35 - Sheet1!$B$34) -> 0.2514251 | I17: =(Sheet1!I17 - Sheet1!$B$34) / (Sheet1!$B$35 - Sheet1!$B$34) -> 0.36019964 | ... M17: =(Sheet1!M17 - Sheet1!$B$34) / (Sheet1!$B$35 - Sheet1!$B$34) -> 0.3978067 | P17: =IFERROR(__xludf.DUMMYFUNCTION("""COMPUTED_VALUE"""),0.15910703446415325) -> 0.15910703
A18: Maruti Suzuki India Ltd | B18: =(Sheet1!B18 - Sheet1!$B$34) / (Sheet1!$B$35 - Sheet1!$B$34) -> 1 | C18: =(Sheet1!C18 - Sheet1!$B$34) / (Sheet1!$B$35 - Sheet1!$B$34) -> 1 | D18: =(Sheet1!D18 - Sheet1!$B$34) / (Sheet1!$B$35 - Sheet1!$B$34) -> 1 | E18: =(Sheet1!E18 - Sheet1!$B$34) / (Sheet1!$B$35 - Sheet1!$B$34) -> 0.68161327 | F18: =(Sheet1!F18 - Sheet1!$B$34) / (Sheet1!$B$35 - Sheet1!$B$34) -> 0.77263641 | G18: =(Sheet1!G18 - Sheet1!$B$34) / (Sheet1!$B$35 - Sheet1!$B$34) -> 1 | H18: =(Sheet1!H18 - Sheet1!$B$34) / (Sheet1!$B$35 - Sheet1!$B$34) -> 1 | I18: =(Sheet1!I18 - Sheet1!$B$34) / (Sheet1!$B$35 - Sheet1!$B$34) -> 1 | ... M18: =(Sheet1!M18 - Sheet1!$B$34) / (Sheet1!$B$35 - Sheet1!$B$34) -> 0.49821812 | P18: =IFERROR(__xludf.DUMMYFUNCTION("""COMPUTED_VALUE"""),0.16525797531530315) -> 0.16525798
A19: NTPC Ltd | B19: =(Sheet1!B19 - Sheet1!$B$34) / (Sheet1!$B$35 - Sheet1!$B$34) -> 0.09840696 | C19: =(Sheet1!C19 - Sheet1!$B$34) / (Sheet1!$B$35 - Sheet1!$B$34) -> 0.10444999 | D19: =(Sheet1!D19 - Sheet1!$B$34) / (Sheet1!$B$35 - Sheet1!$B$34) -> 0.085079922 | E19: =(Sheet1!E19 - Sheet1!$B$34) / (Sheet1!$B$35 - Sheet1!$B$34) -> 0.073155729 | F19: =(Sheet1!F19 - Sheet1!$B$34) / (Sheet1!$B$35 - Sheet1!$B$34) -> 0.068893235 | G19: =(Sheet1!G19 - Sheet1!$B$34) / (Sheet1!$B$35 - Sheet1!$B$34) -> 0.051897215 | H19: =(Sheet1!H19 - Sheet1!$B$34) / (Sheet1!$B$35 - Sheet1!$B$34) -> 0.063551629 | I19: =(Sheet1!I19 - Sheet1!$B$34) / (Sheet1!$B$35 - Sheet1!$B$34) -> 0.046177919 | ... M19: =(Sheet1!M19 - Sheet1!$B$34) / (Sheet1!$B$35 - Sheet1!$B$34) -> 0.063281851 | P19: =IFERROR(__xludf.DUMMYFUNCTION("""COMPUTED_VALUE"""),0.1408160787752074) -> 0.14081608
A20: Power Grid Corporation of India Ltd | B20: =(Sheet1!B20 - Sheet1!$B$34) / (Sheet1!$B$35 - Sheet1!$B$34) -> 0.078713158 | C20: =(Sheet1!C20 - Sheet1!$B$34) / (Sheet1!$B$35 - Sheet1!$B$34) -> 0.082328185 | D20: =(Sheet1!D20 - Sheet1!$B$34) / (Sheet1!$B$35 - Sheet1!$B$34) -> 0.10790315 | E20: =(Sheet1!E20 - Sheet1!$B$34) / (Sheet1!$B$35 - Sheet1!$B$34) -> 0.11880219 | F20: =(Sheet1!F20 - Sheet1!$B$34) / (Sheet1!$B$35 - Sheet1!$B$34) -> 0.11281311 | G20: =(Sheet1!G20 - Sheet1!$B$34) / (Sheet1!$B$35 - Sheet1!$B$34) -> 0.10272341 | H20: =(Sheet1!H20 - Sheet1!$B$34) / (Sheet1!$B$35 - Sheet1!$B$34) -> 0.092148108 | I20: =(Sheet1!I20 - Sheet1!$B$34) / (Sheet1!$B$35 - Sheet1!$B$34) -> 0.073263641 | ... M20: =(Sheet1!M20 - Sheet1!$B$34) / (Sheet1!$B$35 - Sheet1!$B$34) -> 0.0397572 | P20: =IFERROR(__xludf.DUMMYFUNCTION("""COMPUTED_VALUE"""),0.10995346327645512) -> 0.10995346
A21: Reliance Industries Ltd | B21: =(Sheet1!B21 - Sheet1!$B$34) / (Sheet1!$B$35 - Sheet1!$B$34) -> 0.26637081 | C21: =(Sheet1!C21 - Sheet1!$B$34) / (Sheet1!$B$35 - Sheet1!$B$34) -> 0.54386457 | D21: =(Sheet1!D21 - Sheet1!$B$34) / (Sheet1!$B$35 - Sheet1!$B$34) -> 0.5206097 | E21: =(Sheet1!E21 - Sheet1!$B$34) / (Sheet1!$B$35 - Sheet1!$B$34) -> 0.47884805 | F21: =(Sheet1!F21 - Sheet1!$B$34) / (Sheet1!$B$35 - Sheet1!$B$34) -> 0.39446146 | G21: =(Sheet1!G21 - Sheet1!$B$34) / (Sheet1!$B$35 - Sheet1!$B$34) -> 0.32890538 | H21: =(Sheet1!H21 - Sheet1!$B$34) / (Sheet1!$B$35 - Sheet1!$B$34) -> 0.34908478 | I21: =(Sheet1!I21 - Sheet1!$B$34) / (Sheet1!$B$35 - Sheet1!$B$34) -> 0.31719701 | ... M21: =(Sheet1!M21 - Sheet1!$B$34) / (Sheet1!$B$35 - Sheet1!$B$34) -> 0.40169151 | P21: =IFERROR(__xludf.DUMMYFUNCTION("""COMPUTED_VALUE"""),0.10337087745329468) -> 0.10337088
A22: State Bank of India | B22: =(Sheet1!B22 - Sheet1!$B$34) / (Sheet1!$B$35 - Sheet1!$B$34) -> 0.45758953 | C22: =(Sheet1!C22 - Sheet1!$B$34) / (Sheet1!$B$35 - Sheet1!$B$34) -> 0.39424563 | D22: =(Sheet1!D22 - Sheet1!$B$34) / (Sheet1!$B$35 - Sheet1!$B$34) -> 0.32507453 | E22: =(Sheet1!E22 - Sheet1!$B$34) / (Sheet1!$B$35 - Sheet1!$B$34) -> 0.20254131 | F22: =(Sheet1!F22 - Sheet1!$B$34) / (Sheet1!$B$35 - Sheet1!$B$34) -> 0.12414379 | G22: =(Sheet1!G22 - Sheet1!$B$34) / (Sheet1!$B$35 - Sheet1!$B$34) -> 0.10817293 | H22: =(Sheet1!H22 - Sheet1!$B$34) / (Sheet1!$B$35 - Sheet1!$B$34) -> 0.0025817765 | I22: =(Sheet1!I22 - Sheet1!$B$34) / (Sheet1!$B$35 - Sheet1!$B$34) -> 0 | ... M22: =(Sheet1!M22 - Sheet1!$B$34) / (Sheet1!$B$35 - Sheet1!$B$34) -> 1 | P22: =IFERROR(__xludf.DUMMYFUNCTION("""COMPUTED_VALUE"""),0.09775949281715789) -> 0.097759493
A23: Sun Pharmaceutical Industries Ltd | B23: =(Sheet1!B23 - Sheet1!$B$34) / (Sheet1!$B$35 - Sheet1!$B$34) -> 0.23469886 | C23: =(Sheet1!C23 - Sheet1!$B$34) / (Sheet1!$B$35 - Sheet1!$B$34) -> 0.20394416 | D23: =(Sheet1!D23 - Sheet1!$B$34) / (Sheet1!$B$35 - Sheet1!$B$34) -> 0.17912457 | E23: =(Sheet1!E23 - Sheet1!$B$34) / (Sheet1!$B$35 - Sheet1!$B$34) -> 0.062040871 | F23: =(Sheet1!F23 - Sheet1!$B$34) / (Sheet1!$B$35 - Sheet1!$B$34) -> 0.053947528 | G23: =(Sheet1!G23 - Sheet1!$B$34) / (Sheet1!$B$35 - Sheet1!$B$34) -> 0.073371552 | H23: =(Sheet1!H23 - Sheet1!$B$34) / (Sheet1!$B$35 - Sheet1!$B$34) -> 0.048551966 | I23: =(Sheet1!I23 - Sheet1!$B$34) / (Sheet1!$B$35 - Sheet1!$B$34) -> 0.037221285 | ... M23: =(Sheet1!M23 - Sheet1!$B$34) / (Sheet1!$B$35 - Sheet1!$B$34) -> 0.070673771 | P23: =IFERROR(__xludf.DUMMYFUNCTION("""COMPUTED_VALUE"""),0.08680650165239091) -> 0.086806502
A24: Tata Motors Ltd | B24: =(Sheet1!B24 - Sheet1!$B$34) / (Sheet1!$B$35 - Sheet1!$B$34) -> 0.41356175 | C24: =(Sheet1!C24 - Sheet1!$B$34) / (Sheet1!$B$35 - Sheet1!$B$34) -> 0.43044985 | D24: =(Sheet1!D24 - Sheet1!$B$34) / (Sheet1!$B$35 - Sheet1!$B$34) -> 0.022599312 | E24: =(Sheet1!E24 - Sheet1!$B$34) / (Sheet1!$B$35 - Sheet1!$B$34) -> 0 | F24: =(Sheet1!F24 - Sheet1!$B$34) / (Sheet1!$B$35 - Sheet1!$B$34) -> 0 | G24: =(Sheet1!G24 - Sheet1!$B$34) / (Sheet1!$B$35 - Sheet1!$B$34) -> 0 | H24: =(Sheet1!H24 - Sheet1!$B$34) / (Sheet1!$B$35 - Sheet1!$B$34) -> 0 | I24: =(Sheet1!I24 - Sheet1!$B$34) / (Sheet1!$B$35 - Sheet1!$B$34) -> 0.13137384 | ... M24: =(Sheet1!M24 - Sheet1!$B$34) / (Sheet1!$B$35 - Sheet1!$B$34) -> 0.22336818 | P24: =IFERROR(__xludf.DUMMYFUNCTION("""COMPUTED_VALUE"""),0.06711269980441087) -> 0.0671127
A25: Tata Steel Ltd | B25: =(Sheet1!B25 - Sheet1!$B$34) / (Sheet1!$B$35 - Sheet1!$B$34) -> 0.0034450664 | C25: =(Sheet1!C25 - Sheet1!$B$34) / (Sheet1!$B$35 - Sheet1!$B$34) -> 0 | D25: =(Sheet1!D25 - Sheet1!$B$34) / (Sheet1!$B$35 - Sheet1!$B$34) -> 0.027347407 | E25: =(Sheet1!E25 - Sheet1!$B$34) / (Sheet1!$B$35 - Sheet1!$B$34) -> 1 | F25: =(Sheet1!F25 - Sheet1!$B$34) / (Sheet1!$B$35 - Sheet1!$B$34) -> 0.33279018 | G25: =(Sheet1!G25 - Sheet1!$B$34) / (Sheet1!$B$35 - Sheet1!$B$34) -> 0.052652593 | H25: =(Sheet1!H25 - Sheet1!$B$34) / (Sheet1!$B$35 - Sheet1!$B$34) -> 0.46206785 | I25: =(Sheet1!I25 - Sheet1!$B$34) / (Sheet1!$B$35 - Sheet1!$B$34) -> 0.67983274 | ... M25: =(Sheet1!M25 - Sheet1!$B$34) / (Sheet1!$B$35 - Sheet1!$B$34) -> 0.17853106 | P25: =IFERROR(__xludf.DUMMYFUNCTION("""COMPUTED_VALUE"""),0.0572388210696702) -> 0.057238821
A26: Tata Consultancy Services Ltd | B26: =(Sheet1!B26 - Sheet1!$B$34) / (Sheet1!$B$35 - Sheet1!$B$34) -> 0.71269171 | C26: =(Sheet1!C26 - Sheet1!$B$34) / (Sheet1!$B$35 - Sheet1!$B$34) -> 0.66785459 | D26: =(Sheet1!D26 - Sheet1!$B$34) / (Sheet1!$B$35 - Sheet1!$B$34) -> 0.61017603 | E26: =(Sheet1!E26 - Sheet1!$B$34) / (Sheet1!$B$35 - Sheet1!$B$34) -> 0.54774938 | F26: =(Sheet1!F26 - Sheet1!$B$34) / (Sheet1!$B$35 - Sheet1!$B$34) -> 0.45651042 | G26: =(Sheet1!G26 - Sheet1!$B$34) / (Sheet1!$B$35 - Sheet1!$B$34) -> 0.45370473 | H26: =(Sheet1!H26 - Sheet1!$B$34) / (Sheet1!$B$35 - Sheet1!$B$34) -> 0.43676266 | I26: =(Sheet1!I26 - Sheet1!$B$34) / (Sheet1!$B$35 - Sheet1!$B$34) -> 0.71269171 | ... M26: =(Sheet1!M26 - Sheet1!$B$34) / (Sheet1!$B$35 - Sheet1!$B$34) -> 0.51564578 | P26: =IFERROR(__xludf.DUMMYFUNCTION("""COMPUTED_VALUE"""),0.4752330208403589) -> 0.47523302
A27: Tech Mahindra Ltd | B27: =(Sheet1!B27 - Sheet1!$B$34) / (Sheet1!$B$35 - Sheet1!$B$34) -> 0.24716261 | C27: =(Sheet1!C27 - Sheet1!$B$34) / (Sheet1!$B$35 - Sheet1!$B$34) -> 0.13207527 | D27: =(Sheet1!D27 - Sheet1!$B$34) / (Sheet1!$B$35 - Sheet1!$B$34) -> 0.28412221 | E27: =(Sheet1!E27 - Sheet1!$B$34) / (Sheet1!$B$35 - Sheet1!$B$34) -> 0.32755648 | F27: =(Sheet1!F27 - Sheet1!$B$34) / (Sheet1!$B$35 - Sheet1!$B$34) -> 0.25946449 | G27: =(Sheet1!G27 - Sheet1!$B$34) / (Sheet1!$B$35 - Sheet1!$B$34) -> 0.23604775 | H27: =(Sheet1!H27 - Sheet1!$B$34) / (Sheet1!$B$35 - Sheet1!$B$34) -> 0.24613745 | I27: =(Sheet1!I27 - Sheet1!$B$34) / (Sheet1!$B$35 - Sheet1!$B$34) -> 0.21883591 | ... M27: =(Sheet1!M27 - Sheet1!$B$34) / (Sheet1!$B$35 - Sheet1!$B$34) -> 0.6727106 | P27: =IFERROR(__xludf.DUMMYFUNCTION("""COMPUTED_VALUE"""),0.44733796452417895) -> 0.44733796
A28: Titan Company Ltd | B28: =(Sheet1!B28 - Sheet1!$B$34) / (Sheet1!$B$35 - Sheet1!$B$34) -> 0.19158832 | C28: =(Sheet1!C28 - Sheet1!$B$34) / (Sheet1!$B$35 - Sheet1!$B$34) -> 0.20113846 | D28: =(Sheet1!D28 - Sheet1!$B$34) / (Sheet1!$B$35 - Sheet1!$B$34) -> 0.18619276 | E28: =(Sheet1!E28 - Sheet1!$B$34) / (Sheet1!$B$35 - Sheet1!$B$34) -> 0.12079854 | F28: =(Sheet1!F28 - Sheet1!$B$34) / (Sheet1!$B$35 - Sheet1!$B$34) -> 0.047796587 | G28: =(Sheet1!G28 - Sheet1!$B$34) / (Sheet1!$B$35 - Sheet1!$B$34) -> 0.079900182 | H28: =(Sheet1!H28 - Sheet1!$B$34) / (Sheet1!$B$35 - Sheet1!$B$34) -> 0.074019019 | I28: =(Sheet1!I28 - Sheet1!$B$34) / (Sheet1!$B$35 - Sheet1!$B$34) -> 0.057454644 | ... M28: =(Sheet1!M28 - Sheet1!$B$34) / (Sheet1!$B$35 - Sheet1!$B$34) -> 0.033336481 | P28: =IFERROR(__xludf.DUMMYFUNCTION("""COMPUTED_VALUE"""),0.17772172388210697) -> 0.17772172
A29: Trent Ltd | B29: =(Sheet1!B29 - Sheet1!$B$34) / (Sheet1!$B$35 - Sheet1!$B$34) -> 0.22342214 | C29: =(Sheet1!C29 - Sheet1!$B$34) / (Sheet1!$B$35 - Sheet1!$B$34) -> 0.21430364 | D29: =(Sheet1!D29 - Sheet1!$B$34) / (Sheet1!$B$35 - Sheet1!$B$34) -> 0.056159709 | E29: =(Sheet1!E29 - Sheet1!$B$34) / (Sheet1!$B$35 - Sheet1!$B$34) -> 0.0047400013 | F29: =(Sheet1!F29 - Sheet1!$B$34) / (Sheet1!$B$35 - Sheet1!$B$34) -> 0 | G29: =(Sheet1!G29 - Sheet1!$B$34) / (Sheet1!$B$35 - Sheet1!$B$34) -> 0.0077075605 | H29: =(Sheet1!H29 - Sheet1!$B$34) / (Sheet1!$B$35 - Sheet1!$B$34) -> 0.0044162676 | I29: =(Sheet1!I29 - Sheet1!$B$34) / (Sheet1!$B$35 - Sheet1!$B$34) -> 0.002797599 | ... M29: =(Sheet1!M29 - Sheet1!$B$34) / (Sheet1!$B$35 - Sheet1!$B$34) -> 0 | P29: =IFERROR(__xludf.DUMMYFUNCTION("""COMPUTED_VALUE"""),0.23637148445403655) -> 0.23637148
A30: UltraTech Cement Ltd | B30: =(Sheet1!B30 - Sheet1!$B$34) / (Sheet1!$B$35 - Sheet1!$B$34) -> 1 | C30: =(Sheet1!C30 - Sheet1!$B$34) / (Sheet1!$B$35 - Sheet1!$B$34) -> 1 | D30: =(Sheet1!D30 - Sheet1!$B$34) / (Sheet1!$B$35 - Sheet1!$B$34) -> 0.93579821 | E30: =(Sheet1!E30 - Sheet1!$B$34) / (Sheet1!$B$35 - Sheet1!$B$34) -> 1 | F30: =(Sheet1!F30 - Sheet1!$B$34) / (Sheet1!$B$35 - Sheet1!$B$34) -> 1 | G30: =(Sheet1!G30 - Sheet1!$B$34) / (Sheet1!$B$35 - Sheet1!$B$34) -> 1 | H30: =(Sheet1!H30 - Sheet1!$B$34) / (Sheet1!$B$35 - Sheet1!$B$34) -> 0.44188845 | I30: =(Sheet1!I30 - Sheet1!$B$34) / (Sheet1!$B$35 - Sheet1!$B$34) -> 0.42527012 | ... M30: =(Sheet1!M30 - Sheet1!$B$34) / (Sheet1!$B$35 - Sheet1!$B$34) -> 0.42257233 | P30: =IFERROR(__xludf.DUMMYFUNCTION("""COMPUTED_VALUE"""),0.11917987455318002) -> 0.11917987
P31: =IFERROR(__xludf.DUMMYFUNCTION("""COMPUTED_VALUE"""),0.02535104876239293) -> 0.025351049
P32: =IFERROR(__xludf.DUMMYFUNCTION("""COMPUTED_VALUE"""),0.09382073244756188) -> 0.093820732
P33: =IFERROR(__xludf.DUMMYFUNCTION("""COMPUTED_VALUE"""),0.0) -> 0
A34: Global min | B34: =MIN(B2:N30) -> 0 | P34: =IFERROR(__xludf.DUMMYFUNCTION("""COMPUTED_VALUE"""),0.07758009037566602) -> 0.07758009
A35: Global Max | B35: =MAX(B2:N30) -> 1 | P35: =IFERROR(__xludf.DUMMYFUNCTION("""COMPUTED_VALUE"""),0.1771282120455925) -> 0.17712821
P36: =IFERROR(__xludf.DUMMYFUNCTION("""COMPUTED_VALUE"""),0.1571646320901059) -> 0.15716463
P37: =IFERROR(__xludf.DUMMYFUNCTION("""COMPUTED_VALUE"""),0.7127456666891483) -> 0.71274567
P38: =IFERROR(__xludf.DUMMYFUNCTION("""COMPUTED_VALUE"""),0.040998178997774325) -> 0.040998179
P39: =IFERROR(__xludf.DUMMYFUNCTION("""COMPUTED_VALUE"""),0.02804882983745869) -> 0.02804883
P40: =IFERROR(__xludf.DUMMYFUNCTION("""COMPUTED_VALUE"""),0.013480812032103589) -> 0.013480812
...
